<?xml version="1.0" encoding="utf-8"?>
<!-- This URDF was automatically created by SolidWorks to URDF Exporter! Originally created by Stephen Brawner (brawner@gmail.com) 
     Commit Version: 1.6.0-1-g15f4949  Build Version: 1.6.7594.29634
     For more information, please see http://wiki.ros.org/sw_urdf_exporter -->
<robot
  name="refrigerator">

  <link name="world"/>
  <joint name="world_to_base" type="fixed">
    <origin rpy="0 0 0" xyz="0 0 0.0"/>
    <parent link="world"/>
    <child link="base_link"/>
  </joint>
  <link
    name="base_link">
    <inertial>
      <origin
        xyz="-2.04930455894181E-06 0.0743209398662041 0.857562191329433"
        rpy="0 0 0" />
      <mass
        value="321.768557939853" />
      <inertia
        ixx="132.329523767935"
        ixy="-6.6688813024119E-05"
        ixz="0.000264774473428559"
        iyy="144.617052489244"
        iyz="-0.0928755844266581"
        izz="56.8093789329973" />
    </inertial>
    <visual>
      <origin
        xyz="0 0 0"
        rpy="0 0 0" />
      <geometry>
        <mesh
          filename="package://./meshes/base_link.STL" />
      </geometry>
      <material
        name="">
        <color
          rgba="0.792156862745098 0.819607843137255 0.933333333333333 1" />
      </material>
    </visual>
    <collision>
      <origin
        xyz="0 0 0"
        rpy="0 0 0" />
      <geometry>
        <mesh
          filename="package://./meshes/base_link.STL" />
      </geometry>
    </collision>
  </link>
  <link
    name="link1">
    <inertial>
      <origin
        xyz="-0.437315475549018 -0.227483555418937 0.0466655012667492"
        rpy="0 0 0" />
      <mass
        value="13.5487719797606" />
      <inertia
        ixx="0.30969033637339"
        ixy="0.0081913103102789"
        ixz="0.000724794769395062"
        iyy="1.01547309903341"
        iyz="0.00453751652813097"
        izz="1.3183786230929" />
    </inertial>
    <visual>
      <origin
        xyz="0 0 0"
        rpy="0 0 0" />
      <geometry>
        <mesh
          filename="package://./meshes/link1.STL" />
      </geometry>
      <material
        name="">
        <color
          rgba="0.792156862745098 0.819607843137255 0.933333333333333 1" />
      </material>
    </visual>
    <collision>
      <origin
        xyz="0 0 0"
        rpy="0 0 0" />
      <geometry>
        <mesh
          filename="package://./meshes/link1.STL" />
      </geometry>
    </collision>
  </link>
  <joint
    name="joint1"
    type="revolute">
    <origin
      xyz="0.44196 -0.41021 1.7209"
      rpy="1.5708 0 0" />
    <parent
      link="base_link" />
    <child
      link="link1" />
    <axis
      xyz="0 -1 0" />
    <limit
      lower="-1.57"
      upper="0"
      effort="0"
      velocity="0.1" />
  </joint>
  <link
    name="link2">
    <inertial>
      <origin
        xyz="-0.442605450606532 0.582323634349984 0.0478440527208708"
        rpy="0 0 0" />
      <mass
        value="33.2046785590749" />
      <inertia
        ixx="4.61486880570621"
        ixy="-0.032585213170548"
        ixz="0.000798729372475132"
        iyy="2.54269026140779"
        iyz="-0.0241045122886815"
        izz="7.14311247121348" />
    </inertial>
    <visual>
      <origin
        xyz="0 0 0"
        rpy="0 0 0" />
      <geometry>
        <mesh
          filename="package://./meshes/link2.STL" />
      </geometry>
      <material
        name="">
        <color
          rgba="0.792156862745098 0.819607843137255 0.933333333333333 1" />
      </material>
    </visual>
    <collision>
      <origin
        xyz="0 0 0"
        rpy="0 0 0" />
      <geometry>
        <mesh
          filename="package://./meshes/link2.STL" />
      </geometry>
    </collision>
  </link>
  <joint
    name="joint2"
    type="revolute">
    <origin
      xyz="0.4445 -0.41021 0.00254"
      rpy="1.5708 0 0" />
    <parent
      link="base_link" />
    <child
      link="link2" />
    <axis
      xyz="0 -1 0" />
    <limit
      lower="-1.57"
      upper="0"
      effort="0"
      velocity="0" />
  </joint>
</robot>
