<?xml version="1.0" encoding="utf-8"?>
<!-- This URDF was automatically created by SolidWorks to URDF Exporter! Originally created by Stephen Brawner (brawner@gmail.com) 
     Commit Version: 1.6.0-1-g15f4949  Build Version: 1.6.7594.29634
     For more information, please see http://wiki.ros.org/sw_urdf_exporter -->
<robot name="rml_63_description" xmlns:xacro="http://www.ros.org/wiki/xacro">
<xacro:include filename="$(find rm_description)/urdf/RML63/rml_63.transmission.xacro"/>
<xacro:include filename="$(find rm_description)/urdf/RML63/rml_63.gazebo.xacro"/>
<!-- Inertial matrix -->
<xacro:macro name="inertial_matrix" params="mass">
<inertial>
    <mass value="${mass}" />
    <inertia ixx="1.0" ixy="0.0" ixz="0.0" iyy="0.5" iyz="0.0" izz="1.0" />
</inertial>
</xacro:macro>
 <xacro:macro name="Box_inertial_matrix" params="m l w h">
       <inertial>
               <mass value="${m}" />
               <inertia ixx="${m*(h*h + l*l)/12}" ixy = "0" ixz = "0"
                   iyy="${m*(w*w + l*l)/12}" iyz= "0"
                   izz="${m*(w*w + h*h)/12}" />
       </inertial>
  </xacro:macro>
    <link name="dummy">
    </link>
    <joint name="dummy_joint" type="fixed">
    <origin xyz="0 0 0" rpy="0 0 3.14" />
      <parent link="dummy" />
      <child link="base_link" />
    </joint>
    <!-- ///////////////////////////////////////   bottom_joint   ////////////////////////////////////////// -->
    <joint name="bottom_joint" type="fixed">
        <origin xyz="0 0 0" rpy="0 0 0" />
        <parent link="base_link"/>
        <child link="bottom_link"/>
    </joint>
    <link name="bottom_link">
        <visual>
              <origin xyz=" 0 0 -0.02"  rpy="0 0 0"/>
                  <geometry>
                       <box size="0.06 0.06 0.02" />
                  </geometry>
              <material name="Brown" />
        </visual>
        <collision>
            <origin xyz=" 0 0 -0.02"  rpy="0 0 0"/>
            <geometry>
                <box size="0.06 0.06 0.02" />
            </geometry>
        </collision>
        <xacro:Box_inertial_matrix m="500" l="1" w="1" h="0.02"/>
    </link>
  <link
    name="base_link">
    <inertial>
      <origin
        xyz="0.0014231 -0.00010178 0.050147"
        rpy="0 0 0" />
      <mass
        value="0.66171" />
      <inertia
        ixx="0.00099443"
        ixy="3.282E-06"
        ixz="-9.9964E-06"
        iyy="0.0010144"
        iyz="1.2811E-06"
        izz="0.00067929" />
    </inertial>
    <visual>
      <origin
        xyz="0 0 0"
        rpy="0 0 0" />
      <geometry>
        <mesh
          filename="package://rm_description/meshes/RML63/base_link.STL" />
      </geometry>
      <material
        name="">
        <color
          rgba="1 1 1 1" />
      </material>
    </visual>
    <collision>
      <origin
        xyz="0 0 0"
        rpy="0 0 0" />
      <geometry>
        <mesh
          filename="package://rm_description/meshes/RML63/base_link.STL" />
      </geometry>
    </collision>
  </link>
  <link
    name="link1">
    <inertial>
      <origin
        xyz="-0.043281 -0.0072256 -0.012694"
        rpy="0 0 0" />
      <mass
        value="0.89496" />
      <inertia
        ixx="0.0010156"
        ixy="-0.00026764"
        ixz="0.00045014"
        iyy="0.0024107"
        iyz="6.0996E-05"
        izz="0.0022755" />
    </inertial>
    <visual>
      <origin
        xyz="0 0 0"
        rpy="0 0 0" />
      <geometry>
        <mesh
          filename="package://rm_description/meshes/RML63/link1.STL" />
      </geometry>
      <material
        name="">
        <color
          rgba="1 1 1 1" />
      </material>
    </visual>
    <collision>
      <origin
        xyz="0 0 0"
        rpy="0 0 0" />
      <geometry>
        <mesh
          filename="package://rm_description/meshes/RML63/link1.STL" />
      </geometry>
    </collision>
  </link>
  <joint
    name="joint1"
    type="revolute">
    <origin
      xyz="0 0 0.172"
      rpy="0 0 0" />
    <parent
      link="base_link" />
    <child
      link="link1" />
    <axis
      xyz="0 0 1" />
    <limit
      lower="-3.106"
      upper="3.106"
      effort="100"
      velocity="1" />
    <dynamics
      damping="50"
      friction="1" />
  </joint>
  <link
    name="link2">
    <inertial>
      <origin
        xyz="0.17388 3.639E-07 -0.089966"
        rpy="0 0 0" />
      <mass
        value="1.5679" />
      <inertia
        ixx="0.0010615"
        ixy="-7.3371E-08"
        ixz="-0.00025488"
        iyy="0.03035"
        iyz="-1.6148E-08"
        izz="0.030485" />
    </inertial>
    <visual>
      <origin
        xyz="0 0 0"
        rpy="0 0 0" />
      <geometry>
        <mesh
          filename="package://rm_description/meshes/RML63/link2.STL" />
      </geometry>
      <material
        name="">
        <color
          rgba="1 1 1 1" />
      </material>
    </visual>
    <collision>
      <origin
        xyz="0 0 0"
        rpy="0 0 0" />
      <geometry>
        <mesh
          filename="package://rm_description/meshes/RML63/link2.STL" />
      </geometry>
    </collision>
  </link>
  <joint
    name="joint2"
    type="revolute">
    <origin
      xyz="-0.086 0 0"
      rpy="0 -1.5708 -1.5708" />
    <parent
      link="link1" />
    <child
      link="link2" />
    <axis
      xyz="0 0 1" />
    <limit
      lower="-3.106"
      upper="3.106"
      effort="100"
      velocity="1" />
    <dynamics
      damping="50"
      friction="1" />
  </joint>
  <link
    name="link3">
    <inertial>
      <origin
        xyz="0.035968 -0.020568 -0.0048526"
        rpy="0 0 0" />
      <mass
        value="0.67539" />
      <inertia
        ixx="0.00091144"
        ixy="0.00043238"
        ixz="-0.0001205"
        iyy="0.0012128"
        iyz="6.6376E-05"
        izz="0.0015231" />
    </inertial>
    <visual>
      <origin
        xyz="0 0 0"
        rpy="0 0 0" />
      <geometry>
        <mesh
          filename="package://rm_description/meshes/RML63/link3.STL" />
      </geometry>
      <material
        name="">
        <color
          rgba="1 1 1 1" />
      </material>
    </visual>
    <collision>
      <origin
        xyz="0 0 0"
        rpy="0 0 0" />
      <geometry>
        <mesh
          filename="package://rm_description/meshes/RML63/link3.STL" />
      </geometry>
    </collision>
  </link>
  <joint
    name="joint3"
    type="revolute">
    <origin
      xyz="0.38 0 -0.00030011"
      rpy="0 0 1.5708" />
    <parent
      link="link2" />
    <child
      link="link3" />
    <axis
      xyz="0 0 1" />
    <limit
      lower="-3.106"
      upper="2.53"
      effort="100"
      velocity="1" />
    <dynamics
      damping="50"
      friction="1" />
  </joint>
  <link
    name="link4">
    <inertial>
      <origin
        xyz="-2.0098E-06 -0.033559 -0.18296"
        rpy="0 0 0" />
      <mass
        value="0.69687" />
      <inertia
        ixx="0.0085449"
        ixy="4.7796E-08"
        ixz="-1.0943E-08"
        iyy="0.0080043"
        iyz="0.0020032"
        izz="0.00084216" />
    </inertial>
    <visual>
      <origin
        xyz="0 0 0"
        rpy="0 0 0" />
      <geometry>
        <mesh
          filename="package://rm_description/meshes/RML63/link4.STL" />
      </geometry>
      <material
        name="">
        <color
          rgba="1 1 1 1" />
      </material>
    </visual>
    <collision>
      <origin
        xyz="0 0 0"
        rpy="0 0 0" />
      <geometry>
        <mesh
          filename="package://rm_description/meshes/RML63/link4.STL" />
      </geometry>
    </collision>
  </link>
  <joint
    name="joint4"
    type="revolute">
    <origin
      xyz="0.069 -0.405 0.00029958"
      rpy="1.5708 0 0" />
    <parent
      link="link3" />
    <child
      link="link4" />
    <axis
      xyz="0 0 1" />
    <limit
      lower="-3.106"
      upper="3.106"
      effort="100"
      velocity="1" />
    <dynamics
      damping="50"
      friction="1" />
  </joint>
  <link
    name="link5">
    <inertial>
      <origin
        xyz="-1.5679E-07 0.02862 -0.0062118"
        rpy="0 0 0" />
      <mass
        value="0.34759" />
      <inertia
        ixx="0.00049457"
        ixy="-1.0235E-08"
        ixz="-1.8949E-09"
        iyy="0.00019706"
        iyz="-6.3439E-05"
        izz="0.00044565" />
    </inertial>
    <visual>
      <origin
        xyz="0 0 0"
        rpy="0 0 0" />
      <geometry>
        <mesh
          filename="package://rm_description/meshes/RML63/link5.STL" />
      </geometry>
      <material
        name="">
        <color
          rgba="1 1 1 1" />
      </material>
    </visual>
    <collision>
      <origin
        xyz="0 0 0"
        rpy="0 0 0" />
      <geometry>
        <mesh
          filename="package://rm_description/meshes/RML63/link5.STL" />
      </geometry>
    </collision>
  </link>
  <joint
    name="joint5"
    type="revolute">
    <origin
      xyz="0 0 0"
      rpy="1.5708 0 3.1416" />
    <parent
      link="link4" />
    <child
      link="link5" />
    <axis
      xyz="0 0 1" />
    <limit
      lower="-3.106"
      upper="3.106"
      effort="100"
      velocity="1" />
    <dynamics
      damping="50"
      friction="1" />
  </joint>
  <link
    name="link6">
    <inertial>
      <origin
        xyz="-0.0006163 0.00034085 -0.01449"
        rpy="0 0 0" />
      <mass
        value="0.077104" />
      <inertia
        ixx="2.2947E-05"
        ixy="-1.3061E-06"
        ixz="1.1202E-07"
        iyy="2.1475E-05"
        iyz="-5.1151E-08"
        izz="3.4243E-05" />
    </inertial>
    <visual>
      <origin
        xyz="0 0 0"
        rpy="0 0 0" />
      <geometry>
        <mesh
          filename="package://rm_description/meshes/RML63/link6.STL" />
      </geometry>
      <material
        name="">
        <color
          rgba="1 1 1 1" />
      </material>
    </visual>
    <collision>
      <origin
        xyz="0 0 0"
        rpy="0 0 0" />
      <geometry>
        <mesh
          filename="package://rm_description/meshes/RML63/link6.STL" />
      </geometry>
    </collision>
  </link>
  <joint
    name="joint6"
    type="revolute">
    <origin
      xyz="0 0.115 0"
      rpy="1.5708 0 3.1416" />
    <parent
      link="link5" />
    <child
      link="link6" />
    <axis
      xyz="0 0 1" />
    <limit
      lower="-6.28"
      upper="6.28"
      effort="100"
      velocity="1" />
    <dynamics
      damping="50"
      friction="1" />
  </joint>
  
    <!-- Transmissions for ROS Control -->
    <xacro:macro name="transmission_block" params="joint_name">
        <transmission name="tran1">
            <type>transmission_interface/SimpleTransmission</type>
            <joint name="${joint_name}">
                <hardwareInterface>hardware_interface/PositionJointInterface</hardwareInterface>
            </joint>
            <actuator name="motor1">
                <hardwareInterface>hardware_interface/PositionJointInterface</hardwareInterface>
                <mechanicalReduction>1</mechanicalReduction>
            </actuator>
        </transmission>
    </xacro:macro>
    
    <xacro:transmission_block joint_name="joint1"/>
    <xacro:transmission_block joint_name="joint2"/>
    <xacro:transmission_block joint_name="joint3"/>
    <xacro:transmission_block joint_name="joint4"/>
    <xacro:transmission_block joint_name="joint5"/>
    <xacro:transmission_block joint_name="joint6"/>

    <!-- ros_control plugin -->
    <gazebo>
        <plugin name="gazebo_ros_control" filename="libgazebo_ros_control.so">
            <robotNamespace>/arm</robotNamespace>
            <robotSimType>gazebo_ros_control/DefaultRobotHWSim</robotSimType>
            <legacyModeNS>true</legacyModeNS>
        </plugin>
    </gazebo>
</robot>
