<?xml version="1.0" ?>
<robot name="partnet_bf349aa23fd3b57387f1f5120cc1f">
	<link name="base"/>
	<link name="link_0">
		<visual name="wheel-1">
			<origin xyz="0 0.15917912604514112 -0.669895647000993"/>
			<geometry>
				<mesh filename="textured_objs/original-21.obj"/>
			</geometry>
		</visual>
		<collision>
			<origin xyz="0 0.15917912604514112 -0.669895647000993"/>
			<geometry>
				<mesh filename="textured_objs/original-21.obj"/>
			</geometry>
		</collision>
	</link>
	<joint name="joint_0" type="continuous">
		<origin xyz="0 -0.15917912604514112 0.669895647000993"/>
		<axis xyz="1 0 0"/>
		<child link="link_0"/>
		<parent link="link_4"/>
	</joint>
	<link name="link_1">
		<visual name="wheel-2">
			<origin xyz="0 0.15917912604514112 0.385582352999007"/>
			<geometry>
				<mesh filename="textured_objs/original-16.obj"/>
			</geometry>
		</visual>
		<collision>
			<origin xyz="0 0.15917912604514112 0.385582352999007"/>
			<geometry>
				<mesh filename="textured_objs/original-16.obj"/>
			</geometry>
		</collision>
	</link>
	<joint name="joint_1" type="continuous">
		<origin xyz="0 -0.15917912604514112 -0.385582352999007"/>
		<axis xyz="1 0 0"/>
		<child link="link_1"/>
		<parent link="link_4"/>
	</joint>
	<link name="link_2">
		<visual name="wheel-3">
			<origin xyz="0 0.15917960865102374 -0.6704898479005268"/>
			<geometry>
				<mesh filename="textured_objs/original-11.obj"/>
			</geometry>
		</visual>
		<collision>
			<origin xyz="0 0.15917960865102374 -0.6704898479005268"/>
			<geometry>
				<mesh filename="textured_objs/original-11.obj"/>
			</geometry>
		</collision>
	</link>
	<joint name="joint_2" type="continuous">
		<origin xyz="0 -0.15917960865102374 0.6704898479005268"/>
		<axis xyz="-1 0 0"/>
		<child link="link_2"/>
		<parent link="link_4"/>
	</joint>
	<link name="link_3">
		<visual name="wheel-4">
			<origin xyz="0 0.15917960865102374 0.3849881520994733"/>
			<geometry>
				<mesh filename="textured_objs/original-6.obj"/>
			</geometry>
		</visual>
		<collision>
			<origin xyz="0 0.15917960865102374 0.3849881520994733"/>
			<geometry>
				<mesh filename="textured_objs/original-6.obj"/>
			</geometry>
		</collision>
	</link>
	<joint name="joint_3" type="continuous">
		<origin xyz="0 -0.15917960865102374 -0.3849881520994733"/>
		<axis xyz="1 0 0"/>
		<child link="link_3"/>
		<parent link="link_4"/>
	</joint>
	<link name="link_4">
		<visual name="yoke-12">
			<origin xyz="0 0 0"/>
			<geometry>
				<mesh filename="textured_objs/original-5.obj"/>
			</geometry>
		</visual>
		<visual name="yoke-12">
			<origin xyz="0 0 0"/>
			<geometry>
				<mesh filename="textured_objs/original-4.obj"/>
			</geometry>
		</visual>
		<visual name="yoke-12">
			<origin xyz="0 0 0"/>
			<geometry>
				<mesh filename="textured_objs/original-3.obj"/>
			</geometry>
		</visual>
		<visual name="yoke-11">
			<origin xyz="0 0 0"/>
			<geometry>
				<mesh filename="textured_objs/original-14.obj"/>
			</geometry>
		</visual>
		<visual name="yoke-11">
			<origin xyz="0 0 0"/>
			<geometry>
				<mesh filename="textured_objs/original-13.obj"/>
			</geometry>
		</visual>
		<visual name="yoke-11">
			<origin xyz="0 0 0"/>
			<geometry>
				<mesh filename="textured_objs/original-15.obj"/>
			</geometry>
		</visual>
		<visual name="yoke-10">
			<origin xyz="0 0 0"/>
			<geometry>
				<mesh filename="textured_objs/original-20.obj"/>
			</geometry>
		</visual>
		<visual name="yoke-10">
			<origin xyz="0 0 0"/>
			<geometry>
				<mesh filename="textured_objs/original-19.obj"/>
			</geometry>
		</visual>
		<visual name="yoke-10">
			<origin xyz="0 0 0"/>
			<geometry>
				<mesh filename="textured_objs/original-18.obj"/>
			</geometry>
		</visual>
		<visual name="yoke-9">
			<origin xyz="0 0 0"/>
			<geometry>
				<mesh filename="textured_objs/original-8.obj"/>
			</geometry>
		</visual>
		<visual name="yoke-9">
			<origin xyz="0 0 0"/>
			<geometry>
				<mesh filename="textured_objs/original-9.obj"/>
			</geometry>
		</visual>
		<visual name="yoke-9">
			<origin xyz="0 0 0"/>
			<geometry>
				<mesh filename="textured_objs/original-10.obj"/>
			</geometry>
		</visual>
		<visual name="base_body-13">
			<origin xyz="0 0 0"/>
			<geometry>
				<mesh filename="textured_objs/original-22.obj"/>
			</geometry>
		</visual>
		<visual name="base_body-13">
			<origin xyz="0 0 0"/>
			<geometry>
				<mesh filename="textured_objs/original-1.obj"/>
			</geometry>
		</visual>
		<collision>
			<origin xyz="0 0 0"/>
			<geometry>
				<mesh filename="textured_objs/original-5.obj"/>
			</geometry>
		</collision>
		<collision>
			<origin xyz="0 0 0"/>
			<geometry>
				<mesh filename="textured_objs/original-4.obj"/>
			</geometry>
		</collision>
		<collision>
			<origin xyz="0 0 0"/>
			<geometry>
				<mesh filename="textured_objs/original-3.obj"/>
			</geometry>
		</collision>
		<collision>
			<origin xyz="0 0 0"/>
			<geometry>
				<mesh filename="textured_objs/original-14.obj"/>
			</geometry>
		</collision>
		<collision>
			<origin xyz="0 0 0"/>
			<geometry>
				<mesh filename="textured_objs/original-13.obj"/>
			</geometry>
		</collision>
		<collision>
			<origin xyz="0 0 0"/>
			<geometry>
				<mesh filename="textured_objs/original-15.obj"/>
			</geometry>
		</collision>
		<collision>
			<origin xyz="0 0 0"/>
			<geometry>
				<mesh filename="textured_objs/original-20.obj"/>
			</geometry>
		</collision>
		<collision>
			<origin xyz="0 0 0"/>
			<geometry>
				<mesh filename="textured_objs/original-19.obj"/>
			</geometry>
		</collision>
		<collision>
			<origin xyz="0 0 0"/>
			<geometry>
				<mesh filename="textured_objs/original-18.obj"/>
			</geometry>
		</collision>
		<collision>
			<origin xyz="0 0 0"/>
			<geometry>
				<mesh filename="textured_objs/original-8.obj"/>
			</geometry>
		</collision>
		<collision>
			<origin xyz="0 0 0"/>
			<geometry>
				<mesh filename="textured_objs/original-9.obj"/>
			</geometry>
		</collision>
		<collision>
			<origin xyz="0 0 0"/>
			<geometry>
				<mesh filename="textured_objs/original-10.obj"/>
			</geometry>
		</collision>
		<collision>
			<origin xyz="0 0 0"/>
			<geometry>
				<mesh filename="textured_objs/original-22.obj"/>
			</geometry>
		</collision>
		<collision>
			<origin xyz="0 0 0"/>
			<geometry>
				<mesh filename="textured_objs/original-1.obj"/>
			</geometry>
		</collision>
	</link>
	<joint name="joint_4" type="fixed">
		<origin rpy="1.570796326794897 0 -1.570796326794897" xyz="0 0 0"/>
		<child link="link_4"/>
		<parent link="base"/>
	</joint>
</robot>
