<?xml version="1.0" ?>
<!-- =================================================================================== -->
<!-- |    This document was autogenerated by xacro from /home/agilex/agilex_ws/src/moveit_config/cobot_description/urdf/cobot_description.urdf.xacro | -->
<!-- |    EDITING THIS FILE BY HAND IS NOT RECOMMENDED                                 | -->
<!-- =================================================================================== -->
<!-- This URDF was automatically created by SolidWorks to URDF Exporter! Originally created by Stephen Brawner (brawner@gmail.com) 
     Commit Version: 1.6.0-1-g15f4949  Build Version: 1.6.7594.29634
     For more information, please see http://wiki.ros.org/sw_urdf_exporter -->
<robot name="cobot_description">
    <link name="dh_robotics_ag95_base_link">
        <inertial>
            <origin rpy="0 0 0" xyz="0 0 0" />
            <mass value="0.22652" />
            <inertia ixx="0.00020005" ixy="-4.2442E-10" ixz="-2.9069E-10" iyy="0.00017832" iyz="-3.4402E-08" izz="0.00013478" />
        </inertial>
        <visual>
            <origin rpy="0 0 0" xyz="0 0 0" />
            <geometry>
                <mesh filename="package://dh_robotics_ag95_model/meshes/base_link.STL" scale="1 1 1" />
            </geometry>
            <material name="">
                <color rgba="0.1 0.1 0.1 1" />
            </material>
        </visual>
        <collision>
            <origin rpy="0 0 0" xyz="0 0 0" />
            <geometry>
                <mesh filename="package://dh_robotics_ag95_model/meshes/base_link.STL" />
            </geometry>
        </collision>
    </link>
    <link name="left_crank">
        <inertial>
            <origin rpy="0 0 0" xyz="-0.000200000000003065 0.0199435877845359 0.0292245259211331" />
            <mass value="0.00853198276973456" />
            <inertia ixx="2.89328108496468E-06" ixy="-1.57935047237397E-19" ixz="-1.93980378593255E-19" iyy="1.86719750325683E-06" iyz="-1.21858577871576E-06" izz="1.21905238907251E-06" />
        </inertial>
        <visual>
            <origin rpy="0 0 0" xyz="0 0 0" />
            <geometry>
                <mesh filename="package://dh_robotics_ag95_model/meshes/link_crank.STL" scale="1 1 1" />
            </geometry>
            <material name="">
                <color rgba="0.1 0.1 0.1 1" />
            </material>
        </visual>
        <collision>
            <origin rpy="0 0 0" xyz="0 0 0" />
            <geometry>
                <mesh filename="package://dh_robotics_ag95_model/meshes/link_crank.STL" scale="1 1 1" />
            </geometry>
        </collision>
    </link>
    <link name="left_rod">
        <inertial>
            <origin rpy="0 0 0" xyz="0.00030115855001899 0.0373907951953854 -0.0208027427000385" />
            <mass value="0.022614240507152" />
            <inertia ixx="1.52518312458174E-05" ixy="9.76583423954399E-10" ixz="-5.43838577022588E-10" iyy="6.17694243867776E-06" iyz="6.78636130740228E-06" izz="1.16494917907219E-05" />
        </inertial>
        <visual>
            <origin rpy="0 0 0" xyz="0 0 0" />
            <geometry>
                <mesh filename="package://dh_robotics_ag95_model/meshes/link_rod.STL" scale="1 1 1" />
            </geometry>
            <material name="">
                <color rgba="0.1 0.1 0.1 1" />
            </material>
        </visual>
        <collision>
            <origin rpy="0 0 0" xyz="0 0 0" />
            <geometry>
                <mesh filename="package://dh_robotics_ag95_model/meshes/link_rod.STL" scale="1 1 1" />
            </geometry>
        </collision>
    </link>
    <link name="left_distal_phalanx">
        <inertial>
            <origin rpy="0 0 0" xyz="0.000299999999999317 0.0160078233491243 -0.0136945669206257" />
            <mass value="0.0104003125914103" />
            <inertia ixx="2.71909453810972E-06" ixy="1.35402465472579E-21" ixz="-7.1817349065269E-22" iyy="7.69100314106116E-07" iyz="6.74715432769696E-07" izz="2.30315190420171E-06" />
        </inertial>
        <visual>
            <origin rpy="0 0 0" xyz="0 0 0" />
            <geometry>
                <mesh filename="package://dh_robotics_ag95_model/meshes/link_distal_phalanx.STL" scale="1 1 1" />
            </geometry>
            <material name="">
                <color rgba="0.792156862745098 0.819607843137255 0.933333333333333 1" />
            </material>
        </visual>
        <collision>
            <origin rpy="0 0 0" xyz="0 0 0" />
            <geometry>
                <mesh filename="package://dh_robotics_ag95_model/meshes/link_distal_phalanx.STL" scale="1 1 1" />
            </geometry>
        </collision>
    </link>
    <link name="left_proximal_phalanx">
        <inertial>
            <origin rpy="0 0 0" xyz="0.000123011831763771 0.0507850843201817 0.00103968640075166" />
            <mass value="0.0271177346495152" />
            <inertia ixx="2.61910379223783E-05" ixy="-2.43616858946494E-07" ixz="-6.37789906117123E-09" iyy="2.8270243746167E-06" iyz="-5.37200748039765E-07" izz="2.83695868220296E-05" />
        </inertial>
        <visual>
            <origin rpy="0 0 0" xyz="0 0 0" />
            <geometry>
                <mesh filename="package://dh_robotics_ag95_model/meshes/link_proximal_phalanx.STL" scale="1 1 1" />
            </geometry>
            <material name="">
                <color rgba="0.1 0.1 0.1 1" />
            </material>
        </visual>
        <collision>
            <origin rpy="0 0 0" xyz="0 0 0" />
            <geometry>
                <mesh filename="package://dh_robotics_ag95_model/meshes/link_proximal_phalanx.STL" scale="1 1 1" />
            </geometry>
        </collision>
    </link>
    <link name="right_crank">
        <inertial>
            <origin rpy="0 0 0" xyz="-0.000200000000003065 0.0199435877845359 0.0292245259211331" />
            <mass value="0.00853198276973456" />
            <inertia ixx="2.89328108496468E-06" ixy="-1.57935047237397E-19" ixz="-1.93980378593255E-19" iyy="1.86719750325683E-06" iyz="-1.21858577871576E-06" izz="1.21905238907251E-06" />
        </inertial>
        <visual>
            <origin rpy="0 0 0" xyz="0 0 0" />
            <geometry>
                <mesh filename="package://dh_robotics_ag95_model/meshes/link_crank.STL" scale="1 1 1" />
            </geometry>
            <material name="">
                <color rgba="0.1 0.1 0.1 1" />
            </material>
        </visual>
        <collision>
            <origin rpy="0 0 0" xyz="0 0 0" />
            <geometry>
                <mesh filename="package://dh_robotics_ag95_model/meshes/link_crank.STL" scale="1 1 1" />
            </geometry>
        </collision>
    </link>
    <link name="right_rod">
        <inertial>
            <origin rpy="0 0 0" xyz="0.00030115855001899 0.0373907951953854 -0.0208027427000385" />
            <mass value="0.022614240507152" />
            <inertia ixx="1.52518312458174E-05" ixy="9.76583423954399E-10" ixz="-5.43838577022588E-10" iyy="6.17694243867776E-06" iyz="6.78636130740228E-06" izz="1.16494917907219E-05" />
        </inertial>
        <visual>
            <origin rpy="0 0 0" xyz="0 0 0" />
            <geometry>
                <mesh filename="package://dh_robotics_ag95_model/meshes/link_rod.STL" scale="1 1 1" />
            </geometry>
            <material name="">
                <color rgba="0.1 0.1 0.1 1" />
            </material>
        </visual>
        <collision>
            <origin rpy="0 0 0" xyz="0 0 0" />
            <geometry>
                <mesh filename="package://dh_robotics_ag95_model/meshes/link_rod.STL" scale="1 1 1" />
            </geometry>
        </collision>
    </link>
    <link name="right_distal_phalanx">
        <inertial>
            <origin rpy="0 0 0" xyz="0.000299999999999317 0.0160078233491243 -0.0136945669206257" />
            <mass value="0.0104003125914103" />
            <inertia ixx="2.71909453810972E-06" ixy="1.35402465472579E-21" ixz="-7.1817349065269E-22" iyy="7.69100314106116E-07" iyz="6.74715432769696E-07" izz="2.30315190420171E-06" />
        </inertial>
        <visual>
            <origin rpy="0 0 0" xyz="0 0 0" />
            <geometry>
                <mesh filename="package://dh_robotics_ag95_model/meshes/link_distal_phalanx.STL" scale="1 1 1" />
            </geometry>
            <material name="">
                <color rgba="0.792156862745098 0.819607843137255 0.933333333333333 1" />
            </material>
        </visual>
        <collision>
            <origin rpy="0 0 0" xyz="0 0 0" />
            <geometry>
                <mesh filename="package://dh_robotics_ag95_model/meshes/link_distal_phalanx.STL" scale="1 1 1" />
            </geometry>
        </collision>
    </link>
    <link name="right_proximal_phalanx">
        <inertial>
            <origin rpy="0 0 0" xyz="0.000123011831763771 0.0507850843201817 0.00103968640075166" />
            <mass value="0.0271177346495152" />
            <inertia ixx="2.61910379223783E-05" ixy="-2.43616858946494E-07" ixz="-6.37789906117123E-09" iyy="2.8270243746167E-06" iyz="-5.37200748039765E-07" izz="2.83695868220296E-05" />
        </inertial>
        <visual>
            <origin rpy="0 0 0" xyz="0 0 0" />
            <geometry>
                <mesh filename="package://dh_robotics_ag95_model/meshes/link_proximal_phalanx.STL" scale="1 1 1" />
            </geometry>
            <material name="">
                <color rgba="0.1 0.1 0.1 1" />
            </material>
        </visual>
        <collision>
            <origin rpy="0 0 0" xyz="0 0 0" />
            <geometry>
                <mesh filename="package://dh_robotics_ag95_model/meshes/link_proximal_phalanx.STL" scale="1 1 1" />
            </geometry>
        </collision>
    </link>
    <joint name="finger_joint" type="revolute">
        <origin rpy="-0.6523  0 0 " xyz="0 0.016 0.10586 " />
        <parent link="dh_robotics_ag95_base_link" />
        <child link="left_crank" />
        <axis xyz="1 0 0" />
        <limit effort="1000" lower="0" upper="0.6524" velocity="1.0" />
    </joint>
    <joint name="left_rod_joint" type="revolute">
        <origin rpy="0.29795 0 0" xyz="0 0.037 0" />
        <parent link="left_crank" />
        <child link="left_rod" />
        <axis xyz="1 0 0" />
        <limit effort="1000" lower="-1" upper="0" velocity="1.0" />
        <mimic joint="finger_joint" multiplier="0.4563942" offset="0" />
    </joint>
    <joint name="left_proximal_phalanx_joint" type="revolute">
        <origin rpy="-0.801 0 0.0" xyz="0 0.016 0.10586" />
        --&gt;
        <parent link="dh_robotics_ag95_base_link" />
        <child link="left_proximal_phalanx" />
        <axis xyz="1 0 0" />
        <limit effort="1000" lower="0" upper="0.8757" velocity="1.0" />
        <mimic joint="finger_joint" multiplier="1.451855" offset="0" />
    </joint>
    <joint name="left_distal_phalanx_joint" type="revolute">
        <origin rpy="0.0132645 0 0" xyz="0 0 0.06083" />
        <parent link="left_rod" />
        <child link="left_distal_phalanx" />
        <axis xyz="1 0 0" />
        <limit effort="1000" lower="-1" upper="0" velocity="1.0" />
        <mimic joint="finger_joint" multiplier="-1.4563851" offset="0" />
    </joint>
    <joint name="right_crank_joint" type="revolute">
        <origin rpy="-0.6523  0 3.141592653589793 " xyz="0 -0.016 0.10586 " />
        <parent link="dh_robotics_ag95_base_link" />
        <child link="right_crank" />
        <axis xyz="1 0 0" />
        <limit effort="1000" lower="0" upper="0.6524" velocity="1.0" />
        <mimic joint="finger_joint" multiplier="1" offset="0" />
    </joint>
    <joint name="right_rod_joint" type="revolute">
        <origin rpy="0.29795 0 0" xyz="0 0.037 0" />
        <parent link="right_crank" />
        <child link="right_rod" />
        <axis xyz="1 0 0" />
        <limit effort="1000" lower="-1" upper="0" velocity="1.0" />
        <mimic joint="finger_joint" multiplier="0.4563942" offset="0" />
    </joint>
    <joint name="right_proximal_phalanx_joint" type="revolute">
        <origin rpy="-0.801 0 3.141592653589793" xyz="0 -0.016 0.10586" />
        --&gt;
        <parent link="dh_robotics_ag95_base_link" />
        <child link="right_proximal_phalanx" />
        <axis xyz="1 0 0" />
        <limit effort="1000" lower="0" upper="0.8757" velocity="1.0" />
        <mimic joint="finger_joint" multiplier="1.451855" offset="0" />
    </joint>
    <joint name="right_distal_phalanx_joint" type="revolute">
        <origin rpy="0.0132645 0 0" xyz="0 0 0.06083" />
        <parent link="right_rod" />
        <child link="right_distal_phalanx" />
        <axis xyz="1 0 0" />
        <limit effort="1000" lower="-1" upper="0" velocity="1.0" />
        <mimic joint="finger_joint" multiplier="-1.4563851" offset="0" />
    </joint>
    <transmission name="finger_joint_trans">
        <type>transmission_interface/SimpleTransmission</type>
        <joint name="finger_joint">
            <hardwareInterface>PositionJointInterface</hardwareInterface>
        </joint>
        <actuator name="finger_joint_motor">
            <mechanicalReduction>1</mechanicalReduction>
            <hardwareInterface>hardware_interface/EffortJointInterface</hardwareInterface>
        </actuator>
    </transmission>
    <link name="base_footprint" />
    <link name="base_link">
        <inertial>
            <origin rpy="0 0 0" xyz="-0.18605 0.0010457 0.13419" />
            <mass value="35.137" />
            <inertia ixx="0.52213" ixy="0.00028039" ixz="-0.0048629" iyy="1.0698" iyz="-0.0011677" izz="1.4095" />
        </inertial>
        <visual>
            <origin rpy="0 0 0" xyz="0 0 0" />
            <geometry>
                <mesh filename="package://cobot_description/meshes/base_link.STL" />
            </geometry>
            <material name="">
                <color rgba="0.77647 0.77647 0.81961 1" />
            </material>
        </visual>
        <collision>
            <origin rpy="0 0 0" xyz="0 0 0" />
            <geometry>
                <mesh filename="package://cobot_description/meshes/base_link.STL" />
            </geometry>
        </collision>
    </link>
    <joint name="base_link" type="fixed">
        <origin rpy="0 0 0" xyz="0.201 0 0.072" />
        <parent link="base_footprint" />
        <child link="base_link" />
        <axis xyz="0 0 0" />
    </joint>
    <!-- <link
    name="fr_wheel">
    <inertial>
      <origin
        xyz="-1.4155E-15 -1.1102E-16 -0.00027897"
        rpy="0 0 0" />
      <mass
        value="1.1349" />
      <inertia
        ixx="0.0020665"
        ixy="1.4611E-19"
        ixz="6.3436E-18"
        iyy="0.0020665"
        iyz="-2.0749E-19"
        izz="0.0035433" />
    </inertial>
    <visual>
      <origin
        xyz="0 0 0"
        rpy="0 0 0" />
      <geometry>
        <mesh
          filename="package://cobot_description/meshes/fr_wheel.STL" />
      </geometry>
      <material
        name="">
        <color
          rgba="0.79216 0.81961 0.93333 1" />
      </material>
    </visual>
    <collision>
      <origin
        xyz="0 0 0"
        rpy="0 0 0" />
      <geometry>
        <mesh
          filename="package://cobot_description/meshes/fr_wheel.STL" />
      </geometry>
    </collision>
  </link>
  <joint
    name="fr_wheel_joint"
    type="continuous">
    <origin
      xyz="0 -0.2 0.011"
      rpy="1.5708 0 0" />
    <parent
      link="base_link" />
    <child
      link="fr_wheel" />
    <axis
      xyz="0 0 -1" />
  </joint>
  <link
    name="fl_wheel">
    <inertial>
      <origin
        xyz="1.4155E-15 -9.7145E-17 -0.00027897"
        rpy="0 0 0" />
      <mass
        value="1.1349" />
      <inertia
        ixx="0.0020665"
        ixy="-1.9153E-20"
        ixz="-8.9965E-18"
        iyy="0.0020665"
        iyz="3.0668E-20"
        izz="0.0035433" />
    </inertial>
    <visual>
      <origin
        xyz="0 0 0"
        rpy="0 0 0" />
      <geometry>
        <mesh
          filename="package://cobot_description/meshes/fl_wheel.STL" />
      </geometry>
      <material
        name="">
        <color
          rgba="0.79216 0.81961 0.93333 1" />
      </material>
    </visual>
    <collision>
      <origin
        xyz="0 0 0"
        rpy="0 0 0" />
      <geometry>
        <mesh
          filename="package://cobot_description/meshes/fl_wheel.STL" />
      </geometry>
    </collision>
  </link>
  <joint
    name="fl_wheel_joint"
    type="continuous">
    <origin
      xyz="0 0.2 0.011"
      rpy="1.5708 0 3.1416" />
    <parent
      link="base_link" />
    <child
      link="fl_wheel" />
    <axis
      xyz="0 0 1" />
  </joint>
  <link
    name="br_wheel">
    <inertial>
      <origin
        xyz="0.00023168 -0.0094468 -0.051255"
        rpy="0 0 0" />
      <mass
        value="2.4675" />
      <inertia
        ixx="0.0014416"
        ixy="-1.0824E-06"
        ixz="-6.1151E-07"
        iyy="0.0013614"
        iyz="4.2013E-05"
        izz="0.0015992" />
    </inertial>
    <visual>
      <origin
        xyz="0 0 0"
        rpy="0 0 0" />
      <geometry>
        <mesh
          filename="package://cobot_description/meshes/br_wheel.STL" />
      </geometry>
      <material
        name="">
        <color
          rgba="0.41176 0.41176 0.41176 1" />
      </material>
    </visual>
    <collision>
      <origin
        xyz="0 0 0"
        rpy="0 0 0" />
      <geometry>
        <mesh
          filename="package://cobot_description/meshes/br_wheel.STL" />
      </geometry>
    </collision>
  </link>
  <joint
    name="br_wheel_joint"
    type="continuous">
    <origin
      xyz="-0.402 -0.173 0.0405"
      rpy="0 0 -1.5708" />
    <parent
      link="base_link" />
    <child
      link="br_wheel" />
    <axis
      xyz="0 0 -1" />
  </joint>
  <link
    name="bl_wheel">
    <inertial>
      <origin
        xyz="-6.5897E-05 0.0094494 -0.051255"
        rpy="0 0 0" />
      <mass
        value="2.4675" />
      <inertia
        ixx="0.0014415"
        ixy="-2.4885E-06"
        ixz="-1.2571E-07"
        iyy="0.0013615"
        iyz="-4.2017E-05"
        izz="0.0015992" />
    </inertial>
    <visual>
      <origin
        xyz="0 0 0"
        rpy="0 0 0" />
      <geometry>
        <mesh
          filename="package://cobot_description/meshes/bl_wheel.STL" />
      </geometry>
      <material
        name="">
        <color
          rgba="0.41176 0.41176 0.41176 1" />
      </material>
    </visual>
    <collision>
      <origin
        xyz="0 0 0"
        rpy="0 0 0" />
      <geometry>
        <mesh
          filename="package://cobot_description/meshes/bl_wheel.STL" />
      </geometry>
    </collision>
  </link>
  <joint
    name="bl_wheel_joint"
    type="continuous">
    <origin
      xyz="-0.402 0.173 0.0405"
      rpy="0 0 1.5708" />
    <parent
      link="base_link" />
    <child
      link="bl_wheel" />
    <axis
      xyz="0 0 -1" />
  </joint> -->
    <!-- <link
    name="front_lidar">
    <inertial>
      <origin
        xyz="-0.00016986 -2.2612E-10 0.018642"
        rpy="0 0 0" />
      <mass
        value="0.15478" />
      <inertia
        ixx="6.9567E-05"
        ixy="-1.7298E-12"
        ixz="-4.6381E-07"
        iyy="7.1065E-05"
        iyz="-5.4415E-13"
        izz="9.8843E-05" />
    </inertial>
    <visual>
      <origin
        xyz="0 0 0"
        rpy="0 0 0" />
      <geometry>
        <mesh
          filename="package://cobot_description/meshes/front_lidar.STL" />
      </geometry>
      <material
        name="">
        <color
          rgba="1 1 1 1" />
      </material>
    </visual>
    <collision>
      <origin
        xyz="0 0 0"
        rpy="0 0 0" />
      <geometry>
        <mesh
          filename="package://cobot_description/meshes/front_lidar.STL" />
      </geometry>
    </collision>
  </link>
  <joint
    name="front_lidar_joint"
    type="fixed">
    <origin
      xyz="0.083559 0 0.314"
      rpy="0 0 0" />
    <parent
      link="base_link" />
    <child
      link="front_lidar" />
    <axis
      xyz="0 0 0" />
  </joint> -->
    <link name="arm_base">
        <inertial>
            <origin rpy="0 0 0" xyz="-0.024179 0.0061525 0.44341" />
            <mass value="8.0743" />
            <inertia ixx="0.080601" ixy="4.9995E-05" ixz="0.00052048" iyy="0.077325" iyz="-2.0984E-05" izz="0.024026" />
        </inertial>
        <visual>
            <origin rpy="0 0 0" xyz="0 0 0" />
            <geometry>
                <mesh filename="package://cobot_description/meshes/arm_base.STL" />
            </geometry>
            <material name="">
                <color rgba="0.69804 0.69804 0.69804 1" />
            </material>
        </visual>
        <collision>
            <origin rpy="0 0 0" xyz="0 0 0" />
            <geometry>
                <mesh filename="package://cobot_description/meshes/arm_base.STL" />
            </geometry>
        </collision>
    </link>
    <joint name="arm_base" type="fixed">
        <origin rpy="0 0 3.14" xyz="-0.101 0 0.16" />
        <parent link="base_link" />
        <child link="arm_base" />
        <axis xyz="0 0 0" />
    </joint>
    <link name="Link7">
        <inertial>
            <origin rpy="0 0 0" xyz="-0.016412 0.00026497 -0.060445" />
            <mass value="0.53096" />
            <inertia ixx="0.00096525" ixy="1.49E-05" ixz="-1.7049E-05" iyy="0.0018872" iyz="1.0632E-06" izz="0.0018331" />
        </inertial>
        <visual>
            <origin rpy="0 0 0" xyz="0 0 0" />
            <geometry>
                <mesh filename="package://cobot_description/meshes/Link7.STL" />
            </geometry>
            <material name="">
                <color rgba="1 1 1 1" />
            </material>
        </visual>
        <collision>
            <origin rpy="0 0 0" xyz="0 0 0" />
            <geometry>
                <mesh filename="package://cobot_description/meshes/Link7.STL" />
            </geometry>
        </collision>
    </link>
    <joint name="joint_arm_rotary" type="revolute">
        <origin rpy="3.1416 0 -3.1416" xyz="0 0 0.4878" />
        <parent link="arm_base" />
        <child link="Link7" />
        <axis xyz="0 0 -1" />
        <limit effort="300" lower="-1.9" upper="1.9" velocity="3.14" />
        <dynamics damping="50" friction="1" />
    </joint>
    <link name="Link1">
        <inertial>
            <origin rpy="0 0 0" xyz="-1.79862733952242E-05 -0.0216004812887538 0.0719258896443856" />
            <mass value="0.200843839724735" />
            <inertia ixx="0.000531136984021332" ixy="-4.32776127280478E-07" ixz="1.04793272362077E-06" iyy="0.000497444611373595" iyz="0.000106254355496355" izz="0.000282103590137435" />
        </inertial>
        <visual>
            <origin rpy="0 0 0" xyz="0 0 0" />
            <geometry>
                <mesh filename="package://cobot_description/meshes/rm65_meshes/Link1.STL" />
            </geometry>
            <material name="">
                <color rgba="1 1 1 1" />
            </material>
        </visual>
        <collision>
            <origin rpy="0 0 0" xyz="0 0 0" />
            <geometry>
                <mesh filename="package://cobot_description/meshes/rm65_meshes/Link1.STL" />
            </geometry>
        </collision>
    </link>
    <joint name="joint1" type="revolute">
        <origin rpy="1.5708 0 -1.5708" xyz="-0.1157 0 -0.059" />
        <parent link="Link7" />
        <child link="Link1" />
        <axis xyz="0 0 1" />
        <limit effort="300" lower="-3.14" upper="3.14" velocity="3.14" />
        <dynamics damping="50" friction="1" />
    </joint>
    <link name="Link2">
        <inertial>
            <origin rpy="0 0 0" xyz="0.133181684940056 -4.09216469913973E-05 0.0184216581306229" />
            <mass value="0.321307361964397" />
            <inertia ixx="0.000440014028766832" ixy="5.6579315252598E-07" ixz="-0.000654853772254918" iyy="0.00298539844077015" iyz="1.20748806355071E-07" izz="0.00284806640328522" />
        </inertial>
        <visual>
            <origin rpy="0 0 0" xyz="0 0 0" />
            <geometry>
                <mesh filename="package://cobot_description/meshes/rm65_meshes/Link2.STL" />
            </geometry>
            <material name="">
                <color rgba="1 1 1 1" />
            </material>
        </visual>
        <collision>
            <origin rpy="0 0 0" xyz="0 0 0" />
            <geometry>
                <mesh filename="package://cobot_description/meshes/rm65_meshes/Link2.STL" />
            </geometry>
        </collision>
    </link>
    <joint name="joint2" type="revolute">
        <origin rpy="1.5708 -1.5708 0" xyz="0 0.016171 0.1012" />
        <parent link="Link1" />
        <child link="Link2" />
        <axis xyz="0 0 -1" />
        <limit effort="300" lower="-2.26" upper="2.26" velocity="3.14" />
        <dynamics damping="50" friction="1" />
    </joint>
    <link name="Link3">
        <inertial>
            <origin rpy="0 0 0" xyz="-3.56690328818382E-06 -0.0512866037910138 2.10951876323563E-05" />
            <mass value="0.102772515618803" />
            <inertia ixx="0.000236471825455939" ixy="-2.85439143488268E-09" ixz="-4.04883470632046E-10" iyy="7.36858171850124E-05" iyz="5.2218422744868E-05" izz="0.000233873582444284" />
        </inertial>
        <visual>
            <origin rpy="0 0 0" xyz="0 0 0" />
            <geometry>
                <mesh filename="package://cobot_description/meshes/rm65_meshes/Link3.STL" />
            </geometry>
            <material name="">
                <color rgba="1 1 1 1" />
            </material>
        </visual>
        <collision>
            <origin rpy="0 0 0" xyz="0 0 0" />
            <geometry>
                <mesh filename="package://cobot_description/meshes/rm65_meshes/Link3.STL" />
            </geometry>
        </collision>
    </link>
    <joint name="joint3" type="revolute">
        <origin rpy="1.1972E-16 1.4979E-28 1.5708" xyz="0.25576 0 0.0035251" />
        <parent link="Link2" />
        <child link="Link3" />
        <axis xyz="0 0 -1" />
        <limit effort="300" lower="-2.35" upper="2.35" velocity="3.14" />
        <dynamics damping="50" friction="1" />
    </joint>
    <link name="Link4">
        <inertial>
            <origin rpy="0 0 0" xyz="6.79143687717758E-05 0.0172073813582943 0.0550497562490089" />
            <mass value="0.0751534548575527" />
            <inertia ixx="0.000114971629184183" ixy="1.55043636696422E-08" ixz="2.03173541830271E-07" iyy="0.000105991655073516" iyz="-2.1400189980959E-05" izz="5.71243912493456E-05" />
        </inertial>
        <visual>
            <origin rpy="0 0 0" xyz="0 0 0" />
            <geometry>
                <mesh filename="package://cobot_description/meshes/rm65_meshes/Link4.STL" />
            </geometry>
            <material name="">
                <color rgba="1 1 1 1" />
            </material>
        </visual>
        <collision>
            <origin rpy="0 0 0" xyz="0 0 0" />
            <geometry>
                <mesh filename="package://cobot_description/meshes/rm65_meshes/Link4.STL" />
            </geometry>
        </collision>
    </link>
    <joint name="joint4" type="revolute">
        <origin rpy="1.5708 0 1.2512E-12" xyz="0 -0.128 0.013234" />
        <parent link="Link3" />
        <child link="Link4" />
        <axis xyz="0 0 1" />
        <limit effort="300" lower="-3.14" upper="3.14" velocity="3.14" />
        <dynamics damping="50" friction="1" />
    </joint>
    <link name="Link5">
        <inertial>
            <origin rpy="0 0 0" xyz="-2.14593281051834E-06 -0.049119542458982 0.00236936437088902" />
            <mass value="0.0716575200885179" />
            <inertia ixx="0.000135381803103201" ixy="2.17516760135376E-09" ixz="8.55618321137308E-10" iyy="4.67751191123099E-05" iyz="2.92366122866633E-05" izz="0.000132066640473067" />
        </inertial>
        <visual>
            <origin rpy="0 0 0" xyz="0 0 0" />
            <geometry>
                <mesh filename="package://cobot_description/meshes/rm65_meshes/Link5.STL" />
            </geometry>
            <material name="">
                <color rgba="1 1 1 1" />
            </material>
        </visual>
        <collision>
            <origin rpy="0 0 0" xyz="0 0 0" />
            <geometry>
                <mesh filename="package://cobot_description/meshes/rm65_meshes/Link5.STL" />
            </geometry>
        </collision>
    </link>
    <joint name="joint5" type="revolute">
        <origin rpy="-1.5708 2.359E-12 5.6484E-28" xyz="0 -0.0121 0.0815" />
        <parent link="Link4" />
        <child link="Link5" />
        <axis xyz="0 0 -1" />
        <limit effort="300" lower="-2.182" upper="2.182" velocity="3.14" />
        <dynamics damping="50" friction="1" />
    </joint>
    <link name="Link6">
        <inertial>
            <origin rpy="0 0 0" xyz="0.000610923552198394 0.000226239439845178 0.0217158471531674" />
            <mass value="0.0321480840686874" />
            <inertia ixx="1.19996413785174E-05" ixy="-2.82372207081771E-08" ixz="9.42210764600823E-08" iyy="1.15507239688493E-05" iyz="-4.23625640293711E-08" izz="1.77260433647625E-05" />
        </inertial>
        <visual>
            <origin rpy="0 0 0" xyz="0 0 0" />
            <geometry>
                <mesh filename="package://cobot_description/meshes/rm65_meshes/Link6.STL" />
            </geometry>
            <material name="">
                <color rgba="1 1 1 1" />
            </material>
        </visual>
        <collision>
            <origin rpy="0 0 0" xyz="0 0 0" />
            <geometry>
                <mesh filename="package://cobot_description/meshes/rm65_meshes/Link6.STL" />
            </geometry>
        </collision>
    </link>
    <joint name="joint6" type="revolute">
        <origin rpy="1.5708 0 -2.359E-12" xyz="0 -0.115 0.012437" />
        <parent link="Link5" />
        <child link="Link6" />
        <axis xyz="0 0 1" />
        <limit effort="300" lower="-3.14" upper="3.14" velocity="1" />
        <dynamics damping="50" friction="1" />
    </joint>
    <link name="tool_link">
        <inertial>
            <origin rpy="0 0 0" xyz="-1.4586E-14 1.6875E-14 0.0086479" />
            <mass value="0.88542" />
            <inertia ixx="0.00049603" ixy="1.3553E-20" ixz="-6.8101E-19" iyy="0.00049603" iyz="4.0658E-19" izz="0.00097955" />
        </inertial>
        <visual>
            <origin rpy="0 0 0" xyz="0 0 0" />
            <geometry>
                <mesh filename="package://cobot_description/meshes/tool_link.STL" />
            </geometry>
            <material name="">
                <color rgba="0.77647 0.77647 0.81961 1" />
            </material>
        </visual>
        <collision>
            <origin rpy="0 0 0" xyz="0 0 0" />
            <geometry>
                <mesh filename="package://cobot_description/meshes/tool_link.STL" />
            </geometry>
        </collision>
    </link>
    <joint name="tool_joint" type="fixed">
        <origin rpy="0 0 -3.14" xyz="0 0 0.03103" />
        <parent link="Link6" />
        <child link="tool_link" />
    </joint>
    <joint name="hand_joint" type="fixed">
        <origin rpy="0 0 2.3761" xyz="0 0 0.018" />
        <parent link="tool_link" />
        <child link="dh_robotics_ag95_base_link" />
    </joint>
    <link name="hand_camera">
        <inertial>
            <origin rpy="0 0 0" xyz="0.0009804 0.025556 -0.036977" />
            <mass value="0.067926" />
            <inertia ixx="3.7811E-05" ixy="2.2861E-18" ixz="2.2446E-19" iyy="9.4061E-05" iyz="6.1172E-06" izz="0.00012345" />
        </inertial>
        <visual>
            <origin rpy="0 0 0" xyz="0 0 0" />
            <geometry>
                <mesh filename="package://cobot_description/meshes/hand_camera.STL" />
            </geometry>
            <material name="">
                <color rgba="1 1 1 1" />
            </material>
        </visual>
        <collision>
            <origin rpy="0 0 0" xyz="0 0 0" />
            <geometry>
                <mesh filename="package://cobot_description/meshes/hand_camera.STL" />
            </geometry>
        </collision>
    </link>
    <joint name="hand_camera_joint" type="fixed">
        <origin rpy="0.066568 0 -2.3363" xyz="-0.049074 0.048515 0.06645" />
        <parent link="tool_link" />
        <child link="hand_camera" />
        <axis xyz="0 0 0" />
    </joint>
    <!-- <link
    name="neck_lidar">
    <inertial>
      <origin
        xyz="7.4985E-05 4.6845E-07 4.6452E-05"
        rpy="0 0 0" />
      <mass
        value="1555.5" />
      <inertia
        ixx="305.18"
        ixy="-1.6368E-07"
        ixz="-1.1909E-05"
        iyy="305.18"
        iyz="-5.2042E-08"
        izz="583.7" />
    </inertial>
    <visual>
      <origin
        xyz="0 0 0"
        rpy="0 0 0" />
      <geometry>
        <mesh
          filename="package://cobot_description/meshes/neck_lidar.STL" />
      </geometry>
      <material
        name="">
        <color
          rgba="0.24706 0.96471 1 1" />
      </material>
    </visual>
    <collision>
      <origin
        xyz="0 0 0"
        rpy="0 0 0" />
      <geometry>
        <mesh
          filename="package://cobot_description/meshes/neck_lidar.STL" />
      </geometry>
    </collision>
  </link>
  <joint
    name="neck_lidar_joint"
    type="fixed">
    <origin
      xyz="0.041909 0 1.1614"
      rpy="0 0.5236 0" />
    <parent
      link="base_link" />
    <child
      link="neck_lidar" />
    <axis
      xyz="0 0 0" />
  </joint> -->
    <!-- <link
    name="front_camera">
    <inertial>
      <origin
        xyz="0.024537 -0.036831 -0.26799"
        rpy="0 0 0" />
      <mass
        value="91.96" />
      <inertia
        ixx="16.389"
        ixy="0.55033"
        ixz="0.32339"
        iyy="6.87"
        iyz="2.1896"
        izz="13.855" />
    </inertial>
    <visual>
      <origin
        xyz="0 0 0"
        rpy="0 0 0" />
      <geometry>
        <mesh
          filename="package://cobot_description/meshes/front_camera.STL" />
      </geometry>
      <material
        name="">
        <color
          rgba="1 1 1 1" />
      </material>
    </visual>
    <collision>
      <origin
        xyz="0 0 0"
        rpy="0 0 0" />
      <geometry>
        <mesh
          filename="package://cobot_description/meshes/front_camera.STL" />
      </geometry>
    </collision>
  </link>
  <joint
    name="front_camera_joint"
    type="fixed">
    <origin
      xyz="0.12851 0.0009804 0.288"
      rpy="-1.5708 0 -1.5708" />
    <parent
      link="base_link" />
    <child
      link="front_camera" />
    <axis
      xyz="0 0 0" />
  </joint> -->
    <link name="head_Link">
        <inertial>
            <origin rpy="0 0 0" xyz="-0.013341 -0.0030001 0.14378" />
            <mass value="0.10888" />
            <inertia ixx="0.00015548" ixy="5.612E-11" ixz="7.7393E-06" iyy="6.2021E-05" iyz="-3.4676E-10" izz="0.00016861" />
        </inertial>
        <visual>
            <origin rpy="0 0 0" xyz="0 0 0" />
            <geometry>
                <mesh filename="package://cobot_description/meshes/head_Link.STL" />
            </geometry>
            <material name="">
                <color rgba="1 1 1 1" />
            </material>
        </visual>
        <collision>
            <origin rpy="0 0 0" xyz="0 0 0" />
            <geometry>
                <mesh filename="package://cobot_description/meshes/head_Link.STL" />
            </geometry>
        </collision>
    </link>
    <joint name="head_joint" type="fixed">
        <origin rpy="0 0 3.1416" xyz="-0.10013 0 1.1628" />
        <parent link="base_link" />
        <child link="head_Link" />
        <axis xyz="0 0 0" />
    </joint>
    <link name="display_Link">
        <collision>
            <origin rpy="0 0 0" xyz="0 0 0" />
            <geometry>
                <box size="0.03 0.3 0.2" />
            </geometry>
        </collision>
        <inertial>
            <mass value="0.1" />
            <origin xyz="0 0 0" rpy="0 0 0" />
            <inertia ixx="0.03" iyy="0.03" izz="0.03" ixy="0.0" ixz="0.0" iyz="0.0" />
        </inertial>
    </link>
    <joint name="display_joint" type="fixed">
        <origin rpy="0 0 0" xyz="0.15 0 -0.1" />
        <parent link="head_Link" />
        <child link="display_Link" />
        <axis xyz="0 0 0" />
    </joint>
    <link name="head_camera">
        <inertial>
            <origin rpy="0 0 0" xyz="0.027537 -0.14823 -1.1256" />
            <mass value="91.96" />
            <inertia ixx="16.389" ixy="0.28606" ixz="-0.57062" iyy="13.534" iyz="-2.6339" izz="7.1915" />
        </inertial>
        <visual>
            <origin rpy="0 0 0" xyz="0 0 0" />
            <geometry>
                <mesh filename="package://cobot_description/meshes/head_camera.STL" />
            </geometry>
            <material name="">
                <color rgba="1 1 1 1" />
            </material>
        </visual>
        <collision>
            <origin rpy="0 0 0" xyz="0 0 0" />
            <geometry>
                <mesh filename="package://cobot_description/meshes/head_camera.STL" />
            </geometry>
        </collision>
    </link>
    <joint name="head_camera_joint" type="fixed">
        <origin rpy="0.066568 0 1.5708" xyz="-0.033687 -0.0039804 0.18195" />
        <parent link="head_Link" />
        <child link="head_camera" />
        <axis xyz="0 0 0" />
    </joint>
    <!-- <link
    name="basket_Link">
    <inertial>
      <origin
        xyz="-4.1633E-16 -4.4913E-14 0.021251"
        rpy="0 0 0" />
      <mass
        value="0.39699" />
      <inertia
        ixx="0.0056399"
        ixy="-2.6074E-10"
        ixz="5.7967E-18"
        iyy="0.0033409"
        iyz="1.9651E-17"
        izz="0.0081811" />
    </inertial>
    <visual>
      <origin
        xyz="0 0 0"
        rpy="0 0 0" />
      <geometry>
        <mesh
          filename="package://cobot_description/meshes/basket_Link.STL" />
      </geometry>
      <material
        name="">
        <color
          rgba="0.69804 0.69804 0.69804 1" />
      </material>
    </visual>
    <collision>
      <origin
        xyz="0 0 0"
        rpy="0 0 0" />
      <geometry>
        <mesh
          filename="package://cobot_description/meshes/basket_Link.STL" />
      </geometry>
    </collision>
  </link>
  <joint
    name="basket_joint"
    type="fixed">
    <origin
      xyz="-0.3885 0 0.2745"
      rpy="0 0 0" />
    <parent
      link="base_link" />
    <child
      link="basket_Link" />
    <axis
      xyz="0 0 0" />
  </joint> -->
    <transmission name="trans_left_rod_joint">
        <type>transmission_interface/SimpleTransmission</type>
        <joint name="left_rod_joint">
            <hardwareInterface>hardware_interface/EffortJointInterface</hardwareInterface>
        </joint>
        <actuator name="left_rod_joint_motor">
            <hardwareInterface>hardware_interface/EffortJointInterface</hardwareInterface>
            <mechanicalReduction>1</mechanicalReduction>
        </actuator>
    </transmission>
    <transmission name="trans_left_proximal_phalanx_joint">
        <type>transmission_interface/SimpleTransmission</type>
        <joint name="left_proximal_phalanx_joint">
            <hardwareInterface>hardware_interface/EffortJointInterface</hardwareInterface>
        </joint>
        <actuator name="left_proximal_phalanx_joint_motor">
            <hardwareInterface>hardware_interface/EffortJointInterface</hardwareInterface>
            <mechanicalReduction>1</mechanicalReduction>
        </actuator>
    </transmission>
    <transmission name="trans_left_distal_phalanx_joint">
        <type>transmission_interface/SimpleTransmission</type>
        <joint name="left_distal_phalanx_joint">
            <hardwareInterface>hardware_interface/EffortJointInterface</hardwareInterface>
        </joint>
        <actuator name="left_distal_phalanx_joint_motor">
            <hardwareInterface>hardware_interface/EffortJointInterface</hardwareInterface>
            <mechanicalReduction>1</mechanicalReduction>
        </actuator>
    </transmission>
    <transmission name="trans_right_crank_joint">
        <type>transmission_interface/SimpleTransmission</type>
        <joint name="right_crank_joint">
            <hardwareInterface>hardware_interface/EffortJointInterface</hardwareInterface>
        </joint>
        <actuator name="right_crank_joint_motor">
            <hardwareInterface>hardware_interface/EffortJointInterface</hardwareInterface>
            <mechanicalReduction>1</mechanicalReduction>
        </actuator>
    </transmission>
    <transmission name="trans_right_rod_joint">
        <type>transmission_interface/SimpleTransmission</type>
        <joint name="right_rod_joint">
            <hardwareInterface>hardware_interface/EffortJointInterface</hardwareInterface>
        </joint>
        <actuator name="right_rod_joint_motor">
            <hardwareInterface>hardware_interface/EffortJointInterface</hardwareInterface>
            <mechanicalReduction>1</mechanicalReduction>
        </actuator>
    </transmission>
    <transmission name="trans_right_proximal_phalanx_joint">
        <type>transmission_interface/SimpleTransmission</type>
        <joint name="right_proximal_phalanx_joint">
            <hardwareInterface>hardware_interface/EffortJointInterface</hardwareInterface>
        </joint>
        <actuator name="right_proximal_phalanx_joint_motor">
            <hardwareInterface>hardware_interface/EffortJointInterface</hardwareInterface>
            <mechanicalReduction>1</mechanicalReduction>
        </actuator>
    </transmission>
    <transmission name="trans_right_distal_phalanx_joint">
        <type>transmission_interface/SimpleTransmission</type>
        <joint name="right_distal_phalanx_joint">
            <hardwareInterface>hardware_interface/EffortJointInterface</hardwareInterface>
        </joint>
        <actuator name="right_distal_phalanx_joint_motor">
            <hardwareInterface>hardware_interface/EffortJointInterface</hardwareInterface>
            <mechanicalReduction>1</mechanicalReduction>
        </actuator>
    </transmission>
    <transmission name="trans_joint_arm_rotary">
        <type>transmission_interface/SimpleTransmission</type>
        <joint name="joint_arm_rotary">
            <hardwareInterface>hardware_interface/EffortJointInterface</hardwareInterface>
        </joint>
        <actuator name="joint_arm_rotary_motor">
            <hardwareInterface>hardware_interface/EffortJointInterface</hardwareInterface>
            <mechanicalReduction>1</mechanicalReduction>
        </actuator>
    </transmission>
    <transmission name="trans_joint1">
        <type>transmission_interface/SimpleTransmission</type>
        <joint name="joint1">
            <hardwareInterface>hardware_interface/EffortJointInterface</hardwareInterface>
        </joint>
        <actuator name="joint1_motor">
            <hardwareInterface>hardware_interface/EffortJointInterface</hardwareInterface>
            <mechanicalReduction>1</mechanicalReduction>
        </actuator>
    </transmission>
    <transmission name="trans_joint2">
        <type>transmission_interface/SimpleTransmission</type>
        <joint name="joint2">
            <hardwareInterface>hardware_interface/EffortJointInterface</hardwareInterface>
        </joint>
        <actuator name="joint2_motor">
            <hardwareInterface>hardware_interface/EffortJointInterface</hardwareInterface>
            <mechanicalReduction>1</mechanicalReduction>
        </actuator>
    </transmission>
    <transmission name="trans_joint3">
        <type>transmission_interface/SimpleTransmission</type>
        <joint name="joint3">
            <hardwareInterface>hardware_interface/EffortJointInterface</hardwareInterface>
        </joint>
        <actuator name="joint3_motor">
            <hardwareInterface>hardware_interface/EffortJointInterface</hardwareInterface>
            <mechanicalReduction>1</mechanicalReduction>
        </actuator>
    </transmission>
    <transmission name="trans_joint4">
        <type>transmission_interface/SimpleTransmission</type>
        <joint name="joint4">
            <hardwareInterface>hardware_interface/EffortJointInterface</hardwareInterface>
        </joint>
        <actuator name="joint4_motor">
            <hardwareInterface>hardware_interface/EffortJointInterface</hardwareInterface>
            <mechanicalReduction>1</mechanicalReduction>
        </actuator>
    </transmission>
    <transmission name="trans_joint5">
        <type>transmission_interface/SimpleTransmission</type>
        <joint name="joint5">
            <hardwareInterface>hardware_interface/EffortJointInterface</hardwareInterface>
        </joint>
        <actuator name="joint5_motor">
            <hardwareInterface>hardware_interface/EffortJointInterface</hardwareInterface>
            <mechanicalReduction>1</mechanicalReduction>
        </actuator>
    </transmission>
    <transmission name="trans_joint6">
        <type>transmission_interface/SimpleTransmission</type>
        <joint name="joint6">
            <hardwareInterface>hardware_interface/EffortJointInterface</hardwareInterface>
        </joint>
        <actuator name="joint6_motor">
            <hardwareInterface>hardware_interface/EffortJointInterface</hardwareInterface>
            <mechanicalReduction>1</mechanicalReduction>
        </actuator>
    </transmission>
    <gazebo>
        <plugin name="gazebo_ros_control">
            <robotNamespace>/</robotNamespace>
        </plugin>
    </gazebo>
</robot>

