<?xml version="1.0" encoding="utf-8"?>
<!-- This URDF was automatically created by SolidWorks to URDF Exporter! Originally created by Stephen Brawner (brawner@gmail.com) 
     Commit Version: 1.6.0-1-g15f4949  Build Version: 1.6.7594.29634
     For more information, please see http://wiki.ros.org/sw_urdf_exporter -->
<robot
  name="microwave-oven">

  <link name="world"/>
  <joint name="world_to_base" type="fixed">
    <origin rpy="0 0 0" xyz="0 0 0.135"/>
    <parent link="world"/>
    <child link="base_link"/>
  </joint>
  <link
    name="base_link">
    <inertial>
      <origin
        xyz="-0.000806187097213584 -0.00406745447829854 2.55156913070431E-07"
        rpy="0 0 0" />
      <mass
        value="39.1303313785312" />
      <inertia
        ixx="1.11126462075485"
        ixy="0.00879854623714752"
        ixz="-2.16116580137798E-06"
        iyy="1.55033827871687"
        iyz="1.25945693689869E-06"
        izz="1.81485378829434" />
    </inertial>
    <visual>
      <origin
        xyz="0 0 0"
        rpy="0 0 0" />
      <geometry>
        <mesh
          filename="package://./meshes/base_link.STL" />
      </geometry>
      <material
        name="">
        <color
          rgba="0.792156862745098 0.819607843137255 0.933333333333333 1" />
      </material>
    </visual>
    <collision>
      <origin
        xyz="0 0 0"
        rpy="0 0 0" />
      <geometry>
        <mesh
          filename="package://./meshes/base_link.STL" />
      </geometry>
    </collision>
  </link>
  <link
    name="link1">
    <inertial>
      <origin
        xyz="0.177 0.097 0.015"
        rpy="0 0 0" />
      <mass
        value="0.747" />
      <inertia
        ixx="0.004248402"
        ixy="3.45498202963812E-19"
        ixz="-1.23871578503835E-19"
        iyy="0.011457522"
        iyz="-4.86691242862491E-20"
        izz="0.015593874" />
    </inertial>
    <visual>
      <origin
        xyz="0 0 0"
        rpy="0 0 0" />
      <geometry>
        <mesh
          filename="package://./meshes/link1.STL" />
      </geometry>
      <material
        name="">
        <color
          rgba="0.792156862745098 0.819607843137255 0.933333333333333 1" />
      </material>
    </visual>
    <collision>
      <origin
        xyz="0 0 0"
        rpy="0 0 0" />
      <geometry>
        <mesh
          filename="package://./meshes/link1.STL" />
      </geometry>
    </collision>
  </link>
  <joint
    name="joint1"
    type="revolute">
    <origin
      xyz="0.21923 0.19807 -0.097013"
      rpy="1.5708 0 3.1416" />
    <parent
      link="base_link" />
    <child
      link="link1" />
    <axis
      xyz="0 1 0" />
    <limit
      lower="-1.57"
      upper="0"
      effort="0"
      velocity="0" />
  </joint>
</robot>
