<?xml version="1.0" ?>
<robot name="partnet_b9816227a0b977c9b362845c6edb57fc">
	<link name="base"/>
	<link name="link_0">
		<visual name="switch-2">
			<origin xyz="0 0.4051616942026166 0.1858696942026166"/>
			<geometry>
				<mesh filename="textured_objs/original-6.obj"/>
			</geometry>
		</visual>
		<visual name="switch-2">
			<origin xyz="0 0.4051616942026166 0.1858696942026166"/>
			<geometry>
				<mesh filename="textured_objs/new-3.obj"/>
			</geometry>
		</visual>
		<visual name="switch-2">
			<origin xyz="0 0.4051616942026166 0.1858696942026166"/>
			<geometry>
				<mesh filename="textured_objs/original-5.obj"/>
			</geometry>
		</visual>
		<collision>
			<origin xyz="0 0.4051616942026166 0.1858696942026166"/>
			<geometry>
				<mesh filename="textured_objs/original-6.obj"/>
			</geometry>
		</collision>
		<collision>
			<origin xyz="0 0.4051616942026166 0.1858696942026166"/>
			<geometry>
				<mesh filename="textured_objs/new-3.obj"/>
			</geometry>
		</collision>
		<collision>
			<origin xyz="0 0.4051616942026166 0.1858696942026166"/>
			<geometry>
				<mesh filename="textured_objs/original-5.obj"/>
			</geometry>
		</collision>
	</link>
	<joint name="joint_0" type="continuous">
		<origin xyz="0 -0.4051616942026166 -0.1858696942026166"/>
		<axis xyz="1 0 0"/>
		<child link="link_0"/>
		<parent link="link_2"/>
	</joint>
	<link name="link_1">
		<visual name="switch-3">
			<origin xyz="0 0.4051616942026166 0.18586969420261662"/>
			<geometry>
				<mesh filename="textured_objs/original-4.obj"/>
			</geometry>
		</visual>
		<visual name="switch-3">
			<origin xyz="0 0.4051616942026166 0.18586969420261662"/>
			<geometry>
				<mesh filename="textured_objs/original-3.obj"/>
			</geometry>
		</visual>
		<visual name="switch-3">
			<origin xyz="0 0.4051616942026166 0.18586969420261662"/>
			<geometry>
				<mesh filename="textured_objs/new-2.obj"/>
			</geometry>
		</visual>
		<collision>
			<origin xyz="0 0.4051616942026166 0.18586969420261662"/>
			<geometry>
				<mesh filename="textured_objs/original-4.obj"/>
			</geometry>
		</collision>
		<collision>
			<origin xyz="0 0.4051616942026166 0.18586969420261662"/>
			<geometry>
				<mesh filename="textured_objs/original-3.obj"/>
			</geometry>
		</collision>
		<collision>
			<origin xyz="0 0.4051616942026166 0.18586969420261662"/>
			<geometry>
				<mesh filename="textured_objs/new-2.obj"/>
			</geometry>
		</collision>
	</link>
	<joint name="joint_1" type="continuous">
		<origin xyz="0 -0.4051616942026166 -0.18586969420261662"/>
		<axis xyz="1 0 0"/>
		<child link="link_1"/>
		<parent link="link_2"/>
	</joint>
	<link name="link_2">
		<visual name="vertical_support-7">
			<origin xyz="0 0 0"/>
			<geometry>
				<mesh filename="textured_objs/new-10.obj"/>
			</geometry>
		</visual>
		<visual name="horizontal_support-8">
			<origin xyz="0 0 0"/>
			<geometry>
				<mesh filename="textured_objs/new-4.obj"/>
			</geometry>
		</visual>
		<visual name="surface_base-10">
			<origin xyz="0 0 0"/>
			<geometry>
				<mesh filename="textured_objs/new-9.obj"/>
			</geometry>
		</visual>
		<collision>
			<origin xyz="0 0 0"/>
			<geometry>
				<mesh filename="textured_objs/new-10.obj"/>
			</geometry>
		</collision>
		<collision>
			<origin xyz="0 0 0"/>
			<geometry>
				<mesh filename="textured_objs/new-4.obj"/>
			</geometry>
		</collision>
		<collision>
			<origin xyz="0 0 0"/>
			<geometry>
				<mesh filename="textured_objs/new-9.obj"/>
			</geometry>
		</collision>
	</link>
	<joint name="joint_2" type="fixed">
		<origin rpy="1.570796326794897 0 -1.570796326794897" xyz="0 0 0"/>
		<child link="link_2"/>
		<parent link="base"/>
	</joint>
	<link name="link_3">
		<visual name="tube-6">
			<origin xyz="0.0015881912962019719 0 0.18586980870379802"/>
			<geometry>
				<mesh filename="textured_objs/new-8.obj"/>
			</geometry>
		</visual>
		<visual name="mouth-9">
			<origin xyz="0.0015881912962019719 0 0.18586980870379802"/>
			<geometry>
				<mesh filename="textured_objs/new-7.obj"/>
			</geometry>
		</visual>
		<collision>
			<origin xyz="0.0015881912962019719 0 0.18586980870379802"/>
			<geometry>
				<mesh filename="textured_objs/new-8.obj"/>
			</geometry>
		</collision>
		<collision>
			<origin xyz="0.0015881912962019719 0 0.18586980870379802"/>
			<geometry>
				<mesh filename="textured_objs/new-7.obj"/>
			</geometry>
		</collision>
	</link>
	<joint name="joint_3" type="continuous">
		<origin xyz="-0.0015881912962019719 0 -0.18586980870379802"/>
		<axis xyz="0 1 0"/>
		<child link="link_3"/>
		<parent link="link_2"/>
	</joint>
</robot>
