<?xml version="1.0" ?>
<robot name="partnet_ce641a7a7b0cfe1ad85aa63241192dd1">
	<link name="base"/>
	<link name="link_0">
		<visual name="lid-2">
			<origin xyz="0.005388983197718338 0 -0.002775182720567912"/>
			<geometry>
				<mesh filename="textured_objs/new-0.obj"/>
			</geometry>
		</visual>
		<collision>
			<origin xyz="0.005388983197718338 0 -0.002775182720567912"/>
			<geometry>
				<mesh filename="textured_objs/new-0.obj"/>
			</geometry>
		</collision>
	</link>
	<joint name="joint_0" type="continuous">
		<origin xyz="0.0 0 0.0"/>
		<axis xyz="0 1 0"/>
		<child link="link_0"/>
		<parent link="link_0_helper"/>
	</joint>
	<link name="link_1">
		<visual name="container-3">
			<origin xyz="0 0 0"/>
			<geometry>
				<mesh filename="textured_objs/new-1.obj"/>
			</geometry>
		</visual>
		<collision>
			<origin xyz="0 0 0"/>
			<geometry>
				<mesh filename="textured_objs/new-1.obj"/>
			</geometry>
		</collision>
	</link>
	<joint name="joint_1" type="fixed">
		<origin rpy="1.570796326794897 0 -1.570796326794897" xyz="0 0 0"/>
		<child link="link_1"/>
		<parent link="base"/>
	</joint>
	<link name="link_0_helper"/>
	<joint name="joint_2" type="prismatic">
		<origin xyz="-0.005388983197718338 0 0.002775182720567912"/>
		<axis xyz="0 1 0"/>
		<child link="link_0_helper"/>
		<parent link="link_1"/>
		<limit lower="-0.008000000000000007" upper="0.03200000000000003"/>
	</joint>
</robot>
