<?xml version="1.0" ?>
<robot name="partnet_1ec5e12f2b5684a24da5feafe6f1c8fc">
	<link name="base"/>
	<link name="link_0">
		<visual name="cabinet_door_surface-9">
			<origin xyz="-0.7130134511490828 -0.5398004848060416 -0.47620010651538197"/>
			<geometry>
				<mesh filename="textured_objs/original-68.obj"/>
			</geometry>
		</visual>
		<visual name="cabinet_door_surface-9">
			<origin xyz="-0.7130134511490828 -0.5398004848060416 -0.47620010651538197"/>
			<geometry>
				<mesh filename="textured_objs/original-58.obj"/>
			</geometry>
		</visual>
		<visual name="cabinet_door_surface-9">
			<origin xyz="-0.7130134511490828 -0.5398004848060416 -0.47620010651538197"/>
			<geometry>
				<mesh filename="textured_objs/original-62.obj"/>
			</geometry>
		</visual>
		<visual name="cabinet_door_surface-9">
			<origin xyz="-0.7130134511490828 -0.5398004848060416 -0.47620010651538197"/>
			<geometry>
				<mesh filename="textured_objs/original-59.obj"/>
			</geometry>
		</visual>
		<visual name="cabinet_door_surface-9">
			<origin xyz="-0.7130134511490828 -0.5398004848060416 -0.47620010651538197"/>
			<geometry>
				<mesh filename="textured_objs/original-65.obj"/>
			</geometry>
		</visual>
		<visual name="cabinet_door_surface-9">
			<origin xyz="-0.7130134511490828 -0.5398004848060416 -0.47620010651538197"/>
			<geometry>
				<mesh filename="textured_objs/original-61.obj"/>
			</geometry>
		</visual>
		<visual name="cabinet_door_surface-9">
			<origin xyz="-0.7130134511490828 -0.5398004848060416 -0.47620010651538197"/>
			<geometry>
				<mesh filename="textured_objs/original-63.obj"/>
			</geometry>
		</visual>
		<visual name="cabinet_door_surface-9">
			<origin xyz="-0.7130134511490828 -0.5398004848060416 -0.47620010651538197"/>
			<geometry>
				<mesh filename="textured_objs/original-60.obj"/>
			</geometry>
		</visual>
		<visual name="cabinet_door_surface-9">
			<origin xyz="-0.7130134511490828 -0.5398004848060416 -0.47620010651538197"/>
			<geometry>
				<mesh filename="textured_objs/original-64.obj"/>
			</geometry>
		</visual>
		<visual name="cabinet_door_surface-9">
			<origin xyz="-0.7130134511490828 -0.5398004848060416 -0.47620010651538197"/>
			<geometry>
				<mesh filename="textured_objs/original-67.obj"/>
			</geometry>
		</visual>
		<visual name="handle-10">
			<origin xyz="-0.7130134511490828 -0.5398004848060416 -0.47620010651538197"/>
			<geometry>
				<mesh filename="textured_objs/original-71.obj"/>
			</geometry>
		</visual>
		<visual name="handle-10">
			<origin xyz="-0.7130134511490828 -0.5398004848060416 -0.47620010651538197"/>
			<geometry>
				<mesh filename="textured_objs/original-72.obj"/>
			</geometry>
		</visual>
		<visual name="handle-10">
			<origin xyz="-0.7130134511490828 -0.5398004848060416 -0.47620010651538197"/>
			<geometry>
				<mesh filename="textured_objs/original-76.obj"/>
			</geometry>
		</visual>
		<visual name="handle-10">
			<origin xyz="-0.7130134511490828 -0.5398004848060416 -0.47620010651538197"/>
			<geometry>
				<mesh filename="textured_objs/original-75.obj"/>
			</geometry>
		</visual>
		<visual name="handle-10">
			<origin xyz="-0.7130134511490828 -0.5398004848060416 -0.47620010651538197"/>
			<geometry>
				<mesh filename="textured_objs/original-74.obj"/>
			</geometry>
		</visual>
		<collision>
			<origin xyz="-0.7130134511490828 -0.5398004848060416 -0.47620010651538197"/>
			<geometry>
				<mesh filename="textured_objs/original-68.obj"/>
			</geometry>
		</collision>
		<collision>
			<origin xyz="-0.7130134511490828 -0.5398004848060416 -0.47620010651538197"/>
			<geometry>
				<mesh filename="textured_objs/original-58.obj"/>
			</geometry>
		</collision>
		<collision>
			<origin xyz="-0.7130134511490828 -0.5398004848060416 -0.47620010651538197"/>
			<geometry>
				<mesh filename="textured_objs/original-62.obj"/>
			</geometry>
		</collision>
		<collision>
			<origin xyz="-0.7130134511490828 -0.5398004848060416 -0.47620010651538197"/>
			<geometry>
				<mesh filename="textured_objs/original-59.obj"/>
			</geometry>
		</collision>
		<collision>
			<origin xyz="-0.7130134511490828 -0.5398004848060416 -0.47620010651538197"/>
			<geometry>
				<mesh filename="textured_objs/original-65.obj"/>
			</geometry>
		</collision>
		<collision>
			<origin xyz="-0.7130134511490828 -0.5398004848060416 -0.47620010651538197"/>
			<geometry>
				<mesh filename="textured_objs/original-61.obj"/>
			</geometry>
		</collision>
		<collision>
			<origin xyz="-0.7130134511490828 -0.5398004848060416 -0.47620010651538197"/>
			<geometry>
				<mesh filename="textured_objs/original-63.obj"/>
			</geometry>
		</collision>
		<collision>
			<origin xyz="-0.7130134511490828 -0.5398004848060416 -0.47620010651538197"/>
			<geometry>
				<mesh filename="textured_objs/original-60.obj"/>
			</geometry>
		</collision>
		<collision>
			<origin xyz="-0.7130134511490828 -0.5398004848060416 -0.47620010651538197"/>
			<geometry>
				<mesh filename="textured_objs/original-64.obj"/>
			</geometry>
		</collision>
		<collision>
			<origin xyz="-0.7130134511490828 -0.5398004848060416 -0.47620010651538197"/>
			<geometry>
				<mesh filename="textured_objs/original-67.obj"/>
			</geometry>
		</collision>
		<collision>
			<origin xyz="-0.7130134511490828 -0.5398004848060416 -0.47620010651538197"/>
			<geometry>
				<mesh filename="textured_objs/original-71.obj"/>
			</geometry>
		</collision>
		<collision>
			<origin xyz="-0.7130134511490828 -0.5398004848060416 -0.47620010651538197"/>
			<geometry>
				<mesh filename="textured_objs/original-72.obj"/>
			</geometry>
		</collision>
		<collision>
			<origin xyz="-0.7130134511490828 -0.5398004848060416 -0.47620010651538197"/>
			<geometry>
				<mesh filename="textured_objs/original-76.obj"/>
			</geometry>
		</collision>
		<collision>
			<origin xyz="-0.7130134511490828 -0.5398004848060416 -0.47620010651538197"/>
			<geometry>
				<mesh filename="textured_objs/original-75.obj"/>
			</geometry>
		</collision>
		<collision>
			<origin xyz="-0.7130134511490828 -0.5398004848060416 -0.47620010651538197"/>
			<geometry>
				<mesh filename="textured_objs/original-74.obj"/>
			</geometry>
		</collision>
	</link>
	<joint name="joint_0" type="revolute">
		<origin xyz="0.7130134511490828 0.5398004848060416 0.47620010651538197"/>
		<axis xyz="0 0.9999997700613202 -0.000678142541459935"/>
		<child link="link_0"/>
		<parent link="link_4"/>
		<limit lower="0.0" upper="1.8409732950036186"/>
	</joint>
	<link name="link_1">
		<visual name="cabinet_door_surface-7">
			<origin xyz="0.674567971434532 0.2759116911513315 -0.47648214727952237"/>
			<geometry>
				<mesh filename="textured_objs/original-48.obj"/>
			</geometry>
		</visual>
		<visual name="cabinet_door_surface-7">
			<origin xyz="0.674567971434532 0.2759116911513315 -0.47648214727952237"/>
			<geometry>
				<mesh filename="textured_objs/original-44.obj"/>
			</geometry>
		</visual>
		<visual name="cabinet_door_surface-7">
			<origin xyz="0.674567971434532 0.2759116911513315 -0.47648214727952237"/>
			<geometry>
				<mesh filename="textured_objs/original-42.obj"/>
			</geometry>
		</visual>
		<visual name="cabinet_door_surface-7">
			<origin xyz="0.674567971434532 0.2759116911513315 -0.47648214727952237"/>
			<geometry>
				<mesh filename="textured_objs/original-38.obj"/>
			</geometry>
		</visual>
		<visual name="cabinet_door_surface-7">
			<origin xyz="0.674567971434532 0.2759116911513315 -0.47648214727952237"/>
			<geometry>
				<mesh filename="textured_objs/original-39.obj"/>
			</geometry>
		</visual>
		<visual name="cabinet_door_surface-7">
			<origin xyz="0.674567971434532 0.2759116911513315 -0.47648214727952237"/>
			<geometry>
				<mesh filename="textured_objs/original-45.obj"/>
			</geometry>
		</visual>
		<visual name="cabinet_door_surface-7">
			<origin xyz="0.674567971434532 0.2759116911513315 -0.47648214727952237"/>
			<geometry>
				<mesh filename="textured_objs/original-41.obj"/>
			</geometry>
		</visual>
		<visual name="cabinet_door_surface-7">
			<origin xyz="0.674567971434532 0.2759116911513315 -0.47648214727952237"/>
			<geometry>
				<mesh filename="textured_objs/original-43.obj"/>
			</geometry>
		</visual>
		<visual name="cabinet_door_surface-7">
			<origin xyz="0.674567971434532 0.2759116911513315 -0.47648214727952237"/>
			<geometry>
				<mesh filename="textured_objs/original-40.obj"/>
			</geometry>
		</visual>
		<visual name="cabinet_door_surface-7">
			<origin xyz="0.674567971434532 0.2759116911513315 -0.47648214727952237"/>
			<geometry>
				<mesh filename="textured_objs/original-47.obj"/>
			</geometry>
		</visual>
		<visual name="handle-8">
			<origin xyz="0.674567971434532 0.2759116911513315 -0.47648214727952237"/>
			<geometry>
				<mesh filename="textured_objs/original-56.obj"/>
			</geometry>
		</visual>
		<visual name="handle-8">
			<origin xyz="0.674567971434532 0.2759116911513315 -0.47648214727952237"/>
			<geometry>
				<mesh filename="textured_objs/original-52.obj"/>
			</geometry>
		</visual>
		<visual name="handle-8">
			<origin xyz="0.674567971434532 0.2759116911513315 -0.47648214727952237"/>
			<geometry>
				<mesh filename="textured_objs/original-55.obj"/>
			</geometry>
		</visual>
		<visual name="handle-8">
			<origin xyz="0.674567971434532 0.2759116911513315 -0.47648214727952237"/>
			<geometry>
				<mesh filename="textured_objs/original-51.obj"/>
			</geometry>
		</visual>
		<visual name="handle-8">
			<origin xyz="0.674567971434532 0.2759116911513315 -0.47648214727952237"/>
			<geometry>
				<mesh filename="textured_objs/original-54.obj"/>
			</geometry>
		</visual>
		<collision>
			<origin xyz="0.674567971434532 0.2759116911513315 -0.47648214727952237"/>
			<geometry>
				<mesh filename="textured_objs/original-48.obj"/>
			</geometry>
		</collision>
		<collision>
			<origin xyz="0.674567971434532 0.2759116911513315 -0.47648214727952237"/>
			<geometry>
				<mesh filename="textured_objs/original-44.obj"/>
			</geometry>
		</collision>
		<collision>
			<origin xyz="0.674567971434532 0.2759116911513315 -0.47648214727952237"/>
			<geometry>
				<mesh filename="textured_objs/original-42.obj"/>
			</geometry>
		</collision>
		<collision>
			<origin xyz="0.674567971434532 0.2759116911513315 -0.47648214727952237"/>
			<geometry>
				<mesh filename="textured_objs/original-38.obj"/>
			</geometry>
		</collision>
		<collision>
			<origin xyz="0.674567971434532 0.2759116911513315 -0.47648214727952237"/>
			<geometry>
				<mesh filename="textured_objs/original-39.obj"/>
			</geometry>
		</collision>
		<collision>
			<origin xyz="0.674567971434532 0.2759116911513315 -0.47648214727952237"/>
			<geometry>
				<mesh filename="textured_objs/original-45.obj"/>
			</geometry>
		</collision>
		<collision>
			<origin xyz="0.674567971434532 0.2759116911513315 -0.47648214727952237"/>
			<geometry>
				<mesh filename="textured_objs/original-41.obj"/>
			</geometry>
		</collision>
		<collision>
			<origin xyz="0.674567971434532 0.2759116911513315 -0.47648214727952237"/>
			<geometry>
				<mesh filename="textured_objs/original-43.obj"/>
			</geometry>
		</collision>
		<collision>
			<origin xyz="0.674567971434532 0.2759116911513315 -0.47648214727952237"/>
			<geometry>
				<mesh filename="textured_objs/original-40.obj"/>
			</geometry>
		</collision>
		<collision>
			<origin xyz="0.674567971434532 0.2759116911513315 -0.47648214727952237"/>
			<geometry>
				<mesh filename="textured_objs/original-47.obj"/>
			</geometry>
		</collision>
		<collision>
			<origin xyz="0.674567971434532 0.2759116911513315 -0.47648214727952237"/>
			<geometry>
				<mesh filename="textured_objs/original-56.obj"/>
			</geometry>
		</collision>
		<collision>
			<origin xyz="0.674567971434532 0.2759116911513315 -0.47648214727952237"/>
			<geometry>
				<mesh filename="textured_objs/original-52.obj"/>
			</geometry>
		</collision>
		<collision>
			<origin xyz="0.674567971434532 0.2759116911513315 -0.47648214727952237"/>
			<geometry>
				<mesh filename="textured_objs/original-55.obj"/>
			</geometry>
		</collision>
		<collision>
			<origin xyz="0.674567971434532 0.2759116911513315 -0.47648214727952237"/>
			<geometry>
				<mesh filename="textured_objs/original-51.obj"/>
			</geometry>
		</collision>
		<collision>
			<origin xyz="0.674567971434532 0.2759116911513315 -0.47648214727952237"/>
			<geometry>
				<mesh filename="textured_objs/original-54.obj"/>
			</geometry>
		</collision>
	</link>
	<joint name="joint_1" type="revolute">
		<origin xyz="-0.674567971434532 -0.2759116911513315 0.47648214727952237"/>
		<axis xyz="0 -0.9999997700613203 -0.0006781425414599351"/>
		<child link="link_1"/>
		<parent link="link_4"/>
		<limit lower="0.0" upper="1.8158405537749003"/>
	</joint>
	<link name="link_2">
		<visual name="drawer_front-25">
			<origin xyz="-0.38088184223371396 0.20525192503246686 -0.4952349960803988"/>
			<geometry>
				<mesh filename="textured_objs/original-32.obj"/>
			</geometry>
		</visual>
		<visual name="drawer_side-26">
			<origin xyz="-0.38088184223371396 0.20525192503246686 -0.4952349960803988"/>
			<geometry>
				<mesh filename="textured_objs/original-31.obj"/>
			</geometry>
		</visual>
		<visual name="drawer_side-27">
			<origin xyz="-0.38088184223371396 0.20525192503246686 -0.4952349960803988"/>
			<geometry>
				<mesh filename="textured_objs/original-34.obj"/>
			</geometry>
		</visual>
		<visual name="drawer_back-28">
			<origin xyz="-0.38088184223371396 0.20525192503246686 -0.4952349960803988"/>
			<geometry>
				<mesh filename="textured_objs/original-35.obj"/>
			</geometry>
		</visual>
		<visual name="drawer_bottom-29">
			<origin xyz="-0.38088184223371396 0.20525192503246686 -0.4952349960803988"/>
			<geometry>
				<mesh filename="textured_objs/original-33.obj"/>
			</geometry>
		</visual>
		<visual name="other_leaf-31">
			<origin xyz="-0.38088184223371396 0.20525192503246686 -0.4952349960803988"/>
			<geometry>
				<mesh filename="textured_objs/original-36.obj"/>
			</geometry>
		</visual>
		<collision>
			<origin xyz="-0.38088184223371396 0.20525192503246686 -0.4952349960803988"/>
			<geometry>
				<mesh filename="textured_objs/original-32.obj"/>
			</geometry>
		</collision>
		<collision>
			<origin xyz="-0.38088184223371396 0.20525192503246686 -0.4952349960803988"/>
			<geometry>
				<mesh filename="textured_objs/original-31.obj"/>
			</geometry>
		</collision>
		<collision>
			<origin xyz="-0.38088184223371396 0.20525192503246686 -0.4952349960803988"/>
			<geometry>
				<mesh filename="textured_objs/original-34.obj"/>
			</geometry>
		</collision>
		<collision>
			<origin xyz="-0.38088184223371396 0.20525192503246686 -0.4952349960803988"/>
			<geometry>
				<mesh filename="textured_objs/original-35.obj"/>
			</geometry>
		</collision>
		<collision>
			<origin xyz="-0.38088184223371396 0.20525192503246686 -0.4952349960803988"/>
			<geometry>
				<mesh filename="textured_objs/original-33.obj"/>
			</geometry>
		</collision>
		<collision>
			<origin xyz="-0.38088184223371396 0.20525192503246686 -0.4952349960803988"/>
			<geometry>
				<mesh filename="textured_objs/original-36.obj"/>
			</geometry>
		</collision>
	</link>
	<joint name="joint_2" type="prismatic">
		<origin xyz="0.38088184223371396 -0.20525192503246686 0.4952349960803988"/>
		<axis xyz="0 0 1"/>
		<child link="link_2"/>
		<parent link="link_4"/>
		<limit lower="0" upper="0.7240000000000002"/>
	</joint>
	<link name="link_3">
		<visual name="drawer_front-17">
			<origin xyz="0.36730260895927747 0.20486946987863303 -0.49523499608039856"/>
			<geometry>
				<mesh filename="textured_objs/original-25.obj"/>
			</geometry>
		</visual>
		<visual name="drawer_side-18">
			<origin xyz="0.36730260895927747 0.20486946987863303 -0.49523499608039856"/>
			<geometry>
				<mesh filename="textured_objs/original-24.obj"/>
			</geometry>
		</visual>
		<visual name="drawer_side-19">
			<origin xyz="0.36730260895927747 0.20486946987863303 -0.49523499608039856"/>
			<geometry>
				<mesh filename="textured_objs/original-27.obj"/>
			</geometry>
		</visual>
		<visual name="drawer_back-20">
			<origin xyz="0.36730260895927747 0.20486946987863303 -0.49523499608039856"/>
			<geometry>
				<mesh filename="textured_objs/original-28.obj"/>
			</geometry>
		</visual>
		<visual name="drawer_bottom-21">
			<origin xyz="0.36730260895927747 0.20486946987863303 -0.49523499608039856"/>
			<geometry>
				<mesh filename="textured_objs/original-26.obj"/>
			</geometry>
		</visual>
		<visual name="other_leaf-23">
			<origin xyz="0.36730260895927747 0.20486946987863303 -0.49523499608039856"/>
			<geometry>
				<mesh filename="textured_objs/original-29.obj"/>
			</geometry>
		</visual>
		<collision>
			<origin xyz="0.36730260895927747 0.20486946987863303 -0.49523499608039856"/>
			<geometry>
				<mesh filename="textured_objs/original-25.obj"/>
			</geometry>
		</collision>
		<collision>
			<origin xyz="0.36730260895927747 0.20486946987863303 -0.49523499608039856"/>
			<geometry>
				<mesh filename="textured_objs/original-24.obj"/>
			</geometry>
		</collision>
		<collision>
			<origin xyz="0.36730260895927747 0.20486946987863303 -0.49523499608039856"/>
			<geometry>
				<mesh filename="textured_objs/original-27.obj"/>
			</geometry>
		</collision>
		<collision>
			<origin xyz="0.36730260895927747 0.20486946987863303 -0.49523499608039856"/>
			<geometry>
				<mesh filename="textured_objs/original-28.obj"/>
			</geometry>
		</collision>
		<collision>
			<origin xyz="0.36730260895927747 0.20486946987863303 -0.49523499608039856"/>
			<geometry>
				<mesh filename="textured_objs/original-26.obj"/>
			</geometry>
		</collision>
		<collision>
			<origin xyz="0.36730260895927747 0.20486946987863303 -0.49523499608039856"/>
			<geometry>
				<mesh filename="textured_objs/original-29.obj"/>
			</geometry>
		</collision>
	</link>
	<joint name="joint_3" type="prismatic">
		<origin xyz="-0.36730260895927747 -0.20486946987863303 0.49523499608039856"/>
		<axis xyz="0 0 0.9999999999999999"/>
		<child link="link_3"/>
		<parent link="link_4"/>
		<limit lower="0" upper="0.7360000000000002"/>
	</joint>
	<link name="link_4">
		<visual name="shelf-13">
			<origin xyz="0 0 0"/>
			<geometry>
				<mesh filename="textured_objs/original-22.obj"/>
			</geometry>
		</visual>
		<visual name="vertical_side_panel-37">
			<origin xyz="0 0 0"/>
			<geometry>
				<mesh filename="textured_objs/original-15.obj"/>
			</geometry>
		</visual>
		<visual name="vertical_side_panel-37">
			<origin xyz="0 0 0"/>
			<geometry>
				<mesh filename="textured_objs/original-14.obj"/>
			</geometry>
		</visual>
		<visual name="vertical_side_panel-38">
			<origin xyz="0 0 0"/>
			<geometry>
				<mesh filename="textured_objs/original-11.obj"/>
			</geometry>
		</visual>
		<visual name="vertical_side_panel-38">
			<origin xyz="0 0 0"/>
			<geometry>
				<mesh filename="textured_objs/original-10.obj"/>
			</geometry>
		</visual>
		<visual name="back_panel-39">
			<origin xyz="0 0 0"/>
			<geometry>
				<mesh filename="textured_objs/original-5.obj"/>
			</geometry>
		</visual>
		<visual name="back_panel-39">
			<origin xyz="0 0 0"/>
			<geometry>
				<mesh filename="textured_objs/original-4.obj"/>
			</geometry>
		</visual>
		<visual name="bottom_panel-40">
			<origin xyz="0 0 0"/>
			<geometry>
				<mesh filename="textured_objs/original-2.obj"/>
			</geometry>
		</visual>
		<visual name="frame_vertical_bar-41">
			<origin xyz="0 0 0"/>
			<geometry>
				<mesh filename="textured_objs/original-3.obj"/>
			</geometry>
		</visual>
		<visual name="frame_vertical_bar-42">
			<origin xyz="0 0 0"/>
			<geometry>
				<mesh filename="textured_objs/original-21.obj"/>
			</geometry>
		</visual>
		<visual name="frame_vertical_bar-43">
			<origin xyz="0 0 0"/>
			<geometry>
				<mesh filename="textured_objs/original-7.obj"/>
			</geometry>
		</visual>
		<visual name="frame_horizontal_bar-44">
			<origin xyz="0 0 0"/>
			<geometry>
				<mesh filename="textured_objs/original-8.obj"/>
			</geometry>
		</visual>
		<visual name="frame_horizontal_bar-45">
			<origin xyz="0 0 0"/>
			<geometry>
				<mesh filename="textured_objs/original-6.obj"/>
			</geometry>
		</visual>
		<visual name="frame_horizontal_bar-46">
			<origin xyz="0 0 0"/>
			<geometry>
				<mesh filename="textured_objs/original-20.obj"/>
			</geometry>
		</visual>
		<visual name="frame_horizontal_bar-47">
			<origin xyz="0 0 0"/>
			<geometry>
				<mesh filename="textured_objs/original-19.obj"/>
			</geometry>
		</visual>
		<visual name="other_leaf-49">
			<origin xyz="0 0 0"/>
			<geometry>
				<mesh filename="textured_objs/original-77.obj"/>
			</geometry>
		</visual>
		<visual name="base_side_panel-33">
			<origin xyz="0 0 0"/>
			<geometry>
				<mesh filename="textured_objs/original-12.obj"/>
			</geometry>
		</visual>
		<visual name="base_side_panel-34">
			<origin xyz="0 0 0"/>
			<geometry>
				<mesh filename="textured_objs/original-17.obj"/>
			</geometry>
		</visual>
		<visual name="base_side_panel-35">
			<origin xyz="0 0 0"/>
			<geometry>
				<mesh filename="textured_objs/original-16.obj"/>
			</geometry>
		</visual>
		<visual name="base_side_panel-36">
			<origin xyz="0 0 0"/>
			<geometry>
				<mesh filename="textured_objs/original-18.obj"/>
			</geometry>
		</visual>
		<collision>
			<origin xyz="0 0 0"/>
			<geometry>
				<mesh filename="textured_objs/original-22.obj"/>
			</geometry>
		</collision>
		<collision>
			<origin xyz="0 0 0"/>
			<geometry>
				<mesh filename="textured_objs/original-15.obj"/>
			</geometry>
		</collision>
		<collision>
			<origin xyz="0 0 0"/>
			<geometry>
				<mesh filename="textured_objs/original-14.obj"/>
			</geometry>
		</collision>
		<collision>
			<origin xyz="0 0 0"/>
			<geometry>
				<mesh filename="textured_objs/original-11.obj"/>
			</geometry>
		</collision>
		<collision>
			<origin xyz="0 0 0"/>
			<geometry>
				<mesh filename="textured_objs/original-10.obj"/>
			</geometry>
		</collision>
		<collision>
			<origin xyz="0 0 0"/>
			<geometry>
				<mesh filename="textured_objs/original-5.obj"/>
			</geometry>
		</collision>
		<collision>
			<origin xyz="0 0 0"/>
			<geometry>
				<mesh filename="textured_objs/original-4.obj"/>
			</geometry>
		</collision>
		<collision>
			<origin xyz="0 0 0"/>
			<geometry>
				<mesh filename="textured_objs/original-2.obj"/>
			</geometry>
		</collision>
		<collision>
			<origin xyz="0 0 0"/>
			<geometry>
				<mesh filename="textured_objs/original-3.obj"/>
			</geometry>
		</collision>
		<collision>
			<origin xyz="0 0 0"/>
			<geometry>
				<mesh filename="textured_objs/original-21.obj"/>
			</geometry>
		</collision>
		<collision>
			<origin xyz="0 0 0"/>
			<geometry>
				<mesh filename="textured_objs/original-7.obj"/>
			</geometry>
		</collision>
		<collision>
			<origin xyz="0 0 0"/>
			<geometry>
				<mesh filename="textured_objs/original-8.obj"/>
			</geometry>
		</collision>
		<collision>
			<origin xyz="0 0 0"/>
			<geometry>
				<mesh filename="textured_objs/original-6.obj"/>
			</geometry>
		</collision>
		<collision>
			<origin xyz="0 0 0"/>
			<geometry>
				<mesh filename="textured_objs/original-20.obj"/>
			</geometry>
		</collision>
		<collision>
			<origin xyz="0 0 0"/>
			<geometry>
				<mesh filename="textured_objs/original-19.obj"/>
			</geometry>
		</collision>
		<collision>
			<origin xyz="0 0 0"/>
			<geometry>
				<mesh filename="textured_objs/original-77.obj"/>
			</geometry>
		</collision>
		<collision>
			<origin xyz="0 0 0"/>
			<geometry>
				<mesh filename="textured_objs/original-12.obj"/>
			</geometry>
		</collision>
		<collision>
			<origin xyz="0 0 0"/>
			<geometry>
				<mesh filename="textured_objs/original-17.obj"/>
			</geometry>
		</collision>
		<collision>
			<origin xyz="0 0 0"/>
			<geometry>
				<mesh filename="textured_objs/original-16.obj"/>
			</geometry>
		</collision>
		<collision>
			<origin xyz="0 0 0"/>
			<geometry>
				<mesh filename="textured_objs/original-18.obj"/>
			</geometry>
		</collision>
	</link>
	<joint name="joint_4" type="fixed">
		<origin rpy="1.570796326794897 0 -1.570796326794897" xyz="0 0 0"/>
		<child link="link_4"/>
		<parent link="base"/>
	</joint>
</robot>
