<?xml version="1.0" encoding="utf-8"?>
<!-- This URDF was automatically created by SolidWorks to URDF Exporter! Originally created by Stephen Brawner (brawner@gmail.com) 
     Commit Version: 1.6.0-1-g15f4949  Build Version: 1.6.7594.29634
     For more information, please see http://wiki.ros.org/sw_urdf_exporter -->
<robot  name="rm_63_6f_description" xmlns:xacro="http://www.ros.org/wiki/xacro">
<xacro:include filename="$(find rm_description)/urdf/RML63/rml_63.transmission.xacro"/>
<xacro:include filename="$(find rm_description)/urdf/RML63/rml_63.gazebo.xacro"/>
  <!-- Inertial matrix -->
  <xacro:macro name="inertial_matrix" params="mass">
    <inertial>
      <mass value="${mass}" />
      <inertia ixx="1.0" ixy="0.0" ixz="0.0" iyy="0.5" iyz="0.0" izz="1.0" />
	</inertial>
  </xacro:macro>
  <!-- <xacro:macro name="Box_inertial_matrix" params="m l w h">
    <inertial>
      <mass value="${m}" />
        <inertia ixx="${m*(h*h + l*l)/12}" ixy = "0" ixz = "0"
          iyy="${m*(w*w + l*l)/12}" iyz= "0"
          izz="${m*(w*w + h*h)/12}" />
    </inertial> 
  </xacro:macro>-->
  <!-- <link name="dummy">
  </link>
  <joint name="dummy_joint" type="fixed">
  <origin xyz="0 0 0" rpy="0 0 3.14" />
    <parent link="dummy" />
    <child link="arm_base" />
  </joint>
  
    <joint name="bottom_joint" type="fixed">
    <origin xyz="0 0 0" rpy="0 0 0" />
    <parent link="arm_base"/>
    <child link="bottom_link"/>
  </joint>
  <link name="bottom_link">
    <visual>
      <origin xyz=" 0 0 -0.02"  rpy="0 0 0"/>
      <geometry>
        <box size="0.06 0.06 0.02" />
      </geometry>
      <material name="Brown" />
    </visual>
    <collision>
      <origin xyz=" 0 0 0"  rpy="0 0 0"/>
      <geometry>
        <box size="0.06 0.06 0.02" />
      </geometry>
    </collision>
    <xacro:Box_inertial_matrix m="500" l="1" w="1" h="0.02"/>
  </link> -->
<!-- 
  <link
    name="arm_base">
    <inertial>
      <origin
        xyz="0.001418 -0.00010076 0.050086"
        rpy="0 0 0" />
      <mass
        value="0.66248" />
      <inertia
        ixx="0.00099641"
        ixy="3.2555E-06"
        ixz="-1.005E-05"
        iyy="0.0010163"
        iyz="1.2819E-06"
        izz="0.00067925" />
    </inertial>
    <visual>
      <origin
        xyz="0 0 0"
        rpy="0 0 0" />
      <geometry>
        <mesh
          filename="package://rm_description/meshes/RML63_6F/base_link.STL" />
      </geometry>
      <material
        name="">
        <color
          rgba="1 1 1 1" />
      </material>
    </visual>
    <collision>
      <origin
        xyz="0 0 0"
        rpy="0 0 0" />
      <geometry>
        <mesh
          filename="package://rm_description/meshes/RML63_6F/base_link.STL" />
      </geometry>
    </collision>
  </link> -->
  <link
    name="Link1">
    <inertial>
      <origin
        xyz="-0.043398 -0.0074204 -0.012727"
        rpy="0 0 0" />
      <mass
        value="0.92308" />
      <inertia
        ixx="0.00093348"
        ixy="-0.00032512"
        ixz="0.00049759"
        iyy="0.0021248"
        iyz="0.00010864"
        izz="0.001984" />
    </inertial>
    <visual>
      <origin
        xyz="0 0 0"
        rpy="0 0 0" />
      <geometry>
        <mesh
          filename="package://rm_description/meshes/RML63_6F/Link1.STL" />
      </geometry>
      <material
        name="">
        <color
          rgba="1 1 1 1" />
      </material>
    </visual>
    <collision>
      <origin
        xyz="0 0 0"
        rpy="0 0 0" />
      <geometry>
        <mesh
          filename="package://rm_description/meshes/RML63_6F/Link1.STL" />
      </geometry>
    </collision>
  </link>
  <!-- <joint
    name="joint1"
    type="revolute">
    <origin
      xyz="0 0 0.172"
      rpy="0 0 0" />
    <parent
      link="arm_base" />
    <child
      link="Link1" />
    <axis
      xyz="0 0 1" />
    <limit
      lower="-3.107"
      upper="3.107"
      effort="100"
      velocity="1" />
  </joint> -->
  <link
    name="Link2">
    <inertial>
      <origin
        xyz="0.17251 -1.2589E-07 -0.090386"
        rpy="0 0 0" />
      <mass
        value="1.5577" />
      <inertia
        ixx="0.0009796"
        ixy="-1.2068E-07"
        ixz="-2.8708E-05"
        iyy="0.026357"
        iyz="1.3036E-09"
        izz="0.026573" />
    </inertial>
    <visual>
      <origin
        xyz="0 0 0"
        rpy="0 0 0" />
      <geometry>
        <mesh
          filename="package://rm_description/meshes/RML63_6F/Link2.STL" />
      </geometry>
      <material
        name="">
        <color
          rgba="1 1 1 1" />
      </material>
    </visual>
    <collision>
      <origin
        xyz="0 0 0"
        rpy="0 0 0" />
      <geometry>
        <mesh
          filename="package://rm_description/meshes/RML63_6F/Link2.STL" />
      </geometry>
    </collision>
  </link>
  <joint
    name="joint2"
    type="revolute">
    <origin
      xyz="-0.086 0 0"
      rpy="-1.5708 -1.5708 0" />
    <parent
      link="Link1" />
    <child
      link="Link2" />
    <axis
      xyz="0 0 1" />
    <limit
      lower="-3.107"
      upper="3.107"
      effort="100"
      velocity="1" />
  </joint>
  <link
    name="Link3">
    <inertial>
      <origin
        xyz="0.036479 -0.021595 -0.0052425"
        rpy="0 0 0" />
      <mass
        value="0.71556" />
      <inertia
        ixx="0.00081897"
        ixy="0.0004323"
        ixz="-0.00015721"
        iyy="0.0011167"
        iyz="9.5746E-05"
        izz="0.0013828" />
    </inertial>
    <visual>
      <origin
        xyz="0 0 0"
        rpy="0 0 0" />
      <geometry>
        <mesh
          filename="package://rm_description/meshes/RML63_6F/Link3.STL" />
      </geometry>
      <material
        name="">
        <color
          rgba="1 1 1 1" />
      </material>
    </visual>
    <collision>
      <origin
        xyz="0 0 0"
        rpy="0 0 0" />
      <geometry>
        <mesh
          filename="package://rm_description/meshes/RML63_6F/Link3.STL" />
      </geometry>
    </collision>
  </link>
  <joint
    name="joint3"
    type="revolute">
    <origin
      xyz="0.38 0 -0.00010023"
      rpy="0 0 1.5708" />
    <parent
      link="Link2" />
    <child
      link="Link3" />
    <axis
      xyz="0 0 1" />
    <limit
      lower="-3.107"
      upper="2.531"
      effort="100"
      velocity="1" />
  </joint>
  <link
    name="Link4">
    <inertial>
      <origin
        xyz="-5.2717E-06 -0.033557 -0.18296"
        rpy="0 0 0" />
      <mass
        value="0.69692" />
      <inertia
        ixx="0.0071528"
        ixy="-6.0923E-09"
        ixz="8.8515E-08"
        iyy="0.006708"
        iyz="0.0016525"
        izz="0.00074662" />
    </inertial>
    <visual>
      <origin
        xyz="0 0 0"
        rpy="0 0 0" />
      <geometry>
        <mesh
          filename="package://rm_description/meshes/RML63_6F/Link4.STL" />
      </geometry>
      <material
        name="">
        <color
          rgba="1 1 1 1" />
      </material>
    </visual>
    <collision>
      <origin
        xyz="0 0 0"
        rpy="0 0 0" />
      <geometry>
        <mesh
          filename="package://rm_description/meshes/RML63_6F/Link4.STL" />
      </geometry>
    </collision>
  </link>
  <joint
    name="joint4"
    type="revolute">
    <origin
      xyz="0.069 -0.405 9.9684E-05"
      rpy="1.5708 0 0" />
    <parent
      link="Link3" />
    <child
      link="Link4" />
    <axis
      xyz="0 0 1" />
    <limit
      lower="-3.107"
      upper="3.107"
      effort="100"
      velocity="1" />
  </joint>
  <link
    name="Link5">
    <inertial>
      <origin
        xyz="-2.2615E-07 0.02789 -0.0066313"
        rpy="0 0 0" />
      <mass
        value="0.3567" />
      <inertia
        ixx="0.00041098"
        ixy="-8.4722E-09"
        ixz="-4.3897E-09"
        iyy="0.00017907"
        iyz="-8.7584E-05"
        izz="0.00038034" />
    </inertial>
    <visual>
      <origin
        xyz="0 0 0"
        rpy="0 0 0" />
      <geometry>
        <mesh
          filename="package://rm_description/meshes/RML63_6F/Link5.STL" />
      </geometry>
      <material
        name="">
        <color
          rgba="1 1 1 1" />
      </material>
    </visual>
    <collision>
      <origin
        xyz="0 0 0"
        rpy="0 0 0" />
      <geometry>
        <mesh
          filename="package://rm_description/meshes/RML63_6F/Link5.STL" />
      </geometry>
    </collision>
  </link>
  <joint
    name="joint5"
    type="revolute">
    <origin
      xyz="0 0 0"
      rpy="1.5708 0 3.1416" />
    <parent
      link="Link4" />
    <child
      link="Link5" />
    <axis
      xyz="0 0 1" />
    <limit
      lower="-3.107"
      upper="3.107"
      effort="100"
      velocity="1" />
  </joint>
  <link
    name="Link6">
    <inertial>
      <origin
        xyz="-0.00032091 0.00017748 -0.028468"
        rpy="0 0 0" />
      <mass
        value="0.14814" />
      <inertia
        ixx="7.2093E-05"
        ixy="-1.2989E-06"
        ixz="7.9524E-07"
        iyy="7.063E-05"
        iyz="-4.3017E-07"
        izz="6.2819E-05" />
    </inertial>
    <visual>
      <origin
        xyz="0 0 0"
        rpy="0 0 0" />
      <geometry>
        <mesh
          filename="package://rm_description/meshes/RML63_6F/Link6.STL" />
      </geometry>
      <material
        name="">
        <color
          rgba="1 1 1 1" />
      </material>
    </visual>
    <collision>
      <origin
        xyz="0 0 0"
        rpy="0 0 0" />
      <geometry>
        <mesh
          filename="package://rm_description/meshes/RML63_6F/Link6.STL" />
      </geometry>
    </collision>
  </link>
  <joint
    name="joint6"
    type="revolute">
    <origin
      xyz="0 0.1435 0"
      rpy="1.5708 3.14 -3.1416" />
    <parent
      link="Link5" />
    <child
      link="Link6" />
    <axis
      xyz="0 0 1" />
    <limit
      lower="-6.283"
      upper="6.283"
      effort="100"
      velocity="1" />
  </joint>

    <!-- Transmissions for ROS Control -->
    <xacro:macro name="transmission_block" params="joint_name">
      <transmission name="tran1">
        <type>transmission_interface/SimpleTransmission</type>
        <joint name="${joint_name}">
          <hardwareInterface>hardware_interface/PositionJointInterface</hardwareInterface>
        </joint>
        <actuator name="motor1">
          <hardwareInterface>hardware_interface/PositionJointInterface</hardwareInterface>
          <mechanicalReduction>1</mechanicalReduction>
        </actuator>
      </transmission>
    </xacro:macro>
      
    <xacro:transmission_block joint_name="joint1"/>
    <xacro:transmission_block joint_name="joint2"/>
    <xacro:transmission_block joint_name="joint3"/>
    <xacro:transmission_block joint_name="joint4"/>
    <xacro:transmission_block joint_name="joint5"/>
    <xacro:transmission_block joint_name="joint6"/>
  
    <!-- ros_control plugin -->
    <gazebo>
      <plugin name="gazebo_ros_control" filename="libgazebo_ros_control.so">
        <robotNamespace>/arm</robotNamespace>
        <robotSimType>gazebo_ros_control/DefaultRobotHWSim</robotSimType>
        <legacyModeNS>true</legacyModeNS>
      </plugin>
    </gazebo>
  </robot>
