<?xml version="1.0" ?>
<robot name="partnet_bc2daa0406ad3324d724d9ce5af6d8e">
	<link name="base"/>
	<link name="link_0">
		<visual name="door-1">
			<origin xyz="-0.792523 0.3494722979075207 -0.3645696355831424"/>
			<geometry>
				<mesh filename="textured_objs/original-36.obj"/>
			</geometry>
		</visual>
		<visual name="door-1">
			<origin xyz="-0.792523 0.3494722979075207 -0.3645696355831424"/>
			<geometry>
				<mesh filename="textured_objs/original-35.obj"/>
			</geometry>
		</visual>
		<visual name="door-1">
			<origin xyz="-0.792523 0.3494722979075207 -0.3645696355831424"/>
			<geometry>
				<mesh filename="textured_objs/original-29.obj"/>
			</geometry>
		</visual>
		<visual name="door-1">
			<origin xyz="-0.792523 0.3494722979075207 -0.3645696355831424"/>
			<geometry>
				<mesh filename="textured_objs/original-37.obj"/>
			</geometry>
		</visual>
		<collision>
			<origin xyz="-0.792523 0.3494722979075207 -0.3645696355831424"/>
			<geometry>
				<mesh filename="textured_objs/original-36.obj"/>
			</geometry>
		</collision>
		<collision>
			<origin xyz="-0.792523 0.3494722979075207 -0.3645696355831424"/>
			<geometry>
				<mesh filename="textured_objs/original-35.obj"/>
			</geometry>
		</collision>
		<collision>
			<origin xyz="-0.792523 0.3494722979075207 -0.3645696355831424"/>
			<geometry>
				<mesh filename="textured_objs/original-29.obj"/>
			</geometry>
		</collision>
		<collision>
			<origin xyz="-0.792523 0.3494722979075207 -0.3645696355831424"/>
			<geometry>
				<mesh filename="textured_objs/original-37.obj"/>
			</geometry>
		</collision>
	</link>
	<joint name="joint_0" type="revolute">
		<origin xyz="0.792523 -0.3494722979075207 0.3645696355831424"/>
		<axis xyz="1 0 0"/>
		<child link="link_0"/>
		<parent link="link_8"/>
		<limit lower="-0.0" upper="1.5707963267948966"/>
	</joint>
	<link name="link_1">
		<visual name="door-2">
			<origin xyz="-0.792523 0.3494722979075207 -0.3645696355831424"/>
			<geometry>
				<mesh filename="textured_objs/original-30.obj"/>
			</geometry>
		</visual>
		<visual name="door-2">
			<origin xyz="-0.792523 0.3494722979075207 -0.3645696355831424"/>
			<geometry>
				<mesh filename="textured_objs/original-40.obj"/>
			</geometry>
		</visual>
		<visual name="door-2">
			<origin xyz="-0.792523 0.3494722979075207 -0.3645696355831424"/>
			<geometry>
				<mesh filename="textured_objs/original-38.obj"/>
			</geometry>
		</visual>
		<visual name="door-2">
			<origin xyz="-0.792523 0.3494722979075207 -0.3645696355831424"/>
			<geometry>
				<mesh filename="textured_objs/original-39.obj"/>
			</geometry>
		</visual>
		<collision>
			<origin xyz="-0.792523 0.3494722979075207 -0.3645696355831424"/>
			<geometry>
				<mesh filename="textured_objs/original-30.obj"/>
			</geometry>
		</collision>
		<collision>
			<origin xyz="-0.792523 0.3494722979075207 -0.3645696355831424"/>
			<geometry>
				<mesh filename="textured_objs/original-40.obj"/>
			</geometry>
		</collision>
		<collision>
			<origin xyz="-0.792523 0.3494722979075207 -0.3645696355831424"/>
			<geometry>
				<mesh filename="textured_objs/original-38.obj"/>
			</geometry>
		</collision>
		<collision>
			<origin xyz="-0.792523 0.3494722979075207 -0.3645696355831424"/>
			<geometry>
				<mesh filename="textured_objs/original-39.obj"/>
			</geometry>
		</collision>
	</link>
	<joint name="joint_1" type="revolute">
		<origin xyz="0.792523 -0.3494722979075207 0.3645696355831424"/>
		<axis xyz="1 0 0"/>
		<child link="link_1"/>
		<parent link="link_8"/>
		<limit lower="-0.0" upper="1.5707963267948966"/>
	</joint>
	<link name="link_2">
		<visual name="knob-3">
			<origin xyz="-0.6224884902815526 -0.041806286052816756 0.041797237383566235"/>
			<geometry>
				<mesh filename="textured_objs/original-24.obj"/>
			</geometry>
		</visual>
		<collision>
			<origin xyz="-0.6224884902815526 -0.041806286052816756 0.041797237383566235"/>
			<geometry>
				<mesh filename="textured_objs/original-24.obj"/>
			</geometry>
		</collision>
	</link>
	<joint name="joint_2" type="continuous">
		<origin xyz="0.6224884902815526 0.041806286052816756 -0.041797237383566235"/>
		<axis xyz="0 -0.7070302586201284 -0.707183295472648"/>
		<child link="link_2"/>
		<parent link="link_8"/>
	</joint>
	<link name="link_3">
		<visual name="knob-4">
			<origin xyz="-0.31255450971844734 -0.04180628605281679 0.04179723738356627"/>
			<geometry>
				<mesh filename="textured_objs/original-21.obj"/>
			</geometry>
		</visual>
		<collision>
			<origin xyz="-0.31255450971844734 -0.04180628605281679 0.04179723738356627"/>
			<geometry>
				<mesh filename="textured_objs/original-21.obj"/>
			</geometry>
		</collision>
	</link>
	<joint name="joint_3" type="continuous">
		<origin xyz="0.31255450971844734 0.04180628605281679 -0.04179723738356627"/>
		<axis xyz="0 -0.7070302586201284 -0.7071832954726479"/>
		<child link="link_3"/>
		<parent link="link_8"/>
	</joint>
	<link name="link_4">
		<visual name="knob-5">
			<origin xyz="-0.0801045 -0.005276350572734332 0.005275208544688067"/>
			<geometry>
				<mesh filename="textured_objs/original-25.obj"/>
			</geometry>
		</visual>
		<collision>
			<origin xyz="-0.0801045 -0.005276350572734332 0.005275208544688067"/>
			<geometry>
				<mesh filename="textured_objs/original-25.obj"/>
			</geometry>
		</collision>
	</link>
	<joint name="joint_4" type="continuous">
		<origin xyz="0.0801045 0.005276350572734332 -0.005275208544688067"/>
		<axis xyz="0 0.7070302586201284 0.7071832954726479"/>
		<child link="link_4"/>
		<parent link="link_8"/>
	</joint>
	<link name="link_5">
		<visual name="knob-6">
			<origin xyz="0.0748625 -0.005276350572734331 0.005275208544688067"/>
			<geometry>
				<mesh filename="textured_objs/original-20.obj"/>
			</geometry>
		</visual>
		<collision>
			<origin xyz="0.0748625 -0.005276350572734331 0.005275208544688067"/>
			<geometry>
				<mesh filename="textured_objs/original-20.obj"/>
			</geometry>
		</collision>
	</link>
	<joint name="joint_5" type="continuous">
		<origin xyz="-0.0748625 0.005276350572734331 -0.005275208544688067"/>
		<axis xyz="0 0.7070302586201284 0.7071832954726479"/>
		<child link="link_5"/>
		<parent link="link_8"/>
	</joint>
	<link name="link_6">
		<visual name="knob-7">
			<origin xyz="0.30731250969002527 -0.04171795072480092 0.04172698222931051"/>
			<geometry>
				<mesh filename="textured_objs/original-23.obj"/>
			</geometry>
		</visual>
		<collision>
			<origin xyz="0.30731250969002527 -0.04171795072480092 0.04172698222931051"/>
			<geometry>
				<mesh filename="textured_objs/original-23.obj"/>
			</geometry>
		</collision>
	</link>
	<joint name="joint_6" type="continuous">
		<origin xyz="-0.30731250969002527 0.04171795072480092 -0.04172698222931051"/>
		<axis xyz="0 -0.7071832954726479 -0.7070302586201284"/>
		<child link="link_6"/>
		<parent link="link_8"/>
	</joint>
	<link name="link_7">
		<visual name="knob-8">
			<origin xyz="0.6172464999999999 -0.04171473445590719 0.041724426474867085"/>
			<geometry>
				<mesh filename="textured_objs/original-22.obj"/>
			</geometry>
		</visual>
		<collision>
			<origin xyz="0.6172464999999999 -0.04171473445590719 0.041724426474867085"/>
			<geometry>
				<mesh filename="textured_objs/original-22.obj"/>
			</geometry>
		</collision>
	</link>
	<joint name="joint_7" type="continuous">
		<origin xyz="-0.6172464999999999 0.04171473445590719 -0.041724426474867085"/>
		<axis xyz="0 -0.7071888931036371 -0.7070246597332039"/>
		<child link="link_7"/>
		<parent link="link_8"/>
	</joint>
	<link name="link_8">
		<visual name="base_body-9">
			<origin xyz="0 0 0"/>
			<geometry>
				<mesh filename="textured_objs/original-28.obj"/>
			</geometry>
		</visual>
		<visual name="base_body-9">
			<origin xyz="0 0 0"/>
			<geometry>
				<mesh filename="textured_objs/original-26.obj"/>
			</geometry>
		</visual>
		<visual name="base_body-9">
			<origin xyz="0 0 0"/>
			<geometry>
				<mesh filename="textured_objs/original-3.obj"/>
			</geometry>
		</visual>
		<visual name="base_body-9">
			<origin xyz="0 0 0"/>
			<geometry>
				<mesh filename="textured_objs/original-33.obj"/>
			</geometry>
		</visual>
		<visual name="base_body-9">
			<origin xyz="0 0 0"/>
			<geometry>
				<mesh filename="textured_objs/original-2.obj"/>
			</geometry>
		</visual>
		<visual name="base_body-9">
			<origin xyz="0 0 0"/>
			<geometry>
				<mesh filename="textured_objs/original-16.obj"/>
			</geometry>
		</visual>
		<visual name="base_body-9">
			<origin xyz="0 0 0"/>
			<geometry>
				<mesh filename="textured_objs/original-13.obj"/>
			</geometry>
		</visual>
		<visual name="base_body-9">
			<origin xyz="0 0 0"/>
			<geometry>
				<mesh filename="textured_objs/original-9.obj"/>
			</geometry>
		</visual>
		<visual name="base_body-9">
			<origin xyz="0 0 0"/>
			<geometry>
				<mesh filename="textured_objs/original-27.obj"/>
			</geometry>
		</visual>
		<visual name="base_body-9">
			<origin xyz="0 0 0"/>
			<geometry>
				<mesh filename="textured_objs/original-6.obj"/>
			</geometry>
		</visual>
		<visual name="base_body-9">
			<origin xyz="0 0 0"/>
			<geometry>
				<mesh filename="textured_objs/original-31.obj"/>
			</geometry>
		</visual>
		<visual name="base_body-9">
			<origin xyz="0 0 0"/>
			<geometry>
				<mesh filename="textured_objs/original-15.obj"/>
			</geometry>
		</visual>
		<visual name="base_body-9">
			<origin xyz="0 0 0"/>
			<geometry>
				<mesh filename="textured_objs/original-11.obj"/>
			</geometry>
		</visual>
		<visual name="base_body-9">
			<origin xyz="0 0 0"/>
			<geometry>
				<mesh filename="textured_objs/original-34.obj"/>
			</geometry>
		</visual>
		<visual name="base_body-9">
			<origin xyz="0 0 0"/>
			<geometry>
				<mesh filename="textured_objs/original-18.obj"/>
			</geometry>
		</visual>
		<visual name="base_body-9">
			<origin xyz="0 0 0"/>
			<geometry>
				<mesh filename="textured_objs/original-17.obj"/>
			</geometry>
		</visual>
		<visual name="base_body-9">
			<origin xyz="0 0 0"/>
			<geometry>
				<mesh filename="textured_objs/original-12.obj"/>
			</geometry>
		</visual>
		<visual name="base_body-9">
			<origin xyz="0 0 0"/>
			<geometry>
				<mesh filename="textured_objs/original-32.obj"/>
			</geometry>
		</visual>
		<visual name="base_body-9">
			<origin xyz="0 0 0"/>
			<geometry>
				<mesh filename="textured_objs/original-7.obj"/>
			</geometry>
		</visual>
		<visual name="base_body-9">
			<origin xyz="0 0 0"/>
			<geometry>
				<mesh filename="textured_objs/original-1.obj"/>
			</geometry>
		</visual>
		<visual name="base_body-9">
			<origin xyz="0 0 0"/>
			<geometry>
				<mesh filename="textured_objs/original-10.obj"/>
			</geometry>
		</visual>
		<visual name="base_body-9">
			<origin xyz="0 0 0"/>
			<geometry>
				<mesh filename="textured_objs/original-14.obj"/>
			</geometry>
		</visual>
		<collision>
			<origin xyz="0 0 0"/>
			<geometry>
				<mesh filename="textured_objs/original-28.obj"/>
			</geometry>
		</collision>
		<collision>
			<origin xyz="0 0 0"/>
			<geometry>
				<mesh filename="textured_objs/original-26.obj"/>
			</geometry>
		</collision>
		<collision>
			<origin xyz="0 0 0"/>
			<geometry>
				<mesh filename="textured_objs/original-3.obj"/>
			</geometry>
		</collision>
		<collision>
			<origin xyz="0 0 0"/>
			<geometry>
				<mesh filename="textured_objs/original-33.obj"/>
			</geometry>
		</collision>
		<collision>
			<origin xyz="0 0 0"/>
			<geometry>
				<mesh filename="textured_objs/original-2.obj"/>
			</geometry>
		</collision>
		<collision>
			<origin xyz="0 0 0"/>
			<geometry>
				<mesh filename="textured_objs/original-16.obj"/>
			</geometry>
		</collision>
		<collision>
			<origin xyz="0 0 0"/>
			<geometry>
				<mesh filename="textured_objs/original-13.obj"/>
			</geometry>
		</collision>
		<collision>
			<origin xyz="0 0 0"/>
			<geometry>
				<mesh filename="textured_objs/original-9.obj"/>
			</geometry>
		</collision>
		<collision>
			<origin xyz="0 0 0"/>
			<geometry>
				<mesh filename="textured_objs/original-27.obj"/>
			</geometry>
		</collision>
		<collision>
			<origin xyz="0 0 0"/>
			<geometry>
				<mesh filename="textured_objs/original-6.obj"/>
			</geometry>
		</collision>
		<collision>
			<origin xyz="0 0 0"/>
			<geometry>
				<mesh filename="textured_objs/original-31.obj"/>
			</geometry>
		</collision>
		<collision>
			<origin xyz="0 0 0"/>
			<geometry>
				<mesh filename="textured_objs/original-15.obj"/>
			</geometry>
		</collision>
		<collision>
			<origin xyz="0 0 0"/>
			<geometry>
				<mesh filename="textured_objs/original-11.obj"/>
			</geometry>
		</collision>
		<collision>
			<origin xyz="0 0 0"/>
			<geometry>
				<mesh filename="textured_objs/original-34.obj"/>
			</geometry>
		</collision>
		<collision>
			<origin xyz="0 0 0"/>
			<geometry>
				<mesh filename="textured_objs/original-18.obj"/>
			</geometry>
		</collision>
		<collision>
			<origin xyz="0 0 0"/>
			<geometry>
				<mesh filename="textured_objs/original-17.obj"/>
			</geometry>
		</collision>
		<collision>
			<origin xyz="0 0 0"/>
			<geometry>
				<mesh filename="textured_objs/original-12.obj"/>
			</geometry>
		</collision>
		<collision>
			<origin xyz="0 0 0"/>
			<geometry>
				<mesh filename="textured_objs/original-32.obj"/>
			</geometry>
		</collision>
		<collision>
			<origin xyz="0 0 0"/>
			<geometry>
				<mesh filename="textured_objs/original-7.obj"/>
			</geometry>
		</collision>
		<collision>
			<origin xyz="0 0 0"/>
			<geometry>
				<mesh filename="textured_objs/original-1.obj"/>
			</geometry>
		</collision>
		<collision>
			<origin xyz="0 0 0"/>
			<geometry>
				<mesh filename="textured_objs/original-10.obj"/>
			</geometry>
		</collision>
		<collision>
			<origin xyz="0 0 0"/>
			<geometry>
				<mesh filename="textured_objs/original-14.obj"/>
			</geometry>
		</collision>
	</link>
	<joint name="joint_8" type="fixed">
		<origin rpy="1.570796326794897 0 -1.570796326794897" xyz="0 0 0"/>
		<child link="link_8"/>
		<parent link="base"/>
	</joint>
</robot>
