<?xml version="1.0"?>
<!-- =================================================================================== -->
<!-- |    This document was autogenerated by xacro from cobot_description_rm_63.urdf.xacro | -->
<!-- |    EDITING THIS FILE BY HAND IS NOT RECOMMENDED                                 | -->
<!-- =================================================================================== -->
<!-- This URDF was automatically created by SolidWorks to URDF Exporter! Originally created by
Stephen Brawner (brawner@gmail.com) 
     Commit Version: 1.6.0-1-g15f4949  Build Version: 1.6.7594.29634
     For more information, please see http://wiki.ros.org/sw_urdf_exporter -->

<robot name="rm63_6f_ag95">
    <!-- arm -->
    <link name="Link1">
        <inertial>
            <origin rpy="0 0 0" xyz="-0.043398 -0.0074204 -0.012727" />
            <mass value="0.92308" />
            <inertia ixx="0.00093348" ixy="-0.00032512" ixz="0.00049759" iyy="0.0021248"
                iyz="0.00010864" izz="0.001984" />
        </inertial>
        <visual>
            <origin rpy="0 0 0" xyz="0 0 0" />
            <geometry>
                <mesh filename="../meshes/RML63_6F/Link1.STL" />
            </geometry>
            <material name="">
                <color rgba="1 1 1 1" />
            </material>
        </visual>
        <collision>
            <origin rpy="0 0 0" xyz="0 0 0" />
            <geometry>
                <mesh filename="../meshes/RML63_6F/Link1.STL" />
            </geometry>
        </collision>
    </link>

    <joint name="joint1" type="revolute">
        <origin rpy="-1.5708 -1.5708 0" xyz="-0.086 0 0" />
        <parent link="Link1" />
        <child link="Link2" />
        <axis xyz="0 0 1" />
        <limit effort="100" lower="-3.107" upper="3.107" velocity="1" />
    </joint>

    <transmission name="tran1">
        <type>transmission_interface/SimpleTransmission</type>
        <joint name="joint1">
            <hardwareInterface>hardware_interface/PositionJointInterface</hardwareInterface>
        </joint>
        <actuator name="motor1">
            <hardwareInterface>hardware_interface/PositionJointInterface</hardwareInterface>
            <mechanicalReduction>1</mechanicalReduction>
        </actuator>
    </transmission>

    <link name="Link2">
        <inertial>
            <origin rpy="0 0 0" xyz="0.17251 -1.2589E-07 -0.090386" />
            <mass value="1.5577" />
            <inertia ixx="0.0009796" ixy="-1.2068E-07" ixz="-2.8708E-05" iyy="0.026357"
                iyz="1.3036E-09" izz="0.026573" />
        </inertial>
        <visual>
            <origin rpy="0 0 0" xyz="0 0 0" />
            <geometry>
                <mesh filename="../meshes/RML63_6F/Link2.STL" />
            </geometry>
            <material name="">
                <color rgba="1 1 1 1" />
            </material>
        </visual>
        <collision>
            <origin rpy="0 0 0" xyz="0 0 0" />
            <geometry>
                <mesh filename="../meshes/RML63_6F/Link2.STL" />
            </geometry>
        </collision>
    </link>

    <joint name="joint2" type="revolute">
        <origin rpy="0 0 1.5708" xyz="0.38 0 -0.00010023" />
        <parent link="Link2" />
        <child link="Link3" />
        <axis xyz="0 0 1" />
        <limit effort="100" lower="-3.107" upper="2.531" velocity="1" />
    </joint>

    <transmission name="tran1">
        <type>transmission_interface/SimpleTransmission</type>
        <joint name="joint2">
            <hardwareInterface>hardware_interface/PositionJointInterface</hardwareInterface>
        </joint>
        <actuator name="motor1">
            <hardwareInterface>hardware_interface/PositionJointInterface</hardwareInterface>
            <mechanicalReduction>1</mechanicalReduction>
        </actuator>
    </transmission>

    <link name="Link3">
        <inertial>
            <origin rpy="0 0 0" xyz="0.036479 -0.021595 -0.0052425" />
            <mass value="0.71556" />
            <inertia ixx="0.00081897" ixy="0.0004323" ixz="-0.00015721" iyy="0.0011167"
                iyz="9.5746E-05" izz="0.0013828" />
        </inertial>
        <visual>
            <origin rpy="0 0 0" xyz="0 0 0" />
            <geometry>
                <mesh filename="../meshes/RML63_6F/Link3.STL" />
            </geometry>
            <material name="">
                <color rgba="1 1 1 1" />
            </material>
        </visual>
        <collision>
            <origin rpy="0 0 0" xyz="0 0 0" />
            <geometry>
                <mesh filename="../meshes/RML63_6F/Link3.STL" />
            </geometry>
        </collision>
    </link>

    <joint name="joint3" type="revolute">
        <origin rpy="1.5708 0 0" xyz="0.069 -0.405 9.9684E-05" />
        <parent link="Link3" />
        <child link="Link4" />
        <axis xyz="0 0 1" />
        <limit effort="100" lower="-3.107" upper="3.107" velocity="1" />
    </joint>

    <transmission name="tran1">
        <type>transmission_interface/SimpleTransmission</type>
        <joint name="joint3">
            <hardwareInterface>hardware_interface/PositionJointInterface</hardwareInterface>
        </joint>
        <actuator name="motor1">
            <hardwareInterface>hardware_interface/PositionJointInterface</hardwareInterface>
            <mechanicalReduction>1</mechanicalReduction>
        </actuator>
    </transmission>

    <link name="Link4">
        <inertial>
            <origin rpy="0 0 0" xyz="-5.2717E-06 -0.033557 -0.18296" />
            <mass value="0.69692" />
            <inertia ixx="0.0071528" ixy="-6.0923E-09" ixz="8.8515E-08" iyy="0.006708"
                iyz="0.0016525" izz="0.00074662" />
        </inertial>
        <visual>
            <origin rpy="0 0 0" xyz="0 0 0" />
            <geometry>
                <mesh filename="../meshes/RML63_6F/Link4.STL" />
            </geometry>
            <material name="">
                <color rgba="1 1 1 1" />
            </material>
        </visual>
        <collision>
            <origin rpy="0 0 0" xyz="0 0 0" />
            <geometry>
                <mesh filename="../meshes/RML63_6F/Link4.STL" />
            </geometry>
        </collision>
    </link>

    <joint name="joint4" type="revolute">
        <origin rpy="1.5708 0 3.1416" xyz="0 0 0" />
        <parent link="Link4" />
        <child link="Link5" />
        <axis xyz="0 0 1" />
        <limit effort="100" lower="-3.107" upper="3.107" velocity="1" />
    </joint>

    <transmission name="tran1">
        <type>transmission_interface/SimpleTransmission</type>
        <joint name="joint4">
            <hardwareInterface>hardware_interface/PositionJointInterface</hardwareInterface>
        </joint>
        <actuator name="motor1">
            <hardwareInterface>hardware_interface/PositionJointInterface</hardwareInterface>
            <mechanicalReduction>1</mechanicalReduction>
        </actuator>
    </transmission>

    <link name="Link5">
        <inertial>
            <origin rpy="0 0 0" xyz="-2.2615E-07 0.02789 -0.0066313" />
            <mass value="0.3567" />
            <inertia ixx="0.00041098" ixy="-8.4722E-09" ixz="-4.3897E-09" iyy="0.00017907"
                iyz="-8.7584E-05" izz="0.00038034" />
        </inertial>
        <visual>
            <origin rpy="0 0 0" xyz="0 0 0" />
            <geometry>
                <mesh filename="../meshes/RML63_6F/Link5.STL" />
            </geometry>
            <material name="">
                <color rgba="1 1 1 1" />
            </material>
        </visual>
        <collision>
            <origin rpy="0 0 0" xyz="0 0 0" />
            <geometry>
                <mesh filename="../meshes/RML63_6F/Link5.STL" />
            </geometry>
        </collision>
    </link>

    <joint name="joint5" type="revolute">
        <origin rpy="1.5708 3.14 -3.1416" xyz="0 0.1435 0" />
        <parent link="Link5" />
        <child link="Link6" />
        <axis xyz="0 0 1" />
        <limit effort="100" lower="-6.283" upper="6.283" velocity="1" />
    </joint>

    <transmission name="tran1">
        <type>transmission_interface/SimpleTransmission</type>
        <joint name="joint5">
            <hardwareInterface>hardware_interface/PositionJointInterface</hardwareInterface>
        </joint>
        <actuator name="motor1">
            <hardwareInterface>hardware_interface/PositionJointInterface</hardwareInterface>
            <mechanicalReduction>1</mechanicalReduction>
        </actuator>
    </transmission>

    <link name="Link6">
        <inertial>
            <origin rpy="0 0 0" xyz="-0.00032091 0.00017748 -0.028468" />
            <mass value="0.14814" />
            <inertia ixx="7.2093E-05" ixy="-1.2989E-06" ixz="7.9524E-07" iyy="7.063E-05"
                iyz="-4.3017E-07" izz="6.2819E-05" />
        </inertial>
        <visual>
            <origin rpy="0 0 0" xyz="0 0 0" />
            <geometry>
                <mesh filename="../meshes/RML63_6F/Link6.STL" />
            </geometry>
            <material name="">
                <color rgba="1 1 1 1" />
            </material>
        </visual>
        <collision>
            <origin rpy="0 0 0" xyz="0 0 0" />
            <geometry>
                <mesh filename="../meshes/RML63_6F/Link6.STL" />
            </geometry>
        </collision>
    </link>

    <!-- connect arm with gripper -->
    <joint name="hand_joint" type="fixed">
        <origin rpy="0 0 0.25" xyz="0 0 0.02" />
        <parent link="Link6" />
        <child link="dh_robotics_ag95_base_link" />
    </joint>

    <!-- gripper -->
    <link name="dh_robotics_ag95_base_link">
        <inertial>
            <origin rpy="0 0 0" xyz="0 0 0" />
            <mass value="0.22652" />
            <inertia ixx="0.00020005" ixy="-4.2442E-10" ixz="-2.9069E-10" iyy="0.00017832"
                iyz="-3.4402E-08" izz="0.00013478" />
        </inertial>
        <visual>
            <origin rpy="0 0 0" xyz="0 0 0" />
            <geometry>
                <mesh filename="../../../end_effector/gripper/ag95/meshes/base_link.STL"
                    scale="1 1 1" />
            </geometry>
            <material name="">
                <color rgba="0.1 0.1 0.1 1" />
            </material>
        </visual>
        <collision>
            <origin rpy="0 0 0" xyz="0 0 0" />
            <geometry>
                <mesh filename="../../../end_effector/gripper/ag95/meshes/base_link.STL" />
            </geometry>
        </collision>
    </link>

    <joint name="left_proximal_phalanx_joint" type="revolute">
        <origin rpy="-0.801 0 0.0" xyz="0 0.016 0.10586" />
        <parent link="dh_robotics_ag95_base_link" />
        <child link="left_proximal_phalanx" />
        <axis xyz="1 0 0" />
        <limit effort="1000" lower="0" upper="0.8757" velocity="1.0" />
        <mimic joint="finger_joint" multiplier="1.451855" offset="0" />
    </joint>

    <link name="left_proximal_phalanx">
        <inertial>
            <origin rpy="0 0 0" xyz="0.000123011831763771 0.0507850843201817 0.00103968640075166" />
            <mass value="0.0271177346495152" />
            <inertia ixx="2.61910379223783E-05" ixy="-2.43616858946494E-07"
                ixz="-6.37789906117123E-09" iyy="2.8270243746167E-06" iyz="-5.37200748039765E-07"
                izz="2.83695868220296E-05" />
        </inertial>
        <visual>
            <origin rpy="0 0 0" xyz="0 0 0" />
            <geometry>
                <mesh filename="../../../end_effector/gripper/ag95/meshes/link_proximal_phalanx.STL"
                    scale="1 1 1" />
            </geometry>
            <material name="">
                <color rgba="0.1 0.1 0.1 1" />
            </material>
        </visual>
        <collision>
            <origin rpy="0 0 0" xyz="0 0 0" />
            <geometry>
                <mesh filename="../../../end_effector/gripper/ag95/meshes/link_proximal_phalanx.STL"
                    scale="1 1 1" />
            </geometry>
        </collision>
    </link>

    <joint name="finger_joint" type="revolute">
        <origin rpy="-0.6523  0 0 " xyz="0 0.016 0.10586 " />
        <parent link="dh_robotics_ag95_base_link" />
        <child link="left_crank" />
        <axis xyz="1 0 0" />
        <limit effort="1000" lower="0" upper="0.6524" velocity="1.0" />
    </joint>

    <transmission name="finger_joint_trans">
        <type>transmission_interface/SimpleTransmission</type>
        <joint name="finger_joint">
            <hardwareInterface>PositionJointInterface</hardwareInterface>
        </joint>
        <actuator name="finger_joint_motor">
            <mechanicalReduction>1</mechanicalReduction>
        </actuator>
    </transmission>

    <link name="left_crank">
        <inertial>
            <origin rpy="0 0 0" xyz="-0.000200000000003065 0.0199435877845359 0.0292245259211331" />
            <mass value="0.00853198276973456" />
            <inertia ixx="2.89328108496468E-06" ixy="-1.57935047237397E-19"
                ixz="-1.93980378593255E-19" iyy="1.86719750325683E-06" iyz="-1.21858577871576E-06"
                izz="1.21905238907251E-06" />
        </inertial>
        <visual>
            <origin rpy="0 0 0" xyz="0 0 0" />
            <geometry>
                <mesh filename="../../../end_effector/gripper/ag95/meshes/link_crank.STL"
                    scale="1 1 1" />
            </geometry>
            <material name="">
                <color rgba="0.1 0.1 0.1 1" />
            </material>
        </visual>
        <collision>
            <origin rpy="0 0 0" xyz="0 0 0" />
            <geometry>
                <mesh filename="../../../end_effector/gripper/ag95/meshes/link_crank.STL"
                    scale="1 1 1" />
            </geometry>
        </collision>
    </link>

    <joint name="left_rod_joint" type="revolute">
        <origin rpy="0.29795 0 0" xyz="0 0.037 0" />
        <parent link="left_crank" />
        <child link="left_rod" />
        <axis xyz="1 0 0" />
        <limit effort="1000" lower="-1" upper="0" velocity="1.0" />
        <mimic joint="finger_joint" multiplier="0.4563942" offset="0" />
    </joint>

    <link name="left_rod">
        <inertial>
            <origin rpy="0 0 0" xyz="0.00030115855001899 0.0373907951953854 -0.0208027427000385" />
            <mass value="0.022614240507152" />
            <inertia ixx="1.52518312458174E-05" ixy="9.76583423954399E-10"
                ixz="-5.43838577022588E-10" iyy="6.17694243867776E-06" iyz="6.78636130740228E-06"
                izz="1.16494917907219E-05" />
        </inertial>
        <visual>
            <origin rpy="0 0 0" xyz="0 0 0" />
            <geometry>
                <mesh filename="../../../end_effector/gripper/ag95/meshes/link_rod.STL"
                    scale="1 1 1" />
            </geometry>
            <material name="">
                <color rgba="0.1 0.1 0.1 1" />
            </material>
        </visual>
        <collision>
            <origin rpy="0 0 0" xyz="0 0 0" />
            <geometry>
                <mesh filename="../../../end_effector/gripper/ag95/meshes/link_rod.STL"
                    scale="1 1 1" />
            </geometry>
        </collision>
    </link>

    <joint name="left_distal_phalanx_joint" type="revolute">
        <origin rpy="0.0132645 0 0" xyz="0 0 0.06083" />
        <parent link="left_rod" />
        <child link="left_distal_phalanx" />
        <axis xyz="1 0 0" />
        <limit effort="1000" lower="-1" upper="0" velocity="1.0" />
        <mimic joint="finger_joint" multiplier="-1.4563851" offset="0" />
    </joint>

    <link name="left_distal_phalanx">
        <inertial>
            <origin rpy="0 0 0" xyz="0.000299999999999317 0.0160078233491243 -0.0136945669206257" />
            <mass value="0.0104003125914103" />
            <inertia ixx="2.71909453810972E-06" ixy="1.35402465472579E-21"
                ixz="-7.1817349065269E-22" iyy="7.69100314106116E-07" iyz="6.74715432769696E-07"
                izz="2.30315190420171E-06" />
        </inertial>
        <visual>
            <origin rpy="0 0 0" xyz="0 0 0" />
            <geometry>
                <mesh filename="../../../end_effector/gripper/ag95/meshes/link_distal_phalanx.STL"
                    scale="1 1 1" />
            </geometry>
            <material name="">
                <color rgba="0.792156862745098 0.819607843137255 0.933333333333333 1" />
            </material>
        </visual>
        <collision>
            <origin rpy="0 0 0" xyz="0 0 0" />
            <geometry>
                <mesh filename="../../../end_effector/gripper/ag95/meshes/link_distal_phalanx.STL"
                    scale="1 1 1" />
            </geometry>
        </collision>
    </link>

    <joint name="right_proximal_phalanx_joint" type="revolute">
        <origin rpy="-0.801 0 3.141592653589793" xyz="0 -0.016 0.10586" />
        <parent link="dh_robotics_ag95_base_link" />
        <child link="right_proximal_phalanx" />
        <axis xyz="1 0 0" />
        <limit effort="1000" lower="0" upper="0.8757" velocity="1.0" />
        <mimic joint="finger_joint" multiplier="1.451855" offset="0" />
    </joint>

    <link name="right_proximal_phalanx">
        <inertial>
            <origin rpy="0 0 0" xyz="0.000123011831763771 0.0507850843201817 0.00103968640075166" />
            <mass value="0.0271177346495152" />
            <inertia ixx="2.61910379223783E-05" ixy="-2.43616858946494E-07"
                ixz="-6.37789906117123E-09" iyy="2.8270243746167E-06" iyz="-5.37200748039765E-07"
                izz="2.83695868220296E-05" />
        </inertial>
        <visual>
            <origin rpy="0 0 0" xyz="0 0 0" />
            <geometry>
                <mesh filename="../../../end_effector/gripper/ag95/meshes/link_proximal_phalanx.STL"
                    scale="1 1 1" />
            </geometry>
            <material name="">
                <color rgba="0.1 0.1 0.1 1" />
            </material>
        </visual>
        <collision>
            <origin rpy="0 0 0" xyz="0 0 0" />
            <geometry>
                <mesh filename="../../../end_effector/gripper/ag95/meshes/link_proximal_phalanx.STL"
                    scale="1 1 1" />
            </geometry>
        </collision>
    </link>

    <joint name="right_crank_joint" type="revolute">
        <origin rpy="-0.6523  0 3.141592653589793 " xyz="0 -0.016 0.10586 " />
        <parent link="dh_robotics_ag95_base_link" />
        <child link="right_crank" />
        <axis xyz="1 0 0" />
        <limit effort="1000" lower="0" upper="0.6524" velocity="1.0" />
        <mimic joint="finger_joint" multiplier="1" offset="0" />
    </joint>

    <link name="right_crank">
        <inertial>
            <origin rpy="0 0 0" xyz="-0.000200000000003065 0.0199435877845359 0.0292245259211331" />
            <mass value="0.00853198276973456" />
            <inertia ixx="2.89328108496468E-06" ixy="-1.57935047237397E-19"
                ixz="-1.93980378593255E-19" iyy="1.86719750325683E-06" iyz="-1.21858577871576E-06"
                izz="1.21905238907251E-06" />
        </inertial>
        <visual>
            <origin rpy="0 0 0" xyz="0 0 0" />
            <geometry>
                <mesh filename="../../../end_effector/gripper/ag95/meshes/link_crank.STL"
                    scale="1 1 1" />
            </geometry>
            <material name="">
                <color rgba="0.1 0.1 0.1 1" />
            </material>
        </visual>
        <collision>
            <origin rpy="0 0 0" xyz="0 0 0" />
            <geometry>
                <mesh filename="../../../end_effector/gripper/ag95/meshes/link_crank.STL"
                    scale="1 1 1" />
            </geometry>
        </collision>
    </link>

    <joint name="right_rod_joint" type="revolute">
        <origin rpy="0.29795 0 0" xyz="0 0.037 0" />
        <parent link="right_crank" />
        <child link="right_rod" />
        <axis xyz="1 0 0" />
        <limit effort="1000" lower="-1" upper="0" velocity="1.0" />
        <mimic joint="finger_joint" multiplier="0.4563942" offset="0" />
    </joint>

    <link name="right_rod">
        <inertial>
            <origin rpy="0 0 0" xyz="0.00030115855001899 0.0373907951953854 -0.0208027427000385" />
            <mass value="0.022614240507152" />
            <inertia ixx="1.52518312458174E-05" ixy="9.76583423954399E-10"
                ixz="-5.43838577022588E-10" iyy="6.17694243867776E-06" iyz="6.78636130740228E-06"
                izz="1.16494917907219E-05" />
        </inertial>
        <visual>
            <origin rpy="0 0 0" xyz="0 0 0" />
            <geometry>
                <mesh filename="../../../end_effector/gripper/ag95/meshes/link_rod.STL"
                    scale="1 1 1" />
            </geometry>
            <material name="">
                <color rgba="0.1 0.1 0.1 1" />
            </material>
        </visual>
        <collision>
            <origin rpy="0 0 0" xyz="0 0 0" />
            <geometry>
                <mesh filename="../../../end_effector/gripper/ag95/meshes/link_rod.STL"
                    scale="1 1 1" />
            </geometry>
        </collision>
    </link>

    <joint name="right_distal_phalanx_joint" type="revolute">
        <origin rpy="0.0132645 0 0" xyz="0 0 0.06083" />
        <parent link="right_rod" />
        <child link="right_distal_phalanx" />
        <axis xyz="1 0 0" />
        <limit effort="1000" lower="-1" upper="0" velocity="1.0" />
        <mimic joint="finger_joint" multiplier="-1.4563851" offset="0" />
    </joint>

    <link name="right_distal_phalanx">
        <inertial>
            <origin rpy="0 0 0" xyz="0.000299999999999317 0.0160078233491243 -0.0136945669206257" />
            <mass value="0.0104003125914103" />
            <inertia ixx="2.71909453810972E-06" ixy="1.35402465472579E-21"
                ixz="-7.1817349065269E-22" iyy="7.69100314106116E-07" iyz="6.74715432769696E-07"
                izz="2.30315190420171E-06" />
        </inertial>
        <visual>
            <origin rpy="0 0 0" xyz="0 0 0" />
            <geometry>
                <mesh filename="../../../end_effector/gripper/ag95/meshes/link_distal_phalanx.STL"
                    scale="1 1 1" />
            </geometry>
            <material name="">
                <color rgba="0.792156862745098 0.819607843137255 0.933333333333333 1" />
            </material>
        </visual>
        <collision>
            <origin rpy="0 0 0" xyz="0 0 0" />
            <geometry>
                <mesh filename="../../../end_effector/gripper/ag95/meshes/link_distal_phalanx.STL"
                    scale="1 1 1" />
            </geometry>
        </collision>
    </link>
</robot>