<?xml version="1.0" ?>
<robot name="partnet_a44c2110f646309bc7fb1a0a584939a5">
	<link name="base"/>
	<link name="link_0">
		<visual name="bottom">
			<origin xyz="0 -0.66 0"/>
			<geometry>
				<box size="1.1 .1 0.7"/>
			</geometry>
			<material name="Black">
				<color rgba="1.0 1.0 1.0 1.0"/>
			</material>
		</visual>

		<visual name="frame-5">
			<origin xyz="0 0 0"/>
			<geometry>
				<mesh filename="textured_objs/new-5-fixed.obj"/>
			</geometry>
		</visual>
		<visual name="frame-5">
			<origin xyz="0 0 0"/>
			<geometry>
				<mesh filename="textured_objs/new-0.obj"/>
			</geometry>
		</visual>
		<!-- <collision>
			<origin xyz="0 0 0"/>
			<geometry>
				<mesh filename="textured_objs/new-5.obj"/>
			</geometry>
		</collision> -->
			<collision name="bottom">
				<origin xyz="0 -0.66 0"/>
				<geometry>
					<box size="1.1 .1 0.7"/>
				</geometry>
			</collision>

		<collision>
			<origin xyz="0 0 0"/>
			<geometry>
				<mesh filename="textured_objs/new-5-left.obj"/>
			</geometry>
		</collision>
		<collision>
			<origin xyz="0 0 0"/>
			<geometry>
				<mesh filename="textured_objs/new-5-right.obj"/>
			</geometry>
		</collision>
		<collision>
			<origin xyz="0 0 0"/>
			<geometry>
				<mesh filename="textured_objs/new-5-top.obj"/>
			</geometry>
		</collision>
		<collision>
			<origin xyz="0 0 0"/>
			<geometry>
				<mesh filename="textured_objs/new-5-back.obj"/>
			</geometry>
		</collision>
		<collision>
			<origin xyz="0 0 0"/>
			<geometry>
				<mesh filename="textured_objs/new-5-front.obj"/>
			</geometry>
		</collision>
		<!-- <collision>
			<origin xyz="0 0 0"/>
			<geometry>
				<mesh filename="textured_objs/new-0.obj"/>
			</geometry>
		</collision> -->
		<collision>
			<origin xyz="0 0 0"/>
			<geometry>
				<mesh filename="textured_objs/new-0-bottom.obj"/>
			</geometry>
		</collision>
	</link>
	<joint name="joint_0" type="fixed">
		<origin rpy="1.570796326794897 0 -1.570796326794897" xyz="0 0 0"/>
		<child link="link_0"/>
		<parent link="base"/>
	</joint>


	<link name="handle_1">
		<visual name="handle-11">
			<origin xyz="-0.5543596224430867 -0.7725170000000001 -0.33093961184787113"/>
			<geometry>
				<mesh filename="textured_objs/new-1-fixing.obj"/>
			</geometry>
		</visual>
		<collision>
			<origin xyz="-0.5543596224430867 -0.7725170000000001 -0.28093961184787113"/>
			<geometry>
				<mesh filename="textured_objs/new-1-fixing.obj"/>
			</geometry>
		</collision>
	</link>
	<joint name="joint_handle_1" type="fixed">
		<origin xyz="0 0 0"/>
		<axis xyz="0 1 0"/>
		<child link="handle_1"/>
		<parent link="link_1"/>
	</joint>

	<link name="link_1">
		<visual name="door_frame-10">
			<origin xyz="-0.5543596224430867 -0.7725170000000001 -0.33093961184787113"/>
			<geometry>
				<mesh filename="textured_objs/new-3.obj"/>
			</geometry>
		</visual>
		<!-- <visual name="handle-11">
			<origin xyz="-0.5543596224430867 -0.7725170000000001 -0.33093961184787113"/>
			<geometry>
				<mesh filename="textured_objs/new-1.obj"/>
			</geometry>
		</visual> -->
		<visual name="other_leaf-13">
			<origin xyz="-0.5543596224430867 -0.7725170000000001 -0.33093961184787113"/>
			<geometry>
				<mesh filename="textured_objs/original-3.obj"/>
			</geometry>
		</visual>
		<visual name="other_leaf-13">
			<origin xyz="-0.5543596224430867 -0.7725170000000001 -0.33093961184787113"/>
			<geometry>
				<mesh filename="textured_objs/original-2.obj"/>
			</geometry>
		</visual>
		<visual name="other_leaf-13">
			<origin xyz="-0.5543596224430867 -0.7725170000000001 -0.33093961184787113"/>
			<geometry>
				<mesh filename="textured_objs/original-4.obj"/>
			</geometry>
		</visual>
		<visual name="other_leaf-13">
			<origin xyz="-0.5543596224430867 -0.7725170000000001 -0.33093961184787113"/>
			<geometry>
				<mesh filename="textured_objs/original-5.obj"/>
			</geometry>
		</visual>
		<visual name="other_leaf-13">
			<origin xyz="-0.5543596224430867 -0.7725170000000001 -0.33093961184787113"/>
			<geometry>
				<mesh filename="textured_objs/original-6.obj"/>
			</geometry>
		</visual>
		<visual name="other_leaf-13">
			<origin xyz="-0.5543596224430867 -0.7725170000000001 -0.33093961184787113"/>
			<geometry>
				<mesh filename="textured_objs/original-7.obj"/>
			</geometry>
		</visual>
		<visual name="other_leaf-13">
			<origin xyz="-0.5543596224430867 -0.7725170000000001 -0.33093961184787113"/>
			<geometry>
				<mesh filename="textured_objs/original-8.obj"/>
			</geometry>
		</visual>
		<visual name="other_leaf-13">
			<origin xyz="-0.5543596224430867 -0.7725170000000001 -0.33093961184787113"/>
			<geometry>
				<mesh filename="textured_objs/original-9.obj"/>
			</geometry>
		</visual>
		<collision>
			<origin xyz="-0.5543596224430867 -0.7725170000000001 -0.33093961184787113"/>
			<geometry>
				<mesh filename="textured_objs/new-3.obj"/>
			</geometry>
		</collision>
		<!-- <collision>
			<origin xyz="-0.5543596224430867 -0.7725170000000001 -0.33093961184787113"/>
			<geometry>
				<mesh filename="textured_objs/new-1.obj"/>
			</geometry>
		</collision> -->
		<collision>
			<origin xyz="-0.5543596224430867 -0.7725170000000001 -0.33093961184787113"/>
			<geometry>
				<mesh filename="textured_objs/original-3.obj"/>
			</geometry>
		</collision>
		<collision>
			<origin xyz="-0.5543596224430867 -0.7725170000000001 -0.33093961184787113"/>
			<geometry>
				<mesh filename="textured_objs/original-2.obj"/>
			</geometry>
		</collision>
		<collision>
			<origin xyz="-0.5543596224430867 -0.7725170000000001 -0.33093961184787113"/>
			<geometry>
				<mesh filename="textured_objs/original-4.obj"/>
			</geometry>
		</collision>
		<collision>
			<origin xyz="-0.5543596224430867 -0.7725170000000001 -0.33093961184787113"/>
			<geometry>
				<mesh filename="textured_objs/original-5.obj"/>
			</geometry>
		</collision>
		<collision>
			<origin xyz="-0.5543596224430867 -0.7725170000000001 -0.33093961184787113"/>
			<geometry>
				<mesh filename="textured_objs/original-6.obj"/>
			</geometry>
		</collision>
		<collision>
			<origin xyz="-0.5543596224430867 -0.7725170000000001 -0.33093961184787113"/>
			<geometry>
				<mesh filename="textured_objs/original-7.obj"/>
			</geometry>
		</collision>
		<collision>
			<origin xyz="-0.5543596224430867 -0.7725170000000001 -0.33093961184787113"/>
			<geometry>
				<mesh filename="textured_objs/original-8.obj"/>
			</geometry>
		</collision>
		<collision>
			<origin xyz="-0.5543596224430867 -0.7725170000000001 -0.33093961184787113"/>
			<geometry>
				<mesh filename="textured_objs/original-9.obj"/>
			</geometry>
		</collision>
	</link>
	<joint name="joint_1" type="revolute">
		<origin xyz="0.5543596224430867 0.7725170000000001 0.33093961184787113"/>
		<axis xyz="0 1 0"/>
		<child link="link_1"/>
		<parent link="link_0"/>
		<limit lower="0.0" upper="3.141592653589793"/>
	</joint>

	<link name="handle_2">
		<visual name="handle-9">
			<origin xyz="0.5350193299146853 -0.7725170000000001 -0.322367571646071"/>
			<geometry>
				<mesh filename="textured_objs/new-2.obj"/>
			</geometry>
		</visual>
		<collision>
			<origin xyz="0.5350193299146853 -0.7725170000000001 -0.272367571646071"/>
			<geometry>
				<mesh filename="textured_objs/new-2.obj"/>
			</geometry>
		</collision>
	</link>
	<joint name="joint_handle_2" type="fixed">
		<origin xyz="0 0 0"/>
		<axis xyz="0 -1 0"/>
		<child link="handle_2"/>
		<parent link="link_2"/>
	</joint>


	<link name="link_2">
		<visual name="door_frame-8">
			<origin xyz="0.5350193299146853 -0.7725170000000001 -0.322367571646071"/>
			<geometry>
				<mesh filename="textured_objs/new-4.obj"/>
			</geometry>
		</visual>
		<!-- <visual name="handle-9">
			<origin xyz="0.5350193299146853 -0.7725170000000001 -0.322367571646071"/>
			<geometry>
				<mesh filename="textured_objs/new-2.obj"/>
			</geometry>
		</visual> -->
		<collision>
			<origin xyz="0.5350193299146853 -0.7725170000000001 -0.322367571646071"/>
			<geometry>
				<mesh filename="textured_objs/new-4.obj"/>
			</geometry>
		</collision>
		<!-- <collision>
			<origin xyz="0.5350193299146853 -0.7725170000000001 -0.322367571646071"/>
			<geometry>
				<mesh filename="textured_objs/new-2.obj"/>
			</geometry>
		</collision> -->
	</link>
	<joint name="joint_2" type="revolute">
		<origin xyz="-0.5350193299146853 0.7725170000000001 0.322367571646071"/>
		<axis xyz="0 -1 0"/>
		<child link="link_2"/>
		<parent link="link_0"/>
		<limit lower="-0.0" upper="3.141592653589793"/>
	</joint>
</robot>
