<?xml version="1.0" ?>
<robot name="partnet_4de724831f09791676c18e71fd49c4dc">
	<link name="base"/>
	<link name="link_0">
		<visual name="switch-2">
			<origin xyz="-0.32039400000000007 0.542293772249544 0.2620664912582102"/>
			<geometry>
				<mesh filename="textured_objs/new-2.obj"/>
			</geometry>
		</visual>
		<collision>
			<origin xyz="-0.32039400000000007 0.542293772249544 0.2620664912582102"/>
			<geometry>
				<mesh filename="textured_objs/new-2.obj"/>
			</geometry>
		</collision>
	</link>
	<joint name="joint_0" type="revolute">
		<origin xyz="0.32039400000000007 -0.542293772249544 -0.2620664912582102"/>
		<axis xyz="1 0 0"/>
		<child link="link_0"/>
		<parent link="link_1"/>
		<limit lower="0.0" upper="1.5707963267948966"/>
	</joint>
	<link name="link_1">
		<visual name="surface_base-10">
			<origin xyz="0 0 0"/>
			<geometry>
				<mesh filename="textured_objs/new-6.obj"/>
			</geometry>
		</visual>
		<visual name="surface_base-10">
			<origin xyz="0 0 0"/>
			<geometry>
				<mesh filename="textured_objs/new-5.obj"/>
			</geometry>
		</visual>
		<visual name="vertical_support-11">
			<origin xyz="0 0 0"/>
			<geometry>
				<mesh filename="textured_objs/new-4.obj"/>
			</geometry>
		</visual>
		<visual name="horizontal_support-12">
			<origin xyz="0 0 0"/>
			<geometry>
				<mesh filename="textured_objs/new-3.obj"/>
			</geometry>
		</visual>
		<collision>
			<origin xyz="0 0 0"/>
			<geometry>
				<mesh filename="textured_objs/new-6.obj"/>
			</geometry>
		</collision>
		<collision>
			<origin xyz="0 0 0"/>
			<geometry>
				<mesh filename="textured_objs/new-5.obj"/>
			</geometry>
		</collision>
		<collision>
			<origin xyz="0 0 0"/>
			<geometry>
				<mesh filename="textured_objs/new-4.obj"/>
			</geometry>
		</collision>
		<collision>
			<origin xyz="0 0 0"/>
			<geometry>
				<mesh filename="textured_objs/new-3.obj"/>
			</geometry>
		</collision>
	</link>
	<joint name="joint_1" type="fixed">
		<origin rpy="1.570796326794897 0 -1.570796326794897" xyz="0 0 0"/>
		<child link="link_1"/>
		<parent link="base"/>
	</joint>
	<link name="link_2">
		<visual name="tube-8">
			<origin xyz="0.032524000000000004 0 0.260397"/>
			<geometry>
				<mesh filename="textured_objs/new-1.obj"/>
			</geometry>
		</visual>
		<visual name="head-9">
			<origin xyz="0.032524000000000004 0 0.260397"/>
			<geometry>
				<mesh filename="textured_objs/new-0.obj"/>
			</geometry>
		</visual>
		<collision>
			<origin xyz="0.032524000000000004 0 0.260397"/>
			<geometry>
				<mesh filename="textured_objs/new-1.obj"/>
			</geometry>
		</collision>
		<collision>
			<origin xyz="0.032524000000000004 0 0.260397"/>
			<geometry>
				<mesh filename="textured_objs/new-0.obj"/>
			</geometry>
		</collision>
	</link>
	<joint name="joint_2" type="continuous">
		<origin xyz="-0.032524000000000004 0 -0.260397"/>
		<axis xyz="0 1 0"/>
		<child link="link_2"/>
		<parent link="link_1"/>
	</joint>
</robot>
