<?xml version="1.0" encoding="utf-8"?>
<!-- This URDF was automatically created by SolidWorks to URDF Exporter! Originally created by Stephen Brawner (brawner@gmail.com) 
     Commit Version: 1.6.0-1-g15f4949  Build Version: 1.6.7594.29634
     For more information, please see http://wiki.ros.org/sw_urdf_exporter -->
<robot name="cobot_description" xmlns:xacro="http://ros.org/wiki/xacro">
  <xacro:include filename="$(find dh_robotics_ag95_model)/urdf/dh_robotics_ag95_model.xacro"/>
  <xacro:include filename="$(find rm_description)/urdf/RML63_6F/rm_63_6f_descriptio.urdf.xacro"/>
  <!-- <link
    name="base_footprint">
  </link> -->
  <link
    name="base_link">
    <inertial>
      <origin
        xyz="-0.18605 0.0010457 0.13419"
        rpy="0 0 0" />
      <mass
        value="35.137" />
      <inertia
        ixx="0.52213"
        ixy="0.00028039"
        ixz="-0.0048629"
        iyy="1.0698"
        iyz="-0.0011677"
        izz="1.4095" />
    </inertial>
    <visual>
      <origin
        xyz="0 0 0"
        rpy="0 0 3.14" />
      <geometry>
        <mesh
          filename="package://cobot_description/meshes/base_link.STL" />
      </geometry>
      <material
        name="">
        <color
          rgba="0.77647 0.77647 0.81961 1" />
      </material>
    </visual>
    <collision>
      <origin
        xyz="0 0 0"
        rpy="0 0 0" />
      <geometry>
        <mesh
          filename="package://cobot_description/meshes/base_link.STL" />
      </geometry>
    </collision>
  </link>
  <!-- <joint
    name="base_link"
    type="fixed">
    <origin
      xyz="0.201 0 0.072"
      rpy="0 0 0" />
    <parent
      link="base_footprint" />
    <child
      link="base_link" />
    <axis
      xyz="0 0 0" />
  </joint> -->
  <link
    name="front_lidar">
    <inertial>
      <origin
        xyz="-0.00016986 -2.2612E-10 0.018642"
        rpy="0 0 0" />
      <mass
        value="0.15478" />
      <inertia
        ixx="6.9567E-05"
        ixy="-1.7298E-12"
        ixz="-4.6381E-07"
        iyy="7.1065E-05"
        iyz="-5.4415E-13"
        izz="9.8843E-05" />
    </inertial>
    <visual>
      <origin
        xyz="0 0 0"
        rpy="0 0 0" />
      <geometry>
        <mesh
          filename="package://cobot_description/meshes/front_lidar.STL" />
      </geometry>
      <material
        name="">
        <color
          rgba="1 1 1 1" />
      </material>
    </visual>
    <collision>
      <origin
        xyz="0 0 0"
        rpy="0 0 0" />
      <geometry>
        <mesh
          filename="package://cobot_description/meshes/front_lidar.STL" />
      </geometry>
    </collision>
  </link>
  <joint
    name="front_lidar_joint"
    type="fixed">
    <origin
      xyz="0.30 0 0.214"
      rpy="0 0 0" />
    <parent
      link="base_link" />
    <child
      link="front_lidar" />
    <axis
      xyz="0 0 0" />
  </joint>
  <link
    name="arm_base">
    <inertial>
      <origin
        xyz="-0.024179 0.0061525 0.44341"
        rpy="0 0 0" />
      <mass
        value="8.0743" />
      <inertia
        ixx="0.080601"
        ixy="4.9995E-05"
        ixz="0.00052048"
        iyy="0.077325"
        iyz="-2.0984E-05"
        izz="0.024026" />
    </inertial>
    <visual>
      <origin
        xyz="0 0 0"
        rpy="0 0 0" />
      <geometry>
        <mesh
          filename="package://cobot_description/meshes/arm_base.STL" />
      </geometry>
      <material
        name="">
        <color
          rgba="0.69804 0.69804 0.69804 1" />
      </material>
    </visual>
    <collision>
      <origin
        xyz="0 0 0"
        rpy="0 0 0" />
      <geometry>
        <mesh
          filename="package://cobot_description/meshes/arm_base.STL" />
      </geometry>
    </collision>
  </link>
  <joint
    name="arm_base"
    type="fixed">
    <origin
      xyz="0.101 0 0.16"
      rpy="0 0 0" />
    <parent
      link="base_link" />
    <child
      link="arm_base" />
    <axis
      xyz="0 0 0" />
  </joint>
  <link
    name="Link7">
    <inertial>
      <origin
        xyz="-0.016412 0.00026497 -0.060445"
        rpy="0 0 0" />
      <mass
        value="0.53096" />
      <inertia
        ixx="0.00096525"
        ixy="1.49E-05"
        ixz="-1.7049E-05"
        iyy="0.0018872"
        iyz="1.0632E-06"
        izz="0.0018331" />
    </inertial>
    <visual>
      <origin
        xyz="0 0 0"
        rpy="0 0 0" />
      <geometry>
        <mesh
          filename="package://cobot_description/meshes/Link7.STL" />
      </geometry>
      <material
        name="">
        <color
          rgba="1 1 1 1" />
      </material>
    </visual>
    <collision>
      <origin
        xyz="0 0 0"
        rpy="0 0 0" />
      <geometry>
        <mesh
          filename="package://cobot_description/meshes/Link7.STL" />
      </geometry>
    </collision>
  </link>
  <joint
    name="joint_arm_rotary"
    type="revolute">
    <origin
      xyz="0 0 0.4878"
      rpy="3.1416 0 -3.1416" />
    <parent
      link="arm_base" />
    <child
      link="Link7" />
    <axis
      xyz="0 0 -1" />
    <limit
      lower="-3.49"
      upper="0.5"
      effort="300"
      velocity="3.14" />
	  <dynamics damping="50" friction="1"/>
  </joint>

  <joint
    name="joint1"
    type="revolute">
    <origin
      xyz="-0.18 0 -0.059"
      rpy="1.5708 0 -1.5708" />
    <parent
      link="Link7" />
    <child
      link="Link1" />
    <axis
      xyz="0 0 1" />
    <limit
      lower="-3.14"
      upper="3.14"
      effort="300"
      velocity="3.14" />
	  <dynamics damping="50" friction="1"/>
  </joint>


  <joint
    name="hand_joint"
    type="fixed">
    <origin
      xyz="0 0 0.02"
      rpy="0 0 0.25" />
    <parent
      link="Link6" />
    <child
      link="dh_robotics_ag95_base_link" />
  </joint>

  <link
    name="hand_camera">
    <inertial>
      <origin
        xyz="0.0009804 0.025556 -0.036977"
        rpy="0 0 0" />
      <mass
        value="0.067926" />
      <inertia
        ixx="3.7811E-05"
        ixy="2.2861E-18"
        ixz="2.2446E-19"
        iyy="9.4061E-05"
        iyz="6.1172E-06"
        izz="0.00012345" />
    </inertial>
    <visual>
      <origin
        xyz="0 0 0"
        rpy="0 0 0" />
      <geometry>
      <box size="0.02 0.088 0.02"/>
      </geometry>
      <material
        name="">
        <color
          rgba="1 1 1 1" />
      </material>
    </visual>
    <collision>
      <origin
        xyz="0 0 0"
        rpy="0 0 0" />
      <geometry>
      <box size="0.01 0.09 0.01"/>

      </geometry>
    </collision>
  </link>
  <joint
    name="hand_camera_joint"
    type="fixed">
    <origin
      xyz="0.05 0.0 0.0"
      rpy="0 0 3.39" />
    <parent
      link="Link6" />
    <child
      link="hand_camera" />
    <axis
      xyz="0 0 0" />
  </joint>
  <link
    name="head_Link">
    <inertial>
      <origin
        xyz="-0.013341 -0.0030001 0.14378"
        rpy="0 0 0" />
      <mass
        value="0.10888" />
      <inertia
        ixx="0.00015548"
        ixy="5.612E-11"
        ixz="7.7393E-06"
        iyy="6.2021E-05"
        iyz="-3.4676E-10"
        izz="0.00016861" />
    </inertial>
    <visual>
      <origin
        xyz="0 0 0"
        rpy="0 0 0" />
      <geometry>
        <mesh
          filename="package://cobot_description/meshes/head_Link.STL" />
      </geometry>
      <material
        name="">
        <color
          rgba="1 1 1 1" />
      </material>
    </visual>
    <collision>
      <origin
        xyz="0 0 0"
        rpy="0 0 0" />
      <geometry>
        <mesh
          filename="package://cobot_description/meshes/head_Link.STL" />
      </geometry>
    </collision>
  </link>
  <joint
    name="head_joint"
    type="fixed">
    <origin
      xyz="0.10013 0 1.1628"
      rpy="0 0 3.1416" />
    <parent
      link="base_link" />
    <child
      link="head_Link" />
    <axis
      xyz="0 0 0" />
  </joint>
  <link
    name="display_Link">
    <collision>
      <origin
        xyz="0 0 0"
        rpy="0 0 0" />
      <geometry>
        <box size="0.03 0.3 0.2" />
      </geometry>
    </collision>
  </link>
  <joint
    name="display_joint"
    type="fixed">
    <origin
      xyz="0.15 0 -0.1"
      rpy="0 0 0" />
    <parent
      link="head_Link" />
    <child
      link="display_Link" />
    <axis
      xyz="0 0 0" />
  </joint>
  <link
    name="head_camera">
    <inertial>
      <origin
        xyz="0.027537 -0.14823 -1.1256"
        rpy="0 0 0" />
      <mass
        value="91.96" />
      <inertia
        ixx="16.389"
        ixy="0.28606"
        ixz="-0.57062"
        iyy="13.534"
        iyz="-2.6339"
        izz="7.1915" />
    </inertial>
    <visual>
      <origin
        xyz="0 0 0"
        rpy="0 0 0" />
      <geometry>
        <mesh
          filename="package://cobot_description/meshes/head_camera.STL" />
      </geometry>
      <material
        name="">
        <color
          rgba="1 1 1 1" />
      </material>
    </visual>
    <collision>
      <origin
        xyz="0 0 0"
        rpy="0 0 0" />
      <geometry>
        <mesh
          filename="package://cobot_description/meshes/head_camera.STL" />
      </geometry>
    </collision>
  </link>
  <joint
    name="head_camera_joint"
    type="fixed">
    <origin
      xyz="-0.033687 -0.0039804 0.18195"
      rpy="0.066568 0 1.5708" />
    <parent
      link="head_Link" />
    <child
      link="head_camera" />
    <axis
      xyz="0 0 0" />
  </joint>
  <link
    name="basket_Link">
    <inertial>
      <origin
        xyz="-4.1633E-16 -4.4913E-14 0.021251"
        rpy="0 0 0" />
      <mass
        value="0.39699" />
      <inertia
        ixx="0.0056399"
        ixy="-2.6074E-10"
        ixz="5.7967E-18"
        iyy="0.0033409"
        iyz="1.9651E-17"
        izz="0.0081811" />
    </inertial>
    <visual>
      <origin
        xyz="0 0 0"
        rpy="0 0 0" />
      <geometry>
      <box size="0.24 0.5 0.2"/>
      </geometry>
      <material
        name="">
        <color
          rgba="0.69804 0.69804 0.69804 1" />
      </material>
    </visual>
    <collision>
      <origin
        xyz="0 0 0"
        rpy="0 0 0" />
      <geometry>
      <box size="0.1 0.1 0.1"/>
      </geometry>
    </collision>
  </link>
  <joint
    name="basket_joint"
    type="fixed">
    <origin
      xyz="-0.21 0 0.26"
      rpy="0 0 0" />
    <parent
      link="base_link" />
    <child
      link="basket_Link" />
    <axis
      xyz="0 0 0" />
  </joint>
</robot>
