<?xml version="1.0" ?>
<!-- =================================================================================== -->
<!-- |    This document was autogenerated by xacro from kitchen_part_right.urdf.xacro  | -->
<!-- |    EDITING THIS FILE BY HAND IS NOT RECOMMENDED                                 | -->
<!-- =================================================================================== -->
<robot name="kitchen_part_right" xmlns:xacro="http://www.ros.org/wiki/xacro">
  <link name="world"/>
  <joint name="sektion_to_parent" type="fixed">
    <origin rpy="0 0 0" xyz="0 0 0"/>
    <parent link="world"/>
    <child link="sektion"/>
  </joint>
  <material name="White">
    <color rgba="0.85 0.85 0.85 1.0"/>
  </material>
  <material name="Grey">
    <color rgba="0.4 0.4 0.4 1.0"/>
  </material>
  <!-- Wall -->
  <joint name="wall_transform" type="fixed">
    <parent link="sektion"/>
    <child link="walls"/>
    <origin rpy="0 0 0" xyz="0 0 0"/>
  </joint>
  <link name="walls">
    <inertial>
      <origin rpy="0 0 0" xyz="0 0 0"/>
      <mass value="10.0"/>
      <inertia ixx="0.0001" ixy="0" ixz="0" iyy="0.0001" iyz="0" izz="0.0001"/>
    </inertial>
    <visual name="sektion_visual">
      <origin rpy="0  0  0" xyz="0  0  0"/>
      <geometry>
        <mesh filename="package://kitchen_description/meshes/obj/walls.obj" scale="1.0 1.0 1.0"/>
      </geometry>
      <material name="White"/>
    </visual>
    <collision>
      <geometry>
        <mesh filename="package://kitchen_description/meshes/obj/walls.obj" scale="1.0 1.0 1.0"/>
      </geometry>
    </collision>
  </link>
  <!-- Extractor Hood -->
  <joint name="extractor_hood_transform" type="fixed">
    <parent link="sektion"/>
    <child link="extractor_hood"/>
    <origin rpy="0 0 0" xyz="-0.14 0.415 0.37"/>
  </joint>
  <link name="extractor_hood">
    <visual>
      <geometry>
        <box size="0.5 0.76 0.6"/>
      </geometry>
    </visual>
    <collision>
      <geometry>
        <box size="0.5 0.76 0.6"/>
      </geometry>
    </collision>
  </link>
  <!-- Range -->
  <joint name="range_transform" type="fixed">
    <parent link="sektion"/>
    <child link="range"/>
    <origin rpy="0 0 0" xyz="0 0.415 -1.00"/>
  </joint>
  <link name="range">
    <visual>
      <geometry>
        <box size="0.71 0.76 0.92"/>
      </geometry>
    </visual>
    <collision>
      <geometry>
        <box size="0.71 0.76 0.92"/>
      </geometry>
    </collision>
  </link>
  <!--
      Width of a single corpus:  13.5inch + 1.5inch = 15inch = 38.1cm
      -->
  <link name="sektion">
    <inertial>
      <origin rpy="0 0 0" xyz="0 0 0"/>
      <mass value="10.0"/>
      <inertia ixx="0.0001" ixy="0" ixz="0" iyy="0.0001" iyz="0" izz="0.0001"/>
    </inertial>
    <visual name="sektion_visual">
      <origin rpy="0  0  0" xyz="0  0  0"/>
      <geometry>
        <mesh filename="package://kitchen_description/meshes/obj/sektion_top_three.obj" scale="1.0 1.0 1.0"/>
      </geometry>
      <material name="White"/>
    </visual>
    <collision>
      <geometry>
        <mesh filename="package://kitchen_description/meshes/obj/sektion_top_three.obj" scale="1.0 1.0 1.0"/>
      </geometry>
    </collision>
  </link>
  <!-- Baker (single hanging drawer in the center) -->
  <joint name="baker_joint_fixed" type="fixed">
    <parent link="sektion"/>
    <child link="baker_anchor_link"/>
    <origin rpy="0 0 3.14159265359" xyz="0 -0.762 0"/>
  </joint>
  <link name="baker_anchor_link"/>
  <joint name="baker_joint" type="revolute">
    <parent link="baker_anchor_link"/>
    <child link="baker_link_tmp"/>
    <origin rpy="0 0 0" xyz="0 0 0"/>
    <axis xyz="0 0 1"/>
    <limit effort="1000.0" lower="0" upper="1.57" velocity="0.1"/>
  </joint>
  <link name="baker_link_tmp"/>
  <joint name="baker_joint_fixed_2" type="fixed">
    <parent link="baker_link_tmp"/>
    <child link="baker_link"/>
    <origin rpy="0 0 0" xyz="-0.01 0.19 0.38"/>
  </joint>
  <link name="baker_link">
    <inertial>
      <origin rpy="0 0 0" xyz="0 0 0"/>
      <mass value="1.0"/>
      <inertia ixx="0.0001" ixy="0" ixz="0" iyy="0.0001" iyz="0" izz="0.0001"/>
    </inertial>
    <visual name="baker_visual">
      <origin rpy="0 0 0" xyz="0 0 0"/>
      <geometry>
        <mesh filename="package://kitchen_description/meshes/obj/front_vertical_right.obj" scale="1.0 1.0 1.0"/>
      </geometry>
      <material name="Grey"/>
    </visual>
    <collision>
      <geometry>
        <mesh filename="package://kitchen_description/meshes/obj/front_vertical_right.obj" scale="1.0 1.0 1.0"/>
      </geometry>
    </collision>
  </link>
  <joint name="baker_handle_transform" type="fixed">
    <parent link="baker_link_tmp"/>
    <child link="baker_handle"/>
    <origin rpy="0 0 3.1514" xyz="-0.05905 0.33 0.13"/>
    <axis xyz="0 0 1"/>
  </joint>
  <link name="baker_handle">
    <inertial>
      <origin rpy="0 0 0" xyz="0 0 0"/>
      <mass value="1.0"/>
      <inertia ixx="0.0001" ixy="0" ixz="0" iyy="0.0001" iyz="0" izz="0.0001"/>
    </inertial>
    <visual name="baker_visual">
      <origin rpy="0  0  0" xyz="0  0  0"/>
      <geometry>
        <mesh filename="package://kitchen_description/meshes/obj/handle.obj" scale="1.0 1.0 1.0"/>
      </geometry>
      <material name="White"/>
    </visual>
    <collision>
      <geometry>
        <mesh filename="package://kitchen_description/meshes/obj/handle.obj" scale="1.0 1.0 1.0"/>
      </geometry>
    </collision>
  </link>
  <!-- Chewie (Right Door) -->
  <joint name="chewie_door_right_joint_fixed" type="fixed">
    <parent link="sektion"/>
    <child link="chewie_door_right_anchor_link"/>
    <origin rpy="0 0 3.14159265359" xyz="0 0 0"/>
  </joint>
  <link name="chewie_door_right_anchor_link"/>
  <joint name="chewie_door_right_joint" type="revolute">
    <parent link="chewie_door_right_anchor_link"/>
    <child link="chewie_door_right_link_tmp"/>
    <origin rpy="0 0 0" xyz="0 0 0"/>
    <axis xyz="0 0 1"/>
    <limit effort="1000.0" lower="0" upper="1.57" velocity="0.1"/>
  </joint>
  <link name="chewie_door_right_link_tmp"/>
  <joint name="chewie_door_right_joint_fixed_2" type="fixed">
    <parent link="chewie_door_right_link_tmp"/>
    <child link="chewie_door_right_link"/>
    <origin rpy="0 0 0" xyz="-0.01 0.19 0.38"/>
  </joint>
  <link name="chewie_door_right_link">
    <inertial>
      <origin rpy="0 0 0" xyz="0 0 0"/>
      <mass value="1.0"/>
      <inertia ixx="0.0001" ixy="0" ixz="0" iyy="0.0001" iyz="0" izz="0.0001"/>
    </inertial>
    <visual name="chewie_door_right_visual">
      <origin rpy="0 0 0" xyz="0 0 0"/>
      <geometry>
        <mesh filename="package://kitchen_description/meshes/obj/front_vertical_right.obj" scale="1.0 1.0 1.0"/>
      </geometry>
      <material name="Grey"/>
    </visual>
    <collision>
      <geometry>
        <mesh filename="package://kitchen_description/meshes/obj/front_vertical_right.obj" scale="1.0 1.0 1.0"/>
      </geometry>
    </collision>
  </link>
  <joint name="chewie_door_right_handle_transform" type="fixed">
    <parent link="chewie_door_right_link_tmp"/>
    <child link="chewie_door_right_handle"/>
    <origin rpy="0 0 3.1514" xyz="-0.05905 0.33 0.13"/>
    <axis xyz="0 0 1"/>
  </joint>
  <link name="chewie_door_right_handle">
    <inertial>
      <origin rpy="0 0 0" xyz="0 0 0"/>
      <mass value="1.0"/>
      <inertia ixx="0.0001" ixy="0" ixz="0" iyy="0.0001" iyz="0" izz="0.0001"/>
    </inertial>
    <visual name="chewie_door_right_handle_visual">
      <origin rpy="0  0  0" xyz="0  0  0"/>
      <geometry>
        <mesh filename="package://kitchen_description/meshes/obj/handle.obj" scale="1.0 1.0 1.0"/>
      </geometry>
      <material name="White"/>
    </visual>
    <collision>
      <geometry>
        <mesh filename="package://kitchen_description/meshes/obj/handle.obj" scale="1.0 1.0 1.0"/>
      </geometry>
    </collision>
  </link>
  <!-- Middle Door -->
  <joint name="chewie_door_left_joint_fixed" type="fixed">
    <parent link="sektion"/>
    <child link="chewie_door_left_anchor_link"/>
    <origin rpy="0 0 3.14159265359" xyz="0 -0.762 0"/>
  </joint>
  <link name="chewie_door_left_anchor_link"/>
  <joint name="chewie_door_left_joint" type="revolute">
    <parent link="chewie_door_left_anchor_link"/>
    <child link="chewie_door_left_link_tmp"/>
    <origin rpy="0 0 0" xyz="0 0 0"/>
    <axis xyz="0 0 1"/>
    <limit effort="1000.0" lower="-1.57" upper="0" velocity="0.1"/>
  </joint>
  <link name="chewie_door_left_link_tmp"/>
  <joint name="chewie_door_left_joint_fixed_2" type="fixed">
    <parent link="chewie_door_left_link_tmp"/>
    <child link="chewie_door_left_link"/>
    <origin rpy="0 0 0" xyz="-0.01 -0.19 0.38"/>
  </joint>
  <link name="chewie_door_left_link">
    <inertial>
      <origin rpy="0 0 0" xyz="0 0 0"/>
      <mass value="1.0"/>
      <inertia ixx="0.0001" ixy="0" ixz="0" iyy="0.0001" iyz="0" izz="0.0001"/>
    </inertial>
    <visual name="chewie_door_left_visual">
      <origin rpy="0 0 0" xyz="0 0 0"/>
      <geometry>
        <mesh filename="package://kitchen_description/meshes/obj/front_vertical_left.obj" scale="1.0 1.0 1.0"/>
      </geometry>
      <material name="Grey"/>
    </visual>
    <collision>
      <geometry>
        <mesh filename="package://kitchen_description/meshes/obj/front_vertical_left.obj" scale="1.0 1.0 1.0"/>
      </geometry>
    </collision>
  </link>
  <joint name="chewie_door_left_handle_transform" type="fixed">
    <parent link="chewie_door_left_link_tmp"/>
    <child link="chewie_door_left_handle"/>
    <origin rpy="0 0 3.1514" xyz="-0.05905 -0.33 0.13"/>
    <axis xyz="0 0 1"/>
  </joint>
  <link name="chewie_door_left_handle">
    <inertial>
      <origin rpy="0 0 0" xyz="0 0 0"/>
      <mass value="1.0"/>
      <inertia ixx="0.0001" ixy="0" ixz="0" iyy="0.0001" iyz="0" izz="0.0001"/>
    </inertial>
    <visual name="chewie_door_left_handle_visual">
      <origin rpy="0  0  0" xyz="0  0  0"/>
      <geometry>
        <mesh filename="package://kitchen_description/meshes/obj/handle.obj" scale="1.0 1.0 1.0"/>
      </geometry>
      <material name="White"/>
    </visual>
    <collision>
      <geometry>
        <mesh filename="package://kitchen_description/meshes/obj/handle.obj" scale="1.0 1.0 1.0"/>
      </geometry>
    </collision>
  </link>
  <!-- Dagger (top two-Door-Glass-Cabinet on the right) -->
  <joint name="dagger_transform" type="fixed">
    <parent link="sektion"/>
    <child link="dagger"/>
    <origin rpy="0 0 0" xyz="0 0.83 0"/>
    <axis xyz="0 0 1"/>
  </joint>
  <link name="dagger">
    <inertial>
      <origin rpy="0 0 0" xyz="0 0 0"/>
      <mass value="10.0"/>
      <inertia ixx="0.0001" ixy="0" ixz="0" iyy="0.0001" iyz="0" izz="0.0001"/>
    </inertial>
    <visual name="dagger_visual">
      <origin rpy="0  0  0" xyz="0  0  0"/>
      <geometry>
        <mesh filename="package://kitchen_description/meshes/obj/sektion_top_two_glass.obj" scale="1.0 1.0 1.0"/>
      </geometry>
      <material name="White"/>
    </visual>
    <collision>
      <geometry>
        <mesh filename="package://kitchen_description/meshes/obj/sektion_top_two_glass.obj" scale="1.0 1.0 1.0"/>
      </geometry>
    </collision>
  </link>
  <!-- Left Door -->
  <joint name="dagger_door_left_joint_fixed" type="fixed">
    <parent link="dagger"/>
    <child link="dagger_door_left_anchor_link"/>
    <origin rpy="0 0 3.14159265359" xyz="0 0 0"/>
  </joint>
  <link name="dagger_door_left_anchor_link"/>
  <joint name="dagger_door_left_joint" type="revolute">
    <parent link="dagger_door_left_anchor_link"/>
    <child link="dagger_door_left_link_tmp"/>
    <origin rpy="0 0 0" xyz="0 0 0"/>
    <axis xyz="0 0 1"/>
    <limit effort="1000.0" lower="-1.57" upper="0" velocity="0.1"/>
  </joint>
  <link name="dagger_door_left_link_tmp"/>
  <joint name="dagger_door_left_joint_fixed_2" type="fixed">
    <parent link="dagger_door_left_link_tmp"/>
    <child link="dagger_door_left_link"/>
    <origin rpy="0 0 0" xyz="-0.01 -0.19 0.38"/>
  </joint>
  <link name="dagger_door_left_link">
    <inertial>
      <origin rpy="0 0 0" xyz="0 0 0"/>
      <mass value="1.0"/>
      <inertia ixx="0.0001" ixy="0" ixz="0" iyy="0.0001" iyz="0" izz="0.0001"/>
    </inertial>
    <visual name="dagger_door_left_visual">
      <origin rpy="0 0 0" xyz="0 0 0"/>
      <geometry>
        <mesh filename="package://kitchen_description/meshes/obj/front_vertical_left.obj" scale="1.0 1.0 1.0"/>
      </geometry>
      <material name="Grey"/>
    </visual>
    <collision>
      <geometry>
        <mesh filename="package://kitchen_description/meshes/obj/front_vertical_left.obj" scale="1.0 1.0 1.0"/>
      </geometry>
    </collision>
  </link>
  <joint name="dagger_door_left_handle_transform" type="fixed">
    <parent link="dagger_door_left_link_tmp"/>
    <child link="dagger_door_left_handle"/>
    <origin rpy="0 0 3.1514" xyz="-0.05905 -0.33 0.13"/>
    <axis xyz="0 0 1"/>
  </joint>
  <link name="dagger_door_left_handle">
    <inertial>
      <origin rpy="0 0 0" xyz="0 0 0"/>
      <mass value="1.0"/>
      <inertia ixx="0.0001" ixy="0" ixz="0" iyy="0.0001" iyz="0" izz="0.0001"/>
    </inertial>
    <visual name="dagger_door_left_handle_visual">
      <origin rpy="0  0  0" xyz="0  0  0"/>
      <geometry>
        <mesh filename="package://kitchen_description/meshes/obj/handle.obj" scale="1.0 1.0 1.0"/>
      </geometry>
      <material name="White"/>
    </visual>
    <collision>
      <geometry>
        <mesh filename="package://kitchen_description/meshes/obj/handle.obj" scale="1.0 1.0 1.0"/>
      </geometry>
    </collision>
  </link>
  <!-- Right Door -->
  <joint name="dagger_door_right_joint_fixed" type="fixed">
    <parent link="dagger"/>
    <child link="dagger_door_right_anchor_link"/>
    <origin rpy="0 0 3.14159265359" xyz="0 0.762 0"/>
  </joint>
  <link name="dagger_door_right_anchor_link"/>
  <joint name="dagger_door_right_joint" type="revolute">
    <parent link="dagger_door_right_anchor_link"/>
    <child link="dagger_door_right_link_tmp"/>
    <origin rpy="0 0 0" xyz="0 0 0"/>
    <axis xyz="0 0 1"/>
    <limit effort="1000.0" lower="0" upper="1.57" velocity="0.1"/>
  </joint>
  <link name="dagger_door_right_link_tmp"/>
  <joint name="dagger_door_right_joint_fixed_2" type="fixed">
    <parent link="dagger_door_right_link_tmp"/>
    <child link="dagger_door_right_link"/>
    <origin rpy="0 0 0" xyz="-0.01 0.19 0.38"/>
  </joint>
  <link name="dagger_door_right_link">
    <inertial>
      <origin rpy="0 0 0" xyz="0 0 0"/>
      <mass value="1.0"/>
      <inertia ixx="0.0001" ixy="0" ixz="0" iyy="0.0001" iyz="0" izz="0.0001"/>
    </inertial>
    <visual name="dagger_door_right_visual">
      <origin rpy="0 0 0" xyz="0 0 0"/>
      <geometry>
        <mesh filename="package://kitchen_description/meshes/obj/front_vertical_right.obj" scale="1.0 1.0 1.0"/>
      </geometry>
      <material name="Grey"/>
    </visual>
    <collision>
      <geometry>
        <mesh filename="package://kitchen_description/meshes/obj/front_vertical_right.obj" scale="1.0 1.0 1.0"/>
      </geometry>
    </collision>
  </link>
  <joint name="dagger_door_right_handle_transform" type="fixed">
    <parent link="dagger_door_right_link_tmp"/>
    <child link="dagger_door_right_handle"/>
    <origin rpy="0 0 3.1514" xyz="-0.05905 0.33 0.13"/>
    <axis xyz="0 0 1"/>
  </joint>
  <link name="dagger_door_right_handle">
    <inertial>
      <origin rpy="0 0 0" xyz="0 0 0"/>
      <mass value="1.0"/>
      <inertia ixx="0.0001" ixy="0" ixz="0" iyy="0.0001" iyz="0" izz="0.0001"/>
    </inertial>
    <visual name="dagger_door_right_handle_visual">
      <origin rpy="0  0  0" xyz="0  0  0"/>
      <geometry>
        <mesh filename="package://kitchen_description/meshes/obj/handle.obj" scale="1.0 1.0 1.0"/>
      </geometry>
      <material name="White"/>
    </visual>
    <collision>
      <geometry>
        <mesh filename="package://kitchen_description/meshes/obj/handle.obj" scale="1.0 1.0 1.0"/>
      </geometry>
    </collision>
  </link>
  <!-- Hitman (Bottom Cabinet Left of Range) -->
  <joint name="hitman_transform" type="fixed">
    <parent link="sektion"/>
    <child link="hitman_tmp"/>
    <origin rpy="0 0 0" xyz="0 0 -0.55"/>
    <axis xyz="0 0 1"/>
  </joint>
  <link name="hitman_tmp">
    <inertial>
      <origin rpy="0 0 0" xyz="0 0 0"/>
      <mass value="10.0"/>
      <inertia ixx="0.0001" ixy="0" ixz="0" iyy="0.0001" iyz="0" izz="0.0001"/>
    </inertial>
    <visual name="hitman_visual">
      <origin rpy="0  0  0" xyz="0  0  0"/>
      <geometry>
        <mesh filename="package://kitchen_description/meshes/obj/sektion_bottom_two_drawers.obj" scale="1.0 1.0 1.0"/>
      </geometry>
      <material name="White"/>
    </visual>
    <collision>
      <geometry>
        <mesh filename="package://kitchen_description/meshes/obj/sektion_bottom_two_drawers.obj" scale="1.0 1.0 1.0"/>
      </geometry>
    </collision>
  </link>
  <joint name="hitman_countertop_transform" type="fixed">
    <parent link="hitman_tmp"/>
    <child link="hitman_countertop"/>
    <origin rpy="0 0 0" xyz="-0.04 -0.75 -0.02"/>
    <axis xyz="0 0 1"/>
  </joint>
  <link name="hitman_countertop">
    <!-- Use this for debugging purposes
        <visual>
          <geometry>
            <box size="0.655 1.5 0.04"/>
          </geometry>
        </visual>
        -->
  </link>
  <joint name="hitman_transform_2" type="fixed">
    <parent link="hitman_tmp"/>
    <child link="hitman"/>
    <origin rpy="0 0 0" xyz="-0.06 -0.381 -0.4215"/>
    <axis xyz="0 0 1"/>
  </joint>
  <link name="hitman"/>
  <joint name="hitman_drawer_top_joint" type="prismatic">
    <parent link="hitman"/>
    <child link="hitman_drawer_top"/>
    <origin rpy="0 0 0" xyz="0.04 0 0.085"/>
    <axis xyz="1 0 0"/>
    <limit effort="1000.0" lower="0.0" upper="0.4" velocity="0.1"/>
  </joint>
  <link name="hitman_drawer_top">
    <inertial>
      <origin rpy="0 0 0" xyz="0 0 0"/>
      <mass value="1.0"/>
      <inertia ixx="0.0001" ixy="0" ixz="0" iyy="0.0001" iyz="0" izz="0.0001"/>
    </inertial>
    <visual name="hitman_drawer_top_visual">
      <origin rpy="0  0  0" xyz="0  0  0"/>
      <geometry>
        <mesh filename="package://kitchen_description/meshes/obj/drawer_large.obj" scale="1.0 1.0 1.0"/>
      </geometry>
      <material name="Grey"/>
    </visual>
    <collision>
      <geometry>
        <mesh filename="package://kitchen_description/meshes/obj/drawer_large.obj" scale="1.0 1.0 1.0"/>
      </geometry>
    </collision>
  </link>
  <joint name="hitman_joint_fixed_top_front" type="fixed">
    <parent link="hitman_drawer_top"/>
    <child link="hitman_drawer_top_front"/>
    <origin rpy="0 0 0" xyz="0.28 0 0.10"/>
    <axis xyz="0 0 1"/>
  </joint>
  <link name="hitman_drawer_top_front"/>
  <joint name="hitman_drawer_handle_top_joint" type="fixed">
    <parent link="hitman_drawer_top"/>
    <child link="hitman_drawer_handle_top"/>
    <origin rpy="1.57079632679 0 0" xyz="0.32 0 0.255"/>
    <axis xyz="1 0 0"/>
    <limit effort="1000.0" lower="0.0" upper="0.4" velocity="0.1"/>
  </joint>
  <link name="hitman_drawer_handle_top">
    <inertial>
      <origin rpy="0 0 0" xyz="0 0 0"/>
      <mass value="1.0"/>
      <inertia ixx="0.0001" ixy="0" ixz="0" iyy="0.0001" iyz="0" izz="0.0001"/>
    </inertial>
    <visual name="hitman_drawer_top_visual">
      <origin rpy="0  0  0" xyz="0  0  0"/>
      <geometry>
        <mesh filename="package://kitchen_description/meshes/obj/handle.obj" scale="1.0 1.0 1.0"/>
      </geometry>
      <material name="White"/>
    </visual>
    <collision>
      <geometry>
        <mesh filename="package://kitchen_description/meshes/obj/handle.obj" scale="1.0 1.0 1.0"/>
      </geometry>
    </collision>
  </link>
  <joint name="hitman_drawer_bottom_joint" type="prismatic">
    <parent link="hitman"/>
    <child link="hitman_drawer_bottom"/>
    <origin rpy="0 0 0" xyz="0.04 0 -0.291"/>
    <axis xyz="1 0 0"/>
    <limit effort="1000.0" lower="0.0" upper="0.4" velocity="0.1"/>
  </joint>
  <link name="hitman_drawer_bottom">
    <inertial>
      <origin rpy="0 0 0" xyz="0 0 0"/>
      <mass value="1.0"/>
      <inertia ixx="0.0001" ixy="0" ixz="0" iyy="0.0001" iyz="0" izz="0.0001"/>
    </inertial>
    <visual name="hitman_drawer_bottom_visual">
      <origin rpy="0  0  0" xyz="0  0  0"/>
      <geometry>
        <mesh filename="package://kitchen_description/meshes/obj/drawer_large.obj" scale="1.0 1.0 1.0"/>
      </geometry>
      <material name="Grey"/>
    </visual>
    <collision>
      <geometry>
        <mesh filename="package://kitchen_description/meshes/obj/drawer_large.obj" scale="1.0 1.0 1.0"/>
      </geometry>
    </collision>
  </link>
  <joint name="hitman_joint_fixed_bottom_front" type="fixed">
    <parent link="hitman_drawer_bottom"/>
    <child link="hitman_drawer_bottom_front"/>
    <origin rpy="0 0 0" xyz="0.28 0 0.10"/>
    <axis xyz="0 0 1"/>
  </joint>
  <link name="hitman_drawer_bottom_front"/>
  <joint name="hitman_drawer_handle_bottom_joint" type="fixed">
    <parent link="hitman_drawer_bottom"/>
    <child link="hitman_drawer_handle_bottom"/>
    <origin rpy="1.57079632679 0 0" xyz="0.32 0 0.255"/>
    <axis xyz="1 0 0"/>
    <limit effort="1000.0" lower="0.0" upper="0.4" velocity="0.1"/>
  </joint>
  <link name="hitman_drawer_handle_bottom">
    <inertial>
      <origin rpy="0 0 0" xyz="0 0 0"/>
      <mass value="1.0"/>
      <inertia ixx="0.0001" ixy="0" ixz="0" iyy="0.0001" iyz="0" izz="0.0001"/>
    </inertial>
    <visual name="hitman_drawer_bottom_visual">
      <origin rpy="0  0  0" xyz="0  0  0"/>
      <geometry>
        <mesh filename="package://kitchen_description/meshes/obj/handle.obj" scale="1.0 1.0 1.0"/>
      </geometry>
      <material name="White"/>
    </visual>
    <collision>
      <geometry>
        <mesh filename="package://kitchen_description/meshes/obj/handle.obj" scale="1.0 1.0 1.0"/>
      </geometry>
    </collision>
  </link>
  <!-- Bottom Cabinet Right of Range (original sektion_cabinet_model) -->
  <joint name="indigo_transform" type="fixed">
    <parent link="sektion"/>
    <child link="indigo_tmp"/>
    <origin rpy="0 0 0" xyz="0 0.83 -0.55"/>
    <axis xyz="0 0 1"/>
  </joint>
  <link name="indigo_tmp">
    <inertial>
      <origin rpy="0 0 0" xyz="0 0 0"/>
      <mass value="10.0"/>
      <inertia ixx="0.0001" ixy="0" ixz="0" iyy="0.0001" iyz="0" izz="0.0001"/>
    </inertial>
    <visual name="indigo_visual">
      <origin rpy="0  0  0" xyz="0  0  0"/>
      <geometry>
        <mesh filename="package://kitchen_description/meshes/obj/sektion_bottom_cabinet.obj" scale="1.0 1.0 1.0"/>
      </geometry>
      <material name="White"/>
    </visual>
    <collision>
      <geometry>
        <mesh filename="package://kitchen_description/meshes/obj/sektion_bottom_cabinet.obj" scale="1.0 1.0 1.0"/>
      </geometry>
    </collision>
  </link>
  <joint name="indigo_countertop_transform" type="fixed">
    <parent link="indigo_tmp"/>
    <child link="indigo_countertop"/>
    <origin rpy="0 0 0" xyz="-0.04 0.4175 -0.02"/>
    <axis xyz="0 0 1"/>
  </joint>
  <link name="indigo_countertop">
    <!-- Use this for debugging purposes
        <visual>
          <geometry>
            <box size="0.655 0.835 0.04"/>
          </geometry>
        </visual>
         -->
  </link>
  <joint name="indigo_transform_2" type="fixed">
    <parent link="indigo_tmp"/>
    <child link="indigo"/>
    <origin rpy="0 0 0" xyz="-0.06 0.381 -0.4215"/>
    <axis xyz="0 0 1"/>
  </joint>
  <link name="indigo"/>
  <link name="indigo_drawer_top">
    <inertial>
      <origin rpy="0 0 0" xyz="0 0 0"/>
      <mass value="1.0"/>
      <inertia ixx="0.0001" ixy="0" ixz="0" iyy="0.0001" iyz="0" izz="0.0001"/>
    </inertial>
    <visual name="sektion_bottom_drawer_top_visual">
      <origin rpy="0  0  0" xyz="0  0  0"/>
      <geometry>
        <mesh filename="package://kitchen_description/meshes/obj/drawer.obj" scale="1.0 1.0 1.0"/>
      </geometry>
      <material name="Grey"/>
    </visual>
    <collision>
      <geometry>
        <mesh filename="package://kitchen_description/meshes/obj/drawer.obj" scale="1.0 1.0 1.0"/>
      </geometry>
    </collision>
  </link>
  <link name="indigo_drawer_handle_top">
    <inertial>
      <origin rpy="0 0 0" xyz="0 0 0"/>
      <mass value="1.0"/>
      <inertia ixx="0.0001" ixy="0" ixz="0" iyy="0.0001" iyz="0" izz="0.0001"/>
    </inertial>
    <visual name="sektion_bottom_drawer_handle_top_visual">
      <origin rpy="0  0  0" xyz="0  0  0"/>
      <geometry>
        <mesh filename="package://kitchen_description/meshes/obj/handle.obj" scale="1.0 1.0 1.0"/>
      </geometry>
      <material name="White"/>
    </visual>
    <collision>
      <geometry>
        <mesh filename="package://kitchen_description/meshes/obj/handle.obj" scale="1.0 1.0 1.0"/>
      </geometry>
    </collision>
  </link>
  <link name="indigo_drawer_bottom">
    <inertial>
      <origin rpy="0 0 0" xyz="0 0 0"/>
      <mass value="1.0"/>
      <inertia ixx="0.0001" ixy="0" ixz="0" iyy="0.0001" iyz="0" izz="0.0001"/>
    </inertial>
    <visual name="sektion_bottom_drawer_bottom_visual">
      <origin rpy="0  0  0" xyz="0  0  0"/>
      <geometry>
        <mesh filename="package://kitchen_description/meshes/obj/drawer.obj" scale="1.0 1.0 1.0"/>
      </geometry>
      <material name="Grey"/>
    </visual>
    <collision>
      <geometry>
        <mesh filename="package://kitchen_description/meshes/obj/drawer.obj" scale="1.0 1.0 1.0"/>
      </geometry>
    </collision>
  </link>
  <link name="indigo_drawer_handle_bottom">
    <inertial>
      <origin rpy="0 0 0" xyz="0 0 0"/>
      <mass value="1.0"/>
      <inertia ixx="0.0001" ixy="0" ixz="0" iyy="0.0001" iyz="0" izz="0.0001"/>
    </inertial>
    <visual name="sektion_bottom_drawer_handle_bottom_visual">
      <origin rpy="0  0  0" xyz="0  0  0"/>
      <geometry>
        <mesh filename="package://kitchen_description/meshes/obj/handle.obj" scale="1.0 1.0 1.0"/>
      </geometry>
      <material name="White"/>
    </visual>
    <collision>
      <geometry>
        <mesh filename="package://kitchen_description/meshes/obj/handle.obj" scale="1.0 1.0 1.0"/>
      </geometry>
    </collision>
  </link>
  <link name="indigo_door_right_anchor_link"/>
  <link name="indigo_door_right_joint_anchor_link"/>
  <link name="indigo_door_right_link">
    <inertial>
      <origin rpy="0 0 0" xyz="0 0 0"/>
      <mass value="1.0"/>
      <inertia ixx="0.0001" ixy="0" ixz="0" iyy="0.0001" iyz="0" izz="0.0001"/>
    </inertial>
    <visual name="indigo_door_right_visual">
      <origin rpy="0  0  0" xyz="0  -0.184706  0"/>
      <geometry>
        <mesh filename="package://kitchen_description/meshes/obj/front_bottom_vertical_door.obj" scale="1.0 1.0 1.0"/>
      </geometry>
      <material name="Grey"/>
    </visual>
    <collision>
      <origin rpy="0  0  0" xyz="0  -0.184706  0"/>
      <geometry>
        <mesh filename="package://kitchen_description/meshes/obj/front_bottom_vertical_door.obj" scale="1.0 1.0 1.0"/>
      </geometry>
    </collision>
  </link>
  <link name="indigo_door_right_nob_link">
    <inertial>
      <origin rpy="0 0 0" xyz="0 0 0"/>
      <mass value="1.0"/>
      <inertia ixx="0.0001" ixy="0" ixz="0" iyy="0.0001" iyz="0" izz="0.0001"/>
    </inertial>
    <visual name="indigo_door_right_nob_visual">
      <origin rpy="0  0  0" xyz="0  -0.184706  0"/>
      <geometry>
        <mesh filename="package://kitchen_description/meshes/obj/handle.obj" scale="1.0 1.0 1.0"/>
      </geometry>
      <material name="White"/>
    </visual>
    <collision>
      <origin rpy="0  0  0" xyz="0  -0.184706  0"/>
      <geometry>
        <mesh filename="package://kitchen_description/meshes/obj/handle.obj" scale="1.0 1.0 1.0"/>
      </geometry>
    </collision>
  </link>
  <link name="indigo_door_right"/>
  <link name="indigo_door_left_anchor_link"/>
  <link name="indigo_door_left_joint_anchor_link"/>
  <link name="indigo_door_left_link">
    <inertial>
      <origin rpy="0 0 0" xyz="0 0 0"/>
      <mass value="1.0"/>
      <inertia ixx="0.0001" ixy="0" ixz="0" iyy="0.0001" iyz="0" izz="0.0001"/>
    </inertial>
    <visual name="indigo_door_left_visual">
      <origin rpy="0  0  0" xyz="0  0.184706  0"/>
      <geometry>
        <mesh filename="package://kitchen_description/meshes/obj/front_bottom_vertical_door.obj" scale="1.0 1.0 1.0"/>
      </geometry>
      <material name="Grey"/>
    </visual>
    <collision>
      <origin rpy="0  0  0" xyz="0  0.184706  0"/>
      <geometry>
        <mesh filename="package://kitchen_description/meshes/obj/front_bottom_vertical_door.obj" scale="1.0 1.0 1.0"/>
      </geometry>
    </collision>
  </link>
  <link name="indigo_door_left_nob_link">
    <inertial>
      <origin rpy="0 0 0" xyz="0 0 0"/>
      <mass value="1.0"/>
      <inertia ixx="0.0001" ixy="0" ixz="0" iyy="0.0001" iyz="0" izz="0.0001"/>
    </inertial>
    <visual name="indigo_door_left_nob_visual">
      <origin rpy="0  0  0" xyz="0  0.184706  0"/>
      <geometry>
        <mesh filename="package://kitchen_description/meshes/obj/handle.obj" scale="1.0 1.0 1.0"/>
      </geometry>
      <material name="White"/>
    </visual>
    <collision>
      <origin rpy="0  0  0" xyz="0  0.184706  0"/>
      <geometry>
        <mesh filename="package://kitchen_description/meshes/obj/handle.obj" scale="1.0 1.0 1.0"/>
      </geometry>
    </collision>
  </link>
  <link name="indigo_door_left"/>
  <joint name="indigo_door_right_joint_fixed" type="fixed">
    <parent link="indigo"/>
    <child link="indigo_door_right_anchor_link"/>
    <origin rpy="0 0 0" xyz="0.3162 0.3757 -0.12973"/>
  </joint>
  <joint name="indigo_door_right_shift_joint" type="fixed">
    <parent link="indigo_door_right_anchor_link"/>
    <child link="indigo_door_right_joint_anchor_link"/>
    <origin rpy="0 0 0" xyz="0 0 0"/>
    <axis xyz="0 1 0"/>
    <limit effort="1000.0" lower="0" upper="-0.015" velocity="0.0"/>
    <mimic joint="indigo_door_right_joint" multiplier="-0.009554" offset="0"/>
  </joint>
  <joint name="indigo_door_right_joint" type="revolute">
    <parent link="indigo_door_right_joint_anchor_link"/>
    <child link="indigo_door_right_link"/>
    <origin rpy="0 0 0" xyz="0 0 0"/>
    <axis xyz="0 0 1"/>
    <limit effort="1000.0" lower="0" upper="1.57" velocity="0.1"/>
  </joint>
  <joint name="indigo_door_right_transform" type="fixed">
    <parent link="indigo_door_right_link"/>
    <child link="indigo_door_right"/>
    <origin rpy="0 0 0" xyz="0 -.181 0"/>
    <axis xyz="0 0 1"/>
  </joint>
  <joint name="indigo_door_right_nob_transform" type="fixed">
    <parent link="indigo_door_right_link"/>
    <child link="indigo_door_right_nob_link"/>
    <origin rpy="0 0 0" xyz="0.0515 -0.13 0.1"/>
    <axis xyz="0 0 1"/>
  </joint>
  <joint name="indigo_door_left_joint_fixed" type="fixed">
    <parent link="indigo"/>
    <child link="indigo_door_left_anchor_link"/>
    <origin rpy="0 0 0" xyz="0.3162 -0.3757 -0.12973"/>
  </joint>
  <joint name="indigo_door_left_shift_joint" type="fixed">
    <parent link="indigo_door_left_anchor_link"/>
    <child link="indigo_door_left_joint_anchor_link"/>
    <origin rpy="0 0 0" xyz="0 0 0"/>
    <axis xyz="0 1 0"/>
    <limit effort="1000.0" lower="0" upper="-0.015" velocity="0.0"/>
    <mimic joint="indigo_door_left_joint" multiplier="-0.009554" offset="0"/>
  </joint>
  <joint name="indigo_door_left_joint" type="revolute">
    <parent link="indigo_door_left_joint_anchor_link"/>
    <child link="indigo_door_left_link"/>
    <origin rpy="0 0 0" xyz="0 0 0"/>
    <axis xyz="0 0 1"/>
    <limit effort="1000.0" lower="-1.57" upper="0" velocity="0.1"/>
  </joint>
  <joint name="indigo_door_left_transform" type="fixed">
    <parent link="indigo_door_left_link"/>
    <child link="indigo_door_left"/>
    <origin rpy="0 0 0" xyz="0 .181 0"/>
    <axis xyz="0 0 1"/>
  </joint>
  <joint name="indigo_door_left_nob_transform" type="fixed">
    <parent link="indigo_door_left_link"/>
    <child link="indigo_door_left_nob_link"/>
    <origin rpy="0 0 0" xyz="0.0515 0.13 0.1"/>
    <axis xyz="0 0 1"/>
  </joint>
  <joint name="indigo_drawer_top_joint" type="prismatic">
    <parent link="indigo"/>
    <child link="indigo_drawer_top"/>
    <origin rpy="0 0 0" xyz="0.0515 0 0.3172"/>
    <axis xyz="1 0 0"/>
    <limit effort="1000.0" lower="0.0" upper="0.4" velocity="0.1"/>
  </joint>
  <joint name="indigo_drawer_handle_top_joint" type="fixed">
    <parent link="indigo_drawer_top"/>
    <child link="indigo_drawer_handle_top"/>
    <origin rpy="1.57079632679 0 0" xyz="0.31 0 0"/>
    <axis xyz="1 0 0"/>
    <limit effort="1000.0" lower="0.0" upper="0.4" velocity="0.1"/>
  </joint>
  <joint name="indigo_drawer_bottom_joint" type="prismatic">
    <parent link="indigo"/>
    <child link="indigo_drawer_bottom"/>
    <origin rpy="0 0 0" xyz="0.0515 0 0.18795"/>
    <axis xyz="1 0 0"/>
    <limit effort="1000.0" lower="0.0" upper="0.4" velocity="0.0"/>
  </joint>
  <joint name="indigo_drawer_handle_bottom_joint" type="fixed">
    <parent link="indigo_drawer_bottom"/>
    <child link="indigo_drawer_handle_bottom"/>
    <origin rpy="1.57079632679 0 0" xyz="0.31 0 0"/>
    <axis xyz="1 0 0"/>
    <limit effort="1000.0" lower="0.0" upper="0.4" velocity="0.1"/>
  </joint>
</robot>
