<?xml version="1.0" ?>
<robot name="partnet_917fd3e68de79bf69ece21a0b0786a69">
	<link name="base"/>
	<link name="link_0">
		<visual name="lid-8">
			<origin xyz="0.002564500000000001 0 -0.00572319807062216"/>
			<geometry>
				<mesh filename="textured_objs/original-1.obj"/>
			</geometry>
		</visual>
		<collision>
			<origin xyz="0.002564500000000001 0 -0.00572319807062216"/>
			<geometry>
				<mesh filename="textured_objs/original-1.obj"/>
			</geometry>
		</collision>
	</link>
	<joint name="joint_0" type="continuous">
		<origin xyz="0.0 0 0.0"/>
		<axis xyz="0 1 0"/>
		<child link="link_0"/>
		<parent link="link_0_helper"/>
	</joint>
	<link name="link_1">
		<visual name="body-6">
			<origin xyz="0 0 0"/>
			<geometry>
				<mesh filename="textured_objs/new-19.obj"/>
			</geometry>
		</visual>
		<visual name="neck-7">
			<origin xyz="0 0 0"/>
			<geometry>
				<mesh filename="textured_objs/new-13.obj"/>
			</geometry>
		</visual>
		<visual name="neck-7">
			<origin xyz="0 0 0"/>
			<geometry>
				<mesh filename="textured_objs/new-14.obj"/>
			</geometry>
		</visual>
		<collision>
			<origin xyz="0 0 0"/>
			<geometry>
				<mesh filename="textured_objs/new-19.obj"/>
			</geometry>
		</collision>
		<collision>
			<origin xyz="0 0 0"/>
			<geometry>
				<mesh filename="textured_objs/new-13.obj"/>
			</geometry>
		</collision>
		<collision>
			<origin xyz="0 0 0"/>
			<geometry>
				<mesh filename="textured_objs/new-14.obj"/>
			</geometry>
		</collision>
	</link>
	<joint name="joint_1" type="fixed">
		<origin rpy="1.570796326794897 0 -1.570796326794897" xyz="0 0 0"/>
		<child link="link_1"/>
		<parent link="base"/>
	</joint>
	<link name="link_0_helper"/>
	<joint name="joint_2" type="prismatic">
		<origin xyz="-0.002564500000000001 0 0.00572319807062216"/>
		<axis xyz="0 1 0"/>
		<child link="link_0_helper"/>
		<parent link="link_1"/>
		<limit lower="-0.016000000000000014" upper="0"/>
	</joint>
</robot>
