<?xml version="1.0" ?>
<robot name="partnet_6601ef650f03e000c49931aa7ca8fecb">
	<link name="base"/>
	<link name="link_0">
		<visual name="frame-7">
			<origin xyz="0 0 0"/>
			<geometry>
				<mesh filename="textured_objs/new-0.obj"/>
			</geometry>
		</visual>
		<visual name="frame-7">
			<origin xyz="0 0 0"/>
			<geometry>
				<mesh filename="textured_objs/new-3.obj"/>
			</geometry>
		</visual>
		<collision>
			<origin xyz="0 0 0"/>
			<geometry>
				<mesh filename="textured_objs/new-0.obj"/>
			</geometry>
		</collision>
		<!-- <collision>
			<origin xyz="0 0 0"/>
			<geometry>
				<mesh filename="textured_objs/new-3.obj"/>
			</geometry>
		</collision> -->
		<collision>
			<origin xyz="0 0 0"/>
			<geometry>
				<mesh filename="textured_objs/new-3-left.obj"/>
			</geometry>
		</collision>
		<collision>
			<origin xyz="0 0 0"/>
			<geometry>
				<mesh filename="textured_objs/new-3-right.obj"/>
			</geometry>
		</collision>
		<collision>
			<origin xyz="0 0 0"/>
			<geometry>
				<mesh filename="textured_objs/new-3-top.obj"/>
			</geometry>
		</collision>
		<collision>
			<origin xyz="0 0 0"/>
			<geometry>
				<mesh filename="textured_objs/new-3-back.obj"/>
			</geometry>
		</collision>
	</link>
	<joint name="joint_0" type="fixed">
		<origin rpy="1.570796326794897 0 -1.570796326794897" xyz="0 0 0"/>
		<child link="link_0"/>
		<parent link="base"/>
	</joint>

	<link name="handle">
		<visual name="handle-10">
			<origin xyz="-0.41948741391591016 -0.77081 -0.4619671850171603"/>
			<geometry>
				<mesh filename="textured_objs/new-1.obj"/>
			</geometry>
		</visual>
		<collision>
			<origin xyz="-0.41948741391591016 -0.77081 -0.4219671850171603"/>
			<geometry>
				<mesh filename="textured_objs/new-1-fixed.obj"/>
			</geometry>
		</collision>
	</link>
	<joint name="joint_handle" type="fixed">
		<origin rpy="0 0 0" xyz="0 0 0"/>
		<child link="handle"/>
		<parent link="link_1"/>
	</joint>

	<link name="link_1">
		<visual name="other_leaf-12">
			<origin xyz="-0.41948741391591016 -0.77081 -0.4619671850171603"/>
			<geometry>
				<mesh filename="textured_objs/original-2.obj"/>
			</geometry>
		</visual>
		<visual name="other_leaf-12">
			<origin xyz="-0.41948741391591016 -0.77081 -0.4619671850171603"/>
			<geometry>
				<mesh filename="textured_objs/original-4.obj"/>
			</geometry>
		</visual>
		<visual name="other_leaf-12">
			<origin xyz="-0.41948741391591016 -0.77081 -0.4619671850171603"/>
			<geometry>
				<mesh filename="textured_objs/original-3.obj"/>
			</geometry>
		</visual>
		<visual name="door_frame-9">
			<origin xyz="-0.41948741391591016 -0.77081 -0.4619671850171603"/>
			<geometry>
				<mesh filename="textured_objs/new-2.obj"/>
			</geometry>
		</visual>
		<collision>
			<origin xyz="-0.41948741391591016 -0.77081 -0.4619671850171603"/>
			<geometry>
				<mesh filename="textured_objs/original-2.obj"/>
			</geometry>
		</collision>
		<collision>
			<origin xyz="-0.41948741391591016 -0.77081 -0.4619671850171603"/>
			<geometry>
				<mesh filename="textured_objs/original-4.obj"/>
			</geometry>
		</collision>
		<collision>
			<origin xyz="-0.41948741391591016 -0.77081 -0.4619671850171603"/>
			<geometry>
				<mesh filename="textured_objs/original-3.obj"/>
			</geometry>
		</collision>
		<collision>
			<origin xyz="-0.41948741391591016 -0.77081 -0.4619671850171603"/>
			<geometry>
				<mesh filename="textured_objs/new-2.obj"/>
			</geometry>
		</collision>
	</link>
	<joint name="joint_1" type="revolute">
		<origin xyz="0.41948741391591016 0.77081 0.4619671850171603"/>
		<axis xyz="0 1 0"/>
		<child link="link_1"/>
		<parent link="link_0"/>
		<limit lower="0.0" upper="3.141592653589793"/>
	</joint>
</robot>
