<?xml version="1.0" ?>
<robot name="partnet_682e6f0b16125b6b842c43a21556b93c">
	<link name="base"/>

	<link name="handle_link_0">
		<inertial>
	      <origin rpy="0 0 0" xyz="0 0 0"/>
	      <mass value="10.0"/>
	      <inertia ixx="0.0001" ixy="0" ixz="0" iyy="0.0001" iyz="0" izz="0.0001"/>
	    </inertial>
		<visual name="handle-14">
			<origin xyz="-0.2861636360363628 -0.892118 -0.2673337997744748"/>
			<geometry>
				<mesh filename="textured_objs/new-6.obj"/>
			</geometry>
		</visual>
		<collision>
			<origin xyz="-0.2861636360363628 -0.892118 -0.2673337997744748"/>
			<geometry>
				<mesh filename="textured_objs/new-6.obj"/>
			</geometry>
		</collision>
	</link>
	<joint name="handle_joint_0" type="fixed">
		<origin xyz="0 0.1 0.05" rpy="0 0 0" />
		<child link="handle_link_0"/>
		<parent link="link_0"/>
	</joint>

	<link name="link_0">
		<visual name="door_frame-13">
			<origin xyz="-0.2861636360363628 -0.892118 -0.2673337997744748"/>
			<geometry>
				<mesh filename="textured_objs/new-8.obj"/>
			</geometry>
		</visual>
		<collision>
			<origin xyz="-0.2861636360363628 -0.892118 -0.2673337997744748"/>
			<geometry>
				<mesh filename="textured_objs/new-8.obj"/>
			</geometry>
		</collision>
	</link>
	<joint name="joint_0" type="revolute">
		<origin xyz="0.2861636360363628 0.892118 0.2673337997744748"/>
		<axis xyz="0 0.9999999999999999 0"/>
		<child link="link_0"/>
		<parent link="link_2"/>
		<limit lower="-0.0" upper="3.141592653589793"/>
	</joint>

	<link name="handle_link_1">
		<inertial>
	      <origin rpy="0 0 0" xyz="0 0 0"/>
	      <mass value="10.0"/>
	      <inertia ixx="0.0001" ixy="0" ixz="0" iyy="0.0001" iyz="0" izz="0.0001"/>
	    </inertial>
		<visual name="handle-12">
			<origin xyz="-0.2861636360363628 -0.892118 -0.2673337997744748"/>
			<geometry>
				<mesh filename="textured_objs/new-5.obj"/>
			</geometry>
		</visual>
		<collision>
			<origin xyz="-0.2861636360363628 -0.892118 -0.2673337997744748"/>
			<geometry>
				<mesh filename="textured_objs/new-5.obj"/>
			</geometry>
		</collision>
	</link>
	<joint name="handle_joint_1" type="fixed">
		<origin xyz="0 -0.1 0.05" rpy="0 0 0" />
		<child link="handle_link_1"/>
		<parent link="link_1"/>
	</joint>

	<link name="link_1">
		<visual name="door_frame-11">
			<origin xyz="-0.2861636360363628 -0.892118 -0.2673337997744748"/>
			<geometry>
				<mesh filename="textured_objs/new-7.obj"/>
			</geometry>
		</visual>
		<collision>
			<origin xyz="-0.2861636360363628 -0.892118 -0.2673337997744748"/>
			<geometry>
				<mesh filename="textured_objs/new-7.obj"/>
			</geometry>
		</collision>
	</link>
	<joint name="joint_1" type="revolute">
		<origin xyz="0.2861636360363628 0.892118 0.2673337997744748"/>
		<axis xyz="0 0.9999999999999999 0"/>
		<child link="link_1"/>
		<parent link="link_2"/>
		<limit lower="-0.0" upper="3.141592653589793"/>
	</joint>

	<link name="link_2">
		<visual name="other_leaf-17">
			<origin xyz="0 0 0"/>
			<geometry>
				<mesh filename="textured_objs/new-0.obj"/>
			</geometry>
		</visual>
		<visual name="frame-8">
			<origin xyz="0 0 0"/>
			<geometry>
				<mesh filename="textured_objs/new-12.obj"/>
			</geometry>
		</visual>
		<visual name="frame-8">
			<origin xyz="0 0 0"/>
			<geometry>
				<mesh filename="textured_objs/new-10.obj"/>
			</geometry>
		</visual>
		<visual name="frame-8">
			<origin xyz="0 0 0"/>
			<geometry>
				<mesh filename="textured_objs/new-11.obj"/>
			</geometry>
		</visual>
		<visual name="foot-18">
			<origin xyz="0 0 0"/>
			<geometry>
				<mesh filename="textured_objs/new-3.obj"/>
			</geometry>
		</visual>
		<visual name="foot-19">
			<origin xyz="0 0 0"/>
			<geometry>
				<mesh filename="textured_objs/new-2.obj"/>
			</geometry>
		</visual>
		<visual name="foot-20">
			<origin xyz="0 0 0"/>
			<geometry>
				<mesh filename="textured_objs/new-1.obj"/>
			</geometry>
		</visual>
		<visual name="foot-21">
			<origin xyz="0 0 0"/>
			<geometry>
				<mesh filename="textured_objs/new-4.obj"/>
			</geometry>
		</visual>
		<collision>
			<origin xyz="0 0 0"/>
			<geometry>
				<mesh filename="textured_objs/new-0.obj"/>
			</geometry>
		</collision>
		<collision>
			<origin xyz="0 0 0"/>
			<geometry>
				<mesh filename="textured_objs/new-12.obj"/>
			</geometry>
		</collision>
		<collision>
			<origin xyz="0 0 0"/>
			<geometry>
				<mesh filename="textured_objs/new-10.obj"/>
			</geometry>
		</collision>
		<collision>
			<origin xyz="0 0 0"/>
			<geometry>
				<mesh filename="textured_objs/new-11.obj"/>
			</geometry>
		</collision>
		<collision>
			<origin xyz="0 0 0"/>
			<geometry>
				<mesh filename="textured_objs/new-3.obj"/>
			</geometry>
		</collision>
		<collision>
			<origin xyz="0 0 0"/>
			<geometry>
				<mesh filename="textured_objs/new-2.obj"/>
			</geometry>
		</collision>
		<collision>
			<origin xyz="0 0 0"/>
			<geometry>
				<mesh filename="textured_objs/new-1.obj"/>
			</geometry>
		</collision>
		<collision>
			<origin xyz="0 0 0"/>
			<geometry>
				<mesh filename="textured_objs/new-4.obj"/>
			</geometry>
		</collision>
	</link>
	<joint name="joint_2" type="fixed">
		<origin rpy="1.570796326794897 0 -1.570796326794897" xyz="0 0 0"/>
		<child link="link_2"/>
		<parent link="base"/>
	</joint>
</robot>
