<?xml version="1.0" encoding="utf-8"?>
<!-- This URDF was automatically created by SolidWorks to URDF Exporter! Originally created by Stephen Brawner (brawner@gmail.com) 
     Commit Version: 1.6.0-1-g15f4949  Build Version: 1.6.7594.29634
     For more information, please see http://wiki.ros.org/sw_urdf_exporter -->
<robot
  name="elementB">
  <link
    name="base_link">
    <inertial>
      <origin
        xyz="0.313537640353887 1.34225796669673 0.402818397418737"
        rpy="0 0 0" />
      <mass
        value="182.199456226381" />
      <inertia
        ixx="34.1515019338191"
        ixy="-0.0795734538173952"
        ixz="-0.397765483189175"
        iyy="14.7254347378066"
        iyz="-0.0283456865477044"
        izz="33.4037867750965" />
    </inertial>
    <visual>
      <origin
        xyz="0 0 0"
        rpy="0 0 0" />
      <geometry>
        <mesh
          filename="package://elementB/meshes/base_link.STL" />
      </geometry>
      <material
        name="">
        <color
          rgba="1.0 0.89 0.8 1" />
      </material>
    </visual>
    <collision>
      <origin
        xyz="0 0 0"
        rpy="0 0 0" />
      <geometry>
        <mesh
          filename="package://elementB/meshes/base_link.STL" />
      </geometry>
    </collision>
  </link>
  <link
    name="link1">
    <inertial>
      <origin
        xyz="0.027339 0.02679 -0.14305"
        rpy="0 0 0" />
      <mass
        value="0.52332" />
      <inertia
        ixx="0.0067791"
        ixy="-0.00096258"
        ixz="0.00094621"
        iyy="0.0054549"
        iyz="0.0022785"
        izz="0.0028764" />
    </inertial>
    <visual>
      <origin
        xyz="0 0 0"
        rpy="0 0 0" />
      <geometry>
        <mesh
          filename="package://elementB/meshes/link1.STL" />
      </geometry>
      <material
        name="">
        <color
          rgba="0.75 0.75 0.75 1" />
      </material>
    </visual>
    <collision>
      <origin
        xyz="0 0 0"
        rpy="0 0 0" />
      <geometry>
        <mesh
          filename="package://elementB/meshes/link1.STL" />
      </geometry>
    </collision>
  </link>
  <joint
    name="joint1"
    type="revolute">
    <origin
      xyz="0.16134 0.63462 0.75051"
      rpy="-3.1416 0 1.5708" />
    <parent
      link="base_link" />
    <child
      link="link1" />
    <axis
      xyz="0 0 1" />
    <limit
      lower="-1.57"
      upper="1.57"
      effort="0"
      velocity="0" />
  </joint>
  <link
    name="link2">
    <inertial>
      <origin
        xyz="-0.019489 -0.17854 0.085513"
        rpy="0 0 0" />
      <mass
        value="1.609" />
      <inertia
        ixx="0.034401"
        ixy="-3.9494E-05"
        ixz="0.010759"
        iyy="0.08397"
        iyz="3.6388E-05"
        izz="0.10488" />
    </inertial>
    <visual>
      <origin
        xyz="0 0 0"
        rpy="0 0 0" />
      <geometry>
        <mesh
          filename="package://elementB/meshes/link2.STL" />
      </geometry>
      <material
        name="">
        <color
          rgba="0.75 0.75 0.75 1" />
      </material>
    </visual>
    <collision>
      <origin
        xyz="0 0 0"
        rpy="0 0 0" />
      <geometry>
        <mesh
          filename="package://elementB/meshes/link2.STL" />
      </geometry>
    </collision>
  </link>
  <joint
    name="joint2"
    type="fixed">
    <origin
      xyz="0.14743 0.71981 0.60301"
      rpy="0 0 1.5708" />
    <parent
      link="base_link" />
    <child
      link="link2" />
    <axis
      xyz="0 0 0" />
  </joint>
  <link
    name="link3">
    <inertial>
      <origin
        xyz="0 0 0"
        rpy="0 0 0" />
      <mass
        value="0" />
      <inertia
        ixx="0"
        ixy="0"
        ixz="0"
        iyy="0"
        iyz="0"
        izz="0" />
    </inertial>
    <visual>
      <origin
        xyz="0 0 0"
        rpy="0 0 0" />
      <geometry>
        <mesh
          filename="package://elementB/meshes/link3.STL" />
      </geometry>
      <material
        name="">
        <color
          rgba="0.0 0.0 0.0 1" />
      </material>
    </visual>
    <collision>
      <origin
        xyz="0 0 0"
        rpy="0 0 0" />
      <geometry>
        <mesh
          filename="package://elementB/meshes/link3.STL" />
      </geometry>
    </collision>
  </link>
  <joint
    name="joint3"
    type="fixed">
    <origin
      xyz="0.0585000000000488 1.82327999999997 0.71051"
      rpy="0 0 1.5707963267949" />
    <parent
      link="base_link" />
    <child
      link="link3" />
    <axis
      xyz="0 0 0" />
  </joint>
</robot>
