<?xml version="1.0" ?>
<robot name="partnet_68a74c8e77db3668605f8bb5e3f9a647">
	<link name="base"/>

	<link name="handle_link_0">
		<inertial>
	      <origin rpy="0 0 0" xyz="0 0 0"/>
	      <mass value="10.0"/>
	      <inertia ixx="0.0001" ixy="0" ixz="0" iyy="0.0001" iyz="0" izz="0.0001"/>
	    </inertial>
	    <visual name="handle-17">
			<origin xyz="-0.32425113275347983 -0.8680459999999999 -0.2173851846737711"/>
			<geometry>
				<mesh filename="textured_objs/new-2.obj"/>
			</geometry>
		</visual>
		<collision>
			<origin xyz="-0.32425113275347983 -0.8680459999999999 -0.2173851846737711"/>
			<geometry>
				<mesh filename="textured_objs/new-2.obj"/>
			</geometry>
		</collision>
	</link>
	<joint name="handle_joint_0" type="fixed">
		<origin xyz="0 -0.1 0.05" rpy="0 0 0" />
		<child link="handle_link_0"/>
		<parent link="link_0"/>
	</joint>

	<link name="link_0">
		<visual name="door_frame-16">
			<origin xyz="-0.32425113275347983 -0.8680459999999999 -0.2173851846737711"/>
			<geometry>
				<mesh filename="textured_objs/new-1.obj"/>
			</geometry>
		</visual>
		
		<collision>
			<origin xyz="-0.32425113275347983 -0.8680459999999999 -0.2173851846737711"/>
			<geometry>
				<mesh filename="textured_objs/new-1.obj"/>
			</geometry>
		</collision>
	</link>
	<joint name="joint_0" type="revolute">
		<origin xyz="0.32425113275347983 0.8680459999999999 0.2173851846737711"/>
		<axis xyz="0 1 0"/>
		<child link="link_0"/>
		<parent link="link_2"/>
		<limit lower="-0.0" upper="3.141592653589793"/>
	</joint>


	<link name="handle_link_1">
		<inertial>
	      <origin rpy="0 0 0" xyz="0 0 0"/>
	      <mass value="10.0"/>
	      <inertia ixx="0.0001" ixy="0" ixz="0" iyy="0.0001" iyz="0" izz="0.0001"/>
	    </inertial>
		<visual name="handle-15">
			<origin xyz="-0.32425113275347983 -0.8680459999999999 -0.2173851846737711"/>
			<geometry>
				<mesh filename="textured_objs/new-3.obj"/>
			</geometry>
		</visual>
		<collision>
			<origin xyz="-0.32425113275347983 -0.8680459999999999 -0.2173851846737711"/>
			<geometry>
				<mesh filename="textured_objs/new-3.obj"/>
			</geometry>
		</collision>
	</link>
	<joint name="handle_joint_1" type="fixed">
		<origin xyz="0 0.1 0.05" rpy="0 0 0" />
		<child link="handle_link_1"/>
		<parent link="link_1"/>
	</joint>

	<link name="link_1">
		<visual name="door_frame-14">
			<origin xyz="-0.32425113275347983 -0.8680459999999999 -0.2173851846737711"/>
			<geometry>
				<mesh filename="textured_objs/new-4.obj"/>
			</geometry>
		</visual>
		<visual name="door_frame-14">
			<origin xyz="-0.32425113275347983 -0.8680459999999999 -0.2173851846737711"/>
			<geometry>
				<mesh filename="textured_objs/original-8.obj"/>
			</geometry>
		</visual>
		<collision>
			<origin xyz="-0.32425113275347983 -0.8680459999999999 -0.2173851846737711"/>
			<geometry>
				<mesh filename="textured_objs/new-4.obj"/>
			</geometry>
		</collision>
		<collision>
			<origin xyz="-0.32425113275347983 -0.8680459999999999 -0.2173851846737711"/>
			<geometry>
				<mesh filename="textured_objs/original-8.obj"/>
			</geometry>
		</collision>
	</link>
	<joint name="joint_1" type="revolute">
		<origin xyz="0.32425113275347983 0.8680459999999999 0.2173851846737711"/>
		<axis xyz="0 1 0"/>
		<child link="link_1"/>
		<parent link="link_2"/>
		<limit lower="-0.0" upper="3.141592653589793"/>
	</joint>
	<link name="link_2">
		<visual name="frame-11">
			<origin xyz="0 0 0"/>
			<geometry>
				<mesh filename="textured_objs/new-0.obj"/>
			</geometry>
		</visual>
		<visual name="frame-11">
			<origin xyz="0 0 0"/>
			<geometry>
				<mesh filename="textured_objs/original-16.obj"/>
			</geometry>
		</visual>
		<visual name="foot-5">
			<origin xyz="0 0 0"/>
			<geometry>
				<mesh filename="textured_objs/original-20.obj"/>
			</geometry>
		</visual>
		<visual name="foot-6">
			<origin xyz="0 0 0"/>
			<geometry>
				<mesh filename="textured_objs/original-18.obj"/>
			</geometry>
		</visual>
		<visual name="foot-7">
			<origin xyz="0 0 0"/>
			<geometry>
				<mesh filename="textured_objs/original-19.obj"/>
			</geometry>
		</visual>
		<visual name="foot-8">
			<origin xyz="0 0 0"/>
			<geometry>
				<mesh filename="textured_objs/original-17.obj"/>
			</geometry>
		</visual>
		<collision>
			<origin xyz="0 0 0"/>
			<geometry>
				<mesh filename="textured_objs/new-0.obj"/>
			</geometry>
		</collision>
		<collision>
			<origin xyz="0 0 0"/>
			<geometry>
				<mesh filename="textured_objs/original-16.obj"/>
			</geometry>
		</collision>
		<collision>
			<origin xyz="0 0 0"/>
			<geometry>
				<mesh filename="textured_objs/original-20.obj"/>
			</geometry>
		</collision>
		<collision>
			<origin xyz="0 0 0"/>
			<geometry>
				<mesh filename="textured_objs/original-18.obj"/>
			</geometry>
		</collision>
		<collision>
			<origin xyz="0 0 0"/>
			<geometry>
				<mesh filename="textured_objs/original-19.obj"/>
			</geometry>
		</collision>
		<collision>
			<origin xyz="0 0 0"/>
			<geometry>
				<mesh filename="textured_objs/original-17.obj"/>
			</geometry>
		</collision>
	</link>
	<joint name="joint_2" type="fixed">
		<origin rpy="1.570796326794897 0 -1.570796326794897" xyz="0 0 0"/>
		<child link="link_2"/>
		<parent link="base"/>
	</joint>
</robot>
