<?xml version="1.0" ?>
<robot name="partnet_6b43398bac2b6979438d8caa9ae106fa">
	<link name="base"/>
	<link name="link_0">
		<visual name="wheel-70">
			<origin xyz="-0.915427212967765 0.25107233412824526 0"/>
			<geometry>
				<mesh filename="textured_objs/original-18.obj"/>
			</geometry>
		</visual>
		<collision>
			<origin xyz="-0.915427212967765 0.25107233412824526 0"/>
			<geometry>
				<mesh filename="textured_objs/original-18.obj"/>
			</geometry>
		</collision>
	</link>
	<joint name="joint_0" type="continuous">
		<origin xyz="0.00901189171621597 -0.25107233412824526 0.226891"/>
		<axis xyz="0 0 -1"/>
		<child link="link_0"/>
		<parent link="link_9"/>
	</joint>
	<link name="link_1">
		<visual name="wheel-71">
			<origin xyz="-0.915427212967765 0.25107233412824526 0"/>
			<geometry>
				<mesh filename="textured_objs/original-19.obj"/>
			</geometry>
		</visual>
		<collision>
			<origin xyz="-0.915427212967765 0.25107233412824526 0"/>
			<geometry>
				<mesh filename="textured_objs/original-19.obj"/>
			</geometry>
		</collision>
	</link>
	<joint name="joint_1" type="continuous">
		<origin xyz="0.00901189171621597 -0.25107233412824526 0.226891"/>
		<axis xyz="0 0 -1"/>
		<child link="link_1"/>
		<parent link="link_9"/>
	</joint>
	<link name="link_2">
		<visual name="wheel-66">
			<origin xyz="0.8778635 0.2510720487913363 0"/>
			<geometry>
				<mesh filename="textured_objs/original-24.obj"/>
			</geometry>
		</visual>
		<collision>
			<origin xyz="0.8778635 0.2510720487913363 0"/>
			<geometry>
				<mesh filename="textured_objs/original-24.obj"/>
			</geometry>
		</collision>
	</link>
	<joint name="joint_2" type="continuous">
		<origin xyz="0.009011630193004772 -0.2510720487913363 0.226891"/>
		<axis xyz="0 0 1"/>
		<child link="link_2"/>
		<parent link="link_10"/>
	</joint>
	<link name="link_3">
		<visual name="wheel-67">
			<origin xyz="0.8778635 0.2510720487913363 0"/>
			<geometry>
				<mesh filename="textured_objs/original-23.obj"/>
			</geometry>
		</visual>
		<collision>
			<origin xyz="0.8778635 0.2510720487913363 0"/>
			<geometry>
				<mesh filename="textured_objs/original-23.obj"/>
			</geometry>
		</collision>
	</link>
	<joint name="joint_3" type="continuous">
		<origin xyz="0.009011630193004772 -0.2510720487913363 0.226891"/>
		<axis xyz="0 0 1"/>
		<child link="link_3"/>
		<parent link="link_10"/>
	</joint>
	<link name="link_4">
		<visual name="wheel-62">
			<origin xyz="0.8778635 0.2510720487913363 0"/>
			<geometry>
				<mesh filename="textured_objs/original-29.obj"/>
			</geometry>
		</visual>
		<collision>
			<origin xyz="0.8778635 0.2510720487913363 0"/>
			<geometry>
				<mesh filename="textured_objs/original-29.obj"/>
			</geometry>
		</collision>
	</link>
	<joint name="joint_4" type="continuous">
		<origin xyz="0.00901179861519874 -0.2510720487913363 -0.225876"/>
		<axis xyz="0 0 1"/>
		<child link="link_4"/>
		<parent link="link_11"/>
	</joint>
	<link name="link_5">
		<visual name="wheel-63">
			<origin xyz="0.8778635 0.2510720487913363 0"/>
			<geometry>
				<mesh filename="textured_objs/original-28.obj"/>
			</geometry>
		</visual>
		<collision>
			<origin xyz="0.8778635 0.2510720487913363 0"/>
			<geometry>
				<mesh filename="textured_objs/original-28.obj"/>
			</geometry>
		</collision>
	</link>
	<joint name="joint_5" type="continuous">
		<origin xyz="0.00901179861519874 -0.2510720487913363 -0.225876"/>
		<axis xyz="0 0 1"/>
		<child link="link_5"/>
		<parent link="link_11"/>
	</joint>
	<link name="link_6">
		<visual name="wheel-58">
			<origin xyz="-0.915427212967765 0.25107233412824526 0"/>
			<geometry>
				<mesh filename="textured_objs/original-13.obj"/>
			</geometry>
		</visual>
		<collision>
			<origin xyz="-0.915427212967765 0.25107233412824526 0"/>
			<geometry>
				<mesh filename="textured_objs/original-13.obj"/>
			</geometry>
		</collision>
	</link>
	<joint name="joint_6" type="continuous">
		<origin xyz="0.01225695647058278 -0.25107233412824526 -0.2244519301483632"/>
		<axis xyz="0 0 1"/>
		<child link="link_6"/>
		<parent link="link_12"/>
	</joint>
	<link name="link_7">
		<visual name="wheel-59">
			<origin xyz="-0.915427212967765 0.25107233412824526 0"/>
			<geometry>
				<mesh filename="textured_objs/original-14.obj"/>
			</geometry>
		</visual>
		<collision>
			<origin xyz="-0.915427212967765 0.25107233412824526 0"/>
			<geometry>
				<mesh filename="textured_objs/original-14.obj"/>
			</geometry>
		</collision>
	</link>
	<joint name="joint_7" type="continuous">
		<origin xyz="0.01225695647058278 -0.25107233412824526 -0.2244519301483632"/>
		<axis xyz="0 0 1"/>
		<child link="link_7"/>
		<parent link="link_12"/>
	</joint>
	<link name="link_8">
		<visual name="glass-51">
			<origin xyz="0 0 0"/>
			<geometry>
				<mesh filename="textured_objs/original-1.obj"/>
			</geometry>
		</visual>
		<visual name="bar-47">
			<origin xyz="0 0 0"/>
			<geometry>
				<mesh filename="textured_objs/new-6.obj"/>
			</geometry>
		</visual>
		<visual name="bar-48">
			<origin xyz="0 0 0"/>
			<geometry>
				<mesh filename="textured_objs/new-4.obj"/>
			</geometry>
		</visual>
		<visual name="bar-49">
			<origin xyz="0 0 0"/>
			<geometry>
				<mesh filename="textured_objs/new-5.obj"/>
			</geometry>
		</visual>
		<visual name="bar-50">
			<origin xyz="0 0 0"/>
			<geometry>
				<mesh filename="textured_objs/new-7.obj"/>
			</geometry>
		</visual>
		<visual name="tabletop_connector-10">
			<origin xyz="0 0 0"/>
			<geometry>
				<mesh filename="textured_objs/original-6.obj"/>
			</geometry>
		</visual>
		<visual name="tabletop_connector-11">
			<origin xyz="0 0 0"/>
			<geometry>
				<mesh filename="textured_objs/original-4.obj"/>
			</geometry>
		</visual>
		<visual name="tabletop_connector-12">
			<origin xyz="0 0 0"/>
			<geometry>
				<mesh filename="textured_objs/original-5.obj"/>
			</geometry>
		</visual>
		<visual name="tabletop_connector-13">
			<origin xyz="0 0 0"/>
			<geometry>
				<mesh filename="textured_objs/original-9.obj"/>
			</geometry>
		</visual>
		<visual name="shelf-14">
			<origin xyz="0 0 0"/>
			<geometry>
				<mesh filename="textured_objs/original-3.obj"/>
			</geometry>
		</visual>
		<visual name="tabletop_connector-19">
			<origin xyz="0 0 0"/>
			<geometry>
				<mesh filename="textured_objs/original-8.obj"/>
			</geometry>
		</visual>
		<visual name="tabletop_connector-20">
			<origin xyz="0 0 0"/>
			<geometry>
				<mesh filename="textured_objs/original-7.obj"/>
			</geometry>
		</visual>
		<visual name="leg-41">
			<origin xyz="0 0 0"/>
			<geometry>
				<mesh filename="textured_objs/new-2.obj"/>
			</geometry>
		</visual>
		<visual name="leg-42">
			<origin xyz="0 0 0"/>
			<geometry>
				<mesh filename="textured_objs/new-1.obj"/>
			</geometry>
		</visual>
		<visual name="leg-43">
			<origin xyz="0 0 0"/>
			<geometry>
				<mesh filename="textured_objs/new-0.obj"/>
			</geometry>
		</visual>
		<visual name="leg-44">
			<origin xyz="0 0 0"/>
			<geometry>
				<mesh filename="textured_objs/new-3.obj"/>
			</geometry>
		</visual>
		<collision>
			<origin xyz="0 0 0"/>
			<geometry>
				<mesh filename="textured_objs/original-1.obj"/>
			</geometry>
		</collision>
		<collision>
			<origin xyz="0 0 0"/>
			<geometry>
				<mesh filename="textured_objs/new-6.obj"/>
			</geometry>
		</collision>
		<collision>
			<origin xyz="0 0 0"/>
			<geometry>
				<mesh filename="textured_objs/new-4.obj"/>
			</geometry>
		</collision>
		<collision>
			<origin xyz="0 0 0"/>
			<geometry>
				<mesh filename="textured_objs/new-5.obj"/>
			</geometry>
		</collision>
		<collision>
			<origin xyz="0 0 0"/>
			<geometry>
				<mesh filename="textured_objs/new-7.obj"/>
			</geometry>
		</collision>
		<collision>
			<origin xyz="0 0 0"/>
			<geometry>
				<mesh filename="textured_objs/original-6.obj"/>
			</geometry>
		</collision>
		<collision>
			<origin xyz="0 0 0"/>
			<geometry>
				<mesh filename="textured_objs/original-4.obj"/>
			</geometry>
		</collision>
		<collision>
			<origin xyz="0 0 0"/>
			<geometry>
				<mesh filename="textured_objs/original-5.obj"/>
			</geometry>
		</collision>
		<collision>
			<origin xyz="0 0 0"/>
			<geometry>
				<mesh filename="textured_objs/original-9.obj"/>
			</geometry>
		</collision>
		<collision>
			<origin xyz="0 0 0"/>
			<geometry>
				<mesh filename="textured_objs/original-3.obj"/>
			</geometry>
		</collision>
		<collision>
			<origin xyz="0 0 0"/>
			<geometry>
				<mesh filename="textured_objs/original-8.obj"/>
			</geometry>
		</collision>
		<collision>
			<origin xyz="0 0 0"/>
			<geometry>
				<mesh filename="textured_objs/original-7.obj"/>
			</geometry>
		</collision>
		<collision>
			<origin xyz="0 0 0"/>
			<geometry>
				<mesh filename="textured_objs/new-2.obj"/>
			</geometry>
		</collision>
		<collision>
			<origin xyz="0 0 0"/>
			<geometry>
				<mesh filename="textured_objs/new-1.obj"/>
			</geometry>
		</collision>
		<collision>
			<origin xyz="0 0 0"/>
			<geometry>
				<mesh filename="textured_objs/new-0.obj"/>
			</geometry>
		</collision>
		<collision>
			<origin xyz="0 0 0"/>
			<geometry>
				<mesh filename="textured_objs/new-3.obj"/>
			</geometry>
		</collision>
	</link>
	<joint name="joint_8" type="fixed">
		<origin rpy="1.570796326794897 0 -1.570796326794897" xyz="0 0 0"/>
		<child link="link_8"/>
		<parent link="base"/>
	</joint>
	<link name="link_9">
		<visual name="caster_stem-69">
			<origin xyz="-0.906415321251549 0 0.226891"/>
			<geometry>
				<mesh filename="textured_objs/original-16.obj"/>
			</geometry>
		</visual>
		<visual name="brake-72">
			<origin xyz="-0.906415321251549 0 0.226891"/>
			<geometry>
				<mesh filename="textured_objs/original-17.obj"/>
			</geometry>
		</visual>
		<collision>
			<origin xyz="-0.906415321251549 0 0.226891"/>
			<geometry>
				<mesh filename="textured_objs/original-16.obj"/>
			</geometry>
		</collision>
		<collision>
			<origin xyz="-0.906415321251549 0 0.226891"/>
			<geometry>
				<mesh filename="textured_objs/original-17.obj"/>
			</geometry>
		</collision>
	</link>
	<joint name="joint_9" type="continuous">
		<origin xyz="0.906415321251549 0 -0.226891"/>
		<axis xyz="0 1 0"/>
		<child link="link_9"/>
		<parent link="link_8"/>
	</joint>
	<link name="link_10">
		<visual name="caster_stem-65">
			<origin xyz="0.8868751301930048 0 0.226891"/>
			<geometry>
				<mesh filename="textured_objs/original-21.obj"/>
			</geometry>
		</visual>
		<visual name="brake-68">
			<origin xyz="0.8868751301930048 0 0.226891"/>
			<geometry>
				<mesh filename="textured_objs/original-22.obj"/>
			</geometry>
		</visual>
		<collision>
			<origin xyz="0.8868751301930048 0 0.226891"/>
			<geometry>
				<mesh filename="textured_objs/original-21.obj"/>
			</geometry>
		</collision>
		<collision>
			<origin xyz="0.8868751301930048 0 0.226891"/>
			<geometry>
				<mesh filename="textured_objs/original-22.obj"/>
			</geometry>
		</collision>
	</link>
	<joint name="joint_10" type="continuous">
		<origin xyz="-0.8868751301930048 0 -0.226891"/>
		<axis xyz="0 1 0"/>
		<child link="link_10"/>
		<parent link="link_8"/>
	</joint>
	<link name="link_11">
		<visual name="caster_stem-61">
			<origin xyz="0.8868752986151988 0 -0.225876"/>
			<geometry>
				<mesh filename="textured_objs/original-26.obj"/>
			</geometry>
		</visual>
		<visual name="brake-64">
			<origin xyz="0.8868752986151988 0 -0.225876"/>
			<geometry>
				<mesh filename="textured_objs/original-27.obj"/>
			</geometry>
		</visual>
		<collision>
			<origin xyz="0.8868752986151988 0 -0.225876"/>
			<geometry>
				<mesh filename="textured_objs/original-26.obj"/>
			</geometry>
		</collision>
		<collision>
			<origin xyz="0.8868752986151988 0 -0.225876"/>
			<geometry>
				<mesh filename="textured_objs/original-27.obj"/>
			</geometry>
		</collision>
	</link>
	<joint name="joint_11" type="continuous">
		<origin xyz="-0.8868752986151988 0 0.225876"/>
		<axis xyz="0 1 0"/>
		<child link="link_11"/>
		<parent link="link_8"/>
	</joint>
	<link name="link_12">
		<visual name="caster_stem-57">
			<origin xyz="-0.9031702564971822 0 -0.2244519301483632"/>
			<geometry>
				<mesh filename="textured_objs/original-11.obj"/>
			</geometry>
		</visual>
		<visual name="brake-60">
			<origin xyz="-0.9031702564971822 0 -0.2244519301483632"/>
			<geometry>
				<mesh filename="textured_objs/original-12.obj"/>
			</geometry>
		</visual>
		<collision>
			<origin xyz="-0.9031702564971822 0 -0.2244519301483632"/>
			<geometry>
				<mesh filename="textured_objs/original-11.obj"/>
			</geometry>
		</collision>
		<collision>
			<origin xyz="-0.9031702564971822 0 -0.2244519301483632"/>
			<geometry>
				<mesh filename="textured_objs/original-12.obj"/>
			</geometry>
		</collision>
	</link>
	<joint name="joint_12" type="continuous">
		<origin xyz="0.9031702564971822 0 0.2244519301483632"/>
		<axis xyz="0 1 0"/>
		<child link="link_12"/>
		<parent link="link_8"/>
	</joint>
</robot>
