<?xml version="1.0" ?>
<robot name="partnet_1f336c9e48f1b54686d53ab0fe94e911">
	<link name="base"/>
	<link name="link_0">
		<visual name="cabinet_door_surface-6">
			<origin xyz="0.6470812234420272 -0.6588979959487915 -0.4316280417581034"/>
			<geometry>
				<mesh filename="textured_objs/original-36.obj"/>
			</geometry>
		</visual>
		<visual name="cabinet_door_surface-6">
			<origin xyz="0.6470812234420272 -0.6588979959487915 -0.4316280417581034"/>
			<geometry>
				<mesh filename="textured_objs/original-30.obj"/>
			</geometry>
		</visual>
		<visual name="cabinet_door_surface-6">
			<origin xyz="0.6470812234420272 -0.6588979959487915 -0.4316280417581034"/>
			<geometry>
				<mesh filename="textured_objs/original-26.obj"/>
			</geometry>
		</visual>
		<visual name="cabinet_door_surface-6">
			<origin xyz="0.6470812234420272 -0.6588979959487915 -0.4316280417581034"/>
			<geometry>
				<mesh filename="textured_objs/original-33.obj"/>
			</geometry>
		</visual>
		<visual name="cabinet_door_surface-6">
			<origin xyz="0.6470812234420272 -0.6588979959487915 -0.4316280417581034"/>
			<geometry>
				<mesh filename="textured_objs/original-29.obj"/>
			</geometry>
		</visual>
		<visual name="cabinet_door_surface-6">
			<origin xyz="0.6470812234420272 -0.6588979959487915 -0.4316280417581034"/>
			<geometry>
				<mesh filename="textured_objs/original-31.obj"/>
			</geometry>
		</visual>
		<visual name="cabinet_door_surface-6">
			<origin xyz="0.6470812234420272 -0.6588979959487915 -0.4316280417581034"/>
			<geometry>
				<mesh filename="textured_objs/original-32.obj"/>
			</geometry>
		</visual>
		<visual name="cabinet_door_surface-6">
			<origin xyz="0.6470812234420272 -0.6588979959487915 -0.4316280417581034"/>
			<geometry>
				<mesh filename="textured_objs/original-27.obj"/>
			</geometry>
		</visual>
		<visual name="cabinet_door_surface-6">
			<origin xyz="0.6470812234420272 -0.6588979959487915 -0.4316280417581034"/>
			<geometry>
				<mesh filename="textured_objs/original-28.obj"/>
			</geometry>
		</visual>
		<visual name="cabinet_door_surface-6">
			<origin xyz="0.6470812234420272 -0.6588979959487915 -0.4316280417581034"/>
			<geometry>
				<mesh filename="textured_objs/original-35.obj"/>
			</geometry>
		</visual>
		<visual name="handle-7">
			<origin xyz="0.6470812234420272 -0.6588979959487915 -0.4316280417581034"/>
			<geometry>
				<mesh filename="textured_objs/original-39.obj"/>
			</geometry>
		</visual>
		<visual name="handle-7">
			<origin xyz="0.6470812234420272 -0.6588979959487915 -0.4316280417581034"/>
			<geometry>
				<mesh filename="textured_objs/original-38.obj"/>
			</geometry>
		</visual>
		<visual name="handle-7">
			<origin xyz="0.6470812234420272 -0.6588979959487915 -0.4316280417581034"/>
			<geometry>
				<mesh filename="textured_objs/original-40.obj"/>
			</geometry>
		</visual>
		<collision>
			<origin xyz="0.6470812234420272 -0.6588979959487915 -0.4316280417581034"/>
			<geometry>
				<mesh filename="textured_objs/original-36.obj"/>
			</geometry>
		</collision>
		<collision>
			<origin xyz="0.6470812234420272 -0.6588979959487915 -0.4316280417581034"/>
			<geometry>
				<mesh filename="textured_objs/original-30.obj"/>
			</geometry>
		</collision>
		<collision>
			<origin xyz="0.6470812234420272 -0.6588979959487915 -0.4316280417581034"/>
			<geometry>
				<mesh filename="textured_objs/original-26.obj"/>
			</geometry>
		</collision>
		<collision>
			<origin xyz="0.6470812234420272 -0.6588979959487915 -0.4316280417581034"/>
			<geometry>
				<mesh filename="textured_objs/original-33.obj"/>
			</geometry>
		</collision>
		<collision>
			<origin xyz="0.6470812234420272 -0.6588979959487915 -0.4316280417581034"/>
			<geometry>
				<mesh filename="textured_objs/original-29.obj"/>
			</geometry>
		</collision>
		<collision>
			<origin xyz="0.6470812234420272 -0.6588979959487915 -0.4316280417581034"/>
			<geometry>
				<mesh filename="textured_objs/original-31.obj"/>
			</geometry>
		</collision>
		<collision>
			<origin xyz="0.6470812234420272 -0.6588979959487915 -0.4316280417581034"/>
			<geometry>
				<mesh filename="textured_objs/original-32.obj"/>
			</geometry>
		</collision>
		<collision>
			<origin xyz="0.6470812234420272 -0.6588979959487915 -0.4316280417581034"/>
			<geometry>
				<mesh filename="textured_objs/original-27.obj"/>
			</geometry>
		</collision>
		<collision>
			<origin xyz="0.6470812234420272 -0.6588979959487915 -0.4316280417581034"/>
			<geometry>
				<mesh filename="textured_objs/original-28.obj"/>
			</geometry>
		</collision>
		<collision>
			<origin xyz="0.6470812234420272 -0.6588979959487915 -0.4316280417581034"/>
			<geometry>
				<mesh filename="textured_objs/original-35.obj"/>
			</geometry>
		</collision>
		<collision>
			<origin xyz="0.6470812234420272 -0.6588979959487915 -0.4316280417581034"/>
			<geometry>
				<mesh filename="textured_objs/original-39.obj"/>
			</geometry>
		</collision>
		<collision>
			<origin xyz="0.6470812234420272 -0.6588979959487915 -0.4316280417581034"/>
			<geometry>
				<mesh filename="textured_objs/original-38.obj"/>
			</geometry>
		</collision>
		<collision>
			<origin xyz="0.6470812234420272 -0.6588979959487915 -0.4316280417581034"/>
			<geometry>
				<mesh filename="textured_objs/original-40.obj"/>
			</geometry>
		</collision>
	</link>
	<joint name="joint_0" type="revolute">
		<origin xyz="-0.6470812234420272 0.6588979959487915 0.4316280417581034"/>
		<axis xyz="0 -1 0"/>
		<child link="link_0"/>
		<parent link="link_2"/>
		<limit lower="-0.0" upper="1.5707963267948966"/>
	</joint>
	<link name="link_1">
		<visual name="cabinet_door_surface-12">
			<origin xyz="-0.6366536242753434 -0.6588979959487915 -0.4305276609120799"/>
			<geometry>
				<mesh filename="textured_objs/original-46.obj"/>
			</geometry>
		</visual>
		<visual name="cabinet_door_surface-12">
			<origin xyz="-0.6366536242753434 -0.6588979959487915 -0.4305276609120799"/>
			<geometry>
				<mesh filename="textured_objs/original-42.obj"/>
			</geometry>
		</visual>
		<visual name="cabinet_door_surface-12">
			<origin xyz="-0.6366536242753434 -0.6588979959487915 -0.4305276609120799"/>
			<geometry>
				<mesh filename="textured_objs/original-48.obj"/>
			</geometry>
		</visual>
		<visual name="cabinet_door_surface-12">
			<origin xyz="-0.6366536242753434 -0.6588979959487915 -0.4305276609120799"/>
			<geometry>
				<mesh filename="textured_objs/original-52.obj"/>
			</geometry>
		</visual>
		<visual name="cabinet_door_surface-12">
			<origin xyz="-0.6366536242753434 -0.6588979959487915 -0.4305276609120799"/>
			<geometry>
				<mesh filename="textured_objs/original-49.obj"/>
			</geometry>
		</visual>
		<visual name="cabinet_door_surface-12">
			<origin xyz="-0.6366536242753434 -0.6588979959487915 -0.4305276609120799"/>
			<geometry>
				<mesh filename="textured_objs/original-43.obj"/>
			</geometry>
		</visual>
		<visual name="cabinet_door_surface-12">
			<origin xyz="-0.6366536242753434 -0.6588979959487915 -0.4305276609120799"/>
			<geometry>
				<mesh filename="textured_objs/original-47.obj"/>
			</geometry>
		</visual>
		<visual name="cabinet_door_surface-12">
			<origin xyz="-0.6366536242753434 -0.6588979959487915 -0.4305276609120799"/>
			<geometry>
				<mesh filename="textured_objs/original-44.obj"/>
			</geometry>
		</visual>
		<visual name="cabinet_door_surface-12">
			<origin xyz="-0.6366536242753434 -0.6588979959487915 -0.4305276609120799"/>
			<geometry>
				<mesh filename="textured_objs/original-45.obj"/>
			</geometry>
		</visual>
		<visual name="cabinet_door_surface-12">
			<origin xyz="-0.6366536242753434 -0.6588979959487915 -0.4305276609120799"/>
			<geometry>
				<mesh filename="textured_objs/original-51.obj"/>
			</geometry>
		</visual>
		<visual name="handle-13">
			<origin xyz="-0.6366536242753434 -0.6588979959487915 -0.4305276609120799"/>
			<geometry>
				<mesh filename="textured_objs/original-55.obj"/>
			</geometry>
		</visual>
		<visual name="handle-13">
			<origin xyz="-0.6366536242753434 -0.6588979959487915 -0.4305276609120799"/>
			<geometry>
				<mesh filename="textured_objs/original-54.obj"/>
			</geometry>
		</visual>
		<visual name="handle-13">
			<origin xyz="-0.6366536242753434 -0.6588979959487915 -0.4305276609120799"/>
			<geometry>
				<mesh filename="textured_objs/original-56.obj"/>
			</geometry>
		</visual>
		<collision>
			<origin xyz="-0.6366536242753434 -0.6588979959487915 -0.4305276609120799"/>
			<geometry>
				<mesh filename="textured_objs/original-46.obj"/>
			</geometry>
		</collision>
		<collision>
			<origin xyz="-0.6366536242753434 -0.6588979959487915 -0.4305276609120799"/>
			<geometry>
				<mesh filename="textured_objs/original-42.obj"/>
			</geometry>
		</collision>
		<collision>
			<origin xyz="-0.6366536242753434 -0.6588979959487915 -0.4305276609120799"/>
			<geometry>
				<mesh filename="textured_objs/original-48.obj"/>
			</geometry>
		</collision>
		<collision>
			<origin xyz="-0.6366536242753434 -0.6588979959487915 -0.4305276609120799"/>
			<geometry>
				<mesh filename="textured_objs/original-52.obj"/>
			</geometry>
		</collision>
		<collision>
			<origin xyz="-0.6366536242753434 -0.6588979959487915 -0.4305276609120799"/>
			<geometry>
				<mesh filename="textured_objs/original-49.obj"/>
			</geometry>
		</collision>
		<collision>
			<origin xyz="-0.6366536242753434 -0.6588979959487915 -0.4305276609120799"/>
			<geometry>
				<mesh filename="textured_objs/original-43.obj"/>
			</geometry>
		</collision>
		<collision>
			<origin xyz="-0.6366536242753434 -0.6588979959487915 -0.4305276609120799"/>
			<geometry>
				<mesh filename="textured_objs/original-47.obj"/>
			</geometry>
		</collision>
		<collision>
			<origin xyz="-0.6366536242753434 -0.6588979959487915 -0.4305276609120799"/>
			<geometry>
				<mesh filename="textured_objs/original-44.obj"/>
			</geometry>
		</collision>
		<collision>
			<origin xyz="-0.6366536242753434 -0.6588979959487915 -0.4305276609120799"/>
			<geometry>
				<mesh filename="textured_objs/original-45.obj"/>
			</geometry>
		</collision>
		<collision>
			<origin xyz="-0.6366536242753434 -0.6588979959487915 -0.4305276609120799"/>
			<geometry>
				<mesh filename="textured_objs/original-51.obj"/>
			</geometry>
		</collision>
		<collision>
			<origin xyz="-0.6366536242753434 -0.6588979959487915 -0.4305276609120799"/>
			<geometry>
				<mesh filename="textured_objs/original-55.obj"/>
			</geometry>
		</collision>
		<collision>
			<origin xyz="-0.6366536242753434 -0.6588979959487915 -0.4305276609120799"/>
			<geometry>
				<mesh filename="textured_objs/original-54.obj"/>
			</geometry>
		</collision>
		<collision>
			<origin xyz="-0.6366536242753434 -0.6588979959487915 -0.4305276609120799"/>
			<geometry>
				<mesh filename="textured_objs/original-56.obj"/>
			</geometry>
		</collision>
	</link>
	<joint name="joint_1" type="revolute">
		<origin xyz="0.6366536242753434 0.6588979959487915 0.4305276609120799"/>
		<axis xyz="0 1 0"/>
		<child link="link_1"/>
		<parent link="link_2"/>
		<limit lower="0.0" upper="1.5707963267948966"/>
	</joint>
	<link name="link_2">
		<visual name="shelf-10">
			<origin xyz="0 0 0"/>
			<geometry>
				<mesh filename="textured_objs/original-13.obj"/>
			</geometry>
		</visual>
		<visual name="other_leaf-41">
			<origin xyz="0 0 0"/>
			<geometry>
				<mesh filename="textured_objs/original-15.obj"/>
			</geometry>
		</visual>
		<visual name="other_leaf-40">
			<origin xyz="0 0 0"/>
			<geometry>
				<mesh filename="textured_objs/original-24.obj"/>
			</geometry>
		</visual>
		<visual name="other_leaf-39">
			<origin xyz="0 0 0"/>
			<geometry>
				<mesh filename="textured_objs/original-14.obj"/>
			</geometry>
		</visual>
		<visual name="other_leaf-38">
			<origin xyz="0 0 0"/>
			<geometry>
				<mesh filename="textured_objs/original-18.obj"/>
			</geometry>
		</visual>
		<visual name="bottom_panel-22">
			<origin xyz="0 0 0"/>
			<geometry>
				<mesh filename="textured_objs/original-12.obj"/>
			</geometry>
		</visual>
		<visual name="frame_vertical_bar-23">
			<origin xyz="0 0 0"/>
			<geometry>
				<mesh filename="textured_objs/original-2.obj"/>
			</geometry>
		</visual>
		<visual name="frame_vertical_bar-24">
			<origin xyz="0 0 0"/>
			<geometry>
				<mesh filename="textured_objs/original-6.obj"/>
			</geometry>
		</visual>
		<visual name="frame_vertical_bar-25">
			<origin xyz="0 0 0"/>
			<geometry>
				<mesh filename="textured_objs/original-4.obj"/>
			</geometry>
		</visual>
		<visual name="frame_horizontal_bar-26">
			<origin xyz="0 0 0"/>
			<geometry>
				<mesh filename="textured_objs/original-5.obj"/>
			</geometry>
		</visual>
		<visual name="frame_horizontal_bar-27">
			<origin xyz="0 0 0"/>
			<geometry>
				<mesh filename="textured_objs/original-3.obj"/>
			</geometry>
		</visual>
		<visual name="vertical_side_panel-28">
			<origin xyz="0 0 0"/>
			<geometry>
				<mesh filename="textured_objs/original-22.obj"/>
			</geometry>
		</visual>
		<visual name="vertical_side_panel-28">
			<origin xyz="0 0 0"/>
			<geometry>
				<mesh filename="textured_objs/original-21.obj"/>
			</geometry>
		</visual>
		<visual name="vertical_side_panel-29">
			<origin xyz="0 0 0"/>
			<geometry>
				<mesh filename="textured_objs/original-9.obj"/>
			</geometry>
		</visual>
		<visual name="vertical_side_panel-29">
			<origin xyz="0 0 0"/>
			<geometry>
				<mesh filename="textured_objs/original-8.obj"/>
			</geometry>
		</visual>
		<visual name="back_panel-30">
			<origin xyz="0 0 0"/>
			<geometry>
				<mesh filename="textured_objs/original-17.obj"/>
			</geometry>
		</visual>
		<visual name="other_leaf-32">
			<origin xyz="0 0 0"/>
			<geometry>
				<mesh filename="textured_objs/original-57.obj"/>
			</geometry>
		</visual>
		<visual name="frame_horizontal_bar-33">
			<origin xyz="0 0 0"/>
			<geometry>
				<mesh filename="textured_objs/original-16.obj"/>
			</geometry>
		</visual>
		<visual name="base_side_panel-15">
			<origin xyz="0 0 0"/>
			<geometry>
				<mesh filename="textured_objs/original-19.obj"/>
			</geometry>
		</visual>
		<visual name="base_side_panel-16">
			<origin xyz="0 0 0"/>
			<geometry>
				<mesh filename="textured_objs/original-23.obj"/>
			</geometry>
		</visual>
		<visual name="base_side_panel-17">
			<origin xyz="0 0 0"/>
			<geometry>
				<mesh filename="textured_objs/original-11.obj"/>
			</geometry>
		</visual>
		<visual name="base_side_panel-18">
			<origin xyz="0 0 0"/>
			<geometry>
				<mesh filename="textured_objs/original-10.obj"/>
			</geometry>
		</visual>
		<collision>
			<origin xyz="0 0 0"/>
			<geometry>
				<mesh filename="textured_objs/original-13.obj"/>
			</geometry>
		</collision>
		<collision>
			<origin xyz="0 0 0"/>
			<geometry>
				<mesh filename="textured_objs/original-15.obj"/>
			</geometry>
		</collision>
		<collision>
			<origin xyz="0 0 0"/>
			<geometry>
				<mesh filename="textured_objs/original-24.obj"/>
			</geometry>
		</collision>
		<collision>
			<origin xyz="0 0 0"/>
			<geometry>
				<mesh filename="textured_objs/original-14.obj"/>
			</geometry>
		</collision>
		<collision>
			<origin xyz="0 0 0"/>
			<geometry>
				<mesh filename="textured_objs/original-18.obj"/>
			</geometry>
		</collision>
		<collision>
			<origin xyz="0 0 0"/>
			<geometry>
				<mesh filename="textured_objs/original-12.obj"/>
			</geometry>
		</collision>
		<collision>
			<origin xyz="0 0 0"/>
			<geometry>
				<mesh filename="textured_objs/original-2.obj"/>
			</geometry>
		</collision>
		<collision>
			<origin xyz="0 0 0"/>
			<geometry>
				<mesh filename="textured_objs/original-6.obj"/>
			</geometry>
		</collision>
		<collision>
			<origin xyz="0 0 0"/>
			<geometry>
				<mesh filename="textured_objs/original-4.obj"/>
			</geometry>
		</collision>
		<collision>
			<origin xyz="0 0 0"/>
			<geometry>
				<mesh filename="textured_objs/original-5.obj"/>
			</geometry>
		</collision>
		<collision>
			<origin xyz="0 0 0"/>
			<geometry>
				<mesh filename="textured_objs/original-3.obj"/>
			</geometry>
		</collision>
		<collision>
			<origin xyz="0 0 0"/>
			<geometry>
				<mesh filename="textured_objs/original-22.obj"/>
			</geometry>
		</collision>
		<collision>
			<origin xyz="0 0 0"/>
			<geometry>
				<mesh filename="textured_objs/original-21.obj"/>
			</geometry>
		</collision>
		<collision>
			<origin xyz="0 0 0"/>
			<geometry>
				<mesh filename="textured_objs/original-9.obj"/>
			</geometry>
		</collision>
		<collision>
			<origin xyz="0 0 0"/>
			<geometry>
				<mesh filename="textured_objs/original-8.obj"/>
			</geometry>
		</collision>
		<collision>
			<origin xyz="0 0 0"/>
			<geometry>
				<mesh filename="textured_objs/original-17.obj"/>
			</geometry>
		</collision>
		<collision>
			<origin xyz="0 0 0"/>
			<geometry>
				<mesh filename="textured_objs/original-57.obj"/>
			</geometry>
		</collision>
		<collision>
			<origin xyz="0 0 0"/>
			<geometry>
				<mesh filename="textured_objs/original-16.obj"/>
			</geometry>
		</collision>
		<collision>
			<origin xyz="0 0 0"/>
			<geometry>
				<mesh filename="textured_objs/original-19.obj"/>
			</geometry>
		</collision>
		<collision>
			<origin xyz="0 0 0"/>
			<geometry>
				<mesh filename="textured_objs/original-23.obj"/>
			</geometry>
		</collision>
		<collision>
			<origin xyz="0 0 0"/>
			<geometry>
				<mesh filename="textured_objs/original-11.obj"/>
			</geometry>
		</collision>
		<collision>
			<origin xyz="0 0 0"/>
			<geometry>
				<mesh filename="textured_objs/original-10.obj"/>
			</geometry>
		</collision>
	</link>
	<joint name="joint_2" type="fixed">
		<origin rpy="1.570796326794897 0 -1.570796326794897" xyz="0 0 0"/>
		<child link="link_2"/>
		<parent link="base"/>
	</joint>
</robot>
