<?xml version="1.0" encoding="utf-8"?>
<!-- This URDF was automatically created by SolidWorks to URDF Exporter! Originally created by Stephen Brawner (brawner@gmail.com) 
     Commit Version: 1.6.0-1-g15f4949  Build Version: 1.6.7594.29634
     For more information, please see http://wiki.ros.org/sw_urdf_exporter -->
<robot
  name="rm_65_6f_description">
  <link
    name="base_link">
    <inertial>
      <origin
        xyz="-0.00043295 -3.5277E-05 0.059942"
        rpy="0 0 0" />
      <mass
        value="0.84105" />
      <inertia
        ixx="0.0017261"
        ixy="2.5273E-06"
        ixz="-3.6769E-05"
        iyy="0.0017099"
        iyz="1.6802E-06"
        izz="0.00090402" />
    </inertial>
    <visual>
      <origin
        xyz="0 0 0"
        rpy="0 0 0" />
      <geometry>
        <mesh
          filename="package://rm_description/meshes/RM65_6F/base_link.STL" />
      </geometry>
      <material
        name="">
        <color
          rgba="1 1 1 1" />
      </material>
    </visual>
    <collision>
      <origin
        xyz="0 0 0"
        rpy="0 0 0" />
      <geometry>
        <mesh
          filename="package://rm_description/meshes/RM65_6F/base_link.STL" />
      </geometry>
    </collision>
  </link>
  <link
    name="Link1">
    <inertial>
      <origin
        xyz="2.1376E-07 0.021108 -0.025186"
        rpy="0 0 0" />
      <mass
        value="0.59356" />
      <inertia
        ixx="0.0012661"
        ixy="-1.2951E-08"
        ixz="-9.8019E-09"
        iyy="0.0011817"
        iyz="-0.00021122"
        izz="0.00056135" />
    </inertial>
    <visual>
      <origin
        xyz="0 0 0"
        rpy="0 0 0" />
      <geometry>
        <mesh
          filename="package://rm_description/meshes/RM65_6F/Link1.STL" />
      </geometry>
      <material
        name="">
        <color
          rgba="1 1 1 1" />
      </material>
    </visual>
    <collision>
      <origin
        xyz="0 0 0"
        rpy="0 0 0" />
      <geometry>
        <mesh
          filename="package://rm_description/meshes/RM65_6F/Link1.STL" />
      </geometry>
    </collision>
  </link>
  <joint
    name="joint1"
    type="revolute">
    <origin
      xyz="0 0 0.2405"
      rpy="0 0 0" />
    <parent
      link="base_link" />
    <child
      link="Link1" />
    <axis
      xyz="0 0 1" />
    <limit
      lower="-3.107"
      upper="3.107"
      effort="100"
      velocity="1" />
  </joint>
  <link
    name="Link2">
    <inertial>
      <origin
        xyz="0.15226 6.0139E-07 -0.0062025"
        rpy="0 0 0" />
      <mass
        value="0.86418" />
      <inertia
        ixx="0.00063254"
        ixy="-5.979E-09"
        ixz="0.00042163"
        iyy="0.0020527"
        iyz="1.8401E-09"
        izz="0.0019528" />
    </inertial>
    <visual>
      <origin
        xyz="0 0 0"
        rpy="0 0 0" />
      <geometry>
        <mesh
          filename="package://rm_description/meshes/RM65_6F/Link2.STL" />
      </geometry>
      <material
        name="">
        <color
          rgba="1 1 1 1" />
      </material>
    </visual>
    <collision>
      <origin
        xyz="0 0 0"
        rpy="0 0 0" />
      <geometry>
        <mesh
          filename="package://rm_description/meshes/RM65_6F/Link2.STL" />
      </geometry>
    </collision>
  </link>
  <joint
    name="joint2"
    type="revolute">
    <origin
      xyz="0 0 0"
      rpy="1.5708 -1.5708 0" />
    <parent
      link="Link1" />
    <child
      link="Link2" />
    <axis
      xyz="0 0 1" />
    <limit
      lower="-2.269"
      upper="2.269"
      effort="100"
      velocity="1" />
  </joint>
  <link
    name="Link3">
    <inertial>
      <origin
        xyz="5.0421E-06 -0.059593 0.010569"
        rpy="0 0 0" />
      <mass
        value="0.28963" />
      <inertia
        ixx="0.00063737"
        ixy="-7.0522E-08"
        ixz="-3.8666E-08"
        iyy="0.00015648"
        iyz="-0.00014461"
        izz="0.00061418" />
    </inertial>
    <visual>
      <origin
        xyz="0 0 0"
        rpy="0 0 0" />
      <geometry>
        <mesh
          filename="package://rm_description/meshes/RM65_6F/Link3.STL" />
      </geometry>
      <material
        name="">
        <color
          rgba="1 1 1 1" />
      </material>
    </visual>
    <collision>
      <origin
        xyz="0 0 0"
        rpy="0 0 0" />
      <geometry>
        <mesh
          filename="package://rm_description/meshes/RM65_6F/Link3.STL" />
      </geometry>
    </collision>
  </link>
  <joint
    name="joint3"
    type="revolute">
    <origin
      xyz="0.256 0 0"
      rpy="0 0 1.5708" />
    <parent
      link="Link2" />
    <child
      link="Link3" />
    <axis
      xyz="0 0 1" />
    <limit
      lower="-2.356"
      upper="2.356"
      effort="100"
      velocity="1" />
  </joint>
  <link
    name="Link4">
    <inertial>
      <origin
        xyz="1.1466E-06 -0.018041 -0.021541"
        rpy="0 0 0" />
      <mass
        value="0.23941" />
      <inertia
        ixx="0.00028594"
        ixy="2.6611E-09"
        ixz="-1.8435E-09"
        iyy="0.00026273"
        iyz="4.4238E-05"
        izz="0.00011989" />
    </inertial>
    <visual>
      <origin
        xyz="0 0 0"
        rpy="0 0 0" />
      <geometry>
        <mesh
          filename="package://rm_description/meshes/RM65_6F/Link4.STL" />
      </geometry>
      <material
        name="">
        <color
          rgba="1 1 1 1" />
      </material>
    </visual>
    <collision>
      <origin
        xyz="0 0 0"
        rpy="0 0 0" />
      <geometry>
        <mesh
          filename="package://rm_description/meshes/RM65_6F/Link4.STL" />
      </geometry>
    </collision>
  </link>
  <joint
    name="joint4"
    type="revolute">
    <origin
      xyz="0 -0.21 0"
      rpy="1.5708 0 0" />
    <parent
      link="Link3" />
    <child
      link="Link4" />
    <axis
      xyz="0 0 1" />
    <limit
      lower="-3.107"
      upper="3.107"
      effort="100"
      velocity="1" />
  </joint>
  <link
    name="Link5">
    <inertial>
      <origin
        xyz="3.4542E-06 -0.059382 0.0073678"
        rpy="0 0 0" />
      <mass
        value="0.21879" />
      <inertia
        ixx="0.00035053"
        ixy="-3.1667E-08"
        ixz="-1.7442E-08"
        iyy="0.00010492"
        iyz="-7.824E-05"
        izz="0.00033447" />
    </inertial>
    <visual>
      <origin
        xyz="0 0 0"
        rpy="0 0 0" />
      <geometry>
        <mesh
          filename="package://rm_description/meshes/RM65_6F/Link5.STL" />
      </geometry>
      <material
        name="">
        <color
          rgba="1 1 1 1" />
      </material>
    </visual>
    <collision>
      <origin
        xyz="0 0 0"
        rpy="0 0 0" />
      <geometry>
        <mesh
          filename="package://rm_description/meshes/RM65_6F/Link5.STL" />
      </geometry>
    </collision>
  </link>
  <joint
    name="joint5"
    type="revolute">
    <origin
      xyz="0 0 0"
      rpy="-1.5708 0 0" />
    <parent
      link="Link4" />
    <child
      link="Link5" />
    <axis
      xyz="0 0 1" />
    <limit
      lower="-2.234"
      upper="2.234"
      effort="100"
      velocity="1" />
  </joint>
  <link
    name="Link6">
    <inertial>
      <origin
        xyz="0.00032231 -0.00017819 -0.028676"
        rpy="0 0 0" />
      <mass
        value="0.14433" />
      <inertia
        ixx="3.6119E-05"
        ixy="-1.3242E-06"
        ixz="-3.2733E-08"
        iyy="3.4626E-05"
        iyz="7.6661E-09"
        izz="6.1463E-05" />
    </inertial>
    <visual>
      <origin
        xyz="0 0 0"
        rpy="0 0 0" />
      <geometry>
        <mesh
          filename="package://rm_description/meshes/RM65_6F/Link6.STL" />
      </geometry>
      <material
        name="">
        <color
          rgba="1 1 1 1" />
      </material>
    </visual>
    <collision>
      <origin
        xyz="0 0 0"
        rpy="0 0 0" />
      <geometry>
        <mesh
          filename="package://rm_description/meshes/RM65_6F/Link6.STL" />
      </geometry>
    </collision>
  </link>
  <joint
    name="joint6"
    type="revolute">
    <origin
      xyz="0 -0.1725 0"
      rpy="1.5708 0 0" />
    <parent
      link="Link5" />
    <child
      link="Link6" />
    <axis
      xyz="0 0 1" />
    <limit
      lower="-6.283"
      upper="6.283"
      effort="100"
      velocity="1" />
  </joint>
</robot>
