<?xml version="1.0" ?>
<robot name="partnet_140f12d10c2b7fd5c77467482d6e756">
	<link name="base"/>
	<link name="link_0">
		<visual name="keyboard_tray_surface-68">
			<origin xyz="0 0 0"/>
			<geometry>
				<mesh filename="textured_objs/original-5.obj"/>
			</geometry>
		</visual>
		<collision>
			<origin xyz="0 0 0"/>
			<geometry>
				<mesh filename="textured_objs/original-5.obj"/>
			</geometry>
		</collision>
	</link>
	<joint name="joint_0" type="prismatic">
		<origin xyz="0 0 0"/>
		<axis xyz="0 0 1"/>
		<child link="link_0"/>
		<parent link="link_7"/>
		<limit lower="0" upper="0.2639999999999998"/>
	</joint>
	<link name="link_1">
		<visual name="drawer_front-40">
			<origin xyz="0 0 0"/>
			<geometry>
				<mesh filename="textured_objs/new-24.obj"/>
			</geometry>
		</visual>
		<visual name="drawer_side-41">
			<origin xyz="0 0 0"/>
			<geometry>
				<mesh filename="textured_objs/new-27.obj"/>
			</geometry>
		</visual>
		<visual name="drawer_side-42">
			<origin xyz="0 0 0"/>
			<geometry>
				<mesh filename="textured_objs/new-25.obj"/>
			</geometry>
		</visual>
		<visual name="drawer_back-43">
			<origin xyz="0 0 0"/>
			<geometry>
				<mesh filename="textured_objs/new-26.obj"/>
			</geometry>
		</visual>
		<visual name="drawer_bottom-44">
			<origin xyz="0 0 0"/>
			<geometry>
				<mesh filename="textured_objs/new-28.obj"/>
			</geometry>
		</visual>
		<visual name="drawer_bottom-44">
			<origin xyz="0 0 0"/>
			<geometry>
				<mesh filename="textured_objs/new-29.obj"/>
			</geometry>
		</visual>
		<collision>
			<origin xyz="0 0 0"/>
			<geometry>
				<mesh filename="textured_objs/new-24.obj"/>
			</geometry>
		</collision>
		<collision>
			<origin xyz="0 0 0"/>
			<geometry>
				<mesh filename="textured_objs/new-27.obj"/>
			</geometry>
		</collision>
		<collision>
			<origin xyz="0 0 0"/>
			<geometry>
				<mesh filename="textured_objs/new-25.obj"/>
			</geometry>
		</collision>
		<collision>
			<origin xyz="0 0 0"/>
			<geometry>
				<mesh filename="textured_objs/new-26.obj"/>
			</geometry>
		</collision>
		<collision>
			<origin xyz="0 0 0"/>
			<geometry>
				<mesh filename="textured_objs/new-28.obj"/>
			</geometry>
		</collision>
		<collision>
			<origin xyz="0 0 0"/>
			<geometry>
				<mesh filename="textured_objs/new-29.obj"/>
			</geometry>
		</collision>
	</link>
	<joint name="joint_1" type="prismatic">
		<origin xyz="0 0 0"/>
		<axis xyz="0 0 1"/>
		<child link="link_1"/>
		<parent link="link_7"/>
		<limit lower="0" upper="0.484"/>
	</joint>
	<link name="link_2">
		<visual name="drawer_front-62">
			<origin xyz="0 0 0"/>
			<geometry>
				<mesh filename="textured_objs/new-30.obj"/>
			</geometry>
		</visual>
		<visual name="drawer_side-63">
			<origin xyz="0 0 0"/>
			<geometry>
				<mesh filename="textured_objs/new-32.obj"/>
			</geometry>
		</visual>
		<visual name="drawer_side-64">
			<origin xyz="0 0 0"/>
			<geometry>
				<mesh filename="textured_objs/new-31.obj"/>
			</geometry>
		</visual>
		<visual name="drawer_back-65">
			<origin xyz="0 0 0"/>
			<geometry>
				<mesh filename="textured_objs/new-33.obj"/>
			</geometry>
		</visual>
		<visual name="drawer_bottom-66">
			<origin xyz="0 0 0"/>
			<geometry>
				<mesh filename="textured_objs/new-34.obj"/>
			</geometry>
		</visual>
		<collision>
			<origin xyz="0 0 0"/>
			<geometry>
				<mesh filename="textured_objs/new-30.obj"/>
			</geometry>
		</collision>
		<collision>
			<origin xyz="0 0 0"/>
			<geometry>
				<mesh filename="textured_objs/new-32.obj"/>
			</geometry>
		</collision>
		<collision>
			<origin xyz="0 0 0"/>
			<geometry>
				<mesh filename="textured_objs/new-31.obj"/>
			</geometry>
		</collision>
		<collision>
			<origin xyz="0 0 0"/>
			<geometry>
				<mesh filename="textured_objs/new-33.obj"/>
			</geometry>
		</collision>
		<collision>
			<origin xyz="0 0 0"/>
			<geometry>
				<mesh filename="textured_objs/new-34.obj"/>
			</geometry>
		</collision>
	</link>
	<joint name="joint_2" type="prismatic">
		<origin xyz="0 0 0"/>
		<axis xyz="0 0 1"/>
		<child link="link_2"/>
		<parent link="link_7"/>
		<limit lower="0" upper="0.484"/>
	</joint>
	<link name="link_3">
		<visual name="drawer_front-56">
			<origin xyz="0 0 0"/>
			<geometry>
				<mesh filename="textured_objs/new-40.obj"/>
			</geometry>
		</visual>
		<visual name="drawer_side-57">
			<origin xyz="0 0 0"/>
			<geometry>
				<mesh filename="textured_objs/new-43.obj"/>
			</geometry>
		</visual>
		<visual name="drawer_side-58">
			<origin xyz="0 0 0"/>
			<geometry>
				<mesh filename="textured_objs/new-41.obj"/>
			</geometry>
		</visual>
		<visual name="drawer_back-59">
			<origin xyz="0 0 0"/>
			<geometry>
				<mesh filename="textured_objs/new-42.obj"/>
			</geometry>
		</visual>
		<visual name="drawer_bottom-60">
			<origin xyz="0 0 0"/>
			<geometry>
				<mesh filename="textured_objs/new-44.obj"/>
			</geometry>
		</visual>
		<collision>
			<origin xyz="0 0 0"/>
			<geometry>
				<mesh filename="textured_objs/new-40.obj"/>
			</geometry>
		</collision>
		<collision>
			<origin xyz="0 0 0"/>
			<geometry>
				<mesh filename="textured_objs/new-43.obj"/>
			</geometry>
		</collision>
		<collision>
			<origin xyz="0 0 0"/>
			<geometry>
				<mesh filename="textured_objs/new-41.obj"/>
			</geometry>
		</collision>
		<collision>
			<origin xyz="0 0 0"/>
			<geometry>
				<mesh filename="textured_objs/new-42.obj"/>
			</geometry>
		</collision>
		<collision>
			<origin xyz="0 0 0"/>
			<geometry>
				<mesh filename="textured_objs/new-44.obj"/>
			</geometry>
		</collision>
	</link>
	<joint name="joint_3" type="prismatic">
		<origin xyz="0 0 0"/>
		<axis xyz="0 0 1"/>
		<child link="link_3"/>
		<parent link="link_7"/>
		<limit lower="0" upper="0.484"/>
	</joint>
	<link name="link_4">
		<visual name="drawer_front-48">
			<origin xyz="0 0 0"/>
			<geometry>
				<mesh filename="textured_objs/new-35.obj"/>
			</geometry>
		</visual>
		<visual name="drawer_side-49">
			<origin xyz="0 0 0"/>
			<geometry>
				<mesh filename="textured_objs/new-36.obj"/>
			</geometry>
		</visual>
		<visual name="drawer_side-50">
			<origin xyz="0 0 0"/>
			<geometry>
				<mesh filename="textured_objs/new-38.obj"/>
			</geometry>
		</visual>
		<visual name="drawer_back-51">
			<origin xyz="0 0 0"/>
			<geometry>
				<mesh filename="textured_objs/new-37.obj"/>
			</geometry>
		</visual>
		<visual name="drawer_bottom-52">
			<origin xyz="0 0 0"/>
			<geometry>
				<mesh filename="textured_objs/new-39.obj"/>
			</geometry>
		</visual>
		<collision>
			<origin xyz="0 0 0"/>
			<geometry>
				<mesh filename="textured_objs/new-35.obj"/>
			</geometry>
		</collision>
		<collision>
			<origin xyz="0 0 0"/>
			<geometry>
				<mesh filename="textured_objs/new-36.obj"/>
			</geometry>
		</collision>
		<collision>
			<origin xyz="0 0 0"/>
			<geometry>
				<mesh filename="textured_objs/new-38.obj"/>
			</geometry>
		</collision>
		<collision>
			<origin xyz="0 0 0"/>
			<geometry>
				<mesh filename="textured_objs/new-37.obj"/>
			</geometry>
		</collision>
		<collision>
			<origin xyz="0 0 0"/>
			<geometry>
				<mesh filename="textured_objs/new-39.obj"/>
			</geometry>
		</collision>
	</link>
	<joint name="joint_4" type="prismatic">
		<origin xyz="0 0 0"/>
		<axis xyz="0 0 1"/>
		<child link="link_4"/>
		<parent link="link_7"/>
		<limit lower="0" upper="0.484"/>
	</joint>
	<link name="link_5">
		<visual name="drawer_front-34">
			<origin xyz="0 0 0"/>
			<geometry>
				<mesh filename="textured_objs/new-19.obj"/>
			</geometry>
		</visual>
		<visual name="drawer_side-35">
			<origin xyz="0 0 0"/>
			<geometry>
				<mesh filename="textured_objs/new-20.obj"/>
			</geometry>
		</visual>
		<visual name="drawer_side-36">
			<origin xyz="0 0 0"/>
			<geometry>
				<mesh filename="textured_objs/new-21.obj"/>
			</geometry>
		</visual>
		<visual name="drawer_back-37">
			<origin xyz="0 0 0"/>
			<geometry>
				<mesh filename="textured_objs/new-22.obj"/>
			</geometry>
		</visual>
		<visual name="drawer_bottom-38">
			<origin xyz="0 0 0"/>
			<geometry>
				<mesh filename="textured_objs/new-23.obj"/>
			</geometry>
		</visual>
		<collision>
			<origin xyz="0 0 0"/>
			<geometry>
				<mesh filename="textured_objs/new-19.obj"/>
			</geometry>
		</collision>
		<collision>
			<origin xyz="0 0 0"/>
			<geometry>
				<mesh filename="textured_objs/new-20.obj"/>
			</geometry>
		</collision>
		<collision>
			<origin xyz="0 0 0"/>
			<geometry>
				<mesh filename="textured_objs/new-21.obj"/>
			</geometry>
		</collision>
		<collision>
			<origin xyz="0 0 0"/>
			<geometry>
				<mesh filename="textured_objs/new-22.obj"/>
			</geometry>
		</collision>
		<collision>
			<origin xyz="0 0 0"/>
			<geometry>
				<mesh filename="textured_objs/new-23.obj"/>
			</geometry>
		</collision>
	</link>
	<joint name="joint_5" type="prismatic">
		<origin xyz="0 0 0"/>
		<axis xyz="0 0 1"/>
		<child link="link_5"/>
		<parent link="link_7"/>
		<limit lower="0" upper="0.484"/>
	</joint>
	<link name="link_6">
		<visual name="drawer_front-28">
			<origin xyz="0 0 0"/>
			<geometry>
				<mesh filename="textured_objs/new-17.obj"/>
			</geometry>
		</visual>
		<visual name="drawer_side-29">
			<origin xyz="0 0 0"/>
			<geometry>
				<mesh filename="textured_objs/new-16.obj"/>
			</geometry>
		</visual>
		<visual name="drawer_side-30">
			<origin xyz="0 0 0"/>
			<geometry>
				<mesh filename="textured_objs/new-14.obj"/>
			</geometry>
		</visual>
		<visual name="drawer_back-31">
			<origin xyz="0 0 0"/>
			<geometry>
				<mesh filename="textured_objs/new-15.obj"/>
			</geometry>
		</visual>
		<visual name="drawer_bottom-32">
			<origin xyz="0 0 0"/>
			<geometry>
				<mesh filename="textured_objs/new-18.obj"/>
			</geometry>
		</visual>
		<collision>
			<origin xyz="0 0 0"/>
			<geometry>
				<mesh filename="textured_objs/new-17.obj"/>
			</geometry>
		</collision>
		<collision>
			<origin xyz="0 0 0"/>
			<geometry>
				<mesh filename="textured_objs/new-16.obj"/>
			</geometry>
		</collision>
		<collision>
			<origin xyz="0 0 0"/>
			<geometry>
				<mesh filename="textured_objs/new-14.obj"/>
			</geometry>
		</collision>
		<collision>
			<origin xyz="0 0 0"/>
			<geometry>
				<mesh filename="textured_objs/new-15.obj"/>
			</geometry>
		</collision>
		<collision>
			<origin xyz="0 0 0"/>
			<geometry>
				<mesh filename="textured_objs/new-18.obj"/>
			</geometry>
		</collision>
	</link>
	<joint name="joint_6" type="prismatic">
		<origin xyz="0 0 0"/>
		<axis xyz="0 0 1"/>
		<child link="link_6"/>
		<parent link="link_7"/>
		<limit lower="0" upper="0.484"/>
	</joint>
	<link name="link_7">
		<visual name="board-70">
			<origin xyz="0 0 0"/>
			<geometry>
				<mesh filename="textured_objs/original-6.obj"/>
			</geometry>
		</visual>
		<visual name="vertical_side_panel-7">
			<origin xyz="0 0 0"/>
			<geometry>
				<mesh filename="textured_objs/new-4.obj"/>
			</geometry>
		</visual>
		<visual name="vertical_side_panel-8">
			<origin xyz="0 0 0"/>
			<geometry>
				<mesh filename="textured_objs/new-5.obj"/>
			</geometry>
		</visual>
		<visual name="vertical_side_panel-9">
			<origin xyz="0 0 0"/>
			<geometry>
				<mesh filename="textured_objs/new-8.obj"/>
			</geometry>
		</visual>
		<visual name="vertical_side_panel-10">
			<origin xyz="0 0 0"/>
			<geometry>
				<mesh filename="textured_objs/new-9.obj"/>
			</geometry>
		</visual>
		<visual name="bottom_panel-11">
			<origin xyz="0 0 0"/>
			<geometry>
				<mesh filename="textured_objs/new-3.obj"/>
			</geometry>
		</visual>
		<visual name="bottom_panel-12">
			<origin xyz="0 0 0"/>
			<geometry>
				<mesh filename="textured_objs/new-7.obj"/>
			</geometry>
		</visual>
		<visual name="tabletop_connector-13">
			<origin xyz="0 0 0"/>
			<geometry>
				<mesh filename="textured_objs/new-1.obj"/>
			</geometry>
		</visual>
		<visual name="tabletop_connector-14">
			<origin xyz="0 0 0"/>
			<geometry>
				<mesh filename="textured_objs/new-0.obj"/>
			</geometry>
		</visual>
		<visual name="tabletop_connector-15">
			<origin xyz="0 0 0"/>
			<geometry>
				<mesh filename="textured_objs/new-12.obj"/>
			</geometry>
		</visual>
		<visual name="back_panel-18">
			<origin xyz="0 0 0"/>
			<geometry>
				<mesh filename="textured_objs/new-11.obj"/>
			</geometry>
		</visual>
		<visual name="back_panel-18">
			<origin xyz="0 0 0"/>
			<geometry>
				<mesh filename="textured_objs/new-10.obj"/>
			</geometry>
		</visual>
		<visual name="back_panel-19">
			<origin xyz="0 0 0"/>
			<geometry>
				<mesh filename="textured_objs/new-13.obj"/>
			</geometry>
		</visual>
		<visual name="back_panel-20">
			<origin xyz="0 0 0"/>
			<geometry>
				<mesh filename="textured_objs/new-2.obj"/>
			</geometry>
		</visual>
		<visual name="back_panel-20">
			<origin xyz="0 0 0"/>
			<geometry>
				<mesh filename="textured_objs/new-6.obj"/>
			</geometry>
		</visual>
		<collision>
			<origin xyz="0 0 0"/>
			<geometry>
				<mesh filename="textured_objs/original-6.obj"/>
			</geometry>
		</collision>
		<collision>
			<origin xyz="0 0 0"/>
			<geometry>
				<mesh filename="textured_objs/new-4.obj"/>
			</geometry>
		</collision>
		<collision>
			<origin xyz="0 0 0"/>
			<geometry>
				<mesh filename="textured_objs/new-5.obj"/>
			</geometry>
		</collision>
		<collision>
			<origin xyz="0 0 0"/>
			<geometry>
				<mesh filename="textured_objs/new-8.obj"/>
			</geometry>
		</collision>
		<collision>
			<origin xyz="0 0 0"/>
			<geometry>
				<mesh filename="textured_objs/new-9.obj"/>
			</geometry>
		</collision>
		<collision>
			<origin xyz="0 0 0"/>
			<geometry>
				<mesh filename="textured_objs/new-3.obj"/>
			</geometry>
		</collision>
		<collision>
			<origin xyz="0 0 0"/>
			<geometry>
				<mesh filename="textured_objs/new-7.obj"/>
			</geometry>
		</collision>
		<collision>
			<origin xyz="0 0 0"/>
			<geometry>
				<mesh filename="textured_objs/new-1.obj"/>
			</geometry>
		</collision>
		<collision>
			<origin xyz="0 0 0"/>
			<geometry>
				<mesh filename="textured_objs/new-0.obj"/>
			</geometry>
		</collision>
		<collision>
			<origin xyz="0 0 0"/>
			<geometry>
				<mesh filename="textured_objs/new-12.obj"/>
			</geometry>
		</collision>
		<collision>
			<origin xyz="0 0 0"/>
			<geometry>
				<mesh filename="textured_objs/new-11.obj"/>
			</geometry>
		</collision>
		<collision>
			<origin xyz="0 0 0"/>
			<geometry>
				<mesh filename="textured_objs/new-10.obj"/>
			</geometry>
		</collision>
		<collision>
			<origin xyz="0 0 0"/>
			<geometry>
				<mesh filename="textured_objs/new-13.obj"/>
			</geometry>
		</collision>
		<collision>
			<origin xyz="0 0 0"/>
			<geometry>
				<mesh filename="textured_objs/new-2.obj"/>
			</geometry>
		</collision>
		<collision>
			<origin xyz="0 0 0"/>
			<geometry>
				<mesh filename="textured_objs/new-6.obj"/>
			</geometry>
		</collision>
	</link>
	<joint name="joint_7" type="fixed">
		<origin rpy="1.570796326794897 0 -1.570796326794897" xyz="0 0 0"/>
		<child link="link_7"/>
		<parent link="base"/>
	</joint>
</robot>
