<?xml version="1.0" ?>
<robot name="partnet_6349f0d123ad1ca62ee5d388bdaf2f">
	<link name="base"/>
	<link name="link_0">
		<visual name="drawer_front-44">
			<origin xyz="0 0 0"/>
			<geometry>
				<mesh filename="textured_objs/new-60.obj"/>
			</geometry>
		</visual>
		<visual name="drawer_side-45">
			<origin xyz="0 0 0"/>
			<geometry>
				<mesh filename="textured_objs/new-59.obj"/>
			</geometry>
		</visual>
		<visual name="drawer_side-46">
			<origin xyz="0 0 0"/>
			<geometry>
				<mesh filename="textured_objs/new-61.obj"/>
			</geometry>
		</visual>
		<visual name="drawer_back-47">
			<origin xyz="0 0 0"/>
			<geometry>
				<mesh filename="textured_objs/new-58.obj"/>
			</geometry>
		</visual>
		<visual name="drawer_bottom-48">
			<origin xyz="0 0 0"/>
			<geometry>
				<mesh filename="textured_objs/new-62.obj"/>
			</geometry>
		</visual>
		<collision>
			<origin xyz="0 0 0"/>
			<geometry>
				<mesh filename="textured_objs/new-60.obj"/>
			</geometry>
		</collision>
		<collision>
			<origin xyz="0 0 0"/>
			<geometry>
				<mesh filename="textured_objs/new-59.obj"/>
			</geometry>
		</collision>
		<collision>
			<origin xyz="0 0 0"/>
			<geometry>
				<mesh filename="textured_objs/new-61.obj"/>
			</geometry>
		</collision>
		<collision>
			<origin xyz="0 0 0"/>
			<geometry>
				<mesh filename="textured_objs/new-58.obj"/>
			</geometry>
		</collision>
		<collision>
			<origin xyz="0 0 0"/>
			<geometry>
				<mesh filename="textured_objs/new-62.obj"/>
			</geometry>
		</collision>
	</link>
	<joint name="joint_0" type="prismatic">
		<origin xyz="0 0 0"/>
		<axis xyz="0 0 1"/>
		<child link="link_0"/>
		<parent link="link_4"/>
		<limit lower="-0.04800000000000004" upper="0.6160000000000001"/>
	</joint>
	<link name="link_1">
		<visual name="drawer_front-56">
			<origin xyz="0 0 0"/>
			<geometry>
				<mesh filename="textured_objs/new-70.obj"/>
			</geometry>
		</visual>
		<visual name="drawer_side-57">
			<origin xyz="0 0 0"/>
			<geometry>
				<mesh filename="textured_objs/new-69.obj"/>
			</geometry>
		</visual>
		<visual name="drawer_side-58">
			<origin xyz="0 0 0"/>
			<geometry>
				<mesh filename="textured_objs/new-71.obj"/>
			</geometry>
		</visual>
		<visual name="drawer_back-59">
			<origin xyz="0 0 0"/>
			<geometry>
				<mesh filename="textured_objs/new-68.obj"/>
			</geometry>
		</visual>
		<visual name="drawer_bottom-60">
			<origin xyz="0 0 0"/>
			<geometry>
				<mesh filename="textured_objs/new-72.obj"/>
			</geometry>
		</visual>
		<collision>
			<origin xyz="0 0 0"/>
			<geometry>
				<mesh filename="textured_objs/new-70.obj"/>
			</geometry>
		</collision>
		<collision>
			<origin xyz="0 0 0"/>
			<geometry>
				<mesh filename="textured_objs/new-69.obj"/>
			</geometry>
		</collision>
		<collision>
			<origin xyz="0 0 0"/>
			<geometry>
				<mesh filename="textured_objs/new-71.obj"/>
			</geometry>
		</collision>
		<collision>
			<origin xyz="0 0 0"/>
			<geometry>
				<mesh filename="textured_objs/new-68.obj"/>
			</geometry>
		</collision>
		<collision>
			<origin xyz="0 0 0"/>
			<geometry>
				<mesh filename="textured_objs/new-72.obj"/>
			</geometry>
		</collision>
	</link>
	<joint name="joint_1" type="prismatic">
		<origin xyz="0 0 0"/>
		<axis xyz="0 0 1"/>
		<child link="link_1"/>
		<parent link="link_4"/>
		<limit lower="-0.04800000000000004" upper="0.6320000000000001"/>
	</joint>
	<link name="link_2">
		<visual name="drawer_front-64">
			<origin xyz="0 0 0"/>
			<geometry>
				<mesh filename="textured_objs/new-64.obj"/>
			</geometry>
		</visual>
		<visual name="drawer_side-65">
			<origin xyz="0 0 0"/>
			<geometry>
				<mesh filename="textured_objs/new-63.obj"/>
			</geometry>
		</visual>
		<visual name="drawer_side-66">
			<origin xyz="0 0 0"/>
			<geometry>
				<mesh filename="textured_objs/new-65.obj"/>
			</geometry>
		</visual>
		<visual name="drawer_back-67">
			<origin xyz="0 0 0"/>
			<geometry>
				<mesh filename="textured_objs/new-66.obj"/>
			</geometry>
		</visual>
		<visual name="drawer_bottom-68">
			<origin xyz="0 0 0"/>
			<geometry>
				<mesh filename="textured_objs/new-67.obj"/>
			</geometry>
		</visual>
		<collision>
			<origin xyz="0 0 0"/>
			<geometry>
				<mesh filename="textured_objs/new-64.obj"/>
			</geometry>
		</collision>
		<collision>
			<origin xyz="0 0 0"/>
			<geometry>
				<mesh filename="textured_objs/new-63.obj"/>
			</geometry>
		</collision>
		<collision>
			<origin xyz="0 0 0"/>
			<geometry>
				<mesh filename="textured_objs/new-65.obj"/>
			</geometry>
		</collision>
		<collision>
			<origin xyz="0 0 0"/>
			<geometry>
				<mesh filename="textured_objs/new-66.obj"/>
			</geometry>
		</collision>
		<collision>
			<origin xyz="0 0 0"/>
			<geometry>
				<mesh filename="textured_objs/new-67.obj"/>
			</geometry>
		</collision>
	</link>
	<joint name="joint_2" type="prismatic">
		<origin xyz="0 0 0"/>
		<axis xyz="0 0 1"/>
		<child link="link_2"/>
		<parent link="link_4"/>
		<limit lower="-0.02400000000000002" upper="0.6400000000000001"/>
	</joint>
	<link name="link_3">
		<visual name="drawer_front-70">
			<origin xyz="0 0 0"/>
			<geometry>
				<mesh filename="textured_objs/new-53.obj"/>
			</geometry>
		</visual>
		<visual name="drawer_side-71">
			<origin xyz="0 0 0"/>
			<geometry>
				<mesh filename="textured_objs/new-56.obj"/>
			</geometry>
		</visual>
		<visual name="drawer_side-72">
			<origin xyz="0 0 0"/>
			<geometry>
				<mesh filename="textured_objs/new-54.obj"/>
			</geometry>
		</visual>
		<visual name="drawer_back-73">
			<origin xyz="0 0 0"/>
			<geometry>
				<mesh filename="textured_objs/new-55.obj"/>
			</geometry>
		</visual>
		<visual name="drawer_bottom-74">
			<origin xyz="0 0 0"/>
			<geometry>
				<mesh filename="textured_objs/new-57.obj"/>
			</geometry>
		</visual>
		<collision>
			<origin xyz="0 0 0"/>
			<geometry>
				<mesh filename="textured_objs/new-53.obj"/>
			</geometry>
		</collision>
		<collision>
			<origin xyz="0 0 0"/>
			<geometry>
				<mesh filename="textured_objs/new-56.obj"/>
			</geometry>
		</collision>
		<collision>
			<origin xyz="0 0 0"/>
			<geometry>
				<mesh filename="textured_objs/new-54.obj"/>
			</geometry>
		</collision>
		<collision>
			<origin xyz="0 0 0"/>
			<geometry>
				<mesh filename="textured_objs/new-55.obj"/>
			</geometry>
		</collision>
		<collision>
			<origin xyz="0 0 0"/>
			<geometry>
				<mesh filename="textured_objs/new-57.obj"/>
			</geometry>
		</collision>
	</link>
	<joint name="joint_3" type="prismatic">
		<origin xyz="0 0 0"/>
		<axis xyz="0 0 1"/>
		<child link="link_3"/>
		<parent link="link_4"/>
		<limit lower="-0.040000000000000036" upper="0.6160000000000001"/>
	</joint>
	<link name="link_4">
		<visual name="board-81">
			<origin xyz="0 0 0"/>
			<geometry>
				<mesh filename="textured_objs/original-12.obj"/>
			</geometry>
		</visual>
		<visual name="other_leaf-79">
			<origin xyz="0 0 0"/>
			<geometry>
				<mesh filename="textured_objs/original-9.obj"/>
			</geometry>
		</visual>
		<visual name="bar-83">
			<origin xyz="0 0 0"/>
			<geometry>
				<mesh filename="textured_objs/new-27.obj"/>
			</geometry>
		</visual>
		<visual name="bar-84">
			<origin xyz="0 0 0"/>
			<geometry>
				<mesh filename="textured_objs/new-20.obj"/>
			</geometry>
		</visual>
		<visual name="bar-85">
			<origin xyz="0 0 0"/>
			<geometry>
				<mesh filename="textured_objs/new-26.obj"/>
			</geometry>
		</visual>
		<visual name="bottom_panel-17">
			<origin xyz="0 0 0"/>
			<geometry>
				<mesh filename="textured_objs/new-6.obj"/>
			</geometry>
		</visual>
		<visual name="bottom_panel-17">
			<origin xyz="0 0 0"/>
			<geometry>
				<mesh filename="textured_objs/new-11.obj"/>
			</geometry>
		</visual>
		<visual name="bottom_panel-18">
			<origin xyz="0 0 0"/>
			<geometry>
				<mesh filename="textured_objs/new-12.obj"/>
			</geometry>
		</visual>
		<visual name="bottom_panel-18">
			<origin xyz="0 0 0"/>
			<geometry>
				<mesh filename="textured_objs/original-10.obj"/>
			</geometry>
		</visual>
		<visual name="leg-19">
			<origin xyz="0 0 0"/>
			<geometry>
				<mesh filename="textured_objs/new-4.obj"/>
			</geometry>
		</visual>
		<visual name="leg-20">
			<origin xyz="0 0 0"/>
			<geometry>
				<mesh filename="textured_objs/new-3.obj"/>
			</geometry>
		</visual>
		<visual name="runner-21">
			<origin xyz="0 0 0"/>
			<geometry>
				<mesh filename="textured_objs/new-17.obj"/>
			</geometry>
		</visual>
		<visual name="runner-22">
			<origin xyz="0 0 0"/>
			<geometry>
				<mesh filename="textured_objs/new-18.obj"/>
			</geometry>
		</visual>
		<visual name="runner-23">
			<origin xyz="0 0 0"/>
			<geometry>
				<mesh filename="textured_objs/new-19.obj"/>
			</geometry>
		</visual>
		<visual name="vertical_side_panel-30">
			<origin xyz="0 0 0"/>
			<geometry>
				<mesh filename="textured_objs/new-13.obj"/>
			</geometry>
		</visual>
		<visual name="vertical_side_panel-31">
			<origin xyz="0 0 0"/>
			<geometry>
				<mesh filename="textured_objs/new-15.obj"/>
			</geometry>
		</visual>
		<visual name="vertical_side_panel-32">
			<origin xyz="0 0 0"/>
			<geometry>
				<mesh filename="textured_objs/new-9.obj"/>
			</geometry>
		</visual>
		<visual name="vertical_side_panel-33">
			<origin xyz="0 0 0"/>
			<geometry>
				<mesh filename="textured_objs/new-5.obj"/>
			</geometry>
		</visual>
		<visual name="vertical_side_panel-33">
			<origin xyz="0 0 0"/>
			<geometry>
				<mesh filename="textured_objs/new-10.obj"/>
			</geometry>
		</visual>
		<visual name="shelf-38">
			<origin xyz="0 0 0"/>
			<geometry>
				<mesh filename="textured_objs/new-25.obj"/>
			</geometry>
		</visual>
		<visual name="shelf-38">
			<origin xyz="0 0 0"/>
			<geometry>
				<mesh filename="textured_objs/new-23.obj"/>
			</geometry>
		</visual>
		<visual name="shelf-38">
			<origin xyz="0 0 0"/>
			<geometry>
				<mesh filename="textured_objs/new-22.obj"/>
			</geometry>
		</visual>
		<visual name="shelf-39">
			<origin xyz="0 0 0"/>
			<geometry>
				<mesh filename="textured_objs/new-14.obj"/>
			</geometry>
		</visual>
		<visual name="shelf-39">
			<origin xyz="0 0 0"/>
			<geometry>
				<mesh filename="textured_objs/new-0.obj"/>
			</geometry>
		</visual>
		<visual name="shelf-39">
			<origin xyz="0 0 0"/>
			<geometry>
				<mesh filename="textured_objs/new-1.obj"/>
			</geometry>
		</visual>
		<visual name="back_panel-40">
			<origin xyz="0 0 0"/>
			<geometry>
				<mesh filename="textured_objs/new-21.obj"/>
			</geometry>
		</visual>
		<visual name="back_panel-41">
			<origin xyz="0 0 0"/>
			<geometry>
				<mesh filename="textured_objs/new-7.obj"/>
			</geometry>
		</visual>
		<visual name="shelf-75">
			<origin xyz="0 0 0"/>
			<geometry>
				<mesh filename="textured_objs/new-8.obj"/>
			</geometry>
		</visual>
		<visual name="shelf-76">
			<origin xyz="0 0 0"/>
			<geometry>
				<mesh filename="textured_objs/new-16.obj"/>
			</geometry>
		</visual>
		<visual name="shelf-76">
			<origin xyz="0 0 0"/>
			<geometry>
				<mesh filename="textured_objs/new-2.obj"/>
			</geometry>
		</visual>
		<visual name="shelf-76">
			<origin xyz="0 0 0"/>
			<geometry>
				<mesh filename="textured_objs/new-24.obj"/>
			</geometry>
		</visual>
		<collision>
			<origin xyz="0 0 0"/>
			<geometry>
				<mesh filename="textured_objs/original-12.obj"/>
			</geometry>
		</collision>
		<collision>
			<origin xyz="0 0 0"/>
			<geometry>
				<mesh filename="textured_objs/original-9.obj"/>
			</geometry>
		</collision>
		<collision>
			<origin xyz="0 0 0"/>
			<geometry>
				<mesh filename="textured_objs/new-27.obj"/>
			</geometry>
		</collision>
		<collision>
			<origin xyz="0 0 0"/>
			<geometry>
				<mesh filename="textured_objs/new-20.obj"/>
			</geometry>
		</collision>
		<collision>
			<origin xyz="0 0 0"/>
			<geometry>
				<mesh filename="textured_objs/new-26.obj"/>
			</geometry>
		</collision>
		<collision>
			<origin xyz="0 0 0"/>
			<geometry>
				<mesh filename="textured_objs/new-6.obj"/>
			</geometry>
		</collision>
		<collision>
			<origin xyz="0 0 0"/>
			<geometry>
				<mesh filename="textured_objs/new-11.obj"/>
			</geometry>
		</collision>
		<collision>
			<origin xyz="0 0 0"/>
			<geometry>
				<mesh filename="textured_objs/new-12.obj"/>
			</geometry>
		</collision>
		<collision>
			<origin xyz="0 0 0"/>
			<geometry>
				<mesh filename="textured_objs/original-10.obj"/>
			</geometry>
		</collision>
		<collision>
			<origin xyz="0 0 0"/>
			<geometry>
				<mesh filename="textured_objs/new-4.obj"/>
			</geometry>
		</collision>
		<collision>
			<origin xyz="0 0 0"/>
			<geometry>
				<mesh filename="textured_objs/new-3.obj"/>
			</geometry>
		</collision>
		<collision>
			<origin xyz="0 0 0"/>
			<geometry>
				<mesh filename="textured_objs/new-17.obj"/>
			</geometry>
		</collision>
		<collision>
			<origin xyz="0 0 0"/>
			<geometry>
				<mesh filename="textured_objs/new-18.obj"/>
			</geometry>
		</collision>
		<collision>
			<origin xyz="0 0 0"/>
			<geometry>
				<mesh filename="textured_objs/new-19.obj"/>
			</geometry>
		</collision>
		<collision>
			<origin xyz="0 0 0"/>
			<geometry>
				<mesh filename="textured_objs/new-13.obj"/>
			</geometry>
		</collision>
		<collision>
			<origin xyz="0 0 0"/>
			<geometry>
				<mesh filename="textured_objs/new-15.obj"/>
			</geometry>
		</collision>
		<collision>
			<origin xyz="0 0 0"/>
			<geometry>
				<mesh filename="textured_objs/new-9.obj"/>
			</geometry>
		</collision>
		<collision>
			<origin xyz="0 0 0"/>
			<geometry>
				<mesh filename="textured_objs/new-5.obj"/>
			</geometry>
		</collision>
		<collision>
			<origin xyz="0 0 0"/>
			<geometry>
				<mesh filename="textured_objs/new-10.obj"/>
			</geometry>
		</collision>
		<collision>
			<origin xyz="0 0 0"/>
			<geometry>
				<mesh filename="textured_objs/new-25.obj"/>
			</geometry>
		</collision>
		<collision>
			<origin xyz="0 0 0"/>
			<geometry>
				<mesh filename="textured_objs/new-23.obj"/>
			</geometry>
		</collision>
		<collision>
			<origin xyz="0 0 0"/>
			<geometry>
				<mesh filename="textured_objs/new-22.obj"/>
			</geometry>
		</collision>
		<collision>
			<origin xyz="0 0 0"/>
			<geometry>
				<mesh filename="textured_objs/new-14.obj"/>
			</geometry>
		</collision>
		<collision>
			<origin xyz="0 0 0"/>
			<geometry>
				<mesh filename="textured_objs/new-0.obj"/>
			</geometry>
		</collision>
		<collision>
			<origin xyz="0 0 0"/>
			<geometry>
				<mesh filename="textured_objs/new-1.obj"/>
			</geometry>
		</collision>
		<collision>
			<origin xyz="0 0 0"/>
			<geometry>
				<mesh filename="textured_objs/new-21.obj"/>
			</geometry>
		</collision>
		<collision>
			<origin xyz="0 0 0"/>
			<geometry>
				<mesh filename="textured_objs/new-7.obj"/>
			</geometry>
		</collision>
		<collision>
			<origin xyz="0 0 0"/>
			<geometry>
				<mesh filename="textured_objs/new-8.obj"/>
			</geometry>
		</collision>
		<collision>
			<origin xyz="0 0 0"/>
			<geometry>
				<mesh filename="textured_objs/new-16.obj"/>
			</geometry>
		</collision>
		<collision>
			<origin xyz="0 0 0"/>
			<geometry>
				<mesh filename="textured_objs/new-2.obj"/>
			</geometry>
		</collision>
		<collision>
			<origin xyz="0 0 0"/>
			<geometry>
				<mesh filename="textured_objs/new-24.obj"/>
			</geometry>
		</collision>
	</link>
	<joint name="joint_4" type="fixed">
		<origin rpy="1.570796326794897 0 -1.570796326794897" xyz="0 0 0"/>
		<child link="link_4"/>
		<parent link="base"/>
	</joint>
</robot>
