<?xml version="1.0" ?>
<robot name="partnet_3a9516eb02206108e0c8359faeb78bbe">
	<link name="base"/>
	<link name="link_0">
		<visual name="mouth-9">
			<origin xyz="-0.004428000000000008 0 -0.0064125000000000015"/>
			<geometry>
				<mesh filename="textured_objs/original-5.obj"/>
			</geometry>
		</visual>
		<visual name="mouth-9">
			<origin xyz="-0.004428000000000008 0 -0.0064125000000000015"/>
			<geometry>
				<mesh filename="textured_objs/original-11.obj"/>
			</geometry>
		</visual>
		<visual name="mouth-9">
			<origin xyz="-0.004428000000000008 0 -0.0064125000000000015"/>
			<geometry>
				<mesh filename="textured_objs/original-6.obj"/>
			</geometry>
		</visual>
		<visual name="mouth-9">
			<origin xyz="-0.004428000000000008 0 -0.0064125000000000015"/>
			<geometry>
				<mesh filename="textured_objs/original-10.obj"/>
			</geometry>
		</visual>
		<collision>
			<origin xyz="-0.004428000000000008 0 -0.0064125000000000015"/>
			<geometry>
				<mesh filename="textured_objs/original-5.obj"/>
			</geometry>
		</collision>
		<collision>
			<origin xyz="-0.004428000000000008 0 -0.0064125000000000015"/>
			<geometry>
				<mesh filename="textured_objs/original-11.obj"/>
			</geometry>
		</collision>
		<collision>
			<origin xyz="-0.004428000000000008 0 -0.0064125000000000015"/>
			<geometry>
				<mesh filename="textured_objs/original-6.obj"/>
			</geometry>
		</collision>
		<collision>
			<origin xyz="-0.004428000000000008 0 -0.0064125000000000015"/>
			<geometry>
				<mesh filename="textured_objs/original-10.obj"/>
			</geometry>
		</collision>
	</link>
	<joint name="joint_0" type="continuous">
		<origin xyz="0.0 0 0.0"/>
		<axis xyz="0 1 0"/>
		<child link="link_0"/>
		<parent link="link_0_helper"/>
	</joint>
	<link name="link_1">
		<visual name="lid-8">
			<origin xyz="0 0 0"/>
			<geometry>
				<mesh filename="textured_objs/original-4.obj"/>
			</geometry>
		</visual>
		<visual name="lid-8">
			<origin xyz="0 0 0"/>
			<geometry>
				<mesh filename="textured_objs/original-3.obj"/>
			</geometry>
		</visual>
		<visual name="body-7">
			<origin xyz="0 0 0"/>
			<geometry>
				<mesh filename="textured_objs/original-2.obj"/>
			</geometry>
		</visual>
		<visual name="body-7">
			<origin xyz="0 0 0"/>
			<geometry>
				<mesh filename="textured_objs/original-1.obj"/>
			</geometry>
		</visual>
		<visual name="liquid-11">
			<origin xyz="0 0 0"/>
			<geometry>
				<mesh filename="textured_objs/original-7.obj"/>
			</geometry>
		</visual>
		<collision>
			<origin xyz="0 0 0"/>
			<geometry>
				<mesh filename="textured_objs/original-4.obj"/>
			</geometry>
		</collision>
		<collision>
			<origin xyz="0 0 0"/>
			<geometry>
				<mesh filename="textured_objs/original-3.obj"/>
			</geometry>
		</collision>
		<collision>
			<origin xyz="0 0 0"/>
			<geometry>
				<mesh filename="textured_objs/original-2.obj"/>
			</geometry>
		</collision>
		<collision>
			<origin xyz="0 0 0"/>
			<geometry>
				<mesh filename="textured_objs/original-1.obj"/>
			</geometry>
		</collision>
		<collision>
			<origin xyz="0 0 0"/>
			<geometry>
				<mesh filename="textured_objs/original-7.obj"/>
			</geometry>
		</collision>
	</link>
	<joint name="joint_1" type="fixed">
		<origin rpy="1.570796326794897 0 -1.570796326794897" xyz="0 0 0"/>
		<child link="link_1"/>
		<parent link="base"/>
	</joint>
	<link name="link_0_helper"/>
	<joint name="joint_2" type="prismatic">
		<origin xyz="0.004428000000000008 0 0.0064125000000000015"/>
		<axis xyz="0 1 0"/>
		<child link="link_0_helper"/>
		<parent link="link_1"/>
		<limit lower="-0.03200000000000003" upper="0.008000000000000007"/>
	</joint>
</robot>
