<?xml version="1.0" ?>
<robot name="partnet_47c68395a5775e10d9deb3f829cc2475">
	<link name="base"/>

	<!-- <link name="oven_top">
		<visual name="bottom">
			<origin xyz="0 0 0"/>
			<geometry>
				<mesh filename="textured_objs/original-66.obj"/>
			</geometry>
			<material name="Transparent">
				<color rgba="1 1 1 0"/>
			</material>
		</visual>
		<collision>
			<origin xyz="0 0 0"/>
			<geometry>
				<mesh filename="textured_objs/original-66.obj"/>
			</geometry>
		</collision>
	</link>
	<joint name="joint_2" type="fixed">
		<origin rpy="0 0 0" xyz="0 0 0"/>
		<child link="oven_top"/>
		<parent link="link_0"/>
	</joint> -->

	<link name="link_0">
		<visual name="door-1">
			<origin xyz="0.4281465047314254 0.5719901858661538 -0.4677611856582847"/>
			<geometry>
				<mesh filename="textured_objs/original-20.obj"/>
			</geometry>
		</visual>
		<visual name="door-1">
			<origin xyz="0.4281465047314254 0.5719901858661538 -0.4677611856582847"/>
			<geometry>
				<mesh filename="textured_objs/original-47.obj"/>
			</geometry>
		</visual>
		<visual name="door-1">
			<origin xyz="0.4281465047314254 0.5719901858661538 -0.4677611856582847"/>
			<geometry>
				<mesh filename="textured_objs/original-23.obj"/>
			</geometry>
		</visual>
		<visual name="door-1">
			<origin xyz="0.4281465047314254 0.5719901858661538 -0.4677611856582847"/>
			<geometry>
				<mesh filename="textured_objs/original-9.obj"/>
			</geometry>
		</visual>
		<collision>
			<origin xyz="0.4281465047314254 0.5719901858661538 -0.4677611856582847"/>
			<geometry>
				<mesh filename="textured_objs/original-20.obj"/>
			</geometry>
		</collision>
		<collision>
			<origin xyz="0.4281465047314254 0.5719901858661538 -0.4677611856582847"/>
			<geometry>
				<mesh filename="textured_objs/original-47.obj"/>
			</geometry>
		</collision>
		<collision>
			<origin xyz="0.4281465047314254 0.5719901858661538 -0.4677611856582847"/>
			<geometry>
				<mesh filename="textured_objs/original-23.obj"/>
			</geometry>
		</collision>
		<collision>
			<origin xyz="0.4281465047314254 0.5719901858661538 -0.4677611856582847"/>
			<geometry>
				<mesh filename="textured_objs/original-9.obj"/>
			</geometry>
		</collision>
	</link>
	<joint name="joint_0" type="revolute">
		<origin xyz="-0.4281465047314254 -0.5719901858661538 0.4677611856582847"/>
		<axis xyz="0.9978013971995803 0.0 0.06627497073983131"/>
		<child link="link_0"/>
		<parent link="link_9"/>
		<limit lower="0.0" upper="1.5707963267948966"/>
	</joint>
	<link name="link_1">
		<visual name="door-2">
			<origin xyz="0.4336921858655555 -0.15593220728466706 -0.468144158905138"/>
			<geometry>
				<mesh filename="textured_objs/original-18.obj"/>
			</geometry>
		</visual>
		<visual name="door-2">
			<origin xyz="0.4336921858655555 -0.15593220728466706 -0.468144158905138"/>
			<geometry>
				<mesh filename="textured_objs/original-46.obj"/>
			</geometry>
		</visual>
		<visual name="door-2">
			<origin xyz="0.4336921858655555 -0.15593220728466706 -0.468144158905138"/>
			<geometry>
				<mesh filename="textured_objs/original-22.obj"/>
			</geometry>
		</visual>
		<visual name="door-2">
			<origin xyz="0.4336921858655555 -0.15593220728466706 -0.468144158905138"/>
			<geometry>
				<mesh filename="textured_objs/original-1.obj"/>
			</geometry>
		</visual>
		<collision>
			<origin xyz="0.4336921858655555 -0.15593220728466706 -0.468144158905138"/>
			<geometry>
				<mesh filename="textured_objs/original-18.obj"/>
			</geometry>
		</collision>
		<collision>
			<origin xyz="0.4336921858655555 -0.15593220728466706 -0.468144158905138"/>
			<geometry>
				<mesh filename="textured_objs/original-46.obj"/>
			</geometry>
		</collision>
		<collision>
			<origin xyz="0.4336921858655555 -0.15593220728466706 -0.468144158905138"/>
			<geometry>
				<mesh filename="textured_objs/original-22.obj"/>
			</geometry>
		</collision>
		<collision>
			<origin xyz="0.4336921858655555 -0.15593220728466706 -0.468144158905138"/>
			<geometry>
				<mesh filename="textured_objs/original-1.obj"/>
			</geometry>
		</collision>
	</link>
	<joint name="joint_1" type="revolute">
		<origin xyz="-0.4336921858655555 0.15593220728466706 0.468144158905138"/>
		<axis xyz="0.9978013971995803 0.0 0.06627497073983166"/>
		<child link="link_1"/>
		<parent link="link_9"/>
		<limit lower="0.0" upper="1.5707963267948966"/>
	</joint>
	<link name="link_2">
		<visual name="knob-3">
			<origin xyz="-0.3666701057131047 -0.6428384801611329 -0.024320726974939557"/>
			<geometry>
				<mesh filename="textured_objs/original-34.obj"/>
			</geometry>
		</visual>
		<visual name="knob-3">
			<origin xyz="-0.3666701057131047 -0.6428384801611329 -0.024320726974939557"/>
			<geometry>
				<mesh filename="textured_objs/original-140.obj"/>
			</geometry>
		</visual>
		<visual name="knob-3">
			<origin xyz="-0.3666701057131047 -0.6428384801611329 -0.024320726974939557"/>
			<geometry>
				<mesh filename="textured_objs/original-71.obj"/>
			</geometry>
		</visual>
		<visual name="knob-3">
			<origin xyz="-0.3666701057131047 -0.6428384801611329 -0.024320726974939557"/>
			<geometry>
				<mesh filename="textured_objs/original-123.obj"/>
			</geometry>
		</visual>
		<collision>
			<origin xyz="-0.3666701057131047 -0.6428384801611329 -0.024320726974939557"/>
			<geometry>
				<mesh filename="textured_objs/original-34.obj"/>
			</geometry>
		</collision>
		<collision>
			<origin xyz="-0.3666701057131047 -0.6428384801611329 -0.024320726974939557"/>
			<geometry>
				<mesh filename="textured_objs/original-140.obj"/>
			</geometry>
		</collision>
		<collision>
			<origin xyz="-0.3666701057131047 -0.6428384801611329 -0.024320726974939557"/>
			<geometry>
				<mesh filename="textured_objs/original-71.obj"/>
			</geometry>
		</collision>
		<collision>
			<origin xyz="-0.3666701057131047 -0.6428384801611329 -0.024320726974939557"/>
			<geometry>
				<mesh filename="textured_objs/original-123.obj"/>
			</geometry>
		</collision>
	</link>
	<joint name="joint_2" type="revolute">
		<origin xyz="0.3666701057131047 0.6428384801611329 0.024320726974939557"/>
		<axis xyz="-0.06616431685170301 -1.0823880716471467e-05 0.9978087407205809"/>
		<child link="link_2"/>
		<parent link="link_9"/>
		<limit lower="-0.0" upper="5.759586531581287"/>
	</joint>
	<link name="link_3">
		<visual name="knob-4">
			<origin xyz="-0.2582035684632654 -0.6428179468991603 -0.017145086458529978"/>
			<geometry>
				<mesh filename="textured_objs/original-38.obj"/>
			</geometry>
		</visual>
		<visual name="knob-4">
			<origin xyz="-0.2582035684632654 -0.6428179468991603 -0.017145086458529978"/>
			<geometry>
				<mesh filename="textured_objs/original-74.obj"/>
			</geometry>
		</visual>
		<visual name="knob-4">
			<origin xyz="-0.2582035684632654 -0.6428179468991603 -0.017145086458529978"/>
			<geometry>
				<mesh filename="textured_objs/original-129.obj"/>
			</geometry>
		</visual>
		<collision>
			<origin xyz="-0.2582035684632654 -0.6428179468991603 -0.017145086458529978"/>
			<geometry>
				<mesh filename="textured_objs/original-38.obj"/>
			</geometry>
		</collision>
		<collision>
			<origin xyz="-0.2582035684632654 -0.6428179468991603 -0.017145086458529978"/>
			<geometry>
				<mesh filename="textured_objs/original-74.obj"/>
			</geometry>
		</collision>
		<collision>
			<origin xyz="-0.2582035684632654 -0.6428179468991603 -0.017145086458529978"/>
			<geometry>
				<mesh filename="textured_objs/original-129.obj"/>
			</geometry>
		</collision>
	</link>
	<joint name="joint_3" type="revolute">
		<origin xyz="0.2582035684632654 0.6428179468991603 0.017145086458529978"/>
		<axis xyz="-0.06633209269933098 3.0890870804835796e-05 0.9977976009812219"/>
		<child link="link_3"/>
		<parent link="link_9"/>
		<limit lower="-0.0" upper="5.759586531581287"/>
	</joint>
	<link name="link_4">
		<visual name="knob-5">
			<origin xyz="-0.14977229147865534 -0.6428279436445825 -0.00998598602767333"/>
			<geometry>
				<mesh filename="textured_objs/original-37.obj"/>
			</geometry>
		</visual>
		<visual name="knob-5">
			<origin xyz="-0.14977229147865534 -0.6428279436445825 -0.00998598602767333"/>
			<geometry>
				<mesh filename="textured_objs/original-73.obj"/>
			</geometry>
		</visual>
		<visual name="knob-5">
			<origin xyz="-0.14977229147865534 -0.6428279436445825 -0.00998598602767333"/>
			<geometry>
				<mesh filename="textured_objs/original-125.obj"/>
			</geometry>
		</visual>
		<collision>
			<origin xyz="-0.14977229147865534 -0.6428279436445825 -0.00998598602767333"/>
			<geometry>
				<mesh filename="textured_objs/original-37.obj"/>
			</geometry>
		</collision>
		<collision>
			<origin xyz="-0.14977229147865534 -0.6428279436445825 -0.00998598602767333"/>
			<geometry>
				<mesh filename="textured_objs/original-73.obj"/>
			</geometry>
		</collision>
		<collision>
			<origin xyz="-0.14977229147865534 -0.6428279436445825 -0.00998598602767333"/>
			<geometry>
				<mesh filename="textured_objs/original-125.obj"/>
			</geometry>
		</collision>
	</link>
	<joint name="joint_4" type="revolute">
		<origin xyz="0.14977229147865534 0.6428279436445825 0.00998598602767333"/>
		<axis xyz="-0.06657184915123522 1.0554231659352238e-05 0.9977816338203432"/>
		<child link="link_4"/>
		<parent link="link_9"/>
		<limit lower="-0.0" upper="5.759586531581287"/>
	</joint>
	<link name="link_5">
		<visual name="knob-6">
			<origin xyz="-0.04138397422716416 -0.6433456026355645 -0.002754114312966408"/>
			<geometry>
				<mesh filename="textured_objs/original-72.obj"/>
			</geometry>
		</visual>
		<visual name="knob-6">
			<origin xyz="-0.04138397422716416 -0.6433456026355645 -0.002754114312966408"/>
			<geometry>
				<mesh filename="textured_objs/original-124.obj"/>
			</geometry>
		</visual>
		<visual name="knob-6">
			<origin xyz="-0.04138397422716416 -0.6433456026355645 -0.002754114312966408"/>
			<geometry>
				<mesh filename="textured_objs/original-33.obj"/>
			</geometry>
		</visual>
		<collision>
			<origin xyz="-0.04138397422716416 -0.6433456026355645 -0.002754114312966408"/>
			<geometry>
				<mesh filename="textured_objs/original-72.obj"/>
			</geometry>
		</collision>
		<collision>
			<origin xyz="-0.04138397422716416 -0.6433456026355645 -0.002754114312966408"/>
			<geometry>
				<mesh filename="textured_objs/original-124.obj"/>
			</geometry>
		</collision>
		<collision>
			<origin xyz="-0.04138397422716416 -0.6433456026355645 -0.002754114312966408"/>
			<geometry>
				<mesh filename="textured_objs/original-33.obj"/>
			</geometry>
		</collision>
	</link>
	<joint name="joint_5" type="revolute">
		<origin xyz="0.04138397422716416 0.6433456026355645 0.002754114312966408"/>
		<axis xyz="-0.0663526444959829 -3.2779089080370087e-06 0.9977962349887101"/>
		<child link="link_5"/>
		<parent link="link_9"/>
		<limit lower="-0.0" upper="5.759586531581287"/>
	</joint>
	<link name="link_6">
		<visual name="knob-7">
			<origin xyz="0.06744595961120593 -0.6428459993383334 0.004466793224164564"/>
			<geometry>
				<mesh filename="textured_objs/original-32.obj"/>
			</geometry>
		</visual>
		<visual name="knob-7">
			<origin xyz="0.06744595961120593 -0.6428459993383334 0.004466793224164564"/>
			<geometry>
				<mesh filename="textured_objs/original-70.obj"/>
			</geometry>
		</visual>
		<visual name="knob-7">
			<origin xyz="0.06744595961120593 -0.6428459993383334 0.004466793224164564"/>
			<geometry>
				<mesh filename="textured_objs/original-119.obj"/>
			</geometry>
		</visual>
		<collision>
			<origin xyz="0.06744595961120593 -0.6428459993383334 0.004466793224164564"/>
			<geometry>
				<mesh filename="textured_objs/original-32.obj"/>
			</geometry>
		</collision>
		<collision>
			<origin xyz="0.06744595961120593 -0.6428459993383334 0.004466793224164564"/>
			<geometry>
				<mesh filename="textured_objs/original-70.obj"/>
			</geometry>
		</collision>
		<collision>
			<origin xyz="0.06744595961120593 -0.6428459993383334 0.004466793224164564"/>
			<geometry>
				<mesh filename="textured_objs/original-119.obj"/>
			</geometry>
		</collision>
	</link>
	<joint name="joint_6" type="revolute">
		<origin xyz="-0.06744595961120593 0.6428459993383334 -0.004466793224164564"/>
		<axis xyz="-0.06632815401844577 -2.5836306187991368e-05 0.9977978629547124"/>
		<child link="link_6"/>
		<parent link="link_9"/>
		<limit lower="-0.0" upper="5.759586531581287"/>
	</joint>
	<link name="link_7">
		<visual name="knob-8">
			<origin xyz="0.17609087365187812 -0.6428119150166791 0.011698414754721508"/>
			<geometry>
				<mesh filename="textured_objs/original-30.obj"/>
			</geometry>
		</visual>
		<visual name="knob-8">
			<origin xyz="0.17609087365187812 -0.6428119150166791 0.011698414754721508"/>
			<geometry>
				<mesh filename="textured_objs/original-68.obj"/>
			</geometry>
		</visual>
		<visual name="knob-8">
			<origin xyz="0.17609087365187812 -0.6428119150166791 0.011698414754721508"/>
			<geometry>
				<mesh filename="textured_objs/original-118.obj"/>
			</geometry>
		</visual>
		<collision>
			<origin xyz="0.17609087365187812 -0.6428119150166791 0.011698414754721508"/>
			<geometry>
				<mesh filename="textured_objs/original-30.obj"/>
			</geometry>
		</collision>
		<collision>
			<origin xyz="0.17609087365187812 -0.6428119150166791 0.011698414754721508"/>
			<geometry>
				<mesh filename="textured_objs/original-68.obj"/>
			</geometry>
		</collision>
		<collision>
			<origin xyz="0.17609087365187812 -0.6428119150166791 0.011698414754721508"/>
			<geometry>
				<mesh filename="textured_objs/original-118.obj"/>
			</geometry>
		</collision>
	</link>
	<joint name="joint_7" type="revolute">
		<origin xyz="-0.17609087365187812 0.6428119150166791 -0.011698414754721508"/>
		<axis xyz="-0.06613454343554552 4.2180839878873594e-05 0.9978107137054346"/>
		<child link="link_7"/>
		<parent link="link_9"/>
		<limit lower="-0.0" upper="5.759586531581287"/>
	</joint>
	<link name="link_8">
		<visual name="knob-9">
			<origin xyz="0.33902694142962475 -0.6428318429255713 0.02240060328065199"/>
			<geometry>
				<mesh filename="textured_objs/original-67.obj"/>
			</geometry>
		</visual>
		<visual name="knob-9">
			<origin xyz="0.33902694142962475 -0.6428318429255713 0.02240060328065199"/>
			<geometry>
				<mesh filename="textured_objs/original-27.obj"/>
			</geometry>
		</visual>
		<visual name="knob-9">
			<origin xyz="0.33902694142962475 -0.6428318429255713 0.02240060328065199"/>
			<geometry>
				<mesh filename="textured_objs/original-112.obj"/>
			</geometry>
		</visual>
		<collision>
			<origin xyz="0.33902694142962475 -0.6428318429255713 0.02240060328065199"/>
			<geometry>
				<mesh filename="textured_objs/original-67.obj"/>
			</geometry>
		</collision>
		<collision>
			<origin xyz="0.33902694142962475 -0.6428318429255713 0.02240060328065199"/>
			<geometry>
				<mesh filename="textured_objs/original-27.obj"/>
			</geometry>
		</collision>
		<collision>
			<origin xyz="0.33902694142962475 -0.6428318429255713 0.02240060328065199"/>
			<geometry>
				<mesh filename="textured_objs/original-112.obj"/>
			</geometry>
		</collision>
	</link>

	<joint name="joint_8" type="revolute">
		<origin xyz="-0.33902694142962475 0.6428318429255713 -0.02240060328065199"/>
		<axis xyz="-0.06592495637620398 2.3863483726360917e-06 0.9978245838428221"/>
		<child link="link_8"/>
		<parent link="link_9"/>
		<limit lower="-0.0" upper="5.759586531581287"/>
	</joint>

	<link name="link_9">
		<visual name="base_body-10">
			<origin xyz="0 0 0"/>
			<geometry>
				<mesh filename="textured_objs/original-29.obj"/>
			</geometry>
		</visual>
		<visual name="base_body-10">
			<origin xyz="0 0 0"/>
			<geometry>
				<mesh filename="textured_objs/original-103.obj"/>
			</geometry>
		</visual>
		<visual name="base_body-10">
			<origin xyz="0 0 0"/>
			<geometry>
				<mesh filename="textured_objs/original-100.obj"/>
			</geometry>
		</visual>
		<!-- <visual name="base_body-10">
			<origin xyz="0 0 0"/>
			<geometry>
				<mesh filename="textured_objs/original-21.obj"/>
			</geometry>
		</visual> -->
		<visual name="base_body-10">
			<origin xyz="0 0 0"/>
			<geometry>
				<mesh filename="textured_objs/original-132.obj"/>
			</geometry>
		</visual>
		<visual name="base_body-10">
			<origin xyz="0 0 0"/>
			<geometry>
				<mesh filename="textured_objs/original-36.obj"/>
			</geometry>
		</visual>
		<visual name="base_body-10">
			<origin xyz="0 0 0"/>
			<geometry>
				<mesh filename="textured_objs/original-126.obj"/>
			</geometry>
		</visual>
		<visual name="base_body-10">
			<origin xyz="0 0 0"/>
			<geometry>
				<mesh filename="textured_objs/original-41.obj"/>
			</geometry>
		</visual>
		<visual name="base_body-10">
			<origin xyz="0 0 0"/>
			<geometry>
				<mesh filename="textured_objs/original-28.obj"/>
			</geometry>
		</visual>
		<visual name="base_body-10">
			<origin xyz="0 0 0"/>
			<geometry>
				<mesh filename="textured_objs/original-96.obj"/>
			</geometry>
		</visual>
		<visual name="base_body-10">
			<origin xyz="0 0 0"/>
			<geometry>
				<mesh filename="textured_objs/original-64.obj"/>
			</geometry>
		</visual>
		<visual name="base_body-10">
			<origin xyz="0 0 0"/>
			<geometry>
				<mesh filename="textured_objs/original-134.obj"/>
			</geometry>
		</visual>
		<visual name="base_body-10">
			<origin xyz="0 0 0"/>
			<geometry>
				<mesh filename="textured_objs/original-43.obj"/>
			</geometry>
		</visual>
		<visual name="base_body-10">
			<origin xyz="0 0 0"/>
			<geometry>
				<mesh filename="textured_objs/original-52.obj"/>
			</geometry>
		</visual>
		<visual name="base_body-10">
			<origin xyz="0 0 0"/>
			<geometry>
				<mesh filename="textured_objs/original-83.obj"/>
			</geometry>
		</visual>
		<!-- <visual name="base_body-10">
			<origin xyz="0 0 0"/>
			<geometry>
				<mesh filename="textured_objs/original-26.obj"/>
			</geometry>
		</visual> -->
		<visual name="base_body-10">
			<origin xyz="0 0 0"/>
			<geometry>
				<mesh filename="textured_objs/original-117.obj"/>
			</geometry>
		</visual>
		<visual name="base_body-10">
			<origin xyz="0 0 0"/>
			<geometry>
				<mesh filename="textured_objs/original-110.obj"/>
			</geometry>
		</visual>
		<visual name="base_body-10">
			<origin xyz="0 0 0"/>
			<geometry>
				<mesh filename="textured_objs/original-107.obj"/>
			</geometry>
		</visual>
		<visual name="base_body-10">
			<origin xyz="0 0 0"/>
			<geometry>
				<mesh filename="textured_objs/original-104.obj"/>
			</geometry>
		</visual>
		<!-- <visual name="base_body-10">
			<origin xyz="0 0 0"/>
			<geometry>
				<mesh filename="textured_objs/original-4.obj"/>
			</geometry>
		</visual> -->
		<!-- <visual name="base_body-10">
			<origin xyz="0 0 0"/>
			<geometry>
				<mesh filename="textured_objs/original-3.obj"/>
			</geometry>
		</visual> -->
		<visual name="base_body-10">
			<origin xyz="0 0 0"/>
			<geometry>
				<mesh filename="textured_objs/original-128.obj"/>
			</geometry>
		</visual>
		<visual name="base_body-10">
			<origin xyz="0 0 0"/>
			<geometry>
				<mesh filename="textured_objs/original-65.obj"/>
			</geometry>
		</visual>
		<!-- <visual name="base_body-10">
			<origin xyz="0 0 0"/>
			<geometry>
				<mesh filename="textured_objs/original-2.obj"/>
			</geometry>
		</visual> -->
		<visual name="base_body-10">
			<origin xyz="0 0 0"/>
			<geometry>
				<mesh filename="textured_objs/original-130.obj"/>
			</geometry>
		</visual>
		<visual name="base_body-10">
			<origin xyz="0 0 0"/>
			<geometry>
				<mesh filename="textured_objs/original-137.obj"/>
			</geometry>
		</visual>
		<visual name="base_body-10">
			<origin xyz="0 0 0"/>
			<geometry>
				<mesh filename="textured_objs/original-139.obj"/>
			</geometry>
		</visual>
		<visual name="base_body-10">
			<origin xyz="0 0 0"/>
			<geometry>
				<mesh filename="textured_objs/original-44.obj"/>
			</geometry>
		</visual>
		<visual name="base_body-10">
			<origin xyz="0 0 0"/>
			<geometry>
				<mesh filename="textured_objs/original-106.obj"/>
			</geometry>
		</visual>
		<visual name="base_body-10">
			<origin xyz="0 0 0"/>
			<geometry>
				<mesh filename="textured_objs/original-16.obj"/>
			</geometry>
		</visual>
		<visual name="base_body-10">
			<origin xyz="0 0 0"/>
			<geometry>
				<mesh filename="textured_objs/original-86.obj"/>
			</geometry>
		</visual>
		<visual name="base_body-10">
			<origin xyz="0 0 0"/>
			<geometry>
				<mesh filename="textured_objs/original-8.obj"/>
			</geometry>
		</visual>
		<visual name="base_body-10">
			<origin xyz="0 0 0"/>
			<geometry>
				<mesh filename="textured_objs/original-109.obj"/>
			</geometry>
		</visual>
		<visual name="base_body-10">
			<origin xyz="0 0 0"/>
			<geometry>
				<mesh filename="textured_objs/original-13.obj"/>
			</geometry>
		</visual>
		<visual name="base_body-10">
			<origin xyz="0 0 0"/>
			<geometry>
				<mesh filename="textured_objs/original-45.obj"/>
			</geometry>
		</visual>
		<visual name="base_body-10">
			<origin xyz="0 0 0"/>
			<geometry>
				<mesh filename="textured_objs/original-35.obj"/>
			</geometry>
		</visual>
		<visual name="base_body-10">
			<origin xyz="0 0 0"/>
			<geometry>
				<mesh filename="textured_objs/original-138.obj"/>
			</geometry>
		</visual>
		<!-- <visual name="base_body-10">
			<origin xyz="0 0 0"/>
			<geometry>
				<mesh filename="textured_objs/original-49.obj"/>
			</geometry>
		</visual> -->
		<visual name="base_body-10">
			<origin xyz="0 0 0"/>
			<geometry>
				<mesh filename="textured_objs/original-93.obj"/>
			</geometry>
		</visual>
		<visual name="base_body-10">
			<origin xyz="0 0 0"/>
			<geometry>
				<mesh filename="textured_objs/original-61.obj"/>
			</geometry>
		</visual>
		<visual name="base_body-10">
			<origin xyz="0 0 0"/>
			<geometry>
				<mesh filename="textured_objs/original-39.obj"/>
			</geometry>
		</visual>
		<visual name="base_body-10">
			<origin xyz="0 0 0"/>
			<geometry>
				<mesh filename="textured_objs/original-120.obj"/>
			</geometry>
		</visual>
		<visual name="base_body-10">
			<origin xyz="0 0 0"/>
			<geometry>
				<mesh filename="textured_objs/original-59.obj"/>
			</geometry>
		</visual>
		<!-- <visual name="base_body-10">
			<origin xyz="0 0 0"/>
			<geometry>
				<mesh filename="textured_objs/original-5.obj"/>
			</geometry>
		</visual> -->
		<visual name="base_body-10">
			<origin xyz="0 0 0"/>
			<geometry>
				<mesh filename="textured_objs/original-77.obj"/>
			</geometry>
		</visual>
		<visual name="base_body-10">
			<origin xyz="0 0 0"/>
			<geometry>
				<mesh filename="textured_objs/original-114.obj"/>
			</geometry>
		</visual>
		<visual name="base_body-10">
			<origin xyz="0 0 0"/>
			<geometry>
				<mesh filename="textured_objs/original-54.obj"/>
			</geometry>
		</visual>
		<visual name="base_body-10">
			<origin xyz="0 0 0"/>
			<geometry>
				<mesh filename="textured_objs/original-63.obj"/>
			</geometry>
		</visual>
		<visual name="base_body-10">
			<origin xyz="0 0 0"/>
			<geometry>
				<mesh filename="textured_objs/original-87.obj"/>
			</geometry>
		</visual>
		<visual name="base_body-10">
			<origin xyz="0 0 0"/>
			<geometry>
				<mesh filename="textured_objs/original-51.obj"/>
			</geometry>
		</visual>
		<visual name="base_body-10">
			<origin xyz="0 0 0"/>
			<geometry>
				<mesh filename="textured_objs/original-55.obj"/>
			</geometry>
		</visual>
		<visual name="base_body-10">
			<origin xyz="0 0 0"/>
			<geometry>
				<mesh filename="textured_objs/original-113.obj"/>
			</geometry>
		</visual>
		<visual name="base_body-10">
			<origin xyz="0 0 0"/>
			<geometry>
				<mesh filename="textured_objs/original-50.obj"/>
			</geometry>
		</visual>
		<visual name="base_body-10">
			<origin xyz="0 0 0"/>
			<geometry>
				<mesh filename="textured_objs/original-111.obj"/>
			</geometry>
		</visual>
		<visual name="base_body-10">
			<origin xyz="0 0 0"/>
			<geometry>
				<mesh filename="textured_objs/original-6.obj"/>
			</geometry>
		</visual>
		<visual name="base_body-10">
			<origin xyz="0 0 0"/>
			<geometry>
				<mesh filename="textured_objs/original-31.obj"/>
			</geometry>
		</visual>
		<!-- <visual name="base_body-10">
			<origin xyz="0 0 0"/>
			<geometry>
				<mesh filename="textured_objs/original-48.obj"/>
			</geometry>
		</visual> -->
		<visual name="base_body-10">
			<origin xyz="0 0 0"/>
			<geometry>
				<mesh filename="textured_objs/original-15.obj"/>
			</geometry>
		</visual>
		<visual name="base_body-10">
			<origin xyz="0 0 0"/>
			<geometry>
				<mesh filename="textured_objs/original-116.obj"/>
			</geometry>
		</visual>
		<visual name="base_body-10">
			<origin xyz="0 0 0"/>
			<geometry>
				<mesh filename="textured_objs/original-85.obj"/>
			</geometry>
		</visual>
		<visual name="base_body-10">
			<origin xyz="0 0 0"/>
			<geometry>
				<mesh filename="textured_objs/original-122.obj"/>
			</geometry>
		</visual>
		<visual name="base_body-10">
			<origin xyz="0 0 0"/>
			<geometry>
				<mesh filename="textured_objs/original-56.obj"/>
			</geometry>
		</visual>
		<visual name="base_body-10">
			<origin xyz="0 0 0"/>
			<geometry>
				<mesh filename="textured_objs/original-135.obj"/>
			</geometry>
		</visual>
		<visual name="base_body-10">
			<origin xyz="0 0 0"/>
			<geometry>
				<mesh filename="textured_objs/original-76.obj"/>
			</geometry>
		</visual>
		<visual name="base_body-10">
			<origin xyz="0 0 0"/>
			<geometry>
				<mesh filename="textured_objs/original-108.obj"/>
			</geometry>
		</visual>
		<visual name="base_body-10">
			<origin xyz="0 0 0"/>
			<geometry>
				<mesh filename="textured_objs/original-99.obj"/>
			</geometry>
		</visual>
		<visual name="base_body-10">
			<origin xyz="0 0 0"/>
			<geometry>
				<mesh filename="textured_objs/original-136.obj"/>
			</geometry>
		</visual>
		<visual name="base_body-10">
			<origin xyz="0 0 0"/>
			<geometry>
				<mesh filename="textured_objs/original-127.obj"/>
			</geometry>
		</visual>
		<visual name="base_body-10">
			<origin xyz="0 0 0"/>
			<geometry>
				<mesh filename="textured_objs/original-62.obj"/>
			</geometry>
		</visual>
		<visual name="base_body-10">
			<origin xyz="0 0 0"/>
			<geometry>
				<mesh filename="textured_objs/original-75.obj"/>
			</geometry>
		</visual>
		<visual name="base_body-10">
			<origin xyz="0 0 0"/>
			<geometry>
				<mesh filename="textured_objs/original-133.obj"/>
			</geometry>
		</visual>
		<!-- <visual name="base_body-10">
			<origin xyz="0 0 0"/>
			<geometry>
				<mesh filename="textured_objs/original-66.obj"/>
			</geometry>
		</visual> -->
		<visual name="base_body-10">
			<origin xyz="0 0 0"/>
			<geometry>
				<mesh filename="textured_objs/original-58.obj"/>
			</geometry>
		</visual>
		<visual name="base_body-10">
			<origin xyz="0 0 0"/>
			<geometry>
				<mesh filename="textured_objs/original-98.obj"/>
			</geometry>
		</visual>
		<visual name="base_body-10">
			<origin xyz="0 0 0"/>
			<geometry>
				<mesh filename="textured_objs/original-69.obj"/>
			</geometry>
		</visual>
		<visual name="base_body-10">
			<origin xyz="0 0 0"/>
			<geometry>
				<mesh filename="textured_objs/original-11.obj"/>
			</geometry>
		</visual>
		<visual name="base_body-10">
			<origin xyz="0 0 0"/>
			<geometry>
				<mesh filename="textured_objs/original-131.obj"/>
			</geometry>
		</visual>
		<visual name="base_body-10">
			<origin xyz="0 0 0"/>
			<geometry>
				<mesh filename="textured_objs/original-80.obj"/>
			</geometry>
		</visual>
		<visual name="base_body-10">
			<origin xyz="0 0 0"/>
			<geometry>
				<mesh filename="textured_objs/original-91.obj"/>
			</geometry>
		</visual>
		<visual name="base_body-10">
			<origin xyz="0 0 0"/>
			<geometry>
				<mesh filename="textured_objs/original-25.obj"/>
			</geometry>
		</visual>
		<visual name="base_body-10">
			<origin xyz="0 0 0"/>
			<geometry>
				<mesh filename="textured_objs/original-17.obj"/>
			</geometry>
		</visual>
		<visual name="base_body-10">
			<origin xyz="0 0 0"/>
			<geometry>
				<mesh filename="textured_objs/original-12.obj"/>
			</geometry>
		</visual>
		<visual name="base_body-10">
			<origin xyz="0 0 0"/>
			<geometry>
				<mesh filename="textured_objs/original-92.obj"/>
			</geometry>
		</visual>
		<visual name="base_body-10">
			<origin xyz="0 0 0"/>
			<geometry>
				<mesh filename="textured_objs/original-42.obj"/>
			</geometry>
		</visual>
		<visual name="base_body-10">
			<origin xyz="0 0 0"/>
			<geometry>
				<mesh filename="textured_objs/original-79.obj"/>
			</geometry>
		</visual>
		<visual name="base_body-10">
			<origin xyz="0 0 0"/>
			<geometry>
				<mesh filename="textured_objs/original-102.obj"/>
			</geometry>
		</visual>
		<visual name="base_body-10">
			<origin xyz="0 0 0"/>
			<geometry>
				<mesh filename="textured_objs/original-24.obj"/>
			</geometry>
		</visual>
		<visual name="base_body-10">
			<origin xyz="0 0 0"/>
			<geometry>
				<mesh filename="textured_objs/original-88.obj"/>
			</geometry>
		</visual>
		<visual name="base_body-10">
			<origin xyz="0 0 0"/>
			<geometry>
				<mesh filename="textured_objs/original-115.obj"/>
			</geometry>
		</visual>
		<visual name="base_body-10">
			<origin xyz="0 0 0"/>
			<geometry>
				<mesh filename="textured_objs/original-95.obj"/>
			</geometry>
		</visual>
		<visual name="base_body-10">
			<origin xyz="0 0 0"/>
			<geometry>
				<mesh filename="textured_objs/original-53.obj"/>
			</geometry>
		</visual>
		<!-- <visual name="base_body-10">
			<origin xyz="0 0 0"/>
			<geometry>
				<mesh filename="textured_objs/original-7.obj"/>
			</geometry>
		</visual> -->
		<visual name="base_body-10">
			<origin xyz="0 0 0"/>
			<geometry>
				<mesh filename="textured_objs/original-105.obj"/>
			</geometry>
		</visual>
		<visual name="base_body-10">
			<origin xyz="0 0 0"/>
			<geometry>
				<mesh filename="textured_objs/original-101.obj"/>
			</geometry>
		</visual>
		<visual name="base_body-10">
			<origin xyz="0 0 0"/>
			<geometry>
				<mesh filename="textured_objs/original-81.obj"/>
			</geometry>
		</visual>
		<visual name="base_body-10">
			<origin xyz="0 0 0"/>
			<geometry>
				<mesh filename="textured_objs/original-84.obj"/>
			</geometry>
		</visual>
		<visual name="base_body-10">
			<origin xyz="0 0 0"/>
			<geometry>
				<mesh filename="textured_objs/original-121.obj"/>
			</geometry>
		</visual>
		<visual name="base_body-10">
			<origin xyz="0 0 0"/>
			<geometry>
				<mesh filename="textured_objs/original-94.obj"/>
			</geometry>
		</visual>
		<visual name="base_body-10">
			<origin xyz="0 0 0"/>
			<geometry>
				<mesh filename="textured_objs/original-78.obj"/>
			</geometry>
		</visual>
		<visual name="base_body-10">
			<origin xyz="0 0 0"/>
			<geometry>
				<mesh filename="textured_objs/original-97.obj"/>
			</geometry>
		</visual>
		<visual name="base_body-10">
			<origin xyz="0 0 0"/>
			<geometry>
				<mesh filename="textured_objs/original-89.obj"/>
			</geometry>
		</visual>
		<!-- <visual name="base_body-10">
			<origin xyz="0 0 0"/>
			<geometry>
				<mesh filename="textured_objs/original-10.obj"/>
			</geometry>
		</visual> -->
		<visual name="base_body-10">
			<origin xyz="0 0 0"/>
			<geometry>
				<mesh filename="textured_objs/original-14.obj"/>
			</geometry>
		</visual>
		<visual name="base_body-10">
			<origin xyz="0 0 0"/>
			<geometry>
				<mesh filename="textured_objs/original-82.obj"/>
			</geometry>
		</visual>
		<visual name="base_body-10">
			<origin xyz="0 0 0"/>
			<geometry>
				<mesh filename="textured_objs/original-60.obj"/>
			</geometry>
		</visual>
		<visual name="base_body-10">
			<origin xyz="0 0 0"/>
			<geometry>
				<mesh filename="textured_objs/original-19.obj"/>
			</geometry>
		</visual>
		<visual name="base_body-10">
			<origin xyz="0 0 0"/>
			<geometry>
				<mesh filename="textured_objs/original-90.obj"/>
			</geometry>
		</visual>
		<visual name="base_body-10">
			<origin xyz="0 0 0"/>
			<geometry>
				<mesh filename="textured_objs/original-40.obj"/>
			</geometry>
		</visual>
		<visual name="base_body-10">
			<origin xyz="0 0 0"/>
			<geometry>
				<mesh filename="textured_objs/original-57.obj"/>
			</geometry>
		</visual>
		<collision>
			<origin xyz="0 0 0"/>
			<geometry>
				<mesh filename="textured_objs/original-29.obj"/>
			</geometry>
		</collision>
		<collision>
			<origin xyz="0 0 0"/>
			<geometry>
				<mesh filename="textured_objs/original-103.obj"/>
			</geometry>
		</collision>
		<collision>
			<origin xyz="0 0 0"/>
			<geometry>
				<mesh filename="textured_objs/original-100.obj"/>
			</geometry>
		</collision>
		<!-- <collision>
			<origin xyz="0 0 0"/>
			<geometry>
				<mesh filename="textured_objs/original-21.obj"/>
			</geometry>
		</collision> -->
		<collision>
			<origin xyz="0 0 0"/>
			<geometry>
				<mesh filename="textured_objs/original-132.obj"/>
			</geometry>
		</collision>
		<collision>
			<origin xyz="0 0 0"/>
			<geometry>
				<mesh filename="textured_objs/original-36.obj"/>
			</geometry>
		</collision>
		<collision>
			<origin xyz="0 0 0"/>
			<geometry>
				<mesh filename="textured_objs/original-126.obj"/>
			</geometry>
		</collision>
		<collision>
			<origin xyz="0 0 0"/>
			<geometry>
				<mesh filename="textured_objs/original-41.obj"/>
			</geometry>
		</collision>
		<collision>
			<origin xyz="0 0 0"/>
			<geometry>
				<mesh filename="textured_objs/original-28.obj"/>
			</geometry>
		</collision>
		<collision>
			<origin xyz="0 0 0"/>
			<geometry>
				<mesh filename="textured_objs/original-96.obj"/>
			</geometry>
		</collision>
		<collision>
			<origin xyz="0 0 0"/>
			<geometry>
				<mesh filename="textured_objs/original-64.obj"/>
			</geometry>
		</collision>
		<collision>
			<origin xyz="0 0 0"/>
			<geometry>
				<mesh filename="textured_objs/original-134.obj"/>
			</geometry>
		</collision>
		<collision>
			<origin xyz="0 0 0"/>
			<geometry>
				<mesh filename="textured_objs/original-43.obj"/>
			</geometry>
		</collision>
		<collision>
			<origin xyz="0 0 0"/>
			<geometry>
				<mesh filename="textured_objs/original-52.obj"/>
			</geometry>
		</collision>
		<collision>
			<origin xyz="0 0 0"/>
			<geometry>
				<mesh filename="textured_objs/original-83.obj"/>
			</geometry>
		</collision>
		<!-- <collision>
			<origin xyz="0 0 0"/>
			<geometry>
				<mesh filename="textured_objs/original-26.obj"/>
			</geometry>
		</collision> -->
		<collision>
			<origin xyz="0 0 0"/>
			<geometry>
				<mesh filename="textured_objs/original-117.obj"/>
			</geometry>
		</collision>
		<collision>
			<origin xyz="0 0 0"/>
			<geometry>
				<mesh filename="textured_objs/original-110.obj"/>
			</geometry>
		</collision>
		<collision>
			<origin xyz="0 0 0"/>
			<geometry>
				<mesh filename="textured_objs/original-107.obj"/>
			</geometry>
		</collision>
		<collision>
			<origin xyz="0 0 0"/>
			<geometry>
				<mesh filename="textured_objs/original-104.obj"/>
			</geometry>
		</collision>
		<!-- <collision>
			<origin xyz="0 0 0"/>
			<geometry>
				<mesh filename="textured_objs/original-4.obj"/>
			</geometry>
		</collision> -->
		<!-- <collision>
			<origin xyz="0 0 0"/>
			<geometry>
				<mesh filename="textured_objs/original-3.obj"/>
			</geometry>
		</collision> -->
		<collision>
			<origin xyz="0 0 0"/>
			<geometry>
				<mesh filename="textured_objs/original-128.obj"/>
			</geometry>
		</collision>
		<collision>
			<origin xyz="0 0 0"/>
			<geometry>
				<mesh filename="textured_objs/original-65.obj"/>
			</geometry>
		</collision>
		<!-- <collision>
			<origin xyz="0 0 0"/>
			<geometry>
				<mesh filename="textured_objs/original-2.obj"/>
			</geometry>
		</collision> -->
		<collision>
			<origin xyz="0 0 0"/>
			<geometry>
				<mesh filename="textured_objs/original-130.obj"/>
			</geometry>
		</collision>
		<collision>
			<origin xyz="0 0 0"/>
			<geometry>
				<mesh filename="textured_objs/original-137.obj"/>
			</geometry>
		</collision>
		<collision>
			<origin xyz="0 0 0"/>
			<geometry>
				<mesh filename="textured_objs/original-139.obj"/>
			</geometry>
		</collision>
		<collision>
			<origin xyz="0 0 0"/>
			<geometry>
				<mesh filename="textured_objs/original-44.obj"/>
			</geometry>
		</collision>
		<collision>
			<origin xyz="0 0 0"/>
			<geometry>
				<mesh filename="textured_objs/original-106.obj"/>
			</geometry>
		</collision>
		<collision>
			<origin xyz="0 0 0"/>
			<geometry>
				<mesh filename="textured_objs/original-16.obj"/>
			</geometry>
		</collision>
		<collision>
			<origin xyz="0 0 0"/>
			<geometry>
				<mesh filename="textured_objs/original-86.obj"/>
			</geometry>
		</collision>
		<collision>
			<origin xyz="0 0 0"/>
			<geometry>
				<mesh filename="textured_objs/original-8.obj"/>
			</geometry>
		</collision>
		<collision>
			<origin xyz="0 0 0"/>
			<geometry>
				<mesh filename="textured_objs/original-109.obj"/>
			</geometry>
		</collision>
		<collision>
			<origin xyz="0 0 0"/>
			<geometry>
				<mesh filename="textured_objs/original-13.obj"/>
			</geometry>
		</collision>
		<collision>
			<origin xyz="0 0 0"/>
			<geometry>
				<mesh filename="textured_objs/original-45.obj"/>
			</geometry>
		</collision>
		<collision>
			<origin xyz="0 0 0"/>
			<geometry>
				<mesh filename="textured_objs/original-35.obj"/>
			</geometry>
		</collision>
		<collision>
			<origin xyz="0 0 0"/>
			<geometry>
				<mesh filename="textured_objs/original-138.obj"/>
			</geometry>
		</collision>
		<!-- <collision>
			<origin xyz="0 0 0"/>
			<geometry>
				<mesh filename="textured_objs/original-49.obj"/>
			</geometry>
		</collision> -->
		<collision>
			<origin xyz="0 0 0"/>
			<geometry>
				<mesh filename="textured_objs/original-93.obj"/>
			</geometry>
		</collision>
		<collision>
			<origin xyz="0 0 0"/>
			<geometry>
				<mesh filename="textured_objs/original-61.obj"/>
			</geometry>
		</collision>
		<collision>
			<origin xyz="0 0 0"/>
			<geometry>
				<mesh filename="textured_objs/original-39.obj"/>
			</geometry>
		</collision>
		<collision>
			<origin xyz="0 0 0"/>
			<geometry>
				<mesh filename="textured_objs/original-120.obj"/>
			</geometry>
		</collision>
		<collision>
			<origin xyz="0 0 0"/>
			<geometry>
				<mesh filename="textured_objs/original-59.obj"/>
			</geometry>
		</collision>
		<!-- <collision>
			<origin xyz="0 0 0"/>
			<geometry>
				<mesh filename="textured_objs/original-5.obj"/>
			</geometry>
		</collision> -->
		<collision>
			<origin xyz="0 0 0"/>
			<geometry>
				<mesh filename="textured_objs/original-77.obj"/>
			</geometry>
		</collision>
		<collision>
			<origin xyz="0 0 0"/>
			<geometry>
				<mesh filename="textured_objs/original-114.obj"/>
			</geometry>
		</collision>
		<collision>
			<origin xyz="0 0 0"/>
			<geometry>
				<mesh filename="textured_objs/original-54.obj"/>
			</geometry>
		</collision>
		<collision>
			<origin xyz="0 0 0"/>
			<geometry>
				<mesh filename="textured_objs/original-63.obj"/>
			</geometry>
		</collision>
		<collision>
			<origin xyz="0 0 0"/>
			<geometry>
				<mesh filename="textured_objs/original-87.obj"/>
			</geometry>
		</collision>
		<collision>
			<origin xyz="0 0 0"/>
			<geometry>
				<mesh filename="textured_objs/original-51.obj"/>
			</geometry>
		</collision>
		<collision>
			<origin xyz="0 0 0"/>
			<geometry>
				<mesh filename="textured_objs/original-55.obj"/>
			</geometry>
		</collision>
		<collision>
			<origin xyz="0 0 0"/>
			<geometry>
				<mesh filename="textured_objs/original-113.obj"/>
			</geometry>
		</collision>
		<collision>
			<origin xyz="0 0 0"/>
			<geometry>
				<mesh filename="textured_objs/original-50.obj"/>
			</geometry>
		</collision>
		<collision>
			<origin xyz="0 0 0"/>
			<geometry>
				<mesh filename="textured_objs/original-111.obj"/>
			</geometry>
		</collision>
		<collision>
			<origin xyz="0 0 0"/>
			<geometry>
				<mesh filename="textured_objs/original-6.obj"/>
			</geometry>
		</collision>
		<collision>
			<origin xyz="0 0 0"/>
			<geometry>
				<mesh filename="textured_objs/original-31.obj"/>
			</geometry>
		</collision>
		<!-- <collision>
			<origin xyz="0 0 0"/>
			<geometry>
				<mesh filename="textured_objs/original-48.obj"/>
			</geometry>
		</collision> -->
		<collision>
			<origin xyz="0 0 0"/>
			<geometry>
				<mesh filename="textured_objs/original-15.obj"/>
			</geometry>
		</collision>
		<collision>
			<origin xyz="0 0 0"/>
			<geometry>
				<mesh filename="textured_objs/original-116.obj"/>
			</geometry>
		</collision>
		<collision>
			<origin xyz="0 0 0"/>
			<geometry>
				<mesh filename="textured_objs/original-85.obj"/>
			</geometry>
		</collision>
		<collision>
			<origin xyz="0 0 0"/>
			<geometry>
				<mesh filename="textured_objs/original-122.obj"/>
			</geometry>
		</collision>
		<collision>
			<origin xyz="0 0 0"/>
			<geometry>
				<mesh filename="textured_objs/original-56.obj"/>
			</geometry>
		</collision>
		<collision>
			<origin xyz="0 0 0"/>
			<geometry>
				<mesh filename="textured_objs/original-135.obj"/>
			</geometry>
		</collision>
		<collision>
			<origin xyz="0 0 0"/>
			<geometry>
				<mesh filename="textured_objs/original-76.obj"/>
			</geometry>
		</collision>
		<collision>
			<origin xyz="0 0 0"/>
			<geometry>
				<mesh filename="textured_objs/original-108.obj"/>
			</geometry>
		</collision>
		<collision>
			<origin xyz="0 0 0"/>
			<geometry>
				<mesh filename="textured_objs/original-99.obj"/>
			</geometry>
		</collision>
		<collision>
			<origin xyz="0 0 0"/>
			<geometry>
				<mesh filename="textured_objs/original-136.obj"/>
			</geometry>
		</collision>
		<collision>
			<origin xyz="0 0 0"/>
			<geometry>
				<mesh filename="textured_objs/original-127.obj"/>
			</geometry>
		</collision>
		<collision>
			<origin xyz="0 0 0"/>
			<geometry>
				<mesh filename="textured_objs/original-62.obj"/>
			</geometry>
		</collision>
		<collision>
			<origin xyz="0 0 0"/>
			<geometry>
				<mesh filename="textured_objs/original-75.obj"/>
			</geometry>
		</collision>
		<collision>
			<origin xyz="0 0 0"/>
			<geometry>
				<mesh filename="textured_objs/original-133.obj"/>
			</geometry>
		</collision>
		<!-- <collision>
			<origin xyz="0 0 0"/>
			<geometry>
				<mesh filename="textured_objs/original-66.obj"/>
			</geometry>
		</collision> -->
		<collision>
			<origin xyz="0 0 0"/>
			<geometry>
				<mesh filename="textured_objs/original-58.obj"/>
			</geometry>
		</collision>
		<collision>
			<origin xyz="0 0 0"/>
			<geometry>
				<mesh filename="textured_objs/original-98.obj"/>
			</geometry>
		</collision>
		<collision>
			<origin xyz="0 0 0"/>
			<geometry>
				<mesh filename="textured_objs/original-69.obj"/>
			</geometry>
		</collision>
		<collision>
			<origin xyz="0 0 0"/>
			<geometry>
				<mesh filename="textured_objs/original-11.obj"/>
			</geometry>
		</collision>
		<collision>
			<origin xyz="0 0 0"/>
			<geometry>
				<mesh filename="textured_objs/original-131.obj"/>
			</geometry>
		</collision>
		<collision>
			<origin xyz="0 0 0"/>
			<geometry>
				<mesh filename="textured_objs/original-80.obj"/>
			</geometry>
		</collision>
		<collision>
			<origin xyz="0 0 0"/>
			<geometry>
				<mesh filename="textured_objs/original-91.obj"/>
			</geometry>
		</collision>
		<collision>
			<origin xyz="0 0 0"/>
			<geometry>
				<mesh filename="textured_objs/original-25.obj"/>
			</geometry>
		</collision>
		<collision>
			<origin xyz="0 0 0"/>
			<geometry>
				<mesh filename="textured_objs/original-17.obj"/>
			</geometry>
		</collision>
		<collision>
			<origin xyz="0 0 0"/>
			<geometry>
				<mesh filename="textured_objs/original-12.obj"/>
			</geometry>
		</collision>
		<collision>
			<origin xyz="0 0 0"/>
			<geometry>
				<mesh filename="textured_objs/original-92.obj"/>
			</geometry>
		</collision>
		<collision>
			<origin xyz="0 0 0"/>
			<geometry>
				<mesh filename="textured_objs/original-42.obj"/>
			</geometry>
		</collision>
		<collision>
			<origin xyz="0 0 0"/>
			<geometry>
				<mesh filename="textured_objs/original-79.obj"/>
			</geometry>
		</collision>
		<collision>
			<origin xyz="0 0 0"/>
			<geometry>
				<mesh filename="textured_objs/original-102.obj"/>
			</geometry>
		</collision>
		<collision>
			<origin xyz="0 0 0"/>
			<geometry>
				<mesh filename="textured_objs/original-24.obj"/>
			</geometry>
		</collision>
		<collision>
			<origin xyz="0 0 0"/>
			<geometry>
				<mesh filename="textured_objs/original-88.obj"/>
			</geometry>
		</collision>
		<collision>
			<origin xyz="0 0 0"/>
			<geometry>
				<mesh filename="textured_objs/original-115.obj"/>
			</geometry>
		</collision>
		<collision>
			<origin xyz="0 0 0"/>
			<geometry>
				<mesh filename="textured_objs/original-95.obj"/>
			</geometry>
		</collision>
		<collision>
			<origin xyz="0 0 0"/>
			<geometry>
				<mesh filename="textured_objs/original-53.obj"/>
			</geometry>
		</collision>
		<!-- <collision>
			<origin xyz="0 0 0"/>
			<geometry>
				<mesh filename="textured_objs/original-7.obj"/>
			</geometry>
		</collision> -->
		<collision>
			<origin xyz="0 0 0"/>
			<geometry>
				<mesh filename="textured_objs/original-105.obj"/>
			</geometry>
		</collision>
		<collision>
			<origin xyz="0 0 0"/>
			<geometry>
				<mesh filename="textured_objs/original-101.obj"/>
			</geometry>
		</collision>
		<collision>
			<origin xyz="0 0 0"/>
			<geometry>
				<mesh filename="textured_objs/original-81.obj"/>
			</geometry>
		</collision>
		<collision>
			<origin xyz="0 0 0"/>
			<geometry>
				<mesh filename="textured_objs/original-84.obj"/>
			</geometry>
		</collision>
		<collision>
			<origin xyz="0 0 0"/>
			<geometry>
				<mesh filename="textured_objs/original-121.obj"/>
			</geometry>
		</collision>
		<collision>
			<origin xyz="0 0 0"/>
			<geometry>
				<mesh filename="textured_objs/original-94.obj"/>
			</geometry>
		</collision>
		<collision>
			<origin xyz="0 0 0"/>
			<geometry>
				<mesh filename="textured_objs/original-78.obj"/>
			</geometry>
		</collision>
		<collision>
			<origin xyz="0 0 0"/>
			<geometry>
				<mesh filename="textured_objs/original-97.obj"/>
			</geometry>
		</collision>
		<collision>
			<origin xyz="0 0 0"/>
			<geometry>
				<mesh filename="textured_objs/original-89.obj"/>
			</geometry>
		</collision>
		<!-- <collision>
			<origin xyz="0 0 0"/>
			<geometry>
				<mesh filename="textured_objs/original-10.obj"/>
			</geometry>
		</collision> -->
		<collision>
			<origin xyz="0 0 0"/>
			<geometry>
				<mesh filename="textured_objs/original-14.obj"/>
			</geometry>
		</collision>
		<collision>
			<origin xyz="0 0 0"/>
			<geometry>
				<mesh filename="textured_objs/original-82.obj"/>
			</geometry>
		</collision>
		<collision>
			<origin xyz="0 0 0"/>
			<geometry>
				<mesh filename="textured_objs/original-60.obj"/>
			</geometry>
		</collision>
		<collision>
			<origin xyz="0 0 0"/>
			<geometry>
				<mesh filename="textured_objs/original-19.obj"/>
			</geometry>
		</collision>
		<collision>
			<origin xyz="0 0 0"/>
			<geometry>
				<mesh filename="textured_objs/original-90.obj"/>
			</geometry>
		</collision>
		<collision>
			<origin xyz="0 0 0"/>
			<geometry>
				<mesh filename="textured_objs/original-40.obj"/>
			</geometry>
		</collision>
		<collision>
			<origin xyz="0 0 0"/>
			<geometry>
				<mesh filename="textured_objs/original-57.obj"/>
			</geometry>
		</collision>
	</link>
	<joint name="joint_9" type="fixed">
		<origin rpy="1.570796326794897 0 -1.500796326794897" xyz="0 0 0"/>
		<child link="link_9"/>
		<parent link="base"/>
	</joint>

	<joint name="joint_9b" type="fixed">
		<origin xyz="0 0 0"/>
		<axis xyz="0 0 0"/>
		<child link="link_9b"/>
		<parent link="link_9"/>
	</joint>
	<link name="link_9b">
		<visual name="base_body-10">
			<origin xyz="0 0 0"/>
			<geometry>
				<mesh filename="textured_objs/original-2.obj"/>
			</geometry>
		</visual>
		<visual name="base_body-10">
			<origin xyz="0 0 0"/>
			<geometry>
				<mesh filename="textured_objs/original-3.obj"/>
			</geometry>
		</visual>
		<visual name="base_body-10">
			<origin xyz="0 0 0"/>
			<geometry>
				<mesh filename="textured_objs/original-4.obj"/>
			</geometry>
		</visual>
		<visual name="base_body-10">
			<origin xyz="0 0 0"/>
			<geometry>
				<mesh filename="textured_objs/original-5.obj"/>
			</geometry>
		</visual>
		<visual name="base_body-10">
			<origin xyz="0 0 0"/>
			<geometry>
				<mesh filename="textured_objs/original-21.obj"/>
			</geometry>
		</visual>
		<visual name="base_body-10">
			<origin xyz="0 0 0"/>
			<geometry>
				<mesh filename="textured_objs/original-7.obj"/>
			</geometry>
		</visual>
		<visual name="base_body-10">
			<origin xyz="0 0 0"/>
			<geometry>
				<mesh filename="textured_objs/original-10.obj"/>
			</geometry>
		</visual>
		<visual name="base_body-10">
			<origin xyz="0 0 0"/>
			<geometry>
				<mesh filename="textured_objs/original-26.obj"/>
			</geometry>
		</visual>
		<visual name="base_body-10-48">
			<origin xyz="0 0 0"/>
			<geometry>
				<mesh filename="textured_objs/original-48.obj"/>
			</geometry>
		</visual>
		<visual name="base_body-10">
			<origin xyz="0 0 0"/>
			<geometry>
				<mesh filename="textured_objs/original-49.obj"/>
			</geometry>
		</visual>
		<visual name="base_body-10-48">
			<origin xyz="0 0 0"/>
			<geometry>
				<mesh filename="textured_objs/original-66.obj"/>
			</geometry>
		</visual>

		<collision>
			<origin xyz="0 0 0"/>
			<geometry>
				<mesh filename="textured_objs/original-2.obj"/>
			</geometry>
		</collision>
		<collision>
			<origin xyz="0 0 0"/>
			<geometry>
				<mesh filename="textured_objs/original-3.obj"/>
			</geometry>
		</collision>
		<collision>
			<origin xyz="0 0 0"/>
			<geometry>
				<mesh filename="textured_objs/original-4.obj"/>
			</geometry>
		</collision>
		<collision>
			<origin xyz="0 0 0"/>
			<geometry>
				<mesh filename="textured_objs/original-5.obj"/>
			</geometry>
		</collision>
		<collision>
			<origin xyz="0 0 0"/>
			<geometry>
				<mesh filename="textured_objs/original-21.obj"/>
			</geometry>
		</collision>
		<collision>
			<origin xyz="0 0 0"/>
			<geometry>
				<mesh filename="textured_objs/original-7.obj"/>
			</geometry>
		</collision>
		<collision>
			<origin xyz="0 0 0"/>
			<geometry>
				<mesh filename="textured_objs/original-10.obj"/>
			</geometry>
		</collision>
		<collision>
			<origin xyz="0 0 0"/>
			<geometry>
				<mesh filename="textured_objs/original-26.obj"/>
			</geometry>
		</collision>
		<collision name="base_body-10">
			<origin xyz="0 0 0"/>
			<geometry>
				<mesh filename="textured_objs/original-48.obj"/>
			</geometry>
		</collision>
		<collision>
			<origin xyz="0 0 0"/>
			<geometry>
				<mesh filename="textured_objs/original-49.obj"/>
			</geometry>
		</collision>
		<collision name="base_body-10">
			<origin xyz="0 0 0"/>
			<geometry>
				<mesh filename="textured_objs/original-66.obj"/>
			</geometry>
		</collision>
	</link>

</robot>
