<?xml version="1.0"?>
<robot xmlns:xacro="http://ros.org/wiki/xacro">
  <xacro:include filename="$(find dh_robotics_ag95_model)/urdf/dh_robotics_ag95_transmission.xacro" />

  <xacro:macro name="crank" params="prefix fingerprefix stroke">
    <link name="${prefix}${fingerprefix}_crank">
      <inertial>
        <origin xyz="-0.000200000000003065 0.0199435877845359 0.0292245259211331" rpy="0 0 0" />
        <mass value="0.00853198276973456" />
        <inertia ixx="2.89328108496468E-06" ixy="-1.57935047237397E-19" ixz="-1.93980378593255E-19" iyy="1.86719750325683E-06" iyz="-1.21858577871576E-06" izz="1.21905238907251E-06" />
        </inertial> 
      <visual>
        <origin xyz="0 0 0" rpy="0 0 0" />
        <geometry>
          <mesh filename="package://dh_robotics_ag95_model/meshes/link_crank.STL" scale="1 1 1"/>
        </geometry>
        <material name="">
          <color rgba="0.1 0.1 0.1 1" />
        </material>
      </visual>
      <collision>
        <origin xyz="0 0 0" rpy="0 0 0" />
        <geometry>
          <mesh filename="package://dh_robotics_ag95_model/meshes/link_crank.STL" scale="1 1 1"/>
        </geometry>
      </collision>
    </link>
  </xacro:macro>

  <xacro:macro name="rod" params="prefix fingerprefix stroke">
    <link name="${prefix}${fingerprefix}_rod">
      <inertial>
        <origin xyz="0.00030115855001899 0.0373907951953854 -0.0208027427000385" rpy="0 0 0" />
        <mass value="0.022614240507152" />
        <inertia ixx="1.52518312458174E-05" ixy="9.76583423954399E-10" ixz="-5.43838577022588E-10" iyy="6.17694243867776E-06" iyz="6.78636130740228E-06" izz="1.16494917907219E-05" />
        </inertial> 
      <visual>
        <origin xyz="0 0 0" rpy="0 0 0" />
        <geometry>
          <mesh filename="package://dh_robotics_ag95_model/meshes/link_rod.STL" scale="1 1 1"/>
        </geometry>
        <material name="">
          <color rgba="0.1 0.1 0.1 1" />
        </material>
      </visual>
      <collision>
        <origin xyz="0 0 0" rpy="0 0 0" />
        <geometry>
          <mesh filename="package://dh_robotics_ag95_model/meshes/link_rod.STL" scale="1 1 1"/>
        </geometry>
      </collision>
    </link>
  </xacro:macro>

  <xacro:macro name="proximal_phalanx" params="prefix fingerprefix stroke">
    <link name="${prefix}${fingerprefix}_proximal_phalanx">
      <inertial>
        <origin xyz="0.000123011831763771 0.0507850843201817 0.00103968640075166" rpy="0 0 0" />
       <mass value="0.0271177346495152" />
        <inertia ixx="2.61910379223783E-05" ixy="-2.43616858946494E-07" ixz="-6.37789906117123E-09" iyy="2.8270243746167E-06" iyz="-5.37200748039765E-07" izz="2.83695868220296E-05" />
        </inertial> 
      <visual>
        <origin xyz="0 0 0" rpy="0 0 0" />
        <geometry>
          <mesh filename="package://dh_robotics_ag95_model/meshes/link_proximal_phalanx.STL" scale="1 1 1"/>
        </geometry>
        <material name="">
          <color rgba="0.1 0.1 0.1 1" />
        </material>
      </visual>
      <collision>
        <origin xyz="0 0 0" rpy="0 0 0" />
        <geometry>
          <mesh filename="package://dh_robotics_ag95_model/meshes/link_proximal_phalanx.STL" scale="1 1 1"/>
        </geometry>
      </collision>
    </link>
  </xacro:macro>

  <xacro:macro name="distal_phalanx" params="prefix fingerprefix stroke">
    <link name="${prefix}${fingerprefix}_distal_phalanx">
     <inertial>
        <origin xyz="0.000299999999999317 0.0160078233491243 -0.0136945669206257" rpy="0 0 0" />
        <mass value="0.0104003125914103" />
        <inertia ixx="2.71909453810972E-06" ixy="1.35402465472579E-21" ixz="-7.1817349065269E-22" iyy="7.69100314106116E-07" iyz="6.74715432769696E-07" izz="2.30315190420171E-06" />
        </inertial> 
      <visual>
        <origin xyz="0 0 0" rpy="0 0 0" />
        <geometry>
          <mesh filename="package://dh_robotics_ag95_model/meshes/link_distal_phalanx.STL" scale="1 1 1"/>
        </geometry>
        <material name="">
          <color rgba="0.792156862745098 0.819607843137255 0.933333333333333 1" />
        </material>
      </visual>
      <collision>
        <origin xyz="0 0 0" rpy="0 0 0" />
        <geometry>
           <mesh filename="package://dh_robotics_ag95_model/meshes/link_distal_phalanx.STL" scale="1 1 1"/>
        </geometry>
      </collision>
    </link>
  </xacro:macro>


  <xacro:macro name="rod_joint" params="prefix fingerprefix">
    <joint name="${prefix}${fingerprefix}_rod_joint" type="revolute">
        <origin xyz="0 0.037 0" rpy="0.29795 0 0" />
      <parent link="${prefix}${fingerprefix}_crank" />
      <child link="${prefix}${fingerprefix}_rod" />
      <axis xyz="1 0 0" />
      <limit lower="-1" upper="0" velocity="1.0" effort="1000" />
      <mimic joint="${prefix}finger_joint" multiplier="0.4563942" offset="0" />
    </joint>
  </xacro:macro>

  <xacro:macro name="proximal_phalanx_joint" params="prefix fingerprefix reflect">
    <joint name="${prefix}${fingerprefix}_proximal_phalanx_joint" type="revolute">
      <origin xyz="0 ${reflect * -0.016} 0.10586" rpy="-0.801 0 ${(1 + reflect) * pi / 2}"/>-->
      <parent link="${prefix}dh_robotics_ag95_base_link" />
      <child link="${prefix}${fingerprefix}_proximal_phalanx" />
      <axis xyz="1 0 0" />
      <limit lower="0" upper="0.8757" velocity="1.0" effort="1000" />
      <mimic joint="${prefix}finger_joint" multiplier="1.451855" offset="0" />
    </joint>
  </xacro:macro>

  <xacro:macro name="distal_phalanx_joint" params="prefix fingerprefix">
    <joint name="${prefix}${fingerprefix}_distal_phalanx_joint" type="revolute">
      <origin xyz="0 0 0.06083" rpy="0.0132645 0 0" />
      <parent link="${prefix}${fingerprefix}_rod" />
      <child link="${prefix}${fingerprefix}_distal_phalanx" />
      <axis xyz="1 0 0" />
      <limit lower="-1" upper="0" velocity="1.0" effort="1000" />
      <mimic joint="${prefix}finger_joint" multiplier="-1.4563851" offset="0" />
    </joint>
  </xacro:macro>


  <xacro:include filename="$(find dh_robotics_ag95_model)/urdf/dh_robotics_ag95.xacro" />

  <xacro:macro name="finger_joint" params="prefix">
    <joint name="${prefix}finger_joint" type="revolute">
      <origin xyz="0 0.016 0.10586 " rpy="-0.6523  0 0 " />
      <parent link="${prefix}dh_robotics_ag95_base_link" />
      <child link="${prefix}left_crank" />
      <axis xyz="1 0 0" />
      <limit lower="0" upper="0.6524" velocity="1.0" effort="1000" />
    </joint>
    <xacro:finger_joints prefix="${prefix}" fingerprefix="left" reflect="-1.0"/>
  </xacro:macro>

  <xacro:macro name="right_crank_joint" params="prefix">
    <joint name="${prefix}right_crank_joint" type="revolute">
      <origin xyz="0 -0.016 0.10586 " rpy="-0.6523  0 ${pi} " />
      <parent link="${prefix}dh_robotics_ag95_base_link" />
      <child link="${prefix}right_crank" />
      <axis xyz="1 0 0" />
      <limit lower="0" upper="0.6524" velocity="1.0" effort="1000" />
      <mimic joint="${prefix}finger_joint" multiplier="1" offset="0" />
    </joint>
    <xacro:finger_joints prefix="${prefix}" fingerprefix="right" reflect="1.0"/>
  </xacro:macro>
  

  <!-- Initialization of all joints and links -->
  <xacro:macro name="dh_robotics_ag95_model" params="prefix">
    <xacro:dh_robotics_ag95_base_link prefix="${prefix}"/>
    <xacro:finger_links prefix="${prefix}" fingerprefix="left" stroke="0"/>
    <xacro:finger_links prefix="${prefix}" fingerprefix="right" stroke="0"/>
    <xacro:finger_joint prefix="${prefix}" />
    <xacro:right_crank_joint prefix="${prefix}"/>
    <xacro:dh_robotics_ag95_transmission prefix="${prefix}"/>
  </xacro:macro>
</robot>
