<?xml version="1.0" ?>
<!-- =================================================================================== -->
<!-- |    This document was autogenerated by xacro from /home/test/realman_ws/src/rm_scr_robot/rm_scr_description/urdf/rm_scr_description.urdf.xacro | -->
<!-- |    EDITING THIS FILE BY HAND IS NOT RECOMMENDED                                 | -->
<!-- =================================================================================== -->
<robot name="rm_scr">
    <link name="base_link_agv">
        <inertial>
            <origin rpy="0 0 0" xyz="-7.4455E-05 0.010453 0.10719" />
            <mass value="70" />
            <inertia ixx="0.094754" ixy="7.7604E-05" ixz="-9.8149E-05" iyy="0.096474" iyz="-0.0019299" izz="0.16261" />
        </inertial>
        <visual>
            <origin rpy="0 0 0" xyz="0 0 0" />
            <geometry>
                <mesh filename="package://rm_scr_description/meshes/base_link_agv.STL" />
            </geometry>
            <material name="">
                <color rgba="1 1 1 1" />
            </material>
        </visual>
        <collision>
            <origin rpy="0 0 0" xyz="0 0 0" />
            <geometry>
                <mesh filename="package://rm_scr_description/meshes/base_link_agv.STL" />
            </geometry>
        </collision>
    </link>
    <link name="baselink_body">
        <inertial>
            <origin rpy="0 0 0" xyz="-0.0019768 0.004672 0.30125" />
            <mass value="2.581" />
            <inertia ixx="0.05009" ixy="1.8262E-05" ixz="0.0003821" iyy="0.057064" iyz="-4.8542E-06" izz="0.016176" />
        </inertial>
        <visual>
            <origin rpy="0 0 0" xyz="0 0 0" />
            <geometry>
                <mesh filename="package://rm_scr_description/meshes/baselink_body.STL" />
            </geometry>
            <material name="">
                <color rgba="0.79216 0.81961 0.93333 1" />
            </material>
        </visual>
        <collision>
            <origin rpy="0 0 0" xyz="0 0 0" />
            <geometry>
                <mesh filename="package://rm_scr_description/meshes/baselink_body.STL" />
            </geometry>
        </collision>
    </link>
    <joint name="joint_fixed_body" type="fixed">
        <origin rpy="0 0 0" xyz="0 0 0.2791" />
        <parent link="base_link_agv" />
        <child link="baselink_body" />
        <axis xyz="0 0 0" />
    </joint>
    <link name="link_arm_rotary">
        <inertial>
            <origin rpy="0 0 0" xyz="-0.026988 -0.0010423 -0.00059756" />
            <mass value="0.31825" />
            <inertia ixx="0.00019457" ixy="-1.4002E-05" ixz="-8.0276E-06" iyy="0.00027255" iyz="-1.9841E-06" izz="0.00027487" />
        </inertial>
        <visual>
            <origin rpy="0 0 0" xyz="0 0 0" />
            <geometry>
                <mesh filename="package://rm_scr_description/meshes/link_arm_rotary.STL" />
            </geometry>
            <material name="">
                <color rgba="0.50196 0.50196 0.50196 1" />
            </material>
        </visual>
        <collision>
            <origin rpy="0 0 0" xyz="0 0 0" />
            <geometry>
                <mesh filename="package://rm_scr_description/meshes/link_arm_rotary.STL" />
            </geometry>
        </collision>
    </link>
    <joint name="joint_arm_rotary" type="revolute">
        <origin rpy="0.0074999 1.5708 0" xyz="0 0 0.489" />
        <parent link="baselink_body" />
        <child link="link_arm_rotary" />
        <axis xyz="-1 0 0" />
        <limit effort="100" lower="-1.3" upper="1.3" velocity="1" />
        <dynamics damping="50" friction="1" />
    </joint>
    <link name="link_arm_connector">
        <inertial>
            <origin rpy="0 0 0" xyz="0.0011319 0.00023344 0.04223" />
            <mass value="0.425" />
            <inertia ixx="0.0011766" ixy="1.2008E-06" ixz="1.7955E-05" iyy="0.0014259" iyz="-1.0264E-05" izz="0.00079079" />
        </inertial>
        <visual>
            <origin rpy="0 0 0" xyz="0 0 0" />
            <geometry>
                <mesh filename="package://rm_scr_description/meshes/link_arm_connector.STL" />
            </geometry>
            <material name="">
                <color rgba="0.79216 0.81961 0.93333 1" />
            </material>
        </visual>
        <collision>
            <origin rpy="0 0 0" xyz="0 0 0" />
            <geometry>
                <mesh filename="package://rm_scr_description/meshes/link_arm_connector.STL" />
            </geometry>
        </collision>
    </link>
    <joint name="fixed_arm_connector" type="fixed">
        <origin rpy="0.0096722 0 0" xyz="-0.065 0.00021859 -0.022599" />
        <parent link="link_arm_rotary" />
        <child link="link_arm_connector" />
        <axis xyz="0 0 0" />
    </joint>
    <link name="arm_link1">
        <inertial>
            <origin rpy="0 0 0" xyz="2.8044E-07 0.021108 -0.025186" />
            <mass value="0.59356" />
            <inertia ixx="0.0012661" ixy="-1.0792E-08" ixz="-8.0898E-09" iyy="0.0011817" iyz="-0.00021122" izz="0.00056135" />
        </inertial>
        <visual>
            <origin rpy="0 0 0" xyz="0 0 0" />
            <geometry>
                <mesh filename="package://rm_scr_description/meshes/arm_link1.STL" />
            </geometry>
            <material name="">
                <color rgba="0.79216 0.81961 0.93333 1" />
            </material>
        </visual>
        <collision>
            <origin rpy="0 0 0" xyz="0 0 0" />
            <geometry>
                <mesh filename="package://rm_scr_description/meshes/arm_link1.STL" />
            </geometry>
        </collision>
    </link>
    <joint name="joint1" type="revolute">
        <origin rpy="0 0 0" xyz="0 0 0.2405" />
        <parent link="link_arm_connector" />
        <child link="arm_link1" />
        <axis xyz="0 0 1" />
        <limit effort="100" lower="-3.107" upper="3.107" velocity="1" />
    </joint>
    <link name="arm_link2">
        <inertial>
            <origin rpy="0 0 0" xyz="0.15226 6.0104E-07 -0.0062025" />
            <mass value="0.86418" />
            <inertia ixx="0.00063254" ixy="-5.9926E-09" ixz="0.00042163" iyy="0.0020527" iyz="1.854E-09" izz="0.0019528" />
        </inertial>
        <visual>
            <origin rpy="0 0 0" xyz="0 0 0" />
            <geometry>
                <mesh filename="package://rm_scr_description/meshes/arm_link2.STL" />
            </geometry>
            <material name="">
                <color rgba="1 1 1 1" />
            </material>
        </visual>
        <collision>
            <origin rpy="0 0 0" xyz="0 0 0" />
            <geometry>
                <mesh filename="package://rm_scr_description/meshes/arm_link2.STL" />
            </geometry>
        </collision>
    </link>
    <joint name="joint2" type="revolute">
        <origin rpy="1.5708 -1.5708 0" xyz="0 0 0" />
        <parent link="arm_link1" />
        <child link="arm_link2" />
        <axis xyz="0 0 1" />
        <limit effort="100" lower="-2.269" upper="2.269" velocity="1" />
    </joint>
    <link name="arm_link3">
        <inertial>
            <origin rpy="0 0 0" xyz="5.0411E-06 -0.059593 0.010569" />
            <mass value="0.28963" />
            <inertia ixx="0.00063737" ixy="-7.0502E-08" ixz="-3.8658E-08" iyy="0.00015648" iyz="-0.00014461" izz="0.00061418" />
        </inertial>
        <visual>
            <origin rpy="0 0 0" xyz="0 0 0" />
            <geometry>
                <mesh filename="package://rm_scr_description/meshes/arm_link3.STL" />
            </geometry>
            <material name="">
                <color rgba="1 1 1 1" />
            </material>
        </visual>
        <collision>
            <origin rpy="0 0 0" xyz="0 0 0" />
            <geometry>
                <mesh filename="package://rm_scr_description/meshes/arm_link3.STL" />
            </geometry>
        </collision>
    </link>
    <joint name="joint3" type="revolute">
        <origin rpy="0 0 1.5708" xyz="0.256 0 0" />
        <parent link="arm_link2" />
        <child link="arm_link3" />
        <axis xyz="0 0 1" />
        <limit effort="100" lower="-2.356" upper="2.356" velocity="1" />
    </joint>
    <link name="arm_link4">
        <inertial>
            <origin rpy="0 0 0" xyz="1.1013E-06 -0.018041 -0.021541" />
            <mass value="0.2394" />
            <inertia ixx="0.00028594" ixy="3.0699E-09" ixz="-2.2186E-09" iyy="0.00026273" iyz="4.4237E-05" izz="0.00011989" />
        </inertial>
        <visual>
            <origin rpy="0 0 0" xyz="0 0 0" />
            <geometry>
                <mesh filename="package://rm_scr_description/meshes/arm_link4.STL" />
            </geometry>
            <material name="">
                <color rgba="1 1 1 1" />
            </material>
        </visual>
        <collision>
            <origin rpy="0 0 0" xyz="0 0 0" />
            <geometry>
                <mesh filename="package://rm_scr_description/meshes/arm_link4.STL" />
            </geometry>
        </collision>
    </link>
    <joint name="joint4" type="revolute">
        <origin rpy="1.5708 0 0" xyz="0 -0.21 0" />
        <parent link="arm_link3" />
        <child link="arm_link4" />
        <axis xyz="0 0 1" />
        <limit effort="100" lower="-3.107" upper="3.107" velocity="1" />
    </joint>
    <link name="arm_link5">
        <inertial>
            <origin rpy="0 0 0" xyz="3.4603E-06 -0.059382 0.0073678" />
            <mass value="0.21879" />
            <inertia ixx="0.00035053" ixy="-3.168E-08" ixz="-1.7437E-08" iyy="0.00010492" iyz="-7.824E-05" izz="0.00033447" />
        </inertial>
        <visual>
            <origin rpy="0 0 0" xyz="0 0 0" />
            <geometry>
                <mesh filename="package://rm_scr_description/meshes/arm_link5.STL" />
            </geometry>
            <material name="">
                <color rgba="1 1 1 1" />
            </material>
        </visual>
        <collision>
            <origin rpy="0 0 0" xyz="0 0 0" />
            <geometry>
                <mesh filename="package://rm_scr_description/meshes/arm_link5.STL" />
            </geometry>
        </collision>
    </link>
    <joint name="joint5" type="revolute">
        <origin rpy="-1.5708 0 0" xyz="0 0 0" />
        <parent link="arm_link4" />
        <child link="arm_link5" />
        <axis xyz="0 0 1" />
        <limit effort="100" lower="-2.234" upper="2.234" velocity="1" />
    </joint>
    <link name="arm_link6">
        <inertial>
            <origin rpy="0 0 0" xyz="0.00081643 1.3288E-05 -0.012705" />
            <mass value="0.065035" />
            <inertia ixx="2.1143E-05" ixy="-2.2878E-08" ixz="-2.5601E-08" iyy="1.811E-05" iyz="-1.0178E-08" izz="3.19E-05" />
        </inertial>
        <visual>
            <origin rpy="0 0 0" xyz="0 0 0" />
            <geometry>
                <mesh filename="package://rm_scr_description/meshes/arm_link6.STL" />
            </geometry>
            <material name="">
                <color rgba="0.79216 0.81961 0.93333 1" />
            </material>
        </visual>
        <collision>
            <origin rpy="0 0 0" xyz="0 0 0" />
            <geometry>
                <mesh filename="package://rm_scr_description/meshes/arm_link6.STL" />
            </geometry>
        </collision>
    </link>
    <joint name="joint6" type="revolute">
        <origin rpy="1.5708 0 0" xyz="0 -0.144 0" />
        <parent link="arm_link5" />
        <child link="arm_link6" />
        <axis xyz="0 0 1" />
        <limit effort="100" lower="-6.283" upper="6.283" velocity="1" />
    </joint>
    <link name="arm_link_hand">
        <inertial>
            <origin rpy="0 0 0" xyz="3.3314E-07 -9.9835E-05 0.00875" />
            <mass value="0.034397" />
            <inertia ixx="7.301E-06" ixy="1.4405E-08" ixz="-1.2054E-10" iyy="7.3591E-06" iyz="-8.1085E-09" izz="1.3696E-05" />
        </inertial>
        <visual>
            <origin rpy="0 0 0" xyz="0 0 0" />
            <geometry>
                <mesh filename="package://rm_scr_description/meshes/arm_link_hand.STL" />
            </geometry>
            <material name="">
                <color rgba="0.79216 0.81961 0.93333 1" />
            </material>
        </visual>
        <collision>
            <origin rpy="0 0 0" xyz="0 0 0" />
            <geometry>
                <mesh filename="package://rm_scr_description/meshes/arm_link_hand.STL" />
            </geometry>
        </collision>
    </link>
    <joint name="joint_fixed_hand" type="fixed">
        <origin rpy="0 0 0" xyz="0 0 0" />
        <parent link="arm_link6" />
        <child link="arm_link_hand" />
        <axis xyz="0 0 0" />
    </joint>
    <link name="head_yaw_link">
        <inertial>
            <origin rpy="0 0 0" xyz="-0.10343 0.024916 -7.6083E-05" />
            <mass value="0.15466" />
            <inertia ixx="0.00016049" ixy="4.5844E-05" ixz="2.6504E-07" iyy="0.00015344" iyz="-2.0817E-07" izz="0.00025161" />
        </inertial>
        <visual>
            <origin rpy="0 0 0" xyz="0 0 0" />
            <geometry>
                <mesh filename="package://rm_scr_description/meshes/head_yaw_link.STL" />
            </geometry>
            <material name="">
                <color rgba="0.79216 0.81961 0.93333 1" />
            </material>
        </visual>
        <collision>
            <origin rpy="0 0 0" xyz="0 0 0" />
            <geometry>
                <mesh filename="package://rm_scr_description/meshes/head_yaw_link.STL" />
            </geometry>
        </collision>
    </link>
    <joint name="joint_head_yaw" type="fixed">
        <origin rpy="0 1.5708 0" xyz="0 0 0.903" />
        <parent link="baselink_body" />
        <child link="head_yaw_link" />
        <axis xyz="-1 0 0" />
    </joint>
    <link name="head_pitch_link">
        <inertial>
            <origin rpy="0 0 0" xyz="-0.00021776 0.035749 -0.032433" />
            <mass value="0.19639" />
            <inertia ixx="0.00039276" ixy="-2.6633E-07" ixz="7.8221E-07" iyy="0.00049944" iyz="-2.5639E-07" izz="0.000142" />
        </inertial>
        <visual>
            <origin rpy="0 0 0" xyz="0 0 0" />
            <geometry>
                <mesh filename="package://rm_scr_description/meshes/head_pitch_link.STL" />
            </geometry>
            <material name="">
                <color rgba="0.79216 0.81961 0.93333 1" />
            </material>
        </visual>
        <collision>
            <origin rpy="0 0 0" xyz="0 0 0" />
            <geometry>
                <mesh filename="package://rm_scr_description/meshes/head_pitch_link.STL" />
            </geometry>
        </collision>
    </link>
    <joint name="joint_pitch_yaw" type="fixed">
        <origin rpy="0 0 0" xyz="-0.127 0.07 0.0315" />
        <parent link="head_yaw_link" />
        <child link="head_pitch_link" />
        <axis xyz="0 0 -1" />
    </joint>
    <transmission name="tran1">
        <type>transmission_interface/SimpleTransmission</type>
        <joint name="joint1">
            <hardwareInterface>hardware_interface/PositionJointInterface</hardwareInterface>
        </joint>
        <actuator name="motor1">
            <hardwareInterface>hardware_interface/PositionJointInterface</hardwareInterface>
            <mechanicalReduction>1</mechanicalReduction>
        </actuator>
    </transmission>
    <transmission name="tran1">
        <type>transmission_interface/SimpleTransmission</type>
        <joint name="joint2">
            <hardwareInterface>hardware_interface/PositionJointInterface</hardwareInterface>
        </joint>
        <actuator name="motor1">
            <hardwareInterface>hardware_interface/PositionJointInterface</hardwareInterface>
            <mechanicalReduction>1</mechanicalReduction>
        </actuator>
    </transmission>
    <transmission name="tran1">
        <type>transmission_interface/SimpleTransmission</type>
        <joint name="joint3">
            <hardwareInterface>hardware_interface/PositionJointInterface</hardwareInterface>
        </joint>
        <actuator name="motor1">
            <hardwareInterface>hardware_interface/PositionJointInterface</hardwareInterface>
            <mechanicalReduction>1</mechanicalReduction>
        </actuator>
    </transmission>
    <transmission name="tran1">
        <type>transmission_interface/SimpleTransmission</type>
        <joint name="joint4">
            <hardwareInterface>hardware_interface/PositionJointInterface</hardwareInterface>
        </joint>
        <actuator name="motor1">
            <hardwareInterface>hardware_interface/PositionJointInterface</hardwareInterface>
            <mechanicalReduction>1</mechanicalReduction>
        </actuator>
    </transmission>
    <transmission name="tran1">
        <type>transmission_interface/SimpleTransmission</type>
        <joint name="joint5">
            <hardwareInterface>hardware_interface/PositionJointInterface</hardwareInterface>
        </joint>
        <actuator name="motor1">
            <hardwareInterface>hardware_interface/PositionJointInterface</hardwareInterface>
            <mechanicalReduction>1</mechanicalReduction>
        </actuator>
    </transmission>
    <transmission name="tran1">
        <type>transmission_interface/SimpleTransmission</type>
        <joint name="joint6">
            <hardwareInterface>hardware_interface/PositionJointInterface</hardwareInterface>
        </joint>
        <actuator name="motor1">
            <hardwareInterface>hardware_interface/PositionJointInterface</hardwareInterface>
            <mechanicalReduction>1</mechanicalReduction>
        </actuator>
    </transmission>
    <!-- ros_control plugin -->
    <gazebo>
        <plugin filename="libgazebo_ros_control.so" name="gazebo_ros_control">
            <robotNamespace>/arm</robotNamespace>
            <robotSimType>gazebo_ros_control/DefaultRobotHWSim</robotSimType>
            <legacyModeNS>true</legacyModeNS>
        </plugin>
    </gazebo>
    <transmission name="trans_joint_arm_rotary">
        <type>transmission_interface/SimpleTransmission</type>
        <joint name="joint_arm_rotary">
            <hardwareInterface>hardware_interface/EffortJointInterface</hardwareInterface>
        </joint>
        <actuator name="joint_arm_rotary_motor">
            <hardwareInterface>hardware_interface/EffortJointInterface</hardwareInterface>
            <mechanicalReduction>1</mechanicalReduction>
        </actuator>
    </transmission>
</robot>

