<?xml version="1.0" encoding="utf-8"?>
<!-- This URDF was automatically created by SolidWorks to URDF Exporter! Originally created by Stephen Brawner (brawner@gmail.com) 
     Commit Version: 1.6.0-1-g15f4949  Build Version: 1.6.7594.29634
     For more information, please see http://wiki.ros.org/sw_urdf_exporter -->
<robot
  name="dishwasher">
  <link name="world"/>
  <joint name="world_to_base" type="fixed">
    <origin rpy="0 0 0" xyz="0 0 0.0"/>
    <parent link="world"/>
    <child link="base_link"/>
  </joint>
  <link
    name="base_link">
    <inertial>
      <origin
        xyz="-4.39760849925142E-05 0.105729139900029 0.0275389837423639"
        rpy="0 0 0" />
      <mass
        value="580.455252152826" />
      <inertia
        ixx="48.9714320407694"
        ixy="0.015429122039624"
        ixz="-0.0368901575236029"
        iyy="62.7979368163053"
        iyz="-0.752361452068393"
        izz="52.023508001152" />
    </inertial>
    <visual>
      <origin
        xyz="0 0 0"
        rpy="0 0 0" />
      <geometry>
        <mesh
          filename="package://./meshes/base_link.STL" />
      </geometry>
      <material
        name="">
        <color
          rgba="0.776470588235294 0.756862745098039 0.737254901960784 1" />
      </material>
    </visual>
    <collision>
      <origin
        xyz="0 0 0"
        rpy="0 0 0" />
      <geometry>
        <mesh
          filename="package://./meshes/base_link.STL" />
      </geometry>
    </collision>
  </link>
  <link
    name="link1">
    <inertial>
      <origin
        xyz="0.275057357630441 -0.277847464664124 0.225907441312431"
        rpy="0 0 0" />
      <mass
        value="126.317119956246" />
      <inertia
        ixx="4.41323347425015"
        ixy="0.00209040071762806"
        ixz="-0.0011522766147734"
        iyy="4.62286442705941"
        iyz="2.07424817150991"
        izz="6.00005579239379" />
    </inertial>
    <visual>
      <origin
        xyz="0 0 0"
        rpy="0 0 0" />
      <geometry>
        <mesh
          filename="package://./meshes/link1.STL" />
      </geometry>
      <material
        name="">
        <color
          rgba="0.776470588235294 0.756862745098039 0.737254901960784 1" />
      </material>
    </visual>
    <collision>
      <origin
        xyz="0 0 0"
        rpy="0 0 0" />
      <geometry>
        <mesh
          filename="package://./meshes/link1.STL" />
      </geometry>
    </collision>
  </link>
  <joint
    name="joint1"
    type="revolute">
    <origin
      xyz="-0.27486 -0.20985 -0.35073"
      rpy="-0.96 0 0" />
    <parent
      link="base_link" />
    <child
      link="link1" />
    <axis
      xyz="1 0 0" />
    <limit
      lower="0"
      upper="1.57"
      effort="0"
      velocity="0" />
  </joint>
  <link
    name="link2">
    <inertial>
      <origin
        xyz="-5.52871263489463E-05 -0.0499352677365905 0.0217687775834519"
        rpy="0 0 0" />
      <mass
        value="1.66002747123097" />
      <inertia
        ixx="0.0515702398565812"
        ixy="-5.94222398280139E-09"
        ixz="5.33785150395627E-06"
        iyy="0.0515702417345417"
        iyz="-6.65630453042583E-06"
        izz="0.0984568998085799" />
    </inertial>
    <visual>
      <origin
        xyz="0 0 0"
        rpy="0 0 0" />
      <geometry>
        <mesh
          filename="package://./meshes/link2.STL" />
      </geometry>
      <material
        name="">
        <color
          rgba="0.776470588235294 0.756862745098039 0.737254901960784 1" />
      </material>
    </visual>
    <collision>
      <origin
        xyz="0 0 0"
        rpy="0 0 0" />
      <geometry>
        <mesh
          filename="package://./meshes/link2.STL" />
      </geometry>
    </collision>
  </link>
  <joint
    name="joint2"
    type="prismatic">
    <origin
      xyz="0.050139 0.070153 -0.22109"
      rpy="0 0 -1.5708" />
    <parent
      link="base_link" />
    <child
      link="link2" />
    <axis
      xyz="-1 0 0" />
    <limit
      lower="-0.3"
      upper="0"
      effort="0"
      velocity="0" />
  </joint>
  <link
    name="link3">
    <inertial>
      <origin
        xyz="-5.52871263456156E-05 -0.0499352677364462 0.0217687775834396"
        rpy="0 0 0" />
      <mass
        value="1.66002747123082" />
      <inertia
        ixx="0.0515702398565785"
        ixy="-5.94219854501972E-09"
        ixz="5.33785150390082E-06"
        iyy="0.0515702417345241"
        iyz="-6.65630454185178E-06"
        izz="0.0984568998085609" />
    </inertial>
    <visual>
      <origin
        xyz="0 0 0"
        rpy="0 0 0" />
      <geometry>
        <mesh
          filename="package://./meshes/link3.STL" />
      </geometry>
      <material
        name="">
        <color
          rgba="0.776470588235294 0.756862745098039 0.737254901960784 1" />
      </material>
    </visual>
    <collision>
      <origin
        xyz="0 0 0"
        rpy="0 0 0" />
      <geometry>
        <mesh
          filename="package://./meshes/link3.STL" />
      </geometry>
    </collision>
  </link>
  <joint
    name="joint3"
    type="prismatic">
    <origin
      xyz="0.050139 0.070153 0.04627"
      rpy="0 0 -1.5708" />
    <parent
      link="base_link" />
    <child
      link="link3" />
    <axis
      xyz="-1 0 0" />
    <limit
      lower="-0.3"
      upper="0"
      effort="0"
      velocity="0" />
  </joint>
</robot>
