<?xml version="1.0" ?>
<robot name="partnet_39a8179c80a38ee130612f5c0ef21eb8">
	<link name="base"/>
	<link name="link_0">
		<visual name="lid-2">
			<origin xyz="-0.0010035000000000044 0 -0.00694800000000001"/>
			<geometry>
				<mesh filename="textured_objs/original-1.obj"/>
			</geometry>
		</visual>
		<collision>
			<origin xyz="-0.0010035000000000044 0 -0.00694800000000001"/>
			<geometry>
				<mesh filename="textured_objs/original-1.obj"/>
			</geometry>
		</collision>
	</link>
	<joint name="joint_0" type="continuous">
		<origin xyz="0.0 0 0.0"/>
		<axis xyz="0 -1 0"/>
		<child link="link_0"/>
		<parent link="link_0_helper"/>
	</joint>
	<link name="link_1">
		<visual name="container-3">
			<origin xyz="0 0 0"/>
			<geometry>
				<mesh filename="textured_objs/original-2.obj"/>
			</geometry>
		</visual>
		<collision>
			<origin xyz="0 0 0"/>
			<geometry>
				<mesh filename="textured_objs/original-2.obj"/>
			</geometry>
		</collision>
	</link>
	<joint name="joint_1" type="fixed">
		<origin rpy="1.570796326794897 0 -1.570796326794897" xyz="0 0 0"/>
		<child link="link_1"/>
		<parent link="base"/>
	</joint>
	<link name="link_0_helper"/>
	<joint name="joint_2" type="prismatic">
		<origin xyz="0.0010035000000000044 0 0.00694800000000001"/>
		<axis xyz="0 1 0"/>
		<child link="link_0_helper"/>
		<parent link="link_1"/>
		<limit lower="-0.07200000000000006" upper="-0.016000000000000014"/>
	</joint>
</robot>
