<?xml version="1.0" ?>
<robot name="partnet_38a5c62d5c03ae0992270dc2e45328b">
	<link name="base"/>
	<link name="link_0">
		<visual name="control_button-12">
			<origin xyz="-0.40733628437633135 -0.5487297337653565 -0.42089200000000027"/>
			<geometry>
				<mesh filename="textured_objs/original-8.obj"/>
			</geometry>
		</visual>
		<collision>
			<origin xyz="-0.40733628437633135 -0.5487297337653565 -0.42089200000000027"/>
			<geometry>
				<mesh filename="textured_objs/original-8.obj"/>
			</geometry>
		</collision>
	</link>
	<joint name="joint_0" type="prismatic">
		<origin xyz="0.40733628437633135 0.5487297337653565 0.42089200000000027"/>
		<axis xyz="0 0 -1"/>
		<child link="link_0"/>
		<parent link="link_5"/>
		<limit lower="0" upper="0.036"/>
	</joint>
	<link name="link_1">
		<visual name="control_button-13">
			<origin xyz="-0.40733628437633135 -0.5487297337653565 -0.42089200000000027"/>
			<geometry>
				<mesh filename="textured_objs/original-5.obj"/>
			</geometry>
		</visual>
		<collision>
			<origin xyz="-0.40733628437633135 -0.5487297337653565 -0.42089200000000027"/>
			<geometry>
				<mesh filename="textured_objs/original-5.obj"/>
			</geometry>
		</collision>
	</link>
	<joint name="joint_1" type="prismatic">
		<origin xyz="0.40733628437633135 0.5487297337653565 0.42089200000000027"/>
		<axis xyz="0 0 -1"/>
		<child link="link_1"/>
		<parent link="link_5"/>
		<limit lower="0" upper="0.036"/>
	</joint>
	<link name="link_2">
		<visual name="control_button-14">
			<origin xyz="-0.40733628437633135 -0.5487297337653565 -0.42089200000000027"/>
			<geometry>
				<mesh filename="textured_objs/original-6.obj"/>
			</geometry>
		</visual>
		<collision>
			<origin xyz="-0.40733628437633135 -0.5487297337653565 -0.42089200000000027"/>
			<geometry>
				<mesh filename="textured_objs/original-6.obj"/>
			</geometry>
		</collision>
	</link>
	<joint name="joint_2" type="prismatic">
		<origin xyz="0.40733628437633135 0.5487297337653565 0.42089200000000027"/>
		<axis xyz="0 0 -1"/>
		<child link="link_2"/>
		<parent link="link_5"/>
		<limit lower="0" upper="0.036"/>
	</joint>
	<link name="link_3">
		<visual name="control_button-15">
			<origin xyz="-0.40733628437633135 -0.5487297337653565 -0.42089200000000027"/>
			<geometry>
				<mesh filename="textured_objs/original-7.obj"/>
			</geometry>
		</visual>
		<collision>
			<origin xyz="-0.40733628437633135 -0.5487297337653565 -0.42089200000000027"/>
			<geometry>
				<mesh filename="textured_objs/original-7.obj"/>
			</geometry>
		</collision>
	</link>
	<joint name="joint_3" type="prismatic">
		<origin xyz="0.40733628437633135 0.5487297337653565 0.42089200000000027"/>
		<axis xyz="0 0 -1"/>
		<child link="link_3"/>
		<parent link="link_5"/>
		<limit lower="0" upper="0.036"/>
	</joint>
	<link name="link_4">
		<visual name="door_frame-20">
			<origin xyz="-0.4643670000000002 0.034841240602452105 -0.398863784270564"/>
			<geometry>
				<mesh filename="textured_objs/new-1.obj"/>
			</geometry>
		</visual>
		<visual name="door_frame-20">
			<origin xyz="-0.4643670000000002 0.034841240602452105 -0.398863784270564"/>
			<geometry>
				<mesh filename="textured_objs/original-18.obj"/>
			</geometry>
		</visual>
		<visual name="door_frame-20">
			<origin xyz="-0.4643670000000002 0.034841240602452105 -0.398863784270564"/>
			<geometry>
				<mesh filename="textured_objs/original-17.obj"/>
			</geometry>
		</visual>
		<visual name="handle-21">
			<origin xyz="-0.4643670000000002 0.034841240602452105 -0.398863784270564"/>
			<geometry>
				<mesh filename="textured_objs/new-0.obj"/>
			</geometry>
		</visual>
		<collision>
			<origin xyz="-0.4643670000000002 0.034841240602452105 -0.398863784270564"/>
			<geometry>
				<mesh filename="textured_objs/new-1.obj"/>
			</geometry>
		</collision>
		<collision>
			<origin xyz="-0.4643670000000002 0.034841240602452105 -0.398863784270564"/>
			<geometry>
				<mesh filename="textured_objs/original-18.obj"/>
			</geometry>
		</collision>
		<collision>
			<origin xyz="-0.4643670000000002 0.034841240602452105 -0.398863784270564"/>
			<geometry>
				<mesh filename="textured_objs/original-17.obj"/>
			</geometry>
		</collision>
		<collision>
			<origin xyz="-0.4643670000000002 0.034841240602452105 -0.398863784270564"/>
			<geometry>
				<mesh filename="textured_objs/new-0.obj"/>
			</geometry>
		</collision>
	</link>
	<joint name="joint_4" type="revolute">
		<origin rpy="-1.570796326794897 0 0"
			xyz="0.4643670000000002 -0.034841240602452105 0.398863784270564" />
		<axis xyz="1 0 0"/>
		<child link="link_4"/>
		<parent link="link_5"/>
		<limit lower="0" upper="1.570796326794897"/>
	</joint>
	<link name="link_5">
		<visual name="frame-17">
			<origin xyz="0 0 0"/>
			<geometry>
				<mesh filename="textured_objs/original-14.obj"/>
			</geometry>
		</visual>
		<visual name="frame-17">
			<origin xyz="0 0 0"/>
			<geometry>
				<mesh filename="textured_objs/original-21.obj"/>
			</geometry>
		</visual>
		<visual name="frame-17">
			<origin xyz="0 0 0"/>
			<geometry>
				<mesh filename="textured_objs/original-20.obj"/>
			</geometry>
		</visual>
		<visual name="foot-4">
			<origin xyz="0 0 0"/>
			<geometry>
				<mesh filename="textured_objs/original-13.obj"/>
			</geometry>
		</visual>
		<visual name="foot-5">
			<origin xyz="0 0 0"/>
			<geometry>
				<mesh filename="textured_objs/original-12.obj"/>
			</geometry>
		</visual>
		<visual name="foot-6">
			<origin xyz="0 0 0"/>
			<geometry>
				<mesh filename="textured_objs/original-11.obj"/>
			</geometry>
		</visual>
		<visual name="foot-7">
			<origin xyz="0 0 0"/>
			<geometry>
				<mesh filename="textured_objs/original-10.obj"/>
			</geometry>
		</visual>
		<visual name="control_panel-16">
			<origin xyz="0 0 0"/>
			<geometry>
				<mesh filename="textured_objs/original-9.obj"/>
			</geometry>
		</visual>
		<visual name="control_panel-16">
			<origin xyz="0 0 0"/>
			<geometry>
				<mesh filename="textured_objs/original-19.obj"/>
			</geometry>
		</visual>
		<visual name="other_leaf-28">
			<origin xyz="0 0 0"/>
			<geometry>
				<mesh filename="textured_objs/original-2.obj"/>
			</geometry>
		</visual>
		<visual name="other_leaf-27">
			<origin xyz="0 0 0"/>
			<geometry>
				<mesh filename="textured_objs/original-3.obj"/>
			</geometry>
		</visual>
		<collision>
			<origin xyz="0 0 0"/>
			<geometry>
				<mesh filename="textured_objs/original-14.obj"/>
			</geometry>
		</collision>
		<collision>
			<origin xyz="0 0 0"/>
			<geometry>
				<mesh filename="textured_objs/original-21.obj"/>
			</geometry>
		</collision>
		<collision>
			<origin xyz="0 0 0"/>
			<geometry>
				<mesh filename="textured_objs/original-20.obj"/>
			</geometry>
		</collision>
		<collision>
			<origin xyz="0 0 0"/>
			<geometry>
				<mesh filename="textured_objs/original-13.obj"/>
			</geometry>
		</collision>
		<collision>
			<origin xyz="0 0 0"/>
			<geometry>
				<mesh filename="textured_objs/original-12.obj"/>
			</geometry>
		</collision>
		<collision>
			<origin xyz="0 0 0"/>
			<geometry>
				<mesh filename="textured_objs/original-11.obj"/>
			</geometry>
		</collision>
		<collision>
			<origin xyz="0 0 0"/>
			<geometry>
				<mesh filename="textured_objs/original-10.obj"/>
			</geometry>
		</collision>
		<collision>
			<origin xyz="0 0 0"/>
			<geometry>
				<mesh filename="textured_objs/original-9.obj"/>
			</geometry>
		</collision>
		<collision>
			<origin xyz="0 0 0"/>
			<geometry>
				<mesh filename="textured_objs/original-19.obj"/>
			</geometry>
		</collision>
		<collision>
			<origin xyz="0 0 0"/>
			<geometry>
				<mesh filename="textured_objs/original-2.obj"/>
			</geometry>
		</collision>
		<collision>
			<origin xyz="0 0 0"/>
			<geometry>
				<mesh filename="textured_objs/original-3.obj"/>
			</geometry>
		</collision>
	</link>
	<joint name="joint_5" type="fixed">
		<origin rpy="1.570796326794897 0 -1.570796326794897" xyz="0 0 0"/>
		<child link="link_5"/>
		<parent link="base"/>
	</joint>
</robot>
