<?xml version="1.0" ?>
<robot name="partnet_5b81d7830eabb7547c6e1fb05e1b9037">
	<material name="Black">
		<color rgba="0.0 0.0 0.0 1.0"/>
	</material>
	<link name="base"/>

	<link name="handle">
		<visual name="handle-8">
			<origin xyz="-0.49549596211149094 -0.6874990000000003 -0.49109900923239014"/>
			<geometry>
				<mesh filename="textured_objs/new-1.obj"/>
			</geometry>
		</visual>
		<collision>
			<origin xyz="-0.49549596211149094 -0.6874990000000003 -0.44109900923239014"/>
			<geometry>
				<mesh filename="textured_objs/new-1.obj"/>
			</geometry>
		</collision>
	</link>
	<joint name="joint_handle" type="fixed">
		<origin xyz="0 0 0"/>
		<axis xyz="0 1 0"/>
		<child link="handle"/>
		<parent link="link_0"/>
	</joint>

	<link name="link_0">
		<visual name="door_frame-7">
			<origin xyz="-0.49549596211149094 -0.6874990000000003 -0.49109900923239014"/>
			<geometry>
				<mesh filename="textured_objs/new-4.obj"/>
			</geometry>
		</visual>
		<visual name="glass-9">
			<origin xyz="-0.49549596211149094 -0.6874990000000003 -0.49109900923239014"/>
			<geometry>
				<mesh filename="textured_objs/new-3.obj"/>
			</geometry>
		</visual>
		<collision>
			<origin xyz="-0.49549596211149094 -0.6874990000000003 -0.49109900923239014"/>
			<geometry>
				<mesh filename="textured_objs/new-4.obj"/>
			</geometry>
		</collision>
		<collision>
			<origin xyz="-0.49549596211149094 -0.6874990000000003 -0.49109900923239014"/>
			<geometry>
				<mesh filename="textured_objs/new-3.obj"/>
			</geometry>
		</collision>
	</link>
	<joint name="joint_0" type="revolute">
		<origin xyz="0.49549596211149094 0.6874990000000003 0.49109900923239014"/>
		<axis xyz="0 1 0"/>
		<child link="link_0"/>
		<parent link="link_1"/>
		<limit lower="-0.0" upper="3.141592653589793"/>
	</joint>
	<link name="link_1">

		<visual name="bottom">
			<origin xyz="0 -0.69 0"/>
			<geometry>
				<box size="1 .12 0.95"/>
			</geometry>
			<material name="Black"/>
		</visual>

		<visual name="surface-4">
			<origin xyz="0 0 0"/>
			<geometry>
				<mesh filename="textured_objs/new-0.obj"/>
			</geometry>
		</visual>
		<visual name="frame-5">
			<origin xyz="0 0 0"/>
			<geometry>
				<mesh filename="textured_objs/new-2.obj"/>
			</geometry>
		</visual>

		<collision name="bottom">
			<origin xyz="0 -0.69 0"/>
			<geometry>
				<box size="1 .12 0.95"/>
			</geometry>
		</collision>

		<collision>
			<origin xyz="0 0 0"/>
			<geometry>
				<mesh filename="textured_objs/new-0.obj"/>
			</geometry>
		</collision>
		<!-- <collision>
			<origin xyz="0 0 0"/>
			<geometry>
				<mesh filename="textured_objs/new-2.obj"/>
			</geometry>
		</collision> -->
		<collision>
			<origin xyz="0 0 0"/>
			<geometry>
				<mesh filename="textured_objs/new-2-left.obj"/>
			</geometry>
		</collision>
		<collision>
			<origin xyz="0 0 0"/>
			<geometry>
				<mesh filename="textured_objs/new-2-right.obj"/>
			</geometry>
		</collision>
		<collision>
			<origin xyz="0 0 0"/>
			<geometry>
				<mesh filename="textured_objs/new-2-top.obj"/>
			</geometry>
		</collision>
		<collision>
			<origin xyz="0 0 0"/>
			<geometry>
				<mesh filename="textured_objs/new-2-bottom.obj"/>
			</geometry>
		</collision>
		<collision>
			<origin xyz="0 0 0"/>
			<geometry>
				<mesh filename="textured_objs/new-2-back.obj"/>
			</geometry>
		</collision>
		<collision>
			<origin xyz="0 0 0"/>
			<geometry>
				<mesh filename="textured_objs/new-2-front.obj"/>
			</geometry>
		</collision>
	</link>
	<joint name="joint_1" type="fixed">
		<origin rpy="1.570796326794897 0 -1.570796326794897" xyz="0 0 0"/>
		<child link="link_1"/>
		<parent link="base"/>
	</joint>
</robot>
