<?xml version="1.0" encoding="utf-8"?>
<!-- This URDF was automatically created by SolidWorks to URDF Exporter! Originally created by Stephen Brawner (brawner@gmail.com) 
     Commit Version: 1.6.0-1-g15f4949  Build Version: 1.6.7594.29634
     For more information, please see http://wiki.ros.org/sw_urdf_exporter -->
<robot
  name="rm_eco65">
  <link
    name="baselink">
    <inertial>
      <origin
        xyz="0.00059982 -9.2932E-05 0.043301"
        rpy="0 0 0" />
      <mass
        value="0.61127" />
      <inertia
        ixx="0.00080212"
        ixy="3.0281E-06"
        ixz="-2.8747E-05"
        iyy="0.00080502"
        iyz="1.9749E-06"
        izz="0.00066167" />
    </inertial>
    <visual>
      <origin
        xyz="0 0 0"
        rpy="0 0 0" />
      <geometry>
        <mesh
          filename="package://rm_description/meshes/ECO65/baselink.STL" />
      </geometry>
      <material
        name="">
        <color
          rgba="1 1 0.9451 1" />
      </material>
    </visual>
    <collision>
      <origin
        xyz="0 0 0"
        rpy="0 0 0" />
      <geometry>
        <mesh
          filename="package://rm_description/meshes/ECO65/baselink.STL" />
      </geometry>
    </collision>
  </link>
  <link
    name="Link1">
    <inertial>
      <origin
        xyz="-0.022858 -2.0784E-06 -0.013658"
        rpy="0 0 0" />
      <mass
        value="0.74247" />
      <inertia
        ixx="0.00081398"
        ixy="-1.9024E-05"
        ixz="0.00022746"
        iyy="0.001848"
        iyz="2.0444E-06"
        izz="0.0015286" />
    </inertial>
    <visual>
      <origin
        xyz="0 0 0"
        rpy="0 0 0" />
      <geometry>
        <mesh
          filename="package://rm_description/meshes/ECO65/Link1.STL" />
      </geometry>
      <material
        name="">
        <color
          rgba="1 1 0.9451 1" />
      </material>
    </visual>
    <collision>
      <origin
        xyz="0 0 0"
        rpy="0 0 0" />
      <geometry>
        <mesh
          filename="package://rm_description/meshes/ECO65/Link1.STL" />
      </geometry>
    </collision>
  </link>
  <joint
    name="joint1"
    type="revolute">
    <origin
      xyz="0 0 0.1625"
      rpy="0 0 0" />
    <parent
      link="baselink" />
    <child
      link="Link1" />
    <axis
      xyz="0 0 1" />
    <limit
      lower="-3.1923"
      upper="3.1923"
      effort="100"
      velocity="1" />
  </joint>
  <link
    name="Link2">
    <inertial>
      <origin
        xyz="-1.6049E-06 0.10336 0.067332"
        rpy="0 0 0" />
      <mass
        value="1.3502" />
      <inertia
        ixx="0.012821"
        ixy="-7.2979E-08"
        ixz="1.1499E-08"
        iyy="0.0011237"
        iyz="-0.00033755"
        izz="0.012933" />
    </inertial>
    <visual>
      <origin
        xyz="0 0 0"
        rpy="0 0 0" />
      <geometry>
        <mesh
          filename="package://rm_description/meshes/ECO65/Link2.STL" />
      </geometry>
      <material
        name="">
        <color
          rgba="1 1 0.9451 1" />
      </material>
    </visual>
    <collision>
      <origin
        xyz="0 0 0"
        rpy="0 0 0" />
      <geometry>
        <mesh
          filename="package://rm_description/meshes/ECO65/Link2.STL" />
      </geometry>
    </collision>
  </link>
  <joint
    name="joint2"
    type="revolute">
    <origin
      xyz="-0.086 0 0"
      rpy="1.5708 0 0" />
    <parent
      link="Link1" />
    <child
      link="Link2" />
    <axis
      xyz="0 0 -1" />
    <limit
      lower="-2.61666"
      upper="2.442"
      effort="100"
      velocity="1" />
  </joint>
  <link
    name="Link3">
    <inertial>
      <origin
        xyz="0.10374 7.0495E-07 0.018599"
        rpy="0 0 0" />
      <mass
        value="1.0422" />
      <inertia
        ixx="0.00084115"
        ixy="-2.2514E-08"
        ixz="-0.00068613"
        iyy="0.0094046"
        iyz="-3.3287E-09"
        izz="0.0092482" />
    </inertial>
    <visual>
      <origin
        xyz="0 0 0"
        rpy="0 0 0" />
      <geometry>
        <mesh
          filename="package://rm_description/meshes/ECO65/Link3.STL" />
      </geometry>
      <material
        name="">
        <color
          rgba="1 1 0.9451 1" />
      </material>
    </visual>
    <collision>
      <origin
        xyz="0 0 0"
        rpy="0 0 0" />
      <geometry>
        <mesh
          filename="package://rm_description/meshes/ECO65/Link3.STL" />
      </geometry>
    </collision>
  </link>
  <joint
    name="joint3"
    type="revolute">
    <origin
      xyz="0 0.26 0"
      rpy="3.1416 0 1.5708" />
    <parent
      link="Link2" />
    <child
      link="Link3" />
    <axis
      xyz="0 0 1" />
    <limit
      lower="-2.61666"
      upper="2.61666"
      effort="100"
      velocity="1" />
  </joint>
  <link
    name="Link4">
    <inertial>
      <origin
        xyz="-0.0069819 -0.016328 0.0067416"
        rpy="0 0 0" />
      <mass
        value="0.27383" />
      <inertia
        ixx="0"
        ixy="0"
        ixz="0"
        iyy="0"
        iyz="0"
        izz="0" />
    </inertial>
    <visual>
      <origin
        xyz="0 0 0"
        rpy="0 0 0" />
      <geometry>
        <mesh
          filename="package://rm_description/meshes/ECO65/Link4.STL" />
      </geometry>
      <material
        name="">
        <color
          rgba="1 1 0.9451 1" />
      </material>
    </visual>
    <collision>
      <origin
        xyz="0 0 0"
        rpy="0 0 0" />
      <geometry>
        <mesh
          filename="package://rm_description/meshes/ECO65/Link4.STL" />
      </geometry>
    </collision>
  </link>
  <joint
    name="joint4"
    type="revolute">
    <origin
      xyz="0.24 0 -0.05888"
      rpy="0 0 1.5708" />
    <parent
      link="Link3" />
    <child
      link="Link4" />
    <axis
      xyz="0 0 1" />
    <limit
      lower="-2.61666"
      upper="2.61666"
      effort="100"
      velocity="1" />
  </joint>
  <link
    name="Link5">
    <inertial>
      <origin
        xyz="-0.00040425 0.0066328 -0.012475"
        rpy="0 0 0" />
      <mass
        value="0.27794" />
      <inertia
        ixx="0.00024751"
        ixy="-5.6849E-09"
        ixz="5.4838E-10"
        iyy="0.00017648"
        iyz="-2.8552E-05"
        izz="0.00019295" />
    </inertial>
    <visual>
      <origin
        xyz="0 0 0"
        rpy="0 0 0" />
      <geometry>
        <mesh
          filename="package://rm_description/meshes/ECO65/Link5.STL" />
      </geometry>
      <material
        name="">
        <color
          rgba="0.29804 0.28627 0.28235 1" />
      </material>
    </visual>
    <collision>
      <origin
        xyz="0 0 0"
        rpy="0 0 0" />
      <geometry>
        <mesh
          filename="package://rm_description/meshes/ECO65/Link5.STL" />
      </geometry>
    </collision>
  </link>
  <joint
    name="joint5"
    type="revolute">
    <origin
      xyz="0.00040486 -0.10983 0"
      rpy="1.5708 0 0" />
    <parent
      link="Link4" />
    <child
      link="Link5" />
    <axis
      xyz="0 0 1" />
    <limit
      lower="-2.96555"
      upper="2.96555"
      effort="100"
      velocity="1" />
  </joint>
  <link
    name="Link6">
    <inertial>
      <origin
        xyz="0.00095587 -0.0013555 -0.010297"
        rpy="0 0 0" />
      <mass
        value="0.033025" />
      <inertia
        ixx="1.2968E-05"
        ixy="-7.8692E-07"
        ixz="8.451E-08"
        iyy="1.1583E-05"
        iyz="-1.2002E-07"
        izz="2.0405E-05" />
    </inertial>
    <visual>
      <origin
        xyz="0 0 0"
        rpy="0 0 0" />
      <geometry>
        <mesh
          filename="package://rm_description/meshes/ECO65/Link6.STL" />
      </geometry>
      <material
        name="">
        <color
          rgba="1 1 0.9451 1" />
      </material>
    </visual>
    <collision>
      <origin
        xyz="0 0 0"
        rpy="0 0 0" />
      <geometry>
        <mesh
          filename="package://rm_description/meshes/ECO65/Link6.STL" />
      </geometry>
    </collision>
  </link>
  <joint
    name="joint6"
    type="revolute">
    <origin
      xyz="0 0.0795 0"
      rpy="-1.5708 0 0" />
    <parent
      link="Link5" />
    <child
      link="Link6" />
    <axis
      xyz="0 0 1" />
    <limit
      lower="-2.96555"
      upper="2.96555"
      effort="100"
      velocity="1" />
  </joint>
</robot>