<?xml version="1.0" ?>
<robot name="partnet_4b80db7aaf0dff0c4da5feafe6f1c8fc">
	<link name="base"/>
	<link name="link_0">
		<visual name="vertical_side_panel-9">
			<origin xyz="0 0 0"/>
			<geometry>
				<mesh filename="textured_objs/original-9.obj"/>
			</geometry>
		</visual>
		<visual name="vertical_side_panel-10">
			<origin xyz="0 0 0"/>
			<geometry>
				<mesh filename="textured_objs/original-10.obj"/>
			</geometry>
		</visual>
		<visual name="back_panel-11">
			<origin xyz="0 0 0"/>
			<geometry>
				<mesh filename="textured_objs/original-7.obj"/>
			</geometry>
		</visual>
		<visual name="back_panel-11">
			<origin xyz="0 0 0"/>
			<geometry>
				<mesh filename="textured_objs/original-8.obj"/>
			</geometry>
		</visual>
		<visual name="back_panel-11">
			<origin xyz="0 0 0"/>
			<geometry>
				<mesh filename="textured_objs/original-59.obj"/>
			</geometry>
		</visual>
		<visual name="bottom_panel-12">
			<origin xyz="0 0 0"/>
			<geometry>
				<mesh filename="textured_objs/original-2.obj"/>
			</geometry>
		</visual>
		<visual name="bottom_panel-12">
			<origin xyz="0 0 0"/>
			<geometry>
				<mesh filename="textured_objs/original-3.obj"/>
			</geometry>
		</visual>
		<visual name="top_panel-13">
			<origin xyz="0 0 0"/>
			<geometry>
				<mesh filename="textured_objs/original-15.obj"/>
			</geometry>
		</visual>
		<visual name="top_panel-13">
			<origin xyz="0 0 0"/>
			<geometry>
				<mesh filename="textured_objs/original-14.obj"/>
			</geometry>
		</visual>
		<visual name="frame_horizontal_bar-22">
			<origin xyz="0 0 0"/>
			<geometry>
				<mesh filename="textured_objs/original-4.obj"/>
			</geometry>
		</visual>
		<visual name="frame_horizontal_bar-23">
			<origin xyz="0 0 0"/>
			<geometry>
				<mesh filename="textured_objs/original-17.obj"/>
			</geometry>
		</visual>
		<visual name="frame_horizontal_bar-24">
			<origin xyz="0 0 0"/>
			<geometry>
				<mesh filename="textured_objs/original-5.obj"/>
			</geometry>
		</visual>
		<visual name="frame_horizontal_bar-25">
			<origin xyz="0 0 0"/>
			<geometry>
				<mesh filename="textured_objs/original-16.obj"/>
			</geometry>
		</visual>
		<visual name="frame_vertical_bar-26">
			<origin xyz="0 0 0"/>
			<geometry>
				<mesh filename="textured_objs/original-11.obj"/>
			</geometry>
		</visual>
		<visual name="frame_vertical_bar-27">
			<origin xyz="0 0 0"/>
			<geometry>
				<mesh filename="textured_objs/original-18.obj"/>
			</geometry>
		</visual>
		<visual name="frame_vertical_bar-28">
			<origin xyz="0 0 0"/>
			<geometry>
				<mesh filename="textured_objs/original-12.obj"/>
			</geometry>
		</visual>
		<collision>
			<origin xyz="0 0 0"/>
			<geometry>
				<mesh filename="textured_objs/original-9.obj"/>
			</geometry>
		</collision>
		<collision>
			<origin xyz="0 0 0"/>
			<geometry>
				<mesh filename="textured_objs/original-10.obj"/>
			</geometry>
		</collision>
		<collision>
			<origin xyz="0 0 0"/>
			<geometry>
				<mesh filename="textured_objs/original-7.obj"/>
			</geometry>
		</collision>
		<collision>
			<origin xyz="0 0 0"/>
			<geometry>
				<mesh filename="textured_objs/original-8.obj"/>
			</geometry>
		</collision>
		<collision>
			<origin xyz="0 0 0"/>
			<geometry>
				<mesh filename="textured_objs/original-59.obj"/>
			</geometry>
		</collision>
		<collision>
			<origin xyz="0 0 0"/>
			<geometry>
				<mesh filename="textured_objs/original-2.obj"/>
			</geometry>
		</collision>
		<collision>
			<origin xyz="0 0 0"/>
			<geometry>
				<mesh filename="textured_objs/original-3.obj"/>
			</geometry>
		</collision>
		<collision>
			<origin xyz="0 0 0"/>
			<geometry>
				<mesh filename="textured_objs/original-15.obj"/>
			</geometry>
		</collision>
		<collision>
			<origin xyz="0 0 0"/>
			<geometry>
				<mesh filename="textured_objs/original-14.obj"/>
			</geometry>
		</collision>
		<collision>
			<origin xyz="0 0 0"/>
			<geometry>
				<mesh filename="textured_objs/original-4.obj"/>
			</geometry>
		</collision>
		<collision>
			<origin xyz="0 0 0"/>
			<geometry>
				<mesh filename="textured_objs/original-17.obj"/>
			</geometry>
		</collision>
		<collision>
			<origin xyz="0 0 0"/>
			<geometry>
				<mesh filename="textured_objs/original-5.obj"/>
			</geometry>
		</collision>
		<collision>
			<origin xyz="0 0 0"/>
			<geometry>
				<mesh filename="textured_objs/original-16.obj"/>
			</geometry>
		</collision>
		<collision>
			<origin xyz="0 0 0"/>
			<geometry>
				<mesh filename="textured_objs/original-11.obj"/>
			</geometry>
		</collision>
		<collision>
			<origin xyz="0 0 0"/>
			<geometry>
				<mesh filename="textured_objs/original-18.obj"/>
			</geometry>
		</collision>
		<collision>
			<origin xyz="0 0 0"/>
			<geometry>
				<mesh filename="textured_objs/original-12.obj"/>
			</geometry>
		</collision>
	</link>
	<joint name="joint_0" type="fixed">
		<origin rpy="1.570796326794897 0 -1.570796326794897" xyz="0 0 0"/>
		<child link="link_0"/>
		<parent link="base"/>
	</joint>
	<link name="link_1">
		<visual name="cabinet_door_surface-7">
			<origin xyz="-0.8646320104598999 -0.3483026078833429 -0.29992122138885247"/>
			<geometry>
				<mesh filename="textured_objs/original-44.obj"/>
			</geometry>
		</visual>
		<visual name="cabinet_door_surface-7">
			<origin xyz="-0.8646320104598999 -0.3483026078833429 -0.29992122138885247"/>
			<geometry>
				<mesh filename="textured_objs/original-40.obj"/>
			</geometry>
		</visual>
		<visual name="cabinet_door_surface-7">
			<origin xyz="-0.8646320104598999 -0.3483026078833429 -0.29992122138885247"/>
			<geometry>
				<mesh filename="textured_objs/original-46.obj"/>
			</geometry>
		</visual>
		<visual name="cabinet_door_surface-7">
			<origin xyz="-0.8646320104598999 -0.3483026078833429 -0.29992122138885247"/>
			<geometry>
				<mesh filename="textured_objs/original-50.obj"/>
			</geometry>
		</visual>
		<visual name="cabinet_door_surface-7">
			<origin xyz="-0.8646320104598999 -0.3483026078833429 -0.29992122138885247"/>
			<geometry>
				<mesh filename="textured_objs/original-41.obj"/>
			</geometry>
		</visual>
		<visual name="cabinet_door_surface-7">
			<origin xyz="-0.8646320104598999 -0.3483026078833429 -0.29992122138885247"/>
			<geometry>
				<mesh filename="textured_objs/original-47.obj"/>
			</geometry>
		</visual>
		<visual name="cabinet_door_surface-7">
			<origin xyz="-0.8646320104598999 -0.3483026078833429 -0.29992122138885247"/>
			<geometry>
				<mesh filename="textured_objs/original-42.obj"/>
			</geometry>
		</visual>
		<visual name="cabinet_door_surface-7">
			<origin xyz="-0.8646320104598999 -0.3483026078833429 -0.29992122138885247"/>
			<geometry>
				<mesh filename="textured_objs/original-45.obj"/>
			</geometry>
		</visual>
		<visual name="cabinet_door_surface-7">
			<origin xyz="-0.8646320104598999 -0.3483026078833429 -0.29992122138885247"/>
			<geometry>
				<mesh filename="textured_objs/original-43.obj"/>
			</geometry>
		</visual>
		<visual name="cabinet_door_surface-7">
			<origin xyz="-0.8646320104598999 -0.3483026078833429 -0.29992122138885247"/>
			<geometry>
				<mesh filename="textured_objs/original-49.obj"/>
			</geometry>
		</visual>
		<visual name="handle-8">
			<origin xyz="-0.8646320104598999 -0.3483026078833429 -0.29992122138885247"/>
			<geometry>
				<mesh filename="textured_objs/original-57.obj"/>
			</geometry>
		</visual>
		<visual name="handle-8">
			<origin xyz="-0.8646320104598999 -0.3483026078833429 -0.29992122138885247"/>
			<geometry>
				<mesh filename="textured_objs/original-56.obj"/>
			</geometry>
		</visual>
		<visual name="handle-8">
			<origin xyz="-0.8646320104598999 -0.3483026078833429 -0.29992122138885247"/>
			<geometry>
				<mesh filename="textured_objs/original-58.obj"/>
			</geometry>
		</visual>
		<visual name="handle-8">
			<origin xyz="-0.8646320104598999 -0.3483026078833429 -0.29992122138885247"/>
			<geometry>
				<mesh filename="textured_objs/original-54.obj"/>
			</geometry>
		</visual>
		<visual name="handle-8">
			<origin xyz="-0.8646320104598999 -0.3483026078833429 -0.29992122138885247"/>
			<geometry>
				<mesh filename="textured_objs/original-53.obj"/>
			</geometry>
		</visual>
		<collision>
			<origin xyz="-0.8646320104598999 -0.3483026078833429 -0.29992122138885247"/>
			<geometry>
				<mesh filename="textured_objs/original-44.obj"/>
			</geometry>
		</collision>
		<collision>
			<origin xyz="-0.8646320104598999 -0.3483026078833429 -0.29992122138885247"/>
			<geometry>
				<mesh filename="textured_objs/original-40.obj"/>
			</geometry>
		</collision>
		<collision>
			<origin xyz="-0.8646320104598999 -0.3483026078833429 -0.29992122138885247"/>
			<geometry>
				<mesh filename="textured_objs/original-46.obj"/>
			</geometry>
		</collision>
		<collision>
			<origin xyz="-0.8646320104598999 -0.3483026078833429 -0.29992122138885247"/>
			<geometry>
				<mesh filename="textured_objs/original-50.obj"/>
			</geometry>
		</collision>
		<collision>
			<origin xyz="-0.8646320104598999 -0.3483026078833429 -0.29992122138885247"/>
			<geometry>
				<mesh filename="textured_objs/original-41.obj"/>
			</geometry>
		</collision>
		<collision>
			<origin xyz="-0.8646320104598999 -0.3483026078833429 -0.29992122138885247"/>
			<geometry>
				<mesh filename="textured_objs/original-47.obj"/>
			</geometry>
		</collision>
		<collision>
			<origin xyz="-0.8646320104598999 -0.3483026078833429 -0.29992122138885247"/>
			<geometry>
				<mesh filename="textured_objs/original-42.obj"/>
			</geometry>
		</collision>
		<collision>
			<origin xyz="-0.8646320104598999 -0.3483026078833429 -0.29992122138885247"/>
			<geometry>
				<mesh filename="textured_objs/original-45.obj"/>
			</geometry>
		</collision>
		<collision>
			<origin xyz="-0.8646320104598999 -0.3483026078833429 -0.29992122138885247"/>
			<geometry>
				<mesh filename="textured_objs/original-43.obj"/>
			</geometry>
		</collision>
		<collision>
			<origin xyz="-0.8646320104598999 -0.3483026078833429 -0.29992122138885247"/>
			<geometry>
				<mesh filename="textured_objs/original-49.obj"/>
			</geometry>
		</collision>
		<collision>
			<origin xyz="-0.8646320104598999 -0.3483026078833429 -0.29992122138885247"/>
			<geometry>
				<mesh filename="textured_objs/original-57.obj"/>
			</geometry>
		</collision>
		<collision>
			<origin xyz="-0.8646320104598999 -0.3483026078833429 -0.29992122138885247"/>
			<geometry>
				<mesh filename="textured_objs/original-56.obj"/>
			</geometry>
		</collision>
		<collision>
			<origin xyz="-0.8646320104598999 -0.3483026078833429 -0.29992122138885247"/>
			<geometry>
				<mesh filename="textured_objs/original-58.obj"/>
			</geometry>
		</collision>
		<collision>
			<origin xyz="-0.8646320104598999 -0.3483026078833429 -0.29992122138885247"/>
			<geometry>
				<mesh filename="textured_objs/original-54.obj"/>
			</geometry>
		</collision>
		<collision>
			<origin xyz="-0.8646320104598999 -0.3483026078833429 -0.29992122138885247"/>
			<geometry>
				<mesh filename="textured_objs/original-53.obj"/>
			</geometry>
		</collision>
	</link>
	<joint name="joint_1" type="revolute">
		<origin xyz="0.8646320104598999 0.3483026078833429 0.29992122138885247"/>
		<axis xyz="-0.9999999999999999 0 0"/>
		<child link="link_1"/>
		<parent link="link_0"/>
		<limit lower="0.0" upper="1.7453292519943295"/>
	</joint>
	<link name="link_2">
		<visual name="cabinet_door_surface-5">
			<origin xyz="-0.8646320104598999 -0.3483026078833429 -0.29992122138885247"/>
			<geometry>
				<mesh filename="textured_objs/original-29.obj"/>
			</geometry>
		</visual>
		<visual name="cabinet_door_surface-5">
			<origin xyz="-0.8646320104598999 -0.3483026078833429 -0.29992122138885247"/>
			<geometry>
				<mesh filename="textured_objs/original-30.obj"/>
			</geometry>
		</visual>
		<visual name="cabinet_door_surface-5">
			<origin xyz="-0.8646320104598999 -0.3483026078833429 -0.29992122138885247"/>
			<geometry>
				<mesh filename="textured_objs/original-24.obj"/>
			</geometry>
		</visual>
		<visual name="cabinet_door_surface-5">
			<origin xyz="-0.8646320104598999 -0.3483026078833429 -0.29992122138885247"/>
			<geometry>
				<mesh filename="textured_objs/original-20.obj"/>
			</geometry>
		</visual>
		<visual name="cabinet_door_surface-5">
			<origin xyz="-0.8646320104598999 -0.3483026078833429 -0.29992122138885247"/>
			<geometry>
				<mesh filename="textured_objs/original-26.obj"/>
			</geometry>
		</visual>
		<visual name="cabinet_door_surface-5">
			<origin xyz="-0.8646320104598999 -0.3483026078833429 -0.29992122138885247"/>
			<geometry>
				<mesh filename="textured_objs/original-22.obj"/>
			</geometry>
		</visual>
		<visual name="cabinet_door_surface-5">
			<origin xyz="-0.8646320104598999 -0.3483026078833429 -0.29992122138885247"/>
			<geometry>
				<mesh filename="textured_objs/original-23.obj"/>
			</geometry>
		</visual>
		<visual name="cabinet_door_surface-5">
			<origin xyz="-0.8646320104598999 -0.3483026078833429 -0.29992122138885247"/>
			<geometry>
				<mesh filename="textured_objs/original-25.obj"/>
			</geometry>
		</visual>
		<visual name="cabinet_door_surface-5">
			<origin xyz="-0.8646320104598999 -0.3483026078833429 -0.29992122138885247"/>
			<geometry>
				<mesh filename="textured_objs/original-27.obj"/>
			</geometry>
		</visual>
		<visual name="cabinet_door_surface-5">
			<origin xyz="-0.8646320104598999 -0.3483026078833429 -0.29992122138885247"/>
			<geometry>
				<mesh filename="textured_objs/original-21.obj"/>
			</geometry>
		</visual>
		<visual name="handle-6">
			<origin xyz="-0.8646320104598999 -0.3483026078833429 -0.29992122138885247"/>
			<geometry>
				<mesh filename="textured_objs/original-36.obj"/>
			</geometry>
		</visual>
		<visual name="handle-6">
			<origin xyz="-0.8646320104598999 -0.3483026078833429 -0.29992122138885247"/>
			<geometry>
				<mesh filename="textured_objs/original-34.obj"/>
			</geometry>
		</visual>
		<visual name="handle-6">
			<origin xyz="-0.8646320104598999 -0.3483026078833429 -0.29992122138885247"/>
			<geometry>
				<mesh filename="textured_objs/original-33.obj"/>
			</geometry>
		</visual>
		<visual name="handle-6">
			<origin xyz="-0.8646320104598999 -0.3483026078833429 -0.29992122138885247"/>
			<geometry>
				<mesh filename="textured_objs/original-37.obj"/>
			</geometry>
		</visual>
		<visual name="handle-6">
			<origin xyz="-0.8646320104598999 -0.3483026078833429 -0.29992122138885247"/>
			<geometry>
				<mesh filename="textured_objs/original-38.obj"/>
			</geometry>
		</visual>
		<collision>
			<origin xyz="-0.8646320104598999 -0.3483026078833429 -0.29992122138885247"/>
			<geometry>
				<mesh filename="textured_objs/original-29.obj"/>
			</geometry>
		</collision>
		<collision>
			<origin xyz="-0.8646320104598999 -0.3483026078833429 -0.29992122138885247"/>
			<geometry>
				<mesh filename="textured_objs/original-30.obj"/>
			</geometry>
		</collision>
		<collision>
			<origin xyz="-0.8646320104598999 -0.3483026078833429 -0.29992122138885247"/>
			<geometry>
				<mesh filename="textured_objs/original-24.obj"/>
			</geometry>
		</collision>
		<collision>
			<origin xyz="-0.8646320104598999 -0.3483026078833429 -0.29992122138885247"/>
			<geometry>
				<mesh filename="textured_objs/original-20.obj"/>
			</geometry>
		</collision>
		<collision>
			<origin xyz="-0.8646320104598999 -0.3483026078833429 -0.29992122138885247"/>
			<geometry>
				<mesh filename="textured_objs/original-26.obj"/>
			</geometry>
		</collision>
		<collision>
			<origin xyz="-0.8646320104598999 -0.3483026078833429 -0.29992122138885247"/>
			<geometry>
				<mesh filename="textured_objs/original-22.obj"/>
			</geometry>
		</collision>
		<collision>
			<origin xyz="-0.8646320104598999 -0.3483026078833429 -0.29992122138885247"/>
			<geometry>
				<mesh filename="textured_objs/original-23.obj"/>
			</geometry>
		</collision>
		<collision>
			<origin xyz="-0.8646320104598999 -0.3483026078833429 -0.29992122138885247"/>
			<geometry>
				<mesh filename="textured_objs/original-25.obj"/>
			</geometry>
		</collision>
		<collision>
			<origin xyz="-0.8646320104598999 -0.3483026078833429 -0.29992122138885247"/>
			<geometry>
				<mesh filename="textured_objs/original-27.obj"/>
			</geometry>
		</collision>
		<collision>
			<origin xyz="-0.8646320104598999 -0.3483026078833429 -0.29992122138885247"/>
			<geometry>
				<mesh filename="textured_objs/original-21.obj"/>
			</geometry>
		</collision>
		<collision>
			<origin xyz="-0.8646320104598999 -0.3483026078833429 -0.29992122138885247"/>
			<geometry>
				<mesh filename="textured_objs/original-36.obj"/>
			</geometry>
		</collision>
		<collision>
			<origin xyz="-0.8646320104598999 -0.3483026078833429 -0.29992122138885247"/>
			<geometry>
				<mesh filename="textured_objs/original-34.obj"/>
			</geometry>
		</collision>
		<collision>
			<origin xyz="-0.8646320104598999 -0.3483026078833429 -0.29992122138885247"/>
			<geometry>
				<mesh filename="textured_objs/original-33.obj"/>
			</geometry>
		</collision>
		<collision>
			<origin xyz="-0.8646320104598999 -0.3483026078833429 -0.29992122138885247"/>
			<geometry>
				<mesh filename="textured_objs/original-37.obj"/>
			</geometry>
		</collision>
		<collision>
			<origin xyz="-0.8646320104598999 -0.3483026078833429 -0.29992122138885247"/>
			<geometry>
				<mesh filename="textured_objs/original-38.obj"/>
			</geometry>
		</collision>
	</link>
	<joint name="joint_2" type="revolute">
		<origin xyz="0.8646320104598999 0.3483026078833429 0.29992122138885247"/>
		<axis xyz="-0.9999999999999999 0 0"/>
		<child link="link_2"/>
		<parent link="link_0"/>
		<limit lower="0.0" upper="1.7453292519943295"/>
	</joint>
</robot>
