<?xml version="1.0" ?>
<robot name="partnet_33b1e78a6d49c2d67aa983983f9bf36">
	<link name="base"/>
	<link name="link_0">
		<visual name="rotation_lid-1">
			<origin xyz="-0.5415320000000001 -0.4928149999999997 -0.12047512562448892"/>
			<geometry>
				<mesh filename="textured_objs/original-8.obj"/>
			</geometry>
		</visual>
		<collision>
			<origin xyz="-0.5415320000000001 -0.4928149999999997 -0.12047512562448892"/>
			<geometry>
				<mesh filename="textured_objs/original-8.obj"/>
			</geometry>
		</collision>
	</link>
	<joint name="joint_0" type="revolute">
		<origin xyz="0.5415320000000001 0.4928149999999997 0.12047512562448892"/>
		<axis xyz="0 0 -0.7071058291548576"/>
		<child link="link_0"/>
		<parent link="link_4"/>
		<limit lower="-3.9269908169872414" upper="0.7853981633974483"/>
	</joint>
	<link name="link_1">
		<visual name="rotation_lid-2">
			<origin xyz="-0.2666913885462854 -0.4928920002488574 -0.5441690000000003"/>
			<geometry>
				<mesh filename="textured_objs/original-2.obj"/>
			</geometry>
		</visual>
		<collision>
			<origin xyz="-0.2666913885462854 -0.4928920002488574 -0.5441690000000003"/>
			<geometry>
				<mesh filename="textured_objs/original-2.obj"/>
			</geometry>
		</collision>
	</link>
	<joint name="joint_1" type="revolute">
		<origin xyz="0.2666913885462854 0.4928920002488574 0.5441690000000003"/>
		<axis xyz="0.7071056385289832 0 0"/>
		<child link="link_1"/>
		<parent link="link_4"/>
		<limit lower="-3.9269908169872414" upper="0.7853981633974483"/>
	</joint>
	<link name="link_2">
		<visual name="rotation_lid-3">
			<origin xyz="0.508651 -0.4929150000000001 -0.3247957845519003"/>
			<geometry>
				<mesh filename="textured_objs/original-7.obj"/>
			</geometry>
		</visual>
		<collision>
			<origin xyz="0.508651 -0.4929150000000001 -0.3247957845519003"/>
			<geometry>
				<mesh filename="textured_objs/original-7.obj"/>
			</geometry>
		</collision>
	</link>
	<joint name="joint_2" type="revolute">
		<origin xyz="-0.508651 0.4929150000000001 0.3247957845519003"/>
		<axis xyz="0 5.0332671997356735e-17 0.7071067811865475"/>
		<child link="link_2"/>
		<parent link="link_4"/>
		<limit lower="-3.9269908169872414" upper="0.7853981633974483"/>
	</joint>
	<link name="link_3">
		<visual name="rotation_lid-4">
			<origin xyz="-0.17643536657736947 -0.492881 0.506014"/>
			<geometry>
				<mesh filename="textured_objs/original-1.obj"/>
			</geometry>
		</visual>
		<collision>
			<origin xyz="-0.17643536657736947 -0.492881 0.506014"/>
			<geometry>
				<mesh filename="textured_objs/original-1.obj"/>
			</geometry>
		</collision>
	</link>
	<joint name="joint_3" type="revolute">
		<origin xyz="0.17643536657736947 0.492881 -0.506014"/>
		<axis xyz="-0.7071079237204103 0 0"/>
		<child link="link_3"/>
		<parent link="link_4"/>
		<limit lower="-3.9269908169872414" upper="0.7853981633974483"/>
	</joint>
	<link name="link_4">
		<visual name="base_body-5">
			<origin xyz="0 0 0"/>
			<geometry>
				<mesh filename="textured_objs/original-4.obj"/>
			</geometry>
		</visual>
		<visual name="base_body-5">
			<origin xyz="0 0 0"/>
			<geometry>
				<mesh filename="textured_objs/original-3.obj"/>
			</geometry>
		</visual>
		<visual name="base_body-5">
			<origin xyz="0 0 0"/>
			<geometry>
				<mesh filename="textured_objs/original-9.obj"/>
			</geometry>
		</visual>
		<visual name="base_body-5">
			<origin xyz="0 0 0"/>
			<geometry>
				<mesh filename="textured_objs/original-5.obj"/>
			</geometry>
		</visual>
		<visual name="base_body-5">
			<origin xyz="0 0 0"/>
			<geometry>
				<mesh filename="textured_objs/original-6.obj"/>
			</geometry>
		</visual>
		<visual name="base_body-5">
			<origin xyz="0 0 0"/>
			<geometry>
				<mesh filename="textured_objs/original-10.obj"/>
			</geometry>
		</visual>
		<collision>
			<origin xyz="0 0 0"/>
			<geometry>
				<mesh filename="textured_objs/original-4.obj"/>
			</geometry>
		</collision>
		<collision>
			<origin xyz="0 0 0"/>
			<geometry>
				<mesh filename="textured_objs/original-3.obj"/>
			</geometry>
		</collision>
		<collision>
			<origin xyz="0 0 0"/>
			<geometry>
				<mesh filename="textured_objs/original-9.obj"/>
			</geometry>
		</collision>
		<collision>
			<origin xyz="0 0 0"/>
			<geometry>
				<mesh filename="textured_objs/original-5.obj"/>
			</geometry>
		</collision>
		<collision>
			<origin xyz="0 0 0"/>
			<geometry>
				<mesh filename="textured_objs/original-6.obj"/>
			</geometry>
		</collision>
		<collision>
			<origin xyz="0 0 0"/>
			<geometry>
				<mesh filename="textured_objs/original-10.obj"/>
			</geometry>
		</collision>
	</link>
	<joint name="joint_4" type="fixed">
		<origin rpy="1.570796326794897 0 -1.570796326794897" xyz="0 0 0"/>
		<child link="link_4"/>
		<parent link="base"/>
	</joint>
</robot>
