<?xml version="1.0" ?>
<robot name="partnet_77699e08e3824eab47765668cf4023ed">
	<link name="base"/>
	<link name="link_0">
		<visual name="body-5">
			<origin xyz="0 0 0"/>
			<geometry>
				<mesh filename="textured_objs/new-1.obj"/>
			</geometry>
		</visual>
		<collision>
			<origin xyz="0 0 0"/>
			<geometry>
				<mesh filename="textured_objs/new-1.obj"/>
			</geometry>
		</collision>
	</link>
	<joint name="joint_0" type="fixed">
		<origin rpy="1.570796326794897 0 -1.570796326794897" xyz="0 0 0"/>
		<child link="link_0"/>
		<parent link="base"/>
	</joint>
	<link name="link_1">
		<visual name="lid-6">
			<origin xyz="-0.01959265898874054 0 0.00449257989956206"/>
			<geometry>
				<mesh filename="textured_objs/original-5.obj"/>
			</geometry>
		</visual>
		<collision>
			<origin xyz="-0.01959265898874054 0 0.00449257989956206"/>
			<geometry>
				<mesh filename="textured_objs/original-5.obj"/>
			</geometry>
		</collision>
	</link>
	<joint name="joint_1" type="continuous">
		<origin xyz="0.0 0 0.0"/>
		<axis xyz="0 -1 0"/>
		<child link="link_1"/>
		<parent link="link_1_helper"/>
	</joint>
	<link name="link_1_helper"/>
	<joint name="joint_2" type="prismatic">
		<origin xyz="0.01959265898874054 0 -0.00449257989956206"/>
		<axis xyz="0 1 0"/>
		<child link="link_1_helper"/>
		<parent link="link_0"/>
		<limit lower="-0.04800000000000004" upper="0.09200000000000008"/>
	</joint>
</robot>
