<?xml version="1.0" ?>
<robot name="partnet_97690c4db20227d248e23e2c398d8046">
	<link name="base"/>
	<link name="link_0">
		<visual name="lens-1">
			<origin xyz="-0.13334950584707037 0.05158279685575972 0.0009453114930599449"/>
			<geometry>
				<mesh filename="textured_objs/original-261.obj"/>
			</geometry>
		</visual>
		<visual name="lens-1">
			<origin xyz="-0.13334950584707037 0.05158279685575972 0.0009453114930599449"/>
			<geometry>
				<mesh filename="textured_objs/original-257.obj"/>
			</geometry>
		</visual>
		<visual name="lens-1">
			<origin xyz="-0.13334950584707037 0.05158279685575972 0.0009453114930599449"/>
			<geometry>
				<mesh filename="textured_objs/original-41.obj"/>
			</geometry>
		</visual>
		<visual name="lens-1">
			<origin xyz="-0.13334950584707037 0.05158279685575972 0.0009453114930599449"/>
			<geometry>
				<mesh filename="textured_objs/original-254.obj"/>
			</geometry>
		</visual>
		<visual name="lens-1">
			<origin xyz="-0.13334950584707037 0.05158279685575972 0.0009453114930599449"/>
			<geometry>
				<mesh filename="textured_objs/original-260.obj"/>
			</geometry>
		</visual>
		<visual name="lens-1">
			<origin xyz="-0.13334950584707037 0.05158279685575972 0.0009453114930599449"/>
			<geometry>
				<mesh filename="textured_objs/original-265.obj"/>
			</geometry>
		</visual>
		<visual name="lens-1">
			<origin xyz="-0.13334950584707037 0.05158279685575972 0.0009453114930599449"/>
			<geometry>
				<mesh filename="textured_objs/original-40.obj"/>
			</geometry>
		</visual>
		<visual name="lens-1">
			<origin xyz="-0.13334950584707037 0.05158279685575972 0.0009453114930599449"/>
			<geometry>
				<mesh filename="textured_objs/original-268.obj"/>
			</geometry>
		</visual>
		<visual name="lens-1">
			<origin xyz="-0.13334950584707037 0.05158279685575972 0.0009453114930599449"/>
			<geometry>
				<mesh filename="textured_objs/original-279.obj"/>
			</geometry>
		</visual>
		<visual name="lens-1">
			<origin xyz="-0.13334950584707037 0.05158279685575972 0.0009453114930599449"/>
			<geometry>
				<mesh filename="textured_objs/original-267.obj"/>
			</geometry>
		</visual>
		<visual name="lens-1">
			<origin xyz="-0.13334950584707037 0.05158279685575972 0.0009453114930599449"/>
			<geometry>
				<mesh filename="textured_objs/original-264.obj"/>
			</geometry>
		</visual>
		<visual name="lens-1">
			<origin xyz="-0.13334950584707037 0.05158279685575972 0.0009453114930599449"/>
			<geometry>
				<mesh filename="textured_objs/original-263.obj"/>
			</geometry>
		</visual>
		<visual name="lens-1">
			<origin xyz="-0.13334950584707037 0.05158279685575972 0.0009453114930599449"/>
			<geometry>
				<mesh filename="textured_objs/original-266.obj"/>
			</geometry>
		</visual>
		<visual name="lens-1">
			<origin xyz="-0.13334950584707037 0.05158279685575972 0.0009453114930599449"/>
			<geometry>
				<mesh filename="textured_objs/original-39.obj"/>
			</geometry>
		</visual>
		<visual name="lens-1">
			<origin xyz="-0.13334950584707037 0.05158279685575972 0.0009453114930599449"/>
			<geometry>
				<mesh filename="textured_objs/original-270.obj"/>
			</geometry>
		</visual>
		<visual name="lens-1">
			<origin xyz="-0.13334950584707037 0.05158279685575972 0.0009453114930599449"/>
			<geometry>
				<mesh filename="textured_objs/original-273.obj"/>
			</geometry>
		</visual>
		<visual name="lens-1">
			<origin xyz="-0.13334950584707037 0.05158279685575972 0.0009453114930599449"/>
			<geometry>
				<mesh filename="textured_objs/original-277.obj"/>
			</geometry>
		</visual>
		<visual name="lens-1">
			<origin xyz="-0.13334950584707037 0.05158279685575972 0.0009453114930599449"/>
			<geometry>
				<mesh filename="textured_objs/original-282.obj"/>
			</geometry>
		</visual>
		<visual name="lens-1">
			<origin xyz="-0.13334950584707037 0.05158279685575972 0.0009453114930599449"/>
			<geometry>
				<mesh filename="textured_objs/original-278.obj"/>
			</geometry>
		</visual>
		<visual name="lens-1">
			<origin xyz="-0.13334950584707037 0.05158279685575972 0.0009453114930599449"/>
			<geometry>
				<mesh filename="textured_objs/original-281.obj"/>
			</geometry>
		</visual>
		<visual name="lens-1">
			<origin xyz="-0.13334950584707037 0.05158279685575972 0.0009453114930599449"/>
			<geometry>
				<mesh filename="textured_objs/original-283.obj"/>
			</geometry>
		</visual>
		<visual name="lens-1">
			<origin xyz="-0.13334950584707037 0.05158279685575972 0.0009453114930599449"/>
			<geometry>
				<mesh filename="textured_objs/original-280.obj"/>
			</geometry>
		</visual>
		<visual name="lens-1">
			<origin xyz="-0.13334950584707037 0.05158279685575972 0.0009453114930599449"/>
			<geometry>
				<mesh filename="textured_objs/original-276.obj"/>
			</geometry>
		</visual>
		<visual name="lens-1">
			<origin xyz="-0.13334950584707037 0.05158279685575972 0.0009453114930599449"/>
			<geometry>
				<mesh filename="textured_objs/original-272.obj"/>
			</geometry>
		</visual>
		<visual name="lens-1">
			<origin xyz="-0.13334950584707037 0.05158279685575972 0.0009453114930599449"/>
			<geometry>
				<mesh filename="textured_objs/original-45.obj"/>
			</geometry>
		</visual>
		<visual name="lens-1">
			<origin xyz="-0.13334950584707037 0.05158279685575972 0.0009453114930599449"/>
			<geometry>
				<mesh filename="textured_objs/original-44.obj"/>
			</geometry>
		</visual>
		<visual name="lens-1">
			<origin xyz="-0.13334950584707037 0.05158279685575972 0.0009453114930599449"/>
			<geometry>
				<mesh filename="textured_objs/original-275.obj"/>
			</geometry>
		</visual>
		<visual name="lens-1">
			<origin xyz="-0.13334950584707037 0.05158279685575972 0.0009453114930599449"/>
			<geometry>
				<mesh filename="textured_objs/original-274.obj"/>
			</geometry>
		</visual>
		<visual name="lens-1">
			<origin xyz="-0.13334950584707037 0.05158279685575972 0.0009453114930599449"/>
			<geometry>
				<mesh filename="textured_objs/original-271.obj"/>
			</geometry>
		</visual>
		<visual name="lens-1">
			<origin xyz="-0.13334950584707037 0.05158279685575972 0.0009453114930599449"/>
			<geometry>
				<mesh filename="textured_objs/original-269.obj"/>
			</geometry>
		</visual>
		<visual name="lens-1">
			<origin xyz="-0.13334950584707037 0.05158279685575972 0.0009453114930599449"/>
			<geometry>
				<mesh filename="textured_objs/original-43.obj"/>
			</geometry>
		</visual>
		<visual name="lens-1">
			<origin xyz="-0.13334950584707037 0.05158279685575972 0.0009453114930599449"/>
			<geometry>
				<mesh filename="textured_objs/original-262.obj"/>
			</geometry>
		</visual>
		<visual name="lens-1">
			<origin xyz="-0.13334950584707037 0.05158279685575972 0.0009453114930599449"/>
			<geometry>
				<mesh filename="textured_objs/original-259.obj"/>
			</geometry>
		</visual>
		<visual name="lens-1">
			<origin xyz="-0.13334950584707037 0.05158279685575972 0.0009453114930599449"/>
			<geometry>
				<mesh filename="textured_objs/original-258.obj"/>
			</geometry>
		</visual>
		<visual name="lens-1">
			<origin xyz="-0.13334950584707037 0.05158279685575972 0.0009453114930599449"/>
			<geometry>
				<mesh filename="textured_objs/original-42.obj"/>
			</geometry>
		</visual>
		<visual name="lens-1">
			<origin xyz="-0.13334950584707037 0.05158279685575972 0.0009453114930599449"/>
			<geometry>
				<mesh filename="textured_objs/original-256.obj"/>
			</geometry>
		</visual>
		<visual name="lens-1">
			<origin xyz="-0.13334950584707037 0.05158279685575972 0.0009453114930599449"/>
			<geometry>
				<mesh filename="textured_objs/original-255.obj"/>
			</geometry>
		</visual>
		<visual name="lens-1">
			<origin xyz="-0.13334950584707037 0.05158279685575972 0.0009453114930599449"/>
			<geometry>
				<mesh filename="textured_objs/original-250.obj"/>
			</geometry>
		</visual>
		<visual name="lens-1">
			<origin xyz="-0.13334950584707037 0.05158279685575972 0.0009453114930599449"/>
			<geometry>
				<mesh filename="textured_objs/original-252.obj"/>
			</geometry>
		</visual>
		<visual name="lens-1">
			<origin xyz="-0.13334950584707037 0.05158279685575972 0.0009453114930599449"/>
			<geometry>
				<mesh filename="textured_objs/original-251.obj"/>
			</geometry>
		</visual>
		<visual name="lens-1">
			<origin xyz="-0.13334950584707037 0.05158279685575972 0.0009453114930599449"/>
			<geometry>
				<mesh filename="textured_objs/original-253.obj"/>
			</geometry>
		</visual>
		<collision>
			<origin xyz="-0.13334950584707037 0.05158279685575972 0.0009453114930599449"/>
			<geometry>
				<mesh filename="textured_objs/original-261.obj"/>
			</geometry>
		</collision>
		<collision>
			<origin xyz="-0.13334950584707037 0.05158279685575972 0.0009453114930599449"/>
			<geometry>
				<mesh filename="textured_objs/original-257.obj"/>
			</geometry>
		</collision>
		<collision>
			<origin xyz="-0.13334950584707037 0.05158279685575972 0.0009453114930599449"/>
			<geometry>
				<mesh filename="textured_objs/original-41.obj"/>
			</geometry>
		</collision>
		<collision>
			<origin xyz="-0.13334950584707037 0.05158279685575972 0.0009453114930599449"/>
			<geometry>
				<mesh filename="textured_objs/original-254.obj"/>
			</geometry>
		</collision>
		<collision>
			<origin xyz="-0.13334950584707037 0.05158279685575972 0.0009453114930599449"/>
			<geometry>
				<mesh filename="textured_objs/original-260.obj"/>
			</geometry>
		</collision>
		<collision>
			<origin xyz="-0.13334950584707037 0.05158279685575972 0.0009453114930599449"/>
			<geometry>
				<mesh filename="textured_objs/original-265.obj"/>
			</geometry>
		</collision>
		<collision>
			<origin xyz="-0.13334950584707037 0.05158279685575972 0.0009453114930599449"/>
			<geometry>
				<mesh filename="textured_objs/original-40.obj"/>
			</geometry>
		</collision>
		<collision>
			<origin xyz="-0.13334950584707037 0.05158279685575972 0.0009453114930599449"/>
			<geometry>
				<mesh filename="textured_objs/original-268.obj"/>
			</geometry>
		</collision>
		<collision>
			<origin xyz="-0.13334950584707037 0.05158279685575972 0.0009453114930599449"/>
			<geometry>
				<mesh filename="textured_objs/original-279.obj"/>
			</geometry>
		</collision>
		<collision>
			<origin xyz="-0.13334950584707037 0.05158279685575972 0.0009453114930599449"/>
			<geometry>
				<mesh filename="textured_objs/original-267.obj"/>
			</geometry>
		</collision>
		<collision>
			<origin xyz="-0.13334950584707037 0.05158279685575972 0.0009453114930599449"/>
			<geometry>
				<mesh filename="textured_objs/original-264.obj"/>
			</geometry>
		</collision>
		<collision>
			<origin xyz="-0.13334950584707037 0.05158279685575972 0.0009453114930599449"/>
			<geometry>
				<mesh filename="textured_objs/original-263.obj"/>
			</geometry>
		</collision>
		<collision>
			<origin xyz="-0.13334950584707037 0.05158279685575972 0.0009453114930599449"/>
			<geometry>
				<mesh filename="textured_objs/original-266.obj"/>
			</geometry>
		</collision>
		<collision>
			<origin xyz="-0.13334950584707037 0.05158279685575972 0.0009453114930599449"/>
			<geometry>
				<mesh filename="textured_objs/original-39.obj"/>
			</geometry>
		</collision>
		<collision>
			<origin xyz="-0.13334950584707037 0.05158279685575972 0.0009453114930599449"/>
			<geometry>
				<mesh filename="textured_objs/original-270.obj"/>
			</geometry>
		</collision>
		<collision>
			<origin xyz="-0.13334950584707037 0.05158279685575972 0.0009453114930599449"/>
			<geometry>
				<mesh filename="textured_objs/original-273.obj"/>
			</geometry>
		</collision>
		<collision>
			<origin xyz="-0.13334950584707037 0.05158279685575972 0.0009453114930599449"/>
			<geometry>
				<mesh filename="textured_objs/original-277.obj"/>
			</geometry>
		</collision>
		<collision>
			<origin xyz="-0.13334950584707037 0.05158279685575972 0.0009453114930599449"/>
			<geometry>
				<mesh filename="textured_objs/original-282.obj"/>
			</geometry>
		</collision>
		<collision>
			<origin xyz="-0.13334950584707037 0.05158279685575972 0.0009453114930599449"/>
			<geometry>
				<mesh filename="textured_objs/original-278.obj"/>
			</geometry>
		</collision>
		<collision>
			<origin xyz="-0.13334950584707037 0.05158279685575972 0.0009453114930599449"/>
			<geometry>
				<mesh filename="textured_objs/original-281.obj"/>
			</geometry>
		</collision>
		<collision>
			<origin xyz="-0.13334950584707037 0.05158279685575972 0.0009453114930599449"/>
			<geometry>
				<mesh filename="textured_objs/original-283.obj"/>
			</geometry>
		</collision>
		<collision>
			<origin xyz="-0.13334950584707037 0.05158279685575972 0.0009453114930599449"/>
			<geometry>
				<mesh filename="textured_objs/original-280.obj"/>
			</geometry>
		</collision>
		<collision>
			<origin xyz="-0.13334950584707037 0.05158279685575972 0.0009453114930599449"/>
			<geometry>
				<mesh filename="textured_objs/original-276.obj"/>
			</geometry>
		</collision>
		<collision>
			<origin xyz="-0.13334950584707037 0.05158279685575972 0.0009453114930599449"/>
			<geometry>
				<mesh filename="textured_objs/original-272.obj"/>
			</geometry>
		</collision>
		<collision>
			<origin xyz="-0.13334950584707037 0.05158279685575972 0.0009453114930599449"/>
			<geometry>
				<mesh filename="textured_objs/original-45.obj"/>
			</geometry>
		</collision>
		<collision>
			<origin xyz="-0.13334950584707037 0.05158279685575972 0.0009453114930599449"/>
			<geometry>
				<mesh filename="textured_objs/original-44.obj"/>
			</geometry>
		</collision>
		<collision>
			<origin xyz="-0.13334950584707037 0.05158279685575972 0.0009453114930599449"/>
			<geometry>
				<mesh filename="textured_objs/original-275.obj"/>
			</geometry>
		</collision>
		<collision>
			<origin xyz="-0.13334950584707037 0.05158279685575972 0.0009453114930599449"/>
			<geometry>
				<mesh filename="textured_objs/original-274.obj"/>
			</geometry>
		</collision>
		<collision>
			<origin xyz="-0.13334950584707037 0.05158279685575972 0.0009453114930599449"/>
			<geometry>
				<mesh filename="textured_objs/original-271.obj"/>
			</geometry>
		</collision>
		<collision>
			<origin xyz="-0.13334950584707037 0.05158279685575972 0.0009453114930599449"/>
			<geometry>
				<mesh filename="textured_objs/original-269.obj"/>
			</geometry>
		</collision>
		<collision>
			<origin xyz="-0.13334950584707037 0.05158279685575972 0.0009453114930599449"/>
			<geometry>
				<mesh filename="textured_objs/original-43.obj"/>
			</geometry>
		</collision>
		<collision>
			<origin xyz="-0.13334950584707037 0.05158279685575972 0.0009453114930599449"/>
			<geometry>
				<mesh filename="textured_objs/original-262.obj"/>
			</geometry>
		</collision>
		<collision>
			<origin xyz="-0.13334950584707037 0.05158279685575972 0.0009453114930599449"/>
			<geometry>
				<mesh filename="textured_objs/original-259.obj"/>
			</geometry>
		</collision>
		<collision>
			<origin xyz="-0.13334950584707037 0.05158279685575972 0.0009453114930599449"/>
			<geometry>
				<mesh filename="textured_objs/original-258.obj"/>
			</geometry>
		</collision>
		<collision>
			<origin xyz="-0.13334950584707037 0.05158279685575972 0.0009453114930599449"/>
			<geometry>
				<mesh filename="textured_objs/original-42.obj"/>
			</geometry>
		</collision>
		<collision>
			<origin xyz="-0.13334950584707037 0.05158279685575972 0.0009453114930599449"/>
			<geometry>
				<mesh filename="textured_objs/original-256.obj"/>
			</geometry>
		</collision>
		<collision>
			<origin xyz="-0.13334950584707037 0.05158279685575972 0.0009453114930599449"/>
			<geometry>
				<mesh filename="textured_objs/original-255.obj"/>
			</geometry>
		</collision>
		<collision>
			<origin xyz="-0.13334950584707037 0.05158279685575972 0.0009453114930599449"/>
			<geometry>
				<mesh filename="textured_objs/original-250.obj"/>
			</geometry>
		</collision>
		<collision>
			<origin xyz="-0.13334950584707037 0.05158279685575972 0.0009453114930599449"/>
			<geometry>
				<mesh filename="textured_objs/original-252.obj"/>
			</geometry>
		</collision>
		<collision>
			<origin xyz="-0.13334950584707037 0.05158279685575972 0.0009453114930599449"/>
			<geometry>
				<mesh filename="textured_objs/original-251.obj"/>
			</geometry>
		</collision>
		<collision>
			<origin xyz="-0.13334950584707037 0.05158279685575972 0.0009453114930599449"/>
			<geometry>
				<mesh filename="textured_objs/original-253.obj"/>
			</geometry>
		</collision>
	</link>
	<joint name="joint_0" type="continuous">
		<origin xyz="0.13334950584707037 -0.05158279685575972 -0.0009453114930599449"/>
		<axis xyz="0.00011592169093518061 0.018622598301703108 -0.9998265776596735"/>
		<child link="link_0"/>
		<parent link="link_9"/>
	</joint>
	<link name="link_1">
		<visual name="button-2">
			<origin xyz="0 0 0"/>
			<geometry>
				<mesh filename="textured_objs/original-168.obj"/>
			</geometry>
		</visual>
		<collision>
			<origin xyz="0 0 0"/>
			<geometry>
				<mesh filename="textured_objs/original-168.obj"/>
			</geometry>
		</collision>
	</link>
	<joint name="joint_1" type="prismatic">
		<origin xyz="0 0 0"/>
		<axis xyz="0 -1 0"/>
		<child link="link_1"/>
		<parent link="link_9"/>
		<limit lower="0" upper="0.005"/>
	</joint>
	<link name="link_2">
		<visual name="button-3">
			<origin xyz="0 0 0"/>
			<geometry>
				<mesh filename="textured_objs/original-163.obj"/>
			</geometry>
		</visual>
		<collision>
			<origin xyz="0 0 0"/>
			<geometry>
				<mesh filename="textured_objs/original-163.obj"/>
			</geometry>
		</collision>
	</link>
	<joint name="joint_2" type="prismatic">
		<origin xyz="0 0 0"/>
		<axis xyz="0 -1 0"/>
		<child link="link_2"/>
		<parent link="link_9"/>
		<limit lower="0" upper="0.005"/>
	</joint>
	<link name="link_3">
		<visual name="button-4">
			<origin xyz="0 0 0"/>
			<geometry>
				<mesh filename="textured_objs/original-167.obj"/>
			</geometry>
		</visual>
		<collision>
			<origin xyz="0 0 0"/>
			<geometry>
				<mesh filename="textured_objs/original-167.obj"/>
			</geometry>
		</collision>
	</link>
	<joint name="joint_3" type="prismatic">
		<origin xyz="0 0 0"/>
		<axis xyz="0 -1 0"/>
		<child link="link_3"/>
		<parent link="link_9"/>
		<limit lower="0" upper="0.005"/>
	</joint>
	<link name="link_4">
		<visual name="button-5">
			<origin xyz="0 0 0"/>
			<geometry>
				<mesh filename="textured_objs/original-165.obj"/>
			</geometry>
		</visual>
		<collision>
			<origin xyz="0 0 0"/>
			<geometry>
				<mesh filename="textured_objs/original-165.obj"/>
			</geometry>
		</collision>
	</link>
	<joint name="joint_4" type="prismatic">
		<origin xyz="0 0 0"/>
		<axis xyz="0 -1 0"/>
		<child link="link_4"/>
		<parent link="link_9"/>
		<limit lower="0" upper="0.005"/>
	</joint>
	<link name="link_5">
		<visual name="button-6">
			<origin xyz="0 0 0"/>
			<geometry>
				<mesh filename="textured_objs/original-166.obj"/>
			</geometry>
		</visual>
		<collision>
			<origin xyz="0 0 0"/>
			<geometry>
				<mesh filename="textured_objs/original-166.obj"/>
			</geometry>
		</collision>
	</link>
	<joint name="joint_5" type="prismatic">
		<origin xyz="0 0 0"/>
		<axis xyz="0 -1 0"/>
		<child link="link_5"/>
		<parent link="link_9"/>
		<limit lower="0" upper="0.005"/>
	</joint>
	<link name="link_6">
		<visual name="lid-7">
			<origin xyz="-0.13334950584707037 0.05158279685575971 0.0009453114930599447"/>
			<geometry>
				<mesh filename="textured_objs/original-196.obj"/>
			</geometry>
		</visual>
		<visual name="lid-7">
			<origin xyz="-0.13334950584707037 0.05158279685575971 0.0009453114930599447"/>
			<geometry>
				<mesh filename="textured_objs/original-35.obj"/>
			</geometry>
		</visual>
		<visual name="lid-7">
			<origin xyz="-0.13334950584707037 0.05158279685575971 0.0009453114930599447"/>
			<geometry>
				<mesh filename="textured_objs/original-197.obj"/>
			</geometry>
		</visual>
		<visual name="lid-7">
			<origin xyz="-0.13334950584707037 0.05158279685575971 0.0009453114930599447"/>
			<geometry>
				<mesh filename="textured_objs/original-200.obj"/>
			</geometry>
		</visual>
		<visual name="lid-7">
			<origin xyz="-0.13334950584707037 0.05158279685575971 0.0009453114930599447"/>
			<geometry>
				<mesh filename="textured_objs/original-202.obj"/>
			</geometry>
		</visual>
		<visual name="lid-7">
			<origin xyz="-0.13334950584707037 0.05158279685575971 0.0009453114930599447"/>
			<geometry>
				<mesh filename="textured_objs/original-205.obj"/>
			</geometry>
		</visual>
		<visual name="lid-7">
			<origin xyz="-0.13334950584707037 0.05158279685575971 0.0009453114930599447"/>
			<geometry>
				<mesh filename="textured_objs/original-215.obj"/>
			</geometry>
		</visual>
		<visual name="lid-7">
			<origin xyz="-0.13334950584707037 0.05158279685575971 0.0009453114930599447"/>
			<geometry>
				<mesh filename="textured_objs/original-226.obj"/>
			</geometry>
		</visual>
		<visual name="lid-7">
			<origin xyz="-0.13334950584707037 0.05158279685575971 0.0009453114930599447"/>
			<geometry>
				<mesh filename="textured_objs/original-234.obj"/>
			</geometry>
		</visual>
		<visual name="lid-7">
			<origin xyz="-0.13334950584707037 0.05158279685575971 0.0009453114930599447"/>
			<geometry>
				<mesh filename="textured_objs/original-235.obj"/>
			</geometry>
		</visual>
		<visual name="lid-7">
			<origin xyz="-0.13334950584707037 0.05158279685575971 0.0009453114930599447"/>
			<geometry>
				<mesh filename="textured_objs/original-227.obj"/>
			</geometry>
		</visual>
		<visual name="lid-7">
			<origin xyz="-0.13334950584707037 0.05158279685575971 0.0009453114930599447"/>
			<geometry>
				<mesh filename="textured_objs/original-213.obj"/>
			</geometry>
		</visual>
		<visual name="lid-7">
			<origin xyz="-0.13334950584707037 0.05158279685575971 0.0009453114930599447"/>
			<geometry>
				<mesh filename="textured_objs/original-206.obj"/>
			</geometry>
		</visual>
		<visual name="lid-7">
			<origin xyz="-0.13334950584707037 0.05158279685575971 0.0009453114930599447"/>
			<geometry>
				<mesh filename="textured_objs/original-207.obj"/>
			</geometry>
		</visual>
		<visual name="lid-7">
			<origin xyz="-0.13334950584707037 0.05158279685575971 0.0009453114930599447"/>
			<geometry>
				<mesh filename="textured_objs/original-209.obj"/>
			</geometry>
		</visual>
		<visual name="lid-7">
			<origin xyz="-0.13334950584707037 0.05158279685575971 0.0009453114930599447"/>
			<geometry>
				<mesh filename="textured_objs/original-218.obj"/>
			</geometry>
		</visual>
		<visual name="lid-7">
			<origin xyz="-0.13334950584707037 0.05158279685575971 0.0009453114930599447"/>
			<geometry>
				<mesh filename="textured_objs/original-208.obj"/>
			</geometry>
		</visual>
		<visual name="lid-7">
			<origin xyz="-0.13334950584707037 0.05158279685575971 0.0009453114930599447"/>
			<geometry>
				<mesh filename="textured_objs/original-223.obj"/>
			</geometry>
		</visual>
		<visual name="lid-7">
			<origin xyz="-0.13334950584707037 0.05158279685575971 0.0009453114930599447"/>
			<geometry>
				<mesh filename="textured_objs/original-212.obj"/>
			</geometry>
		</visual>
		<visual name="lid-7">
			<origin xyz="-0.13334950584707037 0.05158279685575971 0.0009453114930599447"/>
			<geometry>
				<mesh filename="textured_objs/original-222.obj"/>
			</geometry>
		</visual>
		<visual name="lid-7">
			<origin xyz="-0.13334950584707037 0.05158279685575971 0.0009453114930599447"/>
			<geometry>
				<mesh filename="textured_objs/original-224.obj"/>
			</geometry>
		</visual>
		<visual name="lid-7">
			<origin xyz="-0.13334950584707037 0.05158279685575971 0.0009453114930599447"/>
			<geometry>
				<mesh filename="textured_objs/original-214.obj"/>
			</geometry>
		</visual>
		<visual name="lid-7">
			<origin xyz="-0.13334950584707037 0.05158279685575971 0.0009453114930599447"/>
			<geometry>
				<mesh filename="textured_objs/original-229.obj"/>
			</geometry>
		</visual>
		<visual name="lid-7">
			<origin xyz="-0.13334950584707037 0.05158279685575971 0.0009453114930599447"/>
			<geometry>
				<mesh filename="textured_objs/original-239.obj"/>
			</geometry>
		</visual>
		<visual name="lid-7">
			<origin xyz="-0.13334950584707037 0.05158279685575971 0.0009453114930599447"/>
			<geometry>
				<mesh filename="textured_objs/original-216.obj"/>
			</geometry>
		</visual>
		<visual name="lid-7">
			<origin xyz="-0.13334950584707037 0.05158279685575971 0.0009453114930599447"/>
			<geometry>
				<mesh filename="textured_objs/original-228.obj"/>
			</geometry>
		</visual>
		<visual name="lid-7">
			<origin xyz="-0.13334950584707037 0.05158279685575971 0.0009453114930599447"/>
			<geometry>
				<mesh filename="textured_objs/original-238.obj"/>
			</geometry>
		</visual>
		<visual name="lid-7">
			<origin xyz="-0.13334950584707037 0.05158279685575971 0.0009453114930599447"/>
			<geometry>
				<mesh filename="textured_objs/original-233.obj"/>
			</geometry>
		</visual>
		<visual name="lid-7">
			<origin xyz="-0.13334950584707037 0.05158279685575971 0.0009453114930599447"/>
			<geometry>
				<mesh filename="textured_objs/original-241.obj"/>
			</geometry>
		</visual>
		<visual name="lid-7">
			<origin xyz="-0.13334950584707037 0.05158279685575971 0.0009453114930599447"/>
			<geometry>
				<mesh filename="textured_objs/original-240.obj"/>
			</geometry>
		</visual>
		<visual name="lid-7">
			<origin xyz="-0.13334950584707037 0.05158279685575971 0.0009453114930599447"/>
			<geometry>
				<mesh filename="textured_objs/original-217.obj"/>
			</geometry>
		</visual>
		<visual name="lid-7">
			<origin xyz="-0.13334950584707037 0.05158279685575971 0.0009453114930599447"/>
			<geometry>
				<mesh filename="textured_objs/original-220.obj"/>
			</geometry>
		</visual>
		<visual name="lid-7">
			<origin xyz="-0.13334950584707037 0.05158279685575971 0.0009453114930599447"/>
			<geometry>
				<mesh filename="textured_objs/original-237.obj"/>
			</geometry>
		</visual>
		<visual name="lid-7">
			<origin xyz="-0.13334950584707037 0.05158279685575971 0.0009453114930599447"/>
			<geometry>
				<mesh filename="textured_objs/original-221.obj"/>
			</geometry>
		</visual>
		<visual name="lid-7">
			<origin xyz="-0.13334950584707037 0.05158279685575971 0.0009453114930599447"/>
			<geometry>
				<mesh filename="textured_objs/original-230.obj"/>
			</geometry>
		</visual>
		<visual name="lid-7">
			<origin xyz="-0.13334950584707037 0.05158279685575971 0.0009453114930599447"/>
			<geometry>
				<mesh filename="textured_objs/original-225.obj"/>
			</geometry>
		</visual>
		<visual name="lid-7">
			<origin xyz="-0.13334950584707037 0.05158279685575971 0.0009453114930599447"/>
			<geometry>
				<mesh filename="textured_objs/original-191.obj"/>
			</geometry>
		</visual>
		<visual name="lid-7">
			<origin xyz="-0.13334950584707037 0.05158279685575971 0.0009453114930599447"/>
			<geometry>
				<mesh filename="textured_objs/original-231.obj"/>
			</geometry>
		</visual>
		<visual name="lid-7">
			<origin xyz="-0.13334950584707037 0.05158279685575971 0.0009453114930599447"/>
			<geometry>
				<mesh filename="textured_objs/original-243.obj"/>
			</geometry>
		</visual>
		<visual name="lid-7">
			<origin xyz="-0.13334950584707037 0.05158279685575971 0.0009453114930599447"/>
			<geometry>
				<mesh filename="textured_objs/original-245.obj"/>
			</geometry>
		</visual>
		<visual name="lid-7">
			<origin xyz="-0.13334950584707037 0.05158279685575971 0.0009453114930599447"/>
			<geometry>
				<mesh filename="textured_objs/original-248.obj"/>
			</geometry>
		</visual>
		<visual name="lid-7">
			<origin xyz="-0.13334950584707037 0.05158279685575971 0.0009453114930599447"/>
			<geometry>
				<mesh filename="textured_objs/original-247.obj"/>
			</geometry>
		</visual>
		<visual name="lid-7">
			<origin xyz="-0.13334950584707037 0.05158279685575971 0.0009453114930599447"/>
			<geometry>
				<mesh filename="textured_objs/original-246.obj"/>
			</geometry>
		</visual>
		<visual name="lid-7">
			<origin xyz="-0.13334950584707037 0.05158279685575971 0.0009453114930599447"/>
			<geometry>
				<mesh filename="textured_objs/original-244.obj"/>
			</geometry>
		</visual>
		<visual name="lid-7">
			<origin xyz="-0.13334950584707037 0.05158279685575971 0.0009453114930599447"/>
			<geometry>
				<mesh filename="textured_objs/original-242.obj"/>
			</geometry>
		</visual>
		<visual name="lid-7">
			<origin xyz="-0.13334950584707037 0.05158279685575971 0.0009453114930599447"/>
			<geometry>
				<mesh filename="textured_objs/original-236.obj"/>
			</geometry>
		</visual>
		<visual name="lid-7">
			<origin xyz="-0.13334950584707037 0.05158279685575971 0.0009453114930599447"/>
			<geometry>
				<mesh filename="textured_objs/original-232.obj"/>
			</geometry>
		</visual>
		<visual name="lid-7">
			<origin xyz="-0.13334950584707037 0.05158279685575971 0.0009453114930599447"/>
			<geometry>
				<mesh filename="textured_objs/original-219.obj"/>
			</geometry>
		</visual>
		<visual name="lid-7">
			<origin xyz="-0.13334950584707037 0.05158279685575971 0.0009453114930599447"/>
			<geometry>
				<mesh filename="textured_objs/original-210.obj"/>
			</geometry>
		</visual>
		<visual name="lid-7">
			<origin xyz="-0.13334950584707037 0.05158279685575971 0.0009453114930599447"/>
			<geometry>
				<mesh filename="textured_objs/original-211.obj"/>
			</geometry>
		</visual>
		<visual name="lid-7">
			<origin xyz="-0.13334950584707037 0.05158279685575971 0.0009453114930599447"/>
			<geometry>
				<mesh filename="textured_objs/original-204.obj"/>
			</geometry>
		</visual>
		<visual name="lid-7">
			<origin xyz="-0.13334950584707037 0.05158279685575971 0.0009453114930599447"/>
			<geometry>
				<mesh filename="textured_objs/original-203.obj"/>
			</geometry>
		</visual>
		<visual name="lid-7">
			<origin xyz="-0.13334950584707037 0.05158279685575971 0.0009453114930599447"/>
			<geometry>
				<mesh filename="textured_objs/original-201.obj"/>
			</geometry>
		</visual>
		<visual name="lid-7">
			<origin xyz="-0.13334950584707037 0.05158279685575971 0.0009453114930599447"/>
			<geometry>
				<mesh filename="textured_objs/original-199.obj"/>
			</geometry>
		</visual>
		<visual name="lid-7">
			<origin xyz="-0.13334950584707037 0.05158279685575971 0.0009453114930599447"/>
			<geometry>
				<mesh filename="textured_objs/original-198.obj"/>
			</geometry>
		</visual>
		<visual name="lid-7">
			<origin xyz="-0.13334950584707037 0.05158279685575971 0.0009453114930599447"/>
			<geometry>
				<mesh filename="textured_objs/original-195.obj"/>
			</geometry>
		</visual>
		<visual name="lid-7">
			<origin xyz="-0.13334950584707037 0.05158279685575971 0.0009453114930599447"/>
			<geometry>
				<mesh filename="textured_objs/original-193.obj"/>
			</geometry>
		</visual>
		<visual name="lid-7">
			<origin xyz="-0.13334950584707037 0.05158279685575971 0.0009453114930599447"/>
			<geometry>
				<mesh filename="textured_objs/original-192.obj"/>
			</geometry>
		</visual>
		<visual name="lid-7">
			<origin xyz="-0.13334950584707037 0.05158279685575971 0.0009453114930599447"/>
			<geometry>
				<mesh filename="textured_objs/original-194.obj"/>
			</geometry>
		</visual>
		<visual name="lid-7">
			<origin xyz="-0.13334950584707037 0.05158279685575971 0.0009453114930599447"/>
			<geometry>
				<mesh filename="textured_objs/original-249.obj"/>
			</geometry>
		</visual>
		<collision>
			<origin xyz="-0.13334950584707037 0.05158279685575971 0.0009453114930599447"/>
			<geometry>
				<mesh filename="textured_objs/original-196.obj"/>
			</geometry>
		</collision>
		<collision>
			<origin xyz="-0.13334950584707037 0.05158279685575971 0.0009453114930599447"/>
			<geometry>
				<mesh filename="textured_objs/original-35.obj"/>
			</geometry>
		</collision>
		<collision>
			<origin xyz="-0.13334950584707037 0.05158279685575971 0.0009453114930599447"/>
			<geometry>
				<mesh filename="textured_objs/original-197.obj"/>
			</geometry>
		</collision>
		<collision>
			<origin xyz="-0.13334950584707037 0.05158279685575971 0.0009453114930599447"/>
			<geometry>
				<mesh filename="textured_objs/original-200.obj"/>
			</geometry>
		</collision>
		<collision>
			<origin xyz="-0.13334950584707037 0.05158279685575971 0.0009453114930599447"/>
			<geometry>
				<mesh filename="textured_objs/original-202.obj"/>
			</geometry>
		</collision>
		<collision>
			<origin xyz="-0.13334950584707037 0.05158279685575971 0.0009453114930599447"/>
			<geometry>
				<mesh filename="textured_objs/original-205.obj"/>
			</geometry>
		</collision>
		<collision>
			<origin xyz="-0.13334950584707037 0.05158279685575971 0.0009453114930599447"/>
			<geometry>
				<mesh filename="textured_objs/original-215.obj"/>
			</geometry>
		</collision>
		<collision>
			<origin xyz="-0.13334950584707037 0.05158279685575971 0.0009453114930599447"/>
			<geometry>
				<mesh filename="textured_objs/original-226.obj"/>
			</geometry>
		</collision>
		<collision>
			<origin xyz="-0.13334950584707037 0.05158279685575971 0.0009453114930599447"/>
			<geometry>
				<mesh filename="textured_objs/original-234.obj"/>
			</geometry>
		</collision>
		<collision>
			<origin xyz="-0.13334950584707037 0.05158279685575971 0.0009453114930599447"/>
			<geometry>
				<mesh filename="textured_objs/original-235.obj"/>
			</geometry>
		</collision>
		<collision>
			<origin xyz="-0.13334950584707037 0.05158279685575971 0.0009453114930599447"/>
			<geometry>
				<mesh filename="textured_objs/original-227.obj"/>
			</geometry>
		</collision>
		<collision>
			<origin xyz="-0.13334950584707037 0.05158279685575971 0.0009453114930599447"/>
			<geometry>
				<mesh filename="textured_objs/original-213.obj"/>
			</geometry>
		</collision>
		<collision>
			<origin xyz="-0.13334950584707037 0.05158279685575971 0.0009453114930599447"/>
			<geometry>
				<mesh filename="textured_objs/original-206.obj"/>
			</geometry>
		</collision>
		<collision>
			<origin xyz="-0.13334950584707037 0.05158279685575971 0.0009453114930599447"/>
			<geometry>
				<mesh filename="textured_objs/original-207.obj"/>
			</geometry>
		</collision>
		<collision>
			<origin xyz="-0.13334950584707037 0.05158279685575971 0.0009453114930599447"/>
			<geometry>
				<mesh filename="textured_objs/original-209.obj"/>
			</geometry>
		</collision>
		<collision>
			<origin xyz="-0.13334950584707037 0.05158279685575971 0.0009453114930599447"/>
			<geometry>
				<mesh filename="textured_objs/original-218.obj"/>
			</geometry>
		</collision>
		<collision>
			<origin xyz="-0.13334950584707037 0.05158279685575971 0.0009453114930599447"/>
			<geometry>
				<mesh filename="textured_objs/original-208.obj"/>
			</geometry>
		</collision>
		<collision>
			<origin xyz="-0.13334950584707037 0.05158279685575971 0.0009453114930599447"/>
			<geometry>
				<mesh filename="textured_objs/original-223.obj"/>
			</geometry>
		</collision>
		<collision>
			<origin xyz="-0.13334950584707037 0.05158279685575971 0.0009453114930599447"/>
			<geometry>
				<mesh filename="textured_objs/original-212.obj"/>
			</geometry>
		</collision>
		<collision>
			<origin xyz="-0.13334950584707037 0.05158279685575971 0.0009453114930599447"/>
			<geometry>
				<mesh filename="textured_objs/original-222.obj"/>
			</geometry>
		</collision>
		<collision>
			<origin xyz="-0.13334950584707037 0.05158279685575971 0.0009453114930599447"/>
			<geometry>
				<mesh filename="textured_objs/original-224.obj"/>
			</geometry>
		</collision>
		<collision>
			<origin xyz="-0.13334950584707037 0.05158279685575971 0.0009453114930599447"/>
			<geometry>
				<mesh filename="textured_objs/original-214.obj"/>
			</geometry>
		</collision>
		<collision>
			<origin xyz="-0.13334950584707037 0.05158279685575971 0.0009453114930599447"/>
			<geometry>
				<mesh filename="textured_objs/original-229.obj"/>
			</geometry>
		</collision>
		<collision>
			<origin xyz="-0.13334950584707037 0.05158279685575971 0.0009453114930599447"/>
			<geometry>
				<mesh filename="textured_objs/original-239.obj"/>
			</geometry>
		</collision>
		<collision>
			<origin xyz="-0.13334950584707037 0.05158279685575971 0.0009453114930599447"/>
			<geometry>
				<mesh filename="textured_objs/original-216.obj"/>
			</geometry>
		</collision>
		<collision>
			<origin xyz="-0.13334950584707037 0.05158279685575971 0.0009453114930599447"/>
			<geometry>
				<mesh filename="textured_objs/original-228.obj"/>
			</geometry>
		</collision>
		<collision>
			<origin xyz="-0.13334950584707037 0.05158279685575971 0.0009453114930599447"/>
			<geometry>
				<mesh filename="textured_objs/original-238.obj"/>
			</geometry>
		</collision>
		<collision>
			<origin xyz="-0.13334950584707037 0.05158279685575971 0.0009453114930599447"/>
			<geometry>
				<mesh filename="textured_objs/original-233.obj"/>
			</geometry>
		</collision>
		<collision>
			<origin xyz="-0.13334950584707037 0.05158279685575971 0.0009453114930599447"/>
			<geometry>
				<mesh filename="textured_objs/original-241.obj"/>
			</geometry>
		</collision>
		<collision>
			<origin xyz="-0.13334950584707037 0.05158279685575971 0.0009453114930599447"/>
			<geometry>
				<mesh filename="textured_objs/original-240.obj"/>
			</geometry>
		</collision>
		<collision>
			<origin xyz="-0.13334950584707037 0.05158279685575971 0.0009453114930599447"/>
			<geometry>
				<mesh filename="textured_objs/original-217.obj"/>
			</geometry>
		</collision>
		<collision>
			<origin xyz="-0.13334950584707037 0.05158279685575971 0.0009453114930599447"/>
			<geometry>
				<mesh filename="textured_objs/original-220.obj"/>
			</geometry>
		</collision>
		<collision>
			<origin xyz="-0.13334950584707037 0.05158279685575971 0.0009453114930599447"/>
			<geometry>
				<mesh filename="textured_objs/original-237.obj"/>
			</geometry>
		</collision>
		<collision>
			<origin xyz="-0.13334950584707037 0.05158279685575971 0.0009453114930599447"/>
			<geometry>
				<mesh filename="textured_objs/original-221.obj"/>
			</geometry>
		</collision>
		<collision>
			<origin xyz="-0.13334950584707037 0.05158279685575971 0.0009453114930599447"/>
			<geometry>
				<mesh filename="textured_objs/original-230.obj"/>
			</geometry>
		</collision>
		<collision>
			<origin xyz="-0.13334950584707037 0.05158279685575971 0.0009453114930599447"/>
			<geometry>
				<mesh filename="textured_objs/original-225.obj"/>
			</geometry>
		</collision>
		<collision>
			<origin xyz="-0.13334950584707037 0.05158279685575971 0.0009453114930599447"/>
			<geometry>
				<mesh filename="textured_objs/original-191.obj"/>
			</geometry>
		</collision>
		<collision>
			<origin xyz="-0.13334950584707037 0.05158279685575971 0.0009453114930599447"/>
			<geometry>
				<mesh filename="textured_objs/original-231.obj"/>
			</geometry>
		</collision>
		<collision>
			<origin xyz="-0.13334950584707037 0.05158279685575971 0.0009453114930599447"/>
			<geometry>
				<mesh filename="textured_objs/original-243.obj"/>
			</geometry>
		</collision>
		<collision>
			<origin xyz="-0.13334950584707037 0.05158279685575971 0.0009453114930599447"/>
			<geometry>
				<mesh filename="textured_objs/original-245.obj"/>
			</geometry>
		</collision>
		<collision>
			<origin xyz="-0.13334950584707037 0.05158279685575971 0.0009453114930599447"/>
			<geometry>
				<mesh filename="textured_objs/original-248.obj"/>
			</geometry>
		</collision>
		<collision>
			<origin xyz="-0.13334950584707037 0.05158279685575971 0.0009453114930599447"/>
			<geometry>
				<mesh filename="textured_objs/original-247.obj"/>
			</geometry>
		</collision>
		<collision>
			<origin xyz="-0.13334950584707037 0.05158279685575971 0.0009453114930599447"/>
			<geometry>
				<mesh filename="textured_objs/original-246.obj"/>
			</geometry>
		</collision>
		<collision>
			<origin xyz="-0.13334950584707037 0.05158279685575971 0.0009453114930599447"/>
			<geometry>
				<mesh filename="textured_objs/original-244.obj"/>
			</geometry>
		</collision>
		<collision>
			<origin xyz="-0.13334950584707037 0.05158279685575971 0.0009453114930599447"/>
			<geometry>
				<mesh filename="textured_objs/original-242.obj"/>
			</geometry>
		</collision>
		<collision>
			<origin xyz="-0.13334950584707037 0.05158279685575971 0.0009453114930599447"/>
			<geometry>
				<mesh filename="textured_objs/original-236.obj"/>
			</geometry>
		</collision>
		<collision>
			<origin xyz="-0.13334950584707037 0.05158279685575971 0.0009453114930599447"/>
			<geometry>
				<mesh filename="textured_objs/original-232.obj"/>
			</geometry>
		</collision>
		<collision>
			<origin xyz="-0.13334950584707037 0.05158279685575971 0.0009453114930599447"/>
			<geometry>
				<mesh filename="textured_objs/original-219.obj"/>
			</geometry>
		</collision>
		<collision>
			<origin xyz="-0.13334950584707037 0.05158279685575971 0.0009453114930599447"/>
			<geometry>
				<mesh filename="textured_objs/original-210.obj"/>
			</geometry>
		</collision>
		<collision>
			<origin xyz="-0.13334950584707037 0.05158279685575971 0.0009453114930599447"/>
			<geometry>
				<mesh filename="textured_objs/original-211.obj"/>
			</geometry>
		</collision>
		<collision>
			<origin xyz="-0.13334950584707037 0.05158279685575971 0.0009453114930599447"/>
			<geometry>
				<mesh filename="textured_objs/original-204.obj"/>
			</geometry>
		</collision>
		<collision>
			<origin xyz="-0.13334950584707037 0.05158279685575971 0.0009453114930599447"/>
			<geometry>
				<mesh filename="textured_objs/original-203.obj"/>
			</geometry>
		</collision>
		<collision>
			<origin xyz="-0.13334950584707037 0.05158279685575971 0.0009453114930599447"/>
			<geometry>
				<mesh filename="textured_objs/original-201.obj"/>
			</geometry>
		</collision>
		<collision>
			<origin xyz="-0.13334950584707037 0.05158279685575971 0.0009453114930599447"/>
			<geometry>
				<mesh filename="textured_objs/original-199.obj"/>
			</geometry>
		</collision>
		<collision>
			<origin xyz="-0.13334950584707037 0.05158279685575971 0.0009453114930599447"/>
			<geometry>
				<mesh filename="textured_objs/original-198.obj"/>
			</geometry>
		</collision>
		<collision>
			<origin xyz="-0.13334950584707037 0.05158279685575971 0.0009453114930599447"/>
			<geometry>
				<mesh filename="textured_objs/original-195.obj"/>
			</geometry>
		</collision>
		<collision>
			<origin xyz="-0.13334950584707037 0.05158279685575971 0.0009453114930599447"/>
			<geometry>
				<mesh filename="textured_objs/original-193.obj"/>
			</geometry>
		</collision>
		<collision>
			<origin xyz="-0.13334950584707037 0.05158279685575971 0.0009453114930599447"/>
			<geometry>
				<mesh filename="textured_objs/original-192.obj"/>
			</geometry>
		</collision>
		<collision>
			<origin xyz="-0.13334950584707037 0.05158279685575971 0.0009453114930599447"/>
			<geometry>
				<mesh filename="textured_objs/original-194.obj"/>
			</geometry>
		</collision>
		<collision>
			<origin xyz="-0.13334950584707037 0.05158279685575971 0.0009453114930599447"/>
			<geometry>
				<mesh filename="textured_objs/original-249.obj"/>
			</geometry>
		</collision>
	</link>
	<joint name="joint_6" type="prismatic">
		<origin xyz="0.0 6.938893903907228e-18 2.168404344971009e-19"/>
		<axis xyz="-0.00011592169093518061 -0.018622598301703108 0.9998265776596735"/>
		<child link="link_6"/>
		<parent link="link_0"/>
		<limit lower="0" upper="0.01"/>
	</joint>
	<link name="link_7">
		<visual name="button-9">
			<origin xyz="0.5379051141176368 -0.3057729441763128 0.026039327396323766"/>
			<geometry>
				<mesh filename="textured_objs/original-52.obj"/>
			</geometry>
		</visual>
		<visual name="button-9">
			<origin xyz="0.5379051141176368 -0.3057729441763128 0.026039327396323766"/>
			<geometry>
				<mesh filename="textured_objs/original-54.obj"/>
			</geometry>
		</visual>
		<visual name="button-9">
			<origin xyz="0.5379051141176368 -0.3057729441763128 0.026039327396323766"/>
			<geometry>
				<mesh filename="textured_objs/original-53.obj"/>
			</geometry>
		</visual>
		<collision>
			<origin xyz="0.5379051141176368 -0.3057729441763128 0.026039327396323766"/>
			<geometry>
				<mesh filename="textured_objs/original-52.obj"/>
			</geometry>
		</collision>
		<collision>
			<origin xyz="0.5379051141176368 -0.3057729441763128 0.026039327396323766"/>
			<geometry>
				<mesh filename="textured_objs/original-54.obj"/>
			</geometry>
		</collision>
		<collision>
			<origin xyz="0.5379051141176368 -0.3057729441763128 0.026039327396323766"/>
			<geometry>
				<mesh filename="textured_objs/original-53.obj"/>
			</geometry>
		</collision>
	</link>
	<joint name="joint_7" type="continuous">
		<origin xyz="-0.5379051141176368 0.3057729441763128 -0.026039327396323766"/>
		<axis xyz="-0.028119946928981388 0.035603714774429945 0.9989702918900905"/>
		<child link="link_7"/>
		<parent link="link_9"/>
	</joint>
	<link name="link_8">
		<visual name="button-10">
			<origin xyz="0.3656472423649019 0.027752174421209568 0.2745861099795114"/>
			<geometry>
				<mesh filename="textured_objs/original-81.obj"/>
			</geometry>
		</visual>
		<visual name="button-10">
			<origin xyz="0.3656472423649019 0.027752174421209568 0.2745861099795114"/>
			<geometry>
				<mesh filename="textured_objs/original-80.obj"/>
			</geometry>
		</visual>
		<collision>
			<origin xyz="0.3656472423649019 0.027752174421209568 0.2745861099795114"/>
			<geometry>
				<mesh filename="textured_objs/original-81.obj"/>
			</geometry>
		</collision>
		<collision>
			<origin xyz="0.3656472423649019 0.027752174421209568 0.2745861099795114"/>
			<geometry>
				<mesh filename="textured_objs/original-80.obj"/>
			</geometry>
		</collision>
	</link>
	<joint name="joint_8" type="continuous">
		<origin xyz="-0.3656472423649019 -0.027752174421209568 -0.2745861099795114"/>
		<axis xyz="0.07570393242486465 -0.9971303393637376 -3.059034106094696e-05"/>
		<child link="link_8"/>
		<parent link="link_9"/>
	</joint>
	<link name="link_9">
		<visual name="base_body-11">
			<origin xyz="0 0 0"/>
			<geometry>
				<mesh filename="textured_objs/original-103.obj"/>
			</geometry>
		</visual>
		<visual name="base_body-11">
			<origin xyz="0 0 0"/>
			<geometry>
				<mesh filename="textured_objs/original-100.obj"/>
			</geometry>
		</visual>
		<visual name="base_body-11">
			<origin xyz="0 0 0"/>
			<geometry>
				<mesh filename="textured_objs/original-123.obj"/>
			</geometry>
		</visual>
		<visual name="base_body-11">
			<origin xyz="0 0 0"/>
			<geometry>
				<mesh filename="textured_objs/original-21.obj"/>
			</geometry>
		</visual>
		<visual name="base_body-11">
			<origin xyz="0 0 0"/>
			<geometry>
				<mesh filename="textured_objs/original-30.obj"/>
			</geometry>
		</visual>
		<visual name="base_body-11">
			<origin xyz="0 0 0"/>
			<geometry>
				<mesh filename="textured_objs/original-152.obj"/>
			</geometry>
		</visual>
		<visual name="base_body-11">
			<origin xyz="0 0 0"/>
			<geometry>
				<mesh filename="textured_objs/original-132.obj"/>
			</geometry>
		</visual>
		<visual name="base_body-11">
			<origin xyz="0 0 0"/>
			<geometry>
				<mesh filename="textured_objs/original-154.obj"/>
			</geometry>
		</visual>
		<visual name="base_body-11">
			<origin xyz="0 0 0"/>
			<geometry>
				<mesh filename="textured_objs/original-126.obj"/>
			</geometry>
		</visual>
		<visual name="base_body-11">
			<origin xyz="0 0 0"/>
			<geometry>
				<mesh filename="textured_objs/original-169.obj"/>
			</geometry>
		</visual>
		<visual name="base_body-11">
			<origin xyz="0 0 0"/>
			<geometry>
				<mesh filename="textured_objs/original-119.obj"/>
			</geometry>
		</visual>
		<visual name="base_body-11">
			<origin xyz="0 0 0"/>
			<geometry>
				<mesh filename="textured_objs/original-188.obj"/>
			</geometry>
		</visual>
		<visual name="base_body-11">
			<origin xyz="0 0 0"/>
			<geometry>
				<mesh filename="textured_objs/original-124.obj"/>
			</geometry>
		</visual>
		<visual name="base_body-11">
			<origin xyz="0 0 0"/>
			<geometry>
				<mesh filename="textured_objs/original-96.obj"/>
			</geometry>
		</visual>
		<visual name="base_body-11">
			<origin xyz="0 0 0"/>
			<geometry>
				<mesh filename="textured_objs/original-64.obj"/>
			</geometry>
		</visual>
		<visual name="base_body-11">
			<origin xyz="0 0 0"/>
			<geometry>
				<mesh filename="textured_objs/original-134.obj"/>
			</geometry>
		</visual>
		<visual name="base_body-11">
			<origin xyz="0 0 0"/>
			<geometry>
				<mesh filename="textured_objs/original-71.obj"/>
			</geometry>
		</visual>
		<visual name="base_body-11">
			<origin xyz="0 0 0"/>
			<geometry>
				<mesh filename="textured_objs/original-83.obj"/>
			</geometry>
		</visual>
		<visual name="base_body-11">
			<origin xyz="0 0 0"/>
			<geometry>
				<mesh filename="textured_objs/original-22.obj"/>
			</geometry>
		</visual>
		<visual name="base_body-11">
			<origin xyz="0 0 0"/>
			<geometry>
				<mesh filename="textured_objs/original-26.obj"/>
			</geometry>
		</visual>
		<visual name="base_body-11">
			<origin xyz="0 0 0"/>
			<geometry>
				<mesh filename="textured_objs/original-117.obj"/>
			</geometry>
		</visual>
		<visual name="base_body-11">
			<origin xyz="0 0 0"/>
			<geometry>
				<mesh filename="textured_objs/original-110.obj"/>
			</geometry>
		</visual>
		<visual name="base_body-11">
			<origin xyz="0 0 0"/>
			<geometry>
				<mesh filename="textured_objs/original-153.obj"/>
			</geometry>
		</visual>
		<visual name="base_body-11">
			<origin xyz="0 0 0"/>
			<geometry>
				<mesh filename="textured_objs/original-107.obj"/>
			</geometry>
		</visual>
		<visual name="base_body-11">
			<origin xyz="0 0 0"/>
			<geometry>
				<mesh filename="textured_objs/original-160.obj"/>
			</geometry>
		</visual>
		<visual name="base_body-11">
			<origin xyz="0 0 0"/>
			<geometry>
				<mesh filename="textured_objs/original-104.obj"/>
			</geometry>
		</visual>
		<visual name="base_body-11">
			<origin xyz="0 0 0"/>
			<geometry>
				<mesh filename="textured_objs/original-149.obj"/>
			</geometry>
		</visual>
		<visual name="base_body-11">
			<origin xyz="0 0 0"/>
			<geometry>
				<mesh filename="textured_objs/original-128.obj"/>
			</geometry>
		</visual>
		<visual name="base_body-11">
			<origin xyz="0 0 0"/>
			<geometry>
				<mesh filename="textured_objs/original-65.obj"/>
			</geometry>
		</visual>
		<visual name="base_body-11">
			<origin xyz="0 0 0"/>
			<geometry>
				<mesh filename="textured_objs/original-130.obj"/>
			</geometry>
		</visual>
		<visual name="base_body-11">
			<origin xyz="0 0 0"/>
			<geometry>
				<mesh filename="textured_objs/original-137.obj"/>
			</geometry>
		</visual>
		<visual name="base_body-11">
			<origin xyz="0 0 0"/>
			<geometry>
				<mesh filename="textured_objs/original-139.obj"/>
			</geometry>
		</visual>
		<visual name="base_body-11">
			<origin xyz="0 0 0"/>
			<geometry>
				<mesh filename="textured_objs/original-112.obj"/>
			</geometry>
		</visual>
		<visual name="base_body-11">
			<origin xyz="0 0 0"/>
			<geometry>
				<mesh filename="textured_objs/original-162.obj"/>
			</geometry>
		</visual>
		<visual name="base_body-11">
			<origin xyz="0 0 0"/>
			<geometry>
				<mesh filename="textured_objs/original-106.obj"/>
			</geometry>
		</visual>
		<visual name="base_body-11">
			<origin xyz="0 0 0"/>
			<geometry>
				<mesh filename="textured_objs/original-86.obj"/>
			</geometry>
		</visual>
		<visual name="base_body-11">
			<origin xyz="0 0 0"/>
			<geometry>
				<mesh filename="textured_objs/original-8.obj"/>
			</geometry>
		</visual>
		<visual name="base_body-11">
			<origin xyz="0 0 0"/>
			<geometry>
				<mesh filename="textured_objs/original-173.obj"/>
			</geometry>
		</visual>
		<visual name="base_body-11">
			<origin xyz="0 0 0"/>
			<geometry>
				<mesh filename="textured_objs/original-140.obj"/>
			</geometry>
		</visual>
		<visual name="base_body-11">
			<origin xyz="0 0 0"/>
			<geometry>
				<mesh filename="textured_objs/original-147.obj"/>
			</geometry>
		</visual>
		<visual name="base_body-11">
			<origin xyz="0 0 0"/>
			<geometry>
				<mesh filename="textured_objs/original-109.obj"/>
			</geometry>
		</visual>
		<visual name="base_body-11">
			<origin xyz="0 0 0"/>
			<geometry>
				<mesh filename="textured_objs/original-9.obj"/>
			</geometry>
		</visual>
		<visual name="base_body-11">
			<origin xyz="0 0 0"/>
			<geometry>
				<mesh filename="textured_objs/original-125.obj"/>
			</geometry>
		</visual>
		<visual name="base_body-11">
			<origin xyz="0 0 0"/>
			<geometry>
				<mesh filename="textured_objs/original-148.obj"/>
			</geometry>
		</visual>
		<visual name="base_body-11">
			<origin xyz="0 0 0"/>
			<geometry>
				<mesh filename="textured_objs/original-172.obj"/>
			</geometry>
		</visual>
		<visual name="base_body-11">
			<origin xyz="0 0 0"/>
			<geometry>
				<mesh filename="textured_objs/original-138.obj"/>
			</geometry>
		</visual>
		<visual name="base_body-11">
			<origin xyz="0 0 0"/>
			<geometry>
				<mesh filename="textured_objs/original-156.obj"/>
			</geometry>
		</visual>
		<visual name="base_body-11">
			<origin xyz="0 0 0"/>
			<geometry>
				<mesh filename="textured_objs/original-286.obj"/>
			</geometry>
		</visual>
		<visual name="base_body-11">
			<origin xyz="0 0 0"/>
			<geometry>
				<mesh filename="textured_objs/original-49.obj"/>
			</geometry>
		</visual>
		<visual name="base_body-11">
			<origin xyz="0 0 0"/>
			<geometry>
				<mesh filename="textured_objs/original-184.obj"/>
			</geometry>
		</visual>
		<visual name="base_body-11">
			<origin xyz="0 0 0"/>
			<geometry>
				<mesh filename="textured_objs/original-93.obj"/>
			</geometry>
		</visual>
		<visual name="base_body-11">
			<origin xyz="0 0 0"/>
			<geometry>
				<mesh filename="textured_objs/original-61.obj"/>
			</geometry>
		</visual>
		<visual name="base_body-11">
			<origin xyz="0 0 0"/>
			<geometry>
				<mesh filename="textured_objs/original-144.obj"/>
			</geometry>
		</visual>
		<visual name="base_body-11">
			<origin xyz="0 0 0"/>
			<geometry>
				<mesh filename="textured_objs/original-120.obj"/>
			</geometry>
		</visual>
		<visual name="base_body-11">
			<origin xyz="0 0 0"/>
			<geometry>
				<mesh filename="textured_objs/original-59.obj"/>
			</geometry>
		</visual>
		<visual name="base_body-11">
			<origin xyz="0 0 0"/>
			<geometry>
				<mesh filename="textured_objs/original-77.obj"/>
			</geometry>
		</visual>
		<visual name="base_body-11">
			<origin xyz="0 0 0"/>
			<geometry>
				<mesh filename="textured_objs/original-114.obj"/>
			</geometry>
		</visual>
		<visual name="base_body-11">
			<origin xyz="0 0 0"/>
			<geometry>
				<mesh filename="textured_objs/original-150.obj"/>
			</geometry>
		</visual>
		<visual name="base_body-11">
			<origin xyz="0 0 0"/>
			<geometry>
				<mesh filename="textured_objs/original-63.obj"/>
			</geometry>
		</visual>
		<visual name="base_body-11">
			<origin xyz="0 0 0"/>
			<geometry>
				<mesh filename="textured_objs/original-185.obj"/>
			</geometry>
		</visual>
		<visual name="base_body-11">
			<origin xyz="0 0 0"/>
			<geometry>
				<mesh filename="textured_objs/original-159.obj"/>
			</geometry>
		</visual>
		<visual name="base_body-11">
			<origin xyz="0 0 0"/>
			<geometry>
				<mesh filename="textured_objs/original-170.obj"/>
			</geometry>
		</visual>
		<visual name="base_body-11">
			<origin xyz="0 0 0"/>
			<geometry>
				<mesh filename="textured_objs/original-87.obj"/>
			</geometry>
		</visual>
		<visual name="base_body-11">
			<origin xyz="0 0 0"/>
			<geometry>
				<mesh filename="textured_objs/original-51.obj"/>
			</geometry>
		</visual>
		<visual name="base_body-11">
			<origin xyz="0 0 0"/>
			<geometry>
				<mesh filename="textured_objs/original-55.obj"/>
			</geometry>
		</visual>
		<visual name="base_body-11">
			<origin xyz="0 0 0"/>
			<geometry>
				<mesh filename="textured_objs/original-113.obj"/>
			</geometry>
		</visual>
		<visual name="base_body-11">
			<origin xyz="0 0 0"/>
			<geometry>
				<mesh filename="textured_objs/original-50.obj"/>
			</geometry>
		</visual>
		<visual name="base_body-11">
			<origin xyz="0 0 0"/>
			<geometry>
				<mesh filename="textured_objs/original-141.obj"/>
			</geometry>
		</visual>
		<visual name="base_body-11">
			<origin xyz="0 0 0"/>
			<geometry>
				<mesh filename="textured_objs/original-111.obj"/>
			</geometry>
		</visual>
		<visual name="base_body-11">
			<origin xyz="0 0 0"/>
			<geometry>
				<mesh filename="textured_objs/original-287.obj"/>
			</geometry>
		</visual>
		<visual name="base_body-11">
			<origin xyz="0 0 0"/>
			<geometry>
				<mesh filename="textured_objs/original-31.obj"/>
			</geometry>
		</visual>
		<visual name="base_body-11">
			<origin xyz="0 0 0"/>
			<geometry>
				<mesh filename="textured_objs/original-187.obj"/>
			</geometry>
		</visual>
		<visual name="base_body-11">
			<origin xyz="0 0 0"/>
			<geometry>
				<mesh filename="textured_objs/original-178.obj"/>
			</geometry>
		</visual>
		<visual name="base_body-11">
			<origin xyz="0 0 0"/>
			<geometry>
				<mesh filename="textured_objs/original-48.obj"/>
			</geometry>
		</visual>
		<visual name="base_body-11">
			<origin xyz="0 0 0"/>
			<geometry>
				<mesh filename="textured_objs/original-15.obj"/>
			</geometry>
		</visual>
		<visual name="base_body-11">
			<origin xyz="0 0 0"/>
			<geometry>
				<mesh filename="textured_objs/original-116.obj"/>
			</geometry>
		</visual>
		<visual name="base_body-11">
			<origin xyz="0 0 0"/>
			<geometry>
				<mesh filename="textured_objs/original-85.obj"/>
			</geometry>
		</visual>
		<visual name="base_body-11">
			<origin xyz="0 0 0"/>
			<geometry>
				<mesh filename="textured_objs/original-177.obj"/>
			</geometry>
		</visual>
		<visual name="base_body-11">
			<origin xyz="0 0 0"/>
			<geometry>
				<mesh filename="textured_objs/original-122.obj"/>
			</geometry>
		</visual>
		<visual name="base_body-11">
			<origin xyz="0 0 0"/>
			<geometry>
				<mesh filename="textured_objs/original-56.obj"/>
			</geometry>
		</visual>
		<visual name="base_body-11">
			<origin xyz="0 0 0"/>
			<geometry>
				<mesh filename="textured_objs/original-135.obj"/>
			</geometry>
		</visual>
		<visual name="base_body-11">
			<origin xyz="0 0 0"/>
			<geometry>
				<mesh filename="textured_objs/original-76.obj"/>
			</geometry>
		</visual>
		<visual name="base_body-11">
			<origin xyz="0 0 0"/>
			<geometry>
				<mesh filename="textured_objs/original-108.obj"/>
			</geometry>
		</visual>
		<visual name="base_body-11">
			<origin xyz="0 0 0"/>
			<geometry>
				<mesh filename="textured_objs/original-175.obj"/>
			</geometry>
		</visual>
		<visual name="base_body-11">
			<origin xyz="0 0 0"/>
			<geometry>
				<mesh filename="textured_objs/original-186.obj"/>
			</geometry>
		</visual>
		<visual name="base_body-11">
			<origin xyz="0 0 0"/>
			<geometry>
				<mesh filename="textured_objs/original-72.obj"/>
			</geometry>
		</visual>
		<visual name="base_body-11">
			<origin xyz="0 0 0"/>
			<geometry>
				<mesh filename="textured_objs/original-99.obj"/>
			</geometry>
		</visual>
		<visual name="base_body-11">
			<origin xyz="0 0 0"/>
			<geometry>
				<mesh filename="textured_objs/original-136.obj"/>
			</geometry>
		</visual>
		<visual name="base_body-11">
			<origin xyz="0 0 0"/>
			<geometry>
				<mesh filename="textured_objs/original-127.obj"/>
			</geometry>
		</visual>
		<visual name="base_body-11">
			<origin xyz="0 0 0"/>
			<geometry>
				<mesh filename="textured_objs/original-62.obj"/>
			</geometry>
		</visual>
		<visual name="base_body-11">
			<origin xyz="0 0 0"/>
			<geometry>
				<mesh filename="textured_objs/original-75.obj"/>
			</geometry>
		</visual>
		<visual name="base_body-11">
			<origin xyz="0 0 0"/>
			<geometry>
				<mesh filename="textured_objs/original-174.obj"/>
			</geometry>
		</visual>
		<visual name="base_body-11">
			<origin xyz="0 0 0"/>
			<geometry>
				<mesh filename="textured_objs/original-133.obj"/>
			</geometry>
		</visual>
		<visual name="base_body-11">
			<origin xyz="0 0 0"/>
			<geometry>
				<mesh filename="textured_objs/original-158.obj"/>
			</geometry>
		</visual>
		<visual name="base_body-11">
			<origin xyz="0 0 0"/>
			<geometry>
				<mesh filename="textured_objs/original-66.obj"/>
			</geometry>
		</visual>
		<visual name="base_body-11">
			<origin xyz="0 0 0"/>
			<geometry>
				<mesh filename="textured_objs/original-182.obj"/>
			</geometry>
		</visual>
		<visual name="base_body-11">
			<origin xyz="0 0 0"/>
			<geometry>
				<mesh filename="textured_objs/original-58.obj"/>
			</geometry>
		</visual>
		<visual name="base_body-11">
			<origin xyz="0 0 0"/>
			<geometry>
				<mesh filename="textured_objs/original-145.obj"/>
			</geometry>
		</visual>
		<visual name="base_body-11">
			<origin xyz="0 0 0"/>
			<geometry>
				<mesh filename="textured_objs/original-98.obj"/>
			</geometry>
		</visual>
		<visual name="base_body-11">
			<origin xyz="0 0 0"/>
			<geometry>
				<mesh filename="textured_objs/original-67.obj"/>
			</geometry>
		</visual>
		<visual name="base_body-11">
			<origin xyz="0 0 0"/>
			<geometry>
				<mesh filename="textured_objs/original-69.obj"/>
			</geometry>
		</visual>
		<visual name="base_body-11">
			<origin xyz="0 0 0"/>
			<geometry>
				<mesh filename="textured_objs/original-11.obj"/>
			</geometry>
		</visual>
		<visual name="base_body-11">
			<origin xyz="0 0 0"/>
			<geometry>
				<mesh filename="textured_objs/original-131.obj"/>
			</geometry>
		</visual>
		<visual name="base_body-11">
			<origin xyz="0 0 0"/>
			<geometry>
				<mesh filename="textured_objs/original-68.obj"/>
			</geometry>
		</visual>
		<visual name="base_body-11">
			<origin xyz="0 0 0"/>
			<geometry>
				<mesh filename="textured_objs/original-146.obj"/>
			</geometry>
		</visual>
		<visual name="base_body-11">
			<origin xyz="0 0 0"/>
			<geometry>
				<mesh filename="textured_objs/original-190.obj"/>
			</geometry>
		</visual>
		<visual name="base_body-11">
			<origin xyz="0 0 0"/>
			<geometry>
				<mesh filename="textured_objs/original-70.obj"/>
			</geometry>
		</visual>
		<visual name="base_body-11">
			<origin xyz="0 0 0"/>
			<geometry>
				<mesh filename="textured_objs/original-161.obj"/>
			</geometry>
		</visual>
		<visual name="base_body-11">
			<origin xyz="0 0 0"/>
			<geometry>
				<mesh filename="textured_objs/original-74.obj"/>
			</geometry>
		</visual>
		<visual name="base_body-11">
			<origin xyz="0 0 0"/>
			<geometry>
				<mesh filename="textured_objs/original-189.obj"/>
			</geometry>
		</visual>
		<visual name="base_body-11">
			<origin xyz="0 0 0"/>
			<geometry>
				<mesh filename="textured_objs/original-118.obj"/>
			</geometry>
		</visual>
		<visual name="base_body-11">
			<origin xyz="0 0 0"/>
			<geometry>
				<mesh filename="textured_objs/original-91.obj"/>
			</geometry>
		</visual>
		<visual name="base_body-11">
			<origin xyz="0 0 0"/>
			<geometry>
				<mesh filename="textured_objs/original-73.obj"/>
			</geometry>
		</visual>
		<visual name="base_body-11">
			<origin xyz="0 0 0"/>
			<geometry>
				<mesh filename="textured_objs/original-181.obj"/>
			</geometry>
		</visual>
		<visual name="base_body-11">
			<origin xyz="0 0 0"/>
			<geometry>
				<mesh filename="textured_objs/original-92.obj"/>
			</geometry>
		</visual>
		<visual name="base_body-11">
			<origin xyz="0 0 0"/>
			<geometry>
				<mesh filename="textured_objs/original-183.obj"/>
			</geometry>
		</visual>
		<visual name="base_body-11">
			<origin xyz="0 0 0"/>
			<geometry>
				<mesh filename="textured_objs/original-171.obj"/>
			</geometry>
		</visual>
		<visual name="base_body-11">
			<origin xyz="0 0 0"/>
			<geometry>
				<mesh filename="textured_objs/original-288.obj"/>
			</geometry>
		</visual>
		<visual name="base_body-11">
			<origin xyz="0 0 0"/>
			<geometry>
				<mesh filename="textured_objs/original-142.obj"/>
			</geometry>
		</visual>
		<visual name="base_body-11">
			<origin xyz="0 0 0"/>
			<geometry>
				<mesh filename="textured_objs/original-285.obj"/>
			</geometry>
		</visual>
		<visual name="base_body-11">
			<origin xyz="0 0 0"/>
			<geometry>
				<mesh filename="textured_objs/original-79.obj"/>
			</geometry>
		</visual>
		<visual name="base_body-11">
			<origin xyz="0 0 0"/>
			<geometry>
				<mesh filename="textured_objs/original-102.obj"/>
			</geometry>
		</visual>
		<visual name="base_body-11">
			<origin xyz="0 0 0"/>
			<geometry>
				<mesh filename="textured_objs/original-24.obj"/>
			</geometry>
		</visual>
		<visual name="base_body-11">
			<origin xyz="0 0 0"/>
			<geometry>
				<mesh filename="textured_objs/original-20.obj"/>
			</geometry>
		</visual>
		<visual name="base_body-11">
			<origin xyz="0 0 0"/>
			<geometry>
				<mesh filename="textured_objs/original-88.obj"/>
			</geometry>
		</visual>
		<visual name="base_body-11">
			<origin xyz="0 0 0"/>
			<geometry>
				<mesh filename="textured_objs/original-115.obj"/>
			</geometry>
		</visual>
		<visual name="base_body-11">
			<origin xyz="0 0 0"/>
			<geometry>
				<mesh filename="textured_objs/original-47.obj"/>
			</geometry>
		</visual>
		<visual name="base_body-11">
			<origin xyz="0 0 0"/>
			<geometry>
				<mesh filename="textured_objs/original-95.obj"/>
			</geometry>
		</visual>
		<visual name="base_body-11">
			<origin xyz="0 0 0"/>
			<geometry>
				<mesh filename="textured_objs/original-105.obj"/>
			</geometry>
		</visual>
		<visual name="base_body-11">
			<origin xyz="0 0 0"/>
			<geometry>
				<mesh filename="textured_objs/original-101.obj"/>
			</geometry>
		</visual>
		<visual name="base_body-11">
			<origin xyz="0 0 0"/>
			<geometry>
				<mesh filename="textured_objs/original-180.obj"/>
			</geometry>
		</visual>
		<visual name="base_body-11">
			<origin xyz="0 0 0"/>
			<geometry>
				<mesh filename="textured_objs/original-84.obj"/>
			</geometry>
		</visual>
		<visual name="base_body-11">
			<origin xyz="0 0 0"/>
			<geometry>
				<mesh filename="textured_objs/original-121.obj"/>
			</geometry>
		</visual>
		<visual name="base_body-11">
			<origin xyz="0 0 0"/>
			<geometry>
				<mesh filename="textured_objs/original-94.obj"/>
			</geometry>
		</visual>
		<visual name="base_body-11">
			<origin xyz="0 0 0"/>
			<geometry>
				<mesh filename="textured_objs/original-78.obj"/>
			</geometry>
		</visual>
		<visual name="base_body-11">
			<origin xyz="0 0 0"/>
			<geometry>
				<mesh filename="textured_objs/original-97.obj"/>
			</geometry>
		</visual>
		<visual name="base_body-11">
			<origin xyz="0 0 0"/>
			<geometry>
				<mesh filename="textured_objs/original-157.obj"/>
			</geometry>
		</visual>
		<visual name="base_body-11">
			<origin xyz="0 0 0"/>
			<geometry>
				<mesh filename="textured_objs/original-89.obj"/>
			</geometry>
		</visual>
		<visual name="base_body-11">
			<origin xyz="0 0 0"/>
			<geometry>
				<mesh filename="textured_objs/original-179.obj"/>
			</geometry>
		</visual>
		<visual name="base_body-11">
			<origin xyz="0 0 0"/>
			<geometry>
				<mesh filename="textured_objs/original-14.obj"/>
			</geometry>
		</visual>
		<visual name="base_body-11">
			<origin xyz="0 0 0"/>
			<geometry>
				<mesh filename="textured_objs/original-82.obj"/>
			</geometry>
		</visual>
		<visual name="base_body-11">
			<origin xyz="0 0 0"/>
			<geometry>
				<mesh filename="textured_objs/original-129.obj"/>
			</geometry>
		</visual>
		<visual name="base_body-11">
			<origin xyz="0 0 0"/>
			<geometry>
				<mesh filename="textured_objs/original-60.obj"/>
			</geometry>
		</visual>
		<visual name="base_body-11">
			<origin xyz="0 0 0"/>
			<geometry>
				<mesh filename="textured_objs/original-284.obj"/>
			</geometry>
		</visual>
		<visual name="base_body-11">
			<origin xyz="0 0 0"/>
			<geometry>
				<mesh filename="textured_objs/original-90.obj"/>
			</geometry>
		</visual>
		<visual name="base_body-11">
			<origin xyz="0 0 0"/>
			<geometry>
				<mesh filename="textured_objs/original-143.obj"/>
			</geometry>
		</visual>
		<visual name="base_body-11">
			<origin xyz="0 0 0"/>
			<geometry>
				<mesh filename="textured_objs/original-151.obj"/>
			</geometry>
		</visual>
		<visual name="base_body-11">
			<origin xyz="0 0 0"/>
			<geometry>
				<mesh filename="textured_objs/original-155.obj"/>
			</geometry>
		</visual>
		<visual name="base_body-11">
			<origin xyz="0 0 0"/>
			<geometry>
				<mesh filename="textured_objs/original-176.obj"/>
			</geometry>
		</visual>
		<visual name="base_body-11">
			<origin xyz="0 0 0"/>
			<geometry>
				<mesh filename="textured_objs/original-57.obj"/>
			</geometry>
		</visual>
		<visual name="base_body-11">
			<origin xyz="0 0 0"/>
			<geometry>
				<mesh filename="textured_objs/original-164.obj"/>
			</geometry>
		</visual>
		<collision>
			<origin xyz="0 0 0"/>
			<geometry>
				<mesh filename="textured_objs/original-103.obj"/>
			</geometry>
		</collision>
		<collision>
			<origin xyz="0 0 0"/>
			<geometry>
				<mesh filename="textured_objs/original-100.obj"/>
			</geometry>
		</collision>
		<collision>
			<origin xyz="0 0 0"/>
			<geometry>
				<mesh filename="textured_objs/original-123.obj"/>
			</geometry>
		</collision>
		<collision>
			<origin xyz="0 0 0"/>
			<geometry>
				<mesh filename="textured_objs/original-21.obj"/>
			</geometry>
		</collision>
		<collision>
			<origin xyz="0 0 0"/>
			<geometry>
				<mesh filename="textured_objs/original-30.obj"/>
			</geometry>
		</collision>
		<collision>
			<origin xyz="0 0 0"/>
			<geometry>
				<mesh filename="textured_objs/original-152.obj"/>
			</geometry>
		</collision>
		<collision>
			<origin xyz="0 0 0"/>
			<geometry>
				<mesh filename="textured_objs/original-132.obj"/>
			</geometry>
		</collision>
		<collision>
			<origin xyz="0 0 0"/>
			<geometry>
				<mesh filename="textured_objs/original-154.obj"/>
			</geometry>
		</collision>
		<collision>
			<origin xyz="0 0 0"/>
			<geometry>
				<mesh filename="textured_objs/original-126.obj"/>
			</geometry>
		</collision>
		<collision>
			<origin xyz="0 0 0"/>
			<geometry>
				<mesh filename="textured_objs/original-169.obj"/>
			</geometry>
		</collision>
		<collision>
			<origin xyz="0 0 0"/>
			<geometry>
				<mesh filename="textured_objs/original-119.obj"/>
			</geometry>
		</collision>
		<collision>
			<origin xyz="0 0 0"/>
			<geometry>
				<mesh filename="textured_objs/original-188.obj"/>
			</geometry>
		</collision>
		<collision>
			<origin xyz="0 0 0"/>
			<geometry>
				<mesh filename="textured_objs/original-124.obj"/>
			</geometry>
		</collision>
		<collision>
			<origin xyz="0 0 0"/>
			<geometry>
				<mesh filename="textured_objs/original-96.obj"/>
			</geometry>
		</collision>
		<collision>
			<origin xyz="0 0 0"/>
			<geometry>
				<mesh filename="textured_objs/original-64.obj"/>
			</geometry>
		</collision>
		<collision>
			<origin xyz="0 0 0"/>
			<geometry>
				<mesh filename="textured_objs/original-134.obj"/>
			</geometry>
		</collision>
		<collision>
			<origin xyz="0 0 0"/>
			<geometry>
				<mesh filename="textured_objs/original-71.obj"/>
			</geometry>
		</collision>
		<collision>
			<origin xyz="0 0 0"/>
			<geometry>
				<mesh filename="textured_objs/original-83.obj"/>
			</geometry>
		</collision>
		<collision>
			<origin xyz="0 0 0"/>
			<geometry>
				<mesh filename="textured_objs/original-22.obj"/>
			</geometry>
		</collision>
		<collision>
			<origin xyz="0 0 0"/>
			<geometry>
				<mesh filename="textured_objs/original-26.obj"/>
			</geometry>
		</collision>
		<collision>
			<origin xyz="0 0 0"/>
			<geometry>
				<mesh filename="textured_objs/original-117.obj"/>
			</geometry>
		</collision>
		<collision>
			<origin xyz="0 0 0"/>
			<geometry>
				<mesh filename="textured_objs/original-110.obj"/>
			</geometry>
		</collision>
		<collision>
			<origin xyz="0 0 0"/>
			<geometry>
				<mesh filename="textured_objs/original-153.obj"/>
			</geometry>
		</collision>
		<collision>
			<origin xyz="0 0 0"/>
			<geometry>
				<mesh filename="textured_objs/original-107.obj"/>
			</geometry>
		</collision>
		<collision>
			<origin xyz="0 0 0"/>
			<geometry>
				<mesh filename="textured_objs/original-160.obj"/>
			</geometry>
		</collision>
		<collision>
			<origin xyz="0 0 0"/>
			<geometry>
				<mesh filename="textured_objs/original-104.obj"/>
			</geometry>
		</collision>
		<collision>
			<origin xyz="0 0 0"/>
			<geometry>
				<mesh filename="textured_objs/original-149.obj"/>
			</geometry>
		</collision>
		<collision>
			<origin xyz="0 0 0"/>
			<geometry>
				<mesh filename="textured_objs/original-128.obj"/>
			</geometry>
		</collision>
		<collision>
			<origin xyz="0 0 0"/>
			<geometry>
				<mesh filename="textured_objs/original-65.obj"/>
			</geometry>
		</collision>
		<collision>
			<origin xyz="0 0 0"/>
			<geometry>
				<mesh filename="textured_objs/original-130.obj"/>
			</geometry>
		</collision>
		<collision>
			<origin xyz="0 0 0"/>
			<geometry>
				<mesh filename="textured_objs/original-137.obj"/>
			</geometry>
		</collision>
		<collision>
			<origin xyz="0 0 0"/>
			<geometry>
				<mesh filename="textured_objs/original-139.obj"/>
			</geometry>
		</collision>
		<collision>
			<origin xyz="0 0 0"/>
			<geometry>
				<mesh filename="textured_objs/original-112.obj"/>
			</geometry>
		</collision>
		<collision>
			<origin xyz="0 0 0"/>
			<geometry>
				<mesh filename="textured_objs/original-162.obj"/>
			</geometry>
		</collision>
		<collision>
			<origin xyz="0 0 0"/>
			<geometry>
				<mesh filename="textured_objs/original-106.obj"/>
			</geometry>
		</collision>
		<collision>
			<origin xyz="0 0 0"/>
			<geometry>
				<mesh filename="textured_objs/original-86.obj"/>
			</geometry>
		</collision>
		<collision>
			<origin xyz="0 0 0"/>
			<geometry>
				<mesh filename="textured_objs/original-8.obj"/>
			</geometry>
		</collision>
		<collision>
			<origin xyz="0 0 0"/>
			<geometry>
				<mesh filename="textured_objs/original-173.obj"/>
			</geometry>
		</collision>
		<collision>
			<origin xyz="0 0 0"/>
			<geometry>
				<mesh filename="textured_objs/original-140.obj"/>
			</geometry>
		</collision>
		<collision>
			<origin xyz="0 0 0"/>
			<geometry>
				<mesh filename="textured_objs/original-147.obj"/>
			</geometry>
		</collision>
		<collision>
			<origin xyz="0 0 0"/>
			<geometry>
				<mesh filename="textured_objs/original-109.obj"/>
			</geometry>
		</collision>
		<collision>
			<origin xyz="0 0 0"/>
			<geometry>
				<mesh filename="textured_objs/original-9.obj"/>
			</geometry>
		</collision>
		<collision>
			<origin xyz="0 0 0"/>
			<geometry>
				<mesh filename="textured_objs/original-125.obj"/>
			</geometry>
		</collision>
		<collision>
			<origin xyz="0 0 0"/>
			<geometry>
				<mesh filename="textured_objs/original-148.obj"/>
			</geometry>
		</collision>
		<collision>
			<origin xyz="0 0 0"/>
			<geometry>
				<mesh filename="textured_objs/original-172.obj"/>
			</geometry>
		</collision>
		<collision>
			<origin xyz="0 0 0"/>
			<geometry>
				<mesh filename="textured_objs/original-138.obj"/>
			</geometry>
		</collision>
		<collision>
			<origin xyz="0 0 0"/>
			<geometry>
				<mesh filename="textured_objs/original-156.obj"/>
			</geometry>
		</collision>
		<collision>
			<origin xyz="0 0 0"/>
			<geometry>
				<mesh filename="textured_objs/original-286.obj"/>
			</geometry>
		</collision>
		<collision>
			<origin xyz="0 0 0"/>
			<geometry>
				<mesh filename="textured_objs/original-49.obj"/>
			</geometry>
		</collision>
		<collision>
			<origin xyz="0 0 0"/>
			<geometry>
				<mesh filename="textured_objs/original-184.obj"/>
			</geometry>
		</collision>
		<collision>
			<origin xyz="0 0 0"/>
			<geometry>
				<mesh filename="textured_objs/original-93.obj"/>
			</geometry>
		</collision>
		<collision>
			<origin xyz="0 0 0"/>
			<geometry>
				<mesh filename="textured_objs/original-61.obj"/>
			</geometry>
		</collision>
		<collision>
			<origin xyz="0 0 0"/>
			<geometry>
				<mesh filename="textured_objs/original-144.obj"/>
			</geometry>
		</collision>
		<collision>
			<origin xyz="0 0 0"/>
			<geometry>
				<mesh filename="textured_objs/original-120.obj"/>
			</geometry>
		</collision>
		<collision>
			<origin xyz="0 0 0"/>
			<geometry>
				<mesh filename="textured_objs/original-59.obj"/>
			</geometry>
		</collision>
		<collision>
			<origin xyz="0 0 0"/>
			<geometry>
				<mesh filename="textured_objs/original-77.obj"/>
			</geometry>
		</collision>
		<collision>
			<origin xyz="0 0 0"/>
			<geometry>
				<mesh filename="textured_objs/original-114.obj"/>
			</geometry>
		</collision>
		<collision>
			<origin xyz="0 0 0"/>
			<geometry>
				<mesh filename="textured_objs/original-150.obj"/>
			</geometry>
		</collision>
		<collision>
			<origin xyz="0 0 0"/>
			<geometry>
				<mesh filename="textured_objs/original-63.obj"/>
			</geometry>
		</collision>
		<collision>
			<origin xyz="0 0 0"/>
			<geometry>
				<mesh filename="textured_objs/original-185.obj"/>
			</geometry>
		</collision>
		<collision>
			<origin xyz="0 0 0"/>
			<geometry>
				<mesh filename="textured_objs/original-159.obj"/>
			</geometry>
		</collision>
		<collision>
			<origin xyz="0 0 0"/>
			<geometry>
				<mesh filename="textured_objs/original-170.obj"/>
			</geometry>
		</collision>
		<collision>
			<origin xyz="0 0 0"/>
			<geometry>
				<mesh filename="textured_objs/original-87.obj"/>
			</geometry>
		</collision>
		<collision>
			<origin xyz="0 0 0"/>
			<geometry>
				<mesh filename="textured_objs/original-51.obj"/>
			</geometry>
		</collision>
		<collision>
			<origin xyz="0 0 0"/>
			<geometry>
				<mesh filename="textured_objs/original-55.obj"/>
			</geometry>
		</collision>
		<collision>
			<origin xyz="0 0 0"/>
			<geometry>
				<mesh filename="textured_objs/original-113.obj"/>
			</geometry>
		</collision>
		<collision>
			<origin xyz="0 0 0"/>
			<geometry>
				<mesh filename="textured_objs/original-50.obj"/>
			</geometry>
		</collision>
		<collision>
			<origin xyz="0 0 0"/>
			<geometry>
				<mesh filename="textured_objs/original-141.obj"/>
			</geometry>
		</collision>
		<collision>
			<origin xyz="0 0 0"/>
			<geometry>
				<mesh filename="textured_objs/original-111.obj"/>
			</geometry>
		</collision>
		<collision>
			<origin xyz="0 0 0"/>
			<geometry>
				<mesh filename="textured_objs/original-287.obj"/>
			</geometry>
		</collision>
		<collision>
			<origin xyz="0 0 0"/>
			<geometry>
				<mesh filename="textured_objs/original-31.obj"/>
			</geometry>
		</collision>
		<collision>
			<origin xyz="0 0 0"/>
			<geometry>
				<mesh filename="textured_objs/original-187.obj"/>
			</geometry>
		</collision>
		<collision>
			<origin xyz="0 0 0"/>
			<geometry>
				<mesh filename="textured_objs/original-178.obj"/>
			</geometry>
		</collision>
		<collision>
			<origin xyz="0 0 0"/>
			<geometry>
				<mesh filename="textured_objs/original-48.obj"/>
			</geometry>
		</collision>
		<collision>
			<origin xyz="0 0 0"/>
			<geometry>
				<mesh filename="textured_objs/original-15.obj"/>
			</geometry>
		</collision>
		<collision>
			<origin xyz="0 0 0"/>
			<geometry>
				<mesh filename="textured_objs/original-116.obj"/>
			</geometry>
		</collision>
		<collision>
			<origin xyz="0 0 0"/>
			<geometry>
				<mesh filename="textured_objs/original-85.obj"/>
			</geometry>
		</collision>
		<collision>
			<origin xyz="0 0 0"/>
			<geometry>
				<mesh filename="textured_objs/original-177.obj"/>
			</geometry>
		</collision>
		<collision>
			<origin xyz="0 0 0"/>
			<geometry>
				<mesh filename="textured_objs/original-122.obj"/>
			</geometry>
		</collision>
		<collision>
			<origin xyz="0 0 0"/>
			<geometry>
				<mesh filename="textured_objs/original-56.obj"/>
			</geometry>
		</collision>
		<collision>
			<origin xyz="0 0 0"/>
			<geometry>
				<mesh filename="textured_objs/original-135.obj"/>
			</geometry>
		</collision>
		<collision>
			<origin xyz="0 0 0"/>
			<geometry>
				<mesh filename="textured_objs/original-76.obj"/>
			</geometry>
		</collision>
		<collision>
			<origin xyz="0 0 0"/>
			<geometry>
				<mesh filename="textured_objs/original-108.obj"/>
			</geometry>
		</collision>
		<collision>
			<origin xyz="0 0 0"/>
			<geometry>
				<mesh filename="textured_objs/original-175.obj"/>
			</geometry>
		</collision>
		<collision>
			<origin xyz="0 0 0"/>
			<geometry>
				<mesh filename="textured_objs/original-186.obj"/>
			</geometry>
		</collision>
		<collision>
			<origin xyz="0 0 0"/>
			<geometry>
				<mesh filename="textured_objs/original-72.obj"/>
			</geometry>
		</collision>
		<collision>
			<origin xyz="0 0 0"/>
			<geometry>
				<mesh filename="textured_objs/original-99.obj"/>
			</geometry>
		</collision>
		<collision>
			<origin xyz="0 0 0"/>
			<geometry>
				<mesh filename="textured_objs/original-136.obj"/>
			</geometry>
		</collision>
		<collision>
			<origin xyz="0 0 0"/>
			<geometry>
				<mesh filename="textured_objs/original-127.obj"/>
			</geometry>
		</collision>
		<collision>
			<origin xyz="0 0 0"/>
			<geometry>
				<mesh filename="textured_objs/original-62.obj"/>
			</geometry>
		</collision>
		<collision>
			<origin xyz="0 0 0"/>
			<geometry>
				<mesh filename="textured_objs/original-75.obj"/>
			</geometry>
		</collision>
		<collision>
			<origin xyz="0 0 0"/>
			<geometry>
				<mesh filename="textured_objs/original-174.obj"/>
			</geometry>
		</collision>
		<collision>
			<origin xyz="0 0 0"/>
			<geometry>
				<mesh filename="textured_objs/original-133.obj"/>
			</geometry>
		</collision>
		<collision>
			<origin xyz="0 0 0"/>
			<geometry>
				<mesh filename="textured_objs/original-158.obj"/>
			</geometry>
		</collision>
		<collision>
			<origin xyz="0 0 0"/>
			<geometry>
				<mesh filename="textured_objs/original-66.obj"/>
			</geometry>
		</collision>
		<collision>
			<origin xyz="0 0 0"/>
			<geometry>
				<mesh filename="textured_objs/original-182.obj"/>
			</geometry>
		</collision>
		<collision>
			<origin xyz="0 0 0"/>
			<geometry>
				<mesh filename="textured_objs/original-58.obj"/>
			</geometry>
		</collision>
		<collision>
			<origin xyz="0 0 0"/>
			<geometry>
				<mesh filename="textured_objs/original-145.obj"/>
			</geometry>
		</collision>
		<collision>
			<origin xyz="0 0 0"/>
			<geometry>
				<mesh filename="textured_objs/original-98.obj"/>
			</geometry>
		</collision>
		<collision>
			<origin xyz="0 0 0"/>
			<geometry>
				<mesh filename="textured_objs/original-67.obj"/>
			</geometry>
		</collision>
		<collision>
			<origin xyz="0 0 0"/>
			<geometry>
				<mesh filename="textured_objs/original-69.obj"/>
			</geometry>
		</collision>
		<collision>
			<origin xyz="0 0 0"/>
			<geometry>
				<mesh filename="textured_objs/original-11.obj"/>
			</geometry>
		</collision>
		<collision>
			<origin xyz="0 0 0"/>
			<geometry>
				<mesh filename="textured_objs/original-131.obj"/>
			</geometry>
		</collision>
		<collision>
			<origin xyz="0 0 0"/>
			<geometry>
				<mesh filename="textured_objs/original-68.obj"/>
			</geometry>
		</collision>
		<collision>
			<origin xyz="0 0 0"/>
			<geometry>
				<mesh filename="textured_objs/original-146.obj"/>
			</geometry>
		</collision>
		<collision>
			<origin xyz="0 0 0"/>
			<geometry>
				<mesh filename="textured_objs/original-190.obj"/>
			</geometry>
		</collision>
		<collision>
			<origin xyz="0 0 0"/>
			<geometry>
				<mesh filename="textured_objs/original-70.obj"/>
			</geometry>
		</collision>
		<collision>
			<origin xyz="0 0 0"/>
			<geometry>
				<mesh filename="textured_objs/original-161.obj"/>
			</geometry>
		</collision>
		<collision>
			<origin xyz="0 0 0"/>
			<geometry>
				<mesh filename="textured_objs/original-74.obj"/>
			</geometry>
		</collision>
		<collision>
			<origin xyz="0 0 0"/>
			<geometry>
				<mesh filename="textured_objs/original-189.obj"/>
			</geometry>
		</collision>
		<collision>
			<origin xyz="0 0 0"/>
			<geometry>
				<mesh filename="textured_objs/original-118.obj"/>
			</geometry>
		</collision>
		<collision>
			<origin xyz="0 0 0"/>
			<geometry>
				<mesh filename="textured_objs/original-91.obj"/>
			</geometry>
		</collision>
		<collision>
			<origin xyz="0 0 0"/>
			<geometry>
				<mesh filename="textured_objs/original-73.obj"/>
			</geometry>
		</collision>
		<collision>
			<origin xyz="0 0 0"/>
			<geometry>
				<mesh filename="textured_objs/original-181.obj"/>
			</geometry>
		</collision>
		<collision>
			<origin xyz="0 0 0"/>
			<geometry>
				<mesh filename="textured_objs/original-92.obj"/>
			</geometry>
		</collision>
		<collision>
			<origin xyz="0 0 0"/>
			<geometry>
				<mesh filename="textured_objs/original-183.obj"/>
			</geometry>
		</collision>
		<collision>
			<origin xyz="0 0 0"/>
			<geometry>
				<mesh filename="textured_objs/original-171.obj"/>
			</geometry>
		</collision>
		<collision>
			<origin xyz="0 0 0"/>
			<geometry>
				<mesh filename="textured_objs/original-288.obj"/>
			</geometry>
		</collision>
		<collision>
			<origin xyz="0 0 0"/>
			<geometry>
				<mesh filename="textured_objs/original-142.obj"/>
			</geometry>
		</collision>
		<collision>
			<origin xyz="0 0 0"/>
			<geometry>
				<mesh filename="textured_objs/original-285.obj"/>
			</geometry>
		</collision>
		<collision>
			<origin xyz="0 0 0"/>
			<geometry>
				<mesh filename="textured_objs/original-79.obj"/>
			</geometry>
		</collision>
		<collision>
			<origin xyz="0 0 0"/>
			<geometry>
				<mesh filename="textured_objs/original-102.obj"/>
			</geometry>
		</collision>
		<collision>
			<origin xyz="0 0 0"/>
			<geometry>
				<mesh filename="textured_objs/original-24.obj"/>
			</geometry>
		</collision>
		<collision>
			<origin xyz="0 0 0"/>
			<geometry>
				<mesh filename="textured_objs/original-20.obj"/>
			</geometry>
		</collision>
		<collision>
			<origin xyz="0 0 0"/>
			<geometry>
				<mesh filename="textured_objs/original-88.obj"/>
			</geometry>
		</collision>
		<collision>
			<origin xyz="0 0 0"/>
			<geometry>
				<mesh filename="textured_objs/original-115.obj"/>
			</geometry>
		</collision>
		<collision>
			<origin xyz="0 0 0"/>
			<geometry>
				<mesh filename="textured_objs/original-47.obj"/>
			</geometry>
		</collision>
		<collision>
			<origin xyz="0 0 0"/>
			<geometry>
				<mesh filename="textured_objs/original-95.obj"/>
			</geometry>
		</collision>
		<collision>
			<origin xyz="0 0 0"/>
			<geometry>
				<mesh filename="textured_objs/original-105.obj"/>
			</geometry>
		</collision>
		<collision>
			<origin xyz="0 0 0"/>
			<geometry>
				<mesh filename="textured_objs/original-101.obj"/>
			</geometry>
		</collision>
		<collision>
			<origin xyz="0 0 0"/>
			<geometry>
				<mesh filename="textured_objs/original-180.obj"/>
			</geometry>
		</collision>
		<collision>
			<origin xyz="0 0 0"/>
			<geometry>
				<mesh filename="textured_objs/original-84.obj"/>
			</geometry>
		</collision>
		<collision>
			<origin xyz="0 0 0"/>
			<geometry>
				<mesh filename="textured_objs/original-121.obj"/>
			</geometry>
		</collision>
		<collision>
			<origin xyz="0 0 0"/>
			<geometry>
				<mesh filename="textured_objs/original-94.obj"/>
			</geometry>
		</collision>
		<collision>
			<origin xyz="0 0 0"/>
			<geometry>
				<mesh filename="textured_objs/original-78.obj"/>
			</geometry>
		</collision>
		<collision>
			<origin xyz="0 0 0"/>
			<geometry>
				<mesh filename="textured_objs/original-97.obj"/>
			</geometry>
		</collision>
		<collision>
			<origin xyz="0 0 0"/>
			<geometry>
				<mesh filename="textured_objs/original-157.obj"/>
			</geometry>
		</collision>
		<collision>
			<origin xyz="0 0 0"/>
			<geometry>
				<mesh filename="textured_objs/original-89.obj"/>
			</geometry>
		</collision>
		<collision>
			<origin xyz="0 0 0"/>
			<geometry>
				<mesh filename="textured_objs/original-179.obj"/>
			</geometry>
		</collision>
		<collision>
			<origin xyz="0 0 0"/>
			<geometry>
				<mesh filename="textured_objs/original-14.obj"/>
			</geometry>
		</collision>
		<collision>
			<origin xyz="0 0 0"/>
			<geometry>
				<mesh filename="textured_objs/original-82.obj"/>
			</geometry>
		</collision>
		<collision>
			<origin xyz="0 0 0"/>
			<geometry>
				<mesh filename="textured_objs/original-129.obj"/>
			</geometry>
		</collision>
		<collision>
			<origin xyz="0 0 0"/>
			<geometry>
				<mesh filename="textured_objs/original-60.obj"/>
			</geometry>
		</collision>
		<collision>
			<origin xyz="0 0 0"/>
			<geometry>
				<mesh filename="textured_objs/original-284.obj"/>
			</geometry>
		</collision>
		<collision>
			<origin xyz="0 0 0"/>
			<geometry>
				<mesh filename="textured_objs/original-90.obj"/>
			</geometry>
		</collision>
		<collision>
			<origin xyz="0 0 0"/>
			<geometry>
				<mesh filename="textured_objs/original-143.obj"/>
			</geometry>
		</collision>
		<collision>
			<origin xyz="0 0 0"/>
			<geometry>
				<mesh filename="textured_objs/original-151.obj"/>
			</geometry>
		</collision>
		<collision>
			<origin xyz="0 0 0"/>
			<geometry>
				<mesh filename="textured_objs/original-155.obj"/>
			</geometry>
		</collision>
		<collision>
			<origin xyz="0 0 0"/>
			<geometry>
				<mesh filename="textured_objs/original-176.obj"/>
			</geometry>
		</collision>
		<collision>
			<origin xyz="0 0 0"/>
			<geometry>
				<mesh filename="textured_objs/original-57.obj"/>
			</geometry>
		</collision>
		<collision>
			<origin xyz="0 0 0"/>
			<geometry>
				<mesh filename="textured_objs/original-164.obj"/>
			</geometry>
		</collision>
	</link>
	<joint name="joint_9" type="fixed">
		<origin rpy="1.570796326794897 0 -1.570796326794897" xyz="0 0 0"/>
		<child link="link_9"/>
		<parent link="base"/>
	</joint>
</robot>
