<?xml version="1.0" ?>
<!-- =================================================================================== -->
<!-- |    This document was autogenerated by xacro from hand.urdf.xacro                | -->
<!-- |    EDITING THIS FILE BY HAND IS NOT RECOMMENDED                                 | -->
<!-- =================================================================================== -->
<robot name="feg" xmlns:xacro="http://www.ros.org/wiki/xacro">
  <link name="panda_hand">
    <visual>
      <geometry>
        <mesh filename="package://franka_description/meshes/visual/hand.dae"/>
      </geometry>
    </visual>
    <collision>
      <geometry>
        <mesh filename="package://franka_description/meshes/collision/hand.obj"/>
      </geometry>
    </collision>
  </link>
  <link name="panda_leftfinger">
    <visual>
      <geometry>
        <mesh filename="package://franka_description/meshes/visual/finger.dae"/>
      </geometry>
    </visual>
    <collision>
      <geometry>
        <mesh filename="package://franka_description/meshes/collision/finger.obj"/>
      </geometry>
    </collision>
  </link>
  <link name="panda_rightfinger">
    <visual>
      <origin rpy="0 0 3.14159265359" xyz="0 0 0"/>
      <geometry>
        <mesh filename="package://franka_description/meshes/visual/finger.dae"/>
      </geometry>
    </visual>
    <collision>
      <origin rpy="0 0 3.14159265359" xyz="0 0 0"/>
      <geometry>
        <mesh filename="package://franka_description/meshes/collision/finger.obj"/>
      </geometry>
    </collision>
  </link>
  <joint name="panda_finger_joint1" type="prismatic">
    <parent link="panda_hand"/>
    <child link="panda_leftfinger"/>
    <origin rpy="0 0 0" xyz="0 0 0.0584"/>
    <axis xyz="0 1 0"/>
    <limit effort="20" lower="0.0" upper="0.04" velocity="0.2"/>
  </joint>
  <joint name="panda_finger_joint2" type="prismatic">
    <parent link="panda_hand"/>
    <child link="panda_rightfinger"/>
    <origin rpy="0 0 0" xyz="0 0 0.0584"/>
    <axis xyz="0 -1 0"/>
    <limit effort="20" lower="0.0" upper="0.04" velocity="0.2"/>
    <mimic joint="panda_finger_joint1"/>
  </joint>

  <link name="world_link"/>
  <link name="base_link_0"/>
  <link name="base_link_1"/>
  <link name="base_link_2"/>
  <link name="base_footprint_0"/>
  <link name="base_footprint_1"/>
  <link name="base_footprint_2"/>

  <joint name="x" type="prismatic">
    <limit lower="-12" upper="12"/>
    <parent link="world_link"/>
    <child link="base_link_0"/>
    <axis xyz="1 0 0"/>
  </joint>
  <joint name="y" type="prismatic">
    <limit lower="-12" upper="12"/>
    <parent link="base_link_0"/>
    <child link="base_link_1"/>
    <axis xyz="0 1 0"/>
  </joint>
  <joint name="z" type="prismatic">
    <limit lower="-12" upper="12"/>
    <parent link="base_link_1"/>
    <child link="base_link_2"/>
    <axis xyz="0 0 1"/>
  </joint>
  <joint name="roll" type="continuous">
    <parent link="base_link_2"/>
    <child link="base_footprint_0"/>
    <axis xyz="1 0 0"/>
  </joint>
  <joint name="pitch" type="continuous">
    <parent link="base_footprint_0"/>
    <child link="base_footprint_1"/>
    <axis xyz="0 1 0"/>
  </joint>
  <joint name="yaw" type="continuous">
    <parent link="base_footprint_1"/>
    <child link="base_footprint_2"/>
    <axis xyz="0 0 1"/>
  </joint>

  <joint name="base_footprint_joint" type="fixed">
    <origin rpy="0 0 0" xyz="0 0 0"/>
    <child link="panda_hand"/>
    <parent link="base_footprint_2"/>
  </joint>

  <link name="tool_link"/>
  <joint name="tool_joint" type="fixed">
    <origin rpy="0 0 1.57079632679" xyz="0.0 0 0.1"/>
    <axis xyz="0 0 1"/>
    <parent link="panda_hand"/>
    <child link="tool_link"/>
  </joint>
</robot>
