<?xml version="1.0" encoding="utf-8"?>
<!-- This URDF was automatically created by SolidWorks to URDF Exporter! Originally created by Stephen Brawner (brawner@gmail.com) 
     Commit Version: 1.6.0-1-g15f4949  Build Version: 1.6.7594.29634
     For more information, please see http://wiki.ros.org/sw_urdf_exporter -->
<robot
  name="eco65">
  <link
  name="baselink">
  <inertial>
    <origin
      xyz="0.00059974 -9.2907E-05 0.043301"
      rpy="0 0 0" />
    <mass
      value="0.61127" />
    <inertia
      ixx="0.00080212"
      ixy="3.0274E-06"
      ixz="-2.8744E-05"
      iyy="0.00080501"
      iyz="1.9741E-06"
      izz="0.00066167" />
  </inertial>
  <visual>
    <origin
      xyz="0 0 0"
      rpy="0 0 0" />
    <geometry>
      <mesh
        filename="package://rm_description/meshes/ECO65_6F/base_link.STL" />
    </geometry>
    <material
      name="">
      <color
        rgba="1 1 0.9451 1" />
    </material>
  </visual>
  <collision>
    <origin
      xyz="0 0 0"
      rpy="0 0 0" />
    <geometry>
      <mesh
        filename="package://rm_description/meshes/ECO65_6F/base_link.STL" />
    </geometry>
  </collision>
</link>
<link
  name="Link1">
  <inertial>
    <origin
      xyz="-0.0228563669572814 -4.99910293902505E-06 -0.0136576161182959"
      rpy="0 0 0" />
    <mass
      value="0.74252212802658" />
    <inertia
      ixx="0.000814086083162491"
      ixy="-1.88391181098273E-05"
      ixz="0.000227472474818497"
      iyy="0.00184803352381529"
      iyz="1.99528907338362E-06"
      izz="0.0015286811412048" />
  </inertial>
  <visual>
    <origin
      xyz="0 0 0"
      rpy="0 0 0" />
    <geometry>
      <mesh
        filename="package://rm_description/meshes/ECO65_6F/Link1.STL" />
    </geometry>
    <material
      name="">
      <color
        rgba="1 1 0.945098039215686 1" />
    </material>
  </visual>
  <collision>
    <origin
      xyz="0 0 0"
      rpy="0 0 0" />
    <geometry>
      <mesh
        filename="package://rm_description/meshes/ECO65_6F/Link1.STL" />
    </geometry>
  </collision>
</link>
<joint
  name="Joint1"
  type="revolute">
  <origin
    xyz="0 0 0.1625"
    rpy="0 0 0" />
  <parent
    link="baselink" />
  <child
    link="Link1" />
  <axis
    xyz="0 0 -1" />
  <limit
    lower="-3.1923"
    upper="3.1923"
    effort="100"
    velocity="1" />
</joint>
<link
  name="Link2">
  <inertial>
    <origin
      xyz="-1.59429561677471E-06 0.103362466937216 0.0673319328195465"
      rpy="0 0 0" />
    <mass
      value="1.35020712394805" />
    <inertia
      ixx="0.0128209817127053"
      ixy="-7.51100910647581E-08"
      ixz="1.16164018082653E-08"
      iyy="0.00112367171816591"
      iyz="-0.000337549701469296"
      izz="0.0129325779698663" />
  </inertial>
  <visual>
    <origin
      xyz="0 0 0"
      rpy="0 0 0" />
    <geometry>
      <mesh
        filename="package://rm_description/meshes/ECO65_6F/Link2.STL" />
    </geometry>
    <material
      name="">
      <color
        rgba="1 1 0.945098039215686 1" />
    </material>
  </visual>
  <collision>
    <origin
      xyz="0 0 0"
      rpy="0 0 0" />
    <geometry>
      <mesh
        filename="package://rm_description/meshes/ECO65_6F/Link2.STL" />
    </geometry>
  </collision>
</link>
<joint
  name="Joint2"
  type="revolute">
  <origin
    xyz="-0.086 0 0"
    rpy="1.5708 0 0" />
  <parent
    link="Link1" />
  <child
    link="Link2" />
  <axis
    xyz="3.5522E-05 0 -1" />
  <limit
    lower="-2.61666"
    upper="2.442"
    effort="100"
    velocity="1" />
</joint>
<link
  name="Link3">
  <inertial>
    <origin
      xyz="0.103737203833717 6.75061995081272E-07 0.0185992268684813"
      rpy="0 0 0" />
    <mass
      value="1.0422213139163" />
    <inertia
      ixx="0.000841150491675703"
      ixy="-2.19673641011106E-08"
      ixz="-0.000686133542349963"
      iyy="0.00940465035102768"
      iyz="-2.88314026692745E-09"
      izz="0.00924817189739541" />
  </inertial>
  <visual>
    <origin
      xyz="0 0 0"
      rpy="0 0 0" />
    <geometry>
      <mesh
        filename="package://rm_description/meshes/ECO65_6F/Link3.STL" />
    </geometry>
    <material
      name="">
      <color
        rgba="1 1 0.945098039215686 1" />
    </material>
  </visual>
  <collision>
    <origin
      xyz="0 0 0"
      rpy="0 0 0" />
    <geometry>
      <mesh
        filename="package://rm_description/meshes/ECO65_6F/Link3.STL" />
    </geometry>
  </collision>
</link>
<joint
  name="Joint3"
  type="revolute">
  <origin
    xyz="0 0.26 0"
    rpy="3.1416 0 1.5708" />
  <parent
    link="Link2" />
  <child
    link="Link3" />
  <axis
    xyz="0 -3.5522E-05 -1" />
  <limit
    lower="-2.61666"
    upper="2.61666"
    effort="100"
    velocity="1" />
</joint>
<link
  name="Link4">
  <inertial>
    <origin
      xyz="-0.00698041126858398 -0.0163300774411825 0.00674302075461098"
      rpy="0 0 0" />
    <mass
      value="0.273792481713346" />
    <inertia
      ixx="0"
      ixy="0"
      ixz="0"
      iyy="0"
      iyz="0"
      izz="0" />
  </inertial>
  <visual>
    <origin
      xyz="0 0 0"
      rpy="0 0 0" />
    <geometry>
      <mesh
        filename="package://rm_description/meshes/ECO65_6F/Link4.STL" />
    </geometry>
    <material
      name="">
      <color
        rgba="1 1 0.945098039215686 1" />
    </material>
  </visual>
  <collision>
    <origin
      xyz="0 0 0"
      rpy="0 0 0" />
    <geometry>
      <mesh
        filename="package://rm_description/meshes/ECO65_6F/Link4.STL" />
    </geometry>
  </collision>
</link>
<joint
  name="Joint4"
  type="revolute">
  <origin
    xyz="0.24 0 -0.05888"
    rpy="0 0 1.5708" />
  <parent
    link="Link3" />
  <child
    link="Link4" />
  <axis
    xyz="-3.5522E-05 0 -1" />
  <limit
    lower="-2.61666"
    upper="2.61666"
    effort="100"
    velocity="1" />
</joint>
<link
  name="Link5">
  <inertial>
    <origin
      xyz="5.97905018565048E-07 0.00665014405373091 -0.0126472033135854"
      rpy="0 0 0" />
    <mass
      value="0.27793758472494" />
    <inertia
      ixx="0.000247512115419683"
      ixy="-5.76598099571412E-09"
      ixz="5.25510533068683E-10"
      iyy="0.000176476753838992"
      iyz="-2.85521641162257E-05"
      izz="0.000192954294679699" />
  </inertial>
  <visual>
    <origin
      xyz="0 0 0"
      rpy="0 0 0" />
    <geometry>
      <mesh
        filename="package://rm_description/meshes/ECO65_6F/Link5.STL" />
    </geometry>
    <material
      name="">
      <color
        rgba="0.298039215686275 0.286274509803922 0.282352941176471 1" />
    </material>
  </visual>
  <collision>
    <origin
      xyz="0 0 0"
      rpy="0 0 0" />
    <geometry>
      <mesh
        filename="package://rm_description/meshes/ECO65_6F/Link5.STL" />
    </geometry>
  </collision>
</link>
<joint
  name="Joint5"
  type="revolute">
  <origin
    xyz="0 -0.11 -1.7417E-05"
    rpy="1.5708 0 0" />
  <parent
    link="Link4" />
  <child
    link="Link5" />
  <axis
    xyz="0 0 -1" />
  <limit
    lower="-2.96555"
    upper="2.96555"
    effort="100"
    velocity="1" />
</joint>
<link
  name="Link6">
  <inertial>
    <origin
      xyz="0.000342343794440939 -0.000189420093943737 -0.0285766702366254"
      rpy="0 0 0" />
    <mass
      value="0.14611108984048" />
    <inertia
      ixx="7.05928109974802E-05"
      ixy="-1.19201783223218E-06"
      ixz="-8.08327801418456E-07"
      iyy="6.9259426871958E-05"
      iyz="4.34362652271675E-07"
      izz="6.18079595264477E-05" />
  </inertial>
  <visual>
    <origin
      xyz="0 0 0"
      rpy="0 0 0" />
    <geometry>
      <mesh
        filename="package://rm_description/meshes/ECO65_6F/Link6.STL" />
    </geometry>
    <material
      name="">
      <color
        rgba="0.752941176470588 0.752941176470588 0.752941176470588 1" />
    </material>
  </visual>
  <collision>
    <origin
      xyz="0 0 0"
      rpy="0 0 0" />
    <geometry>
      <mesh
        filename="package://rm_description/meshes/ECO65_6F/Link6.STL" />
    </geometry>
  </collision>
</link>
<joint
  name="Joint6"
  type="revolute">
  <origin
    xyz="0 0.108 0"
    rpy="-1.5708 0 0" />
  <parent
    link="Link5" />
  <child
    link="Link6" />
  <axis
    xyz="-3.5522E-05 0 -1" />
  <limit
    lower="-2.96555"
    upper="2.96555"
    effort="100"
    velocity="1" />
</joint>
</robot>