<?xml version="1.0" ?>
<robot name="partnet_3ea1ace396f6ccae48407a54b1fbfda8">
	<link name="base"/>

	<!-- <link name="oven_top">
		<visual name="bottom">
			<origin xyz="0 0 0"/>
			<geometry>
				<mesh filename="textured_objs/original-90.obj"/>
			</geometry>
			<material name="Transparent">
				<color rgba="1 1 1 0"/>
			</material>
		</visual>
		<collision>
			<origin xyz="0 0 0"/>
			<geometry>
				<mesh filename="textured_objs/original-90.obj"/>
			</geometry>
		</collision>
	</link>
	<joint name="joint_2" type="fixed">
		<origin rpy="0 0 0" xyz="0 0 0"/>
		<child link="oven_top"/>
		<parent link="link_0"/>
	</joint> -->

	<link name="link_0">
		<visual name="door-1">
			<origin xyz="-0.58423 0.6423879359070063 -0.5040723291093724"/>
			<geometry>
				<mesh filename="textured_objs/original-48.obj"/>
			</geometry>
		</visual>
		<visual name="door-1">
			<origin xyz="-0.58423 0.6423879359070063 -0.5040723291093724"/>
			<geometry>
				<mesh filename="textured_objs/original-54.obj"/>
			</geometry>
		</visual>
		<visual name="door-1">
			<origin xyz="-0.58423 0.6423879359070063 -0.5040723291093724"/>
			<geometry>
				<mesh filename="textured_objs/original-53.obj"/>
			</geometry>
		</visual>
		<visual name="door-1">
			<origin xyz="-0.58423 0.6423879359070063 -0.5040723291093724"/>
			<geometry>
				<mesh filename="textured_objs/original-52.obj"/>
			</geometry>
		</visual>
		<visual name="door-1">
			<origin xyz="-0.58423 0.6423879359070063 -0.5040723291093724"/>
			<geometry>
				<mesh filename="textured_objs/original-3.obj"/>
			</geometry>
		</visual>
		<visual name="door-1">
			<origin xyz="-0.58423 0.6423879359070063 -0.5040723291093724"/>
			<geometry>
				<mesh filename="textured_objs/original-49.obj"/>
			</geometry>
		</visual>
		<collision>
			<origin xyz="-0.58423 0.6423879359070063 -0.5040723291093724"/>
			<geometry>
				<mesh filename="textured_objs/original-48.obj"/>
			</geometry>
		</collision>
		<collision>
			<origin xyz="-0.58423 0.6423879359070063 -0.5040723291093724"/>
			<geometry>
				<mesh filename="textured_objs/original-54.obj"/>
			</geometry>
		</collision>
		<collision>
			<origin xyz="-0.58423 0.6423879359070063 -0.5040723291093724"/>
			<geometry>
				<mesh filename="textured_objs/original-53.obj"/>
			</geometry>
		</collision>
		<collision>
			<origin xyz="-0.58423 0.6423879359070063 -0.5040723291093724"/>
			<geometry>
				<mesh filename="textured_objs/original-52.obj"/>
			</geometry>
		</collision>
		<collision>
			<origin xyz="-0.58423 0.6423879359070063 -0.5040723291093724"/>
			<geometry>
				<mesh filename="textured_objs/original-3.obj"/>
			</geometry>
		</collision>
		<collision>
			<origin xyz="-0.58423 0.6423879359070063 -0.5040723291093724"/>
			<geometry>
				<mesh filename="textured_objs/original-49.obj"/>
			</geometry>
		</collision>
	</link>
	<joint name="joint_0" type="revolute">
		<origin xyz="0.58423 -0.6423879359070063 0.5040723291093724"/>
		<axis xyz="1 0 0"/>
		<child link="link_0"/>
		<parent link="link_9"/>
		<limit lower="0.0" upper="1.5707963267948966"/>
	</joint>
	<link name="link_1">
		<visual name="knob-2">
			<origin xyz="0.48916950000000003 -0.5199065 0"/>
			<geometry>
				<mesh filename="textured_objs/original-9.obj"/>
			</geometry>
		</visual>
		<collision>
			<origin xyz="0.48916950000000003 -0.5199065 0"/>
			<geometry>
				<mesh filename="textured_objs/original-9.obj"/>
			</geometry>
		</collision>
	</link>
	<joint name="joint_1" type="continuous">
		<origin xyz="-0.48916950000000003 0.5199065 0"/>
		<axis xyz="0 0 1"/>
		<child link="link_1"/>
		<parent link="link_9"/>
	</joint>
	<link name="link_2">
		<visual name="knob-3">
			<origin xyz="0.37333099999999997 -0.5199065 0"/>
			<geometry>
				<mesh filename="textured_objs/original-12.obj"/>
			</geometry>
		</visual>
		<collision>
			<origin xyz="0.37333099999999997 -0.5199065 0"/>
			<geometry>
				<mesh filename="textured_objs/original-12.obj"/>
			</geometry>
		</collision>
	</link>
	<joint name="joint_2" type="continuous">
		<origin xyz="-0.37333099999999997 0.5199065 0"/>
		<axis xyz="0 0 1"/>
		<child link="link_2"/>
		<parent link="link_9"/>
	</joint>
	<link name="link_3">
		<visual name="knob-4">
			<origin xyz="0.25749299999999997 -0.5199065 0"/>
			<geometry>
				<mesh filename="textured_objs/original-15.obj"/>
			</geometry>
		</visual>
		<collision>
			<origin xyz="0.25749299999999997 -0.5199065 0"/>
			<geometry>
				<mesh filename="textured_objs/original-15.obj"/>
			</geometry>
		</collision>
	</link>
	<joint name="joint_3" type="continuous">
		<origin xyz="-0.25749299999999997 0.5199065 0"/>
		<axis xyz="0 0 1"/>
		<child link="link_3"/>
		<parent link="link_9"/>
	</joint>
	<link name="link_4">
		<visual name="button-5">
			<origin xyz="0.076329 -0.518193 0"/>
			<geometry>
				<mesh filename="textured_objs/original-101.obj"/>
			</geometry>
		</visual>
		<collision>
			<origin xyz="0.076329 -0.518193 0"/>
			<geometry>
				<mesh filename="textured_objs/original-101.obj"/>
			</geometry>
		</collision>
	</link>
	<joint name="joint_4" type="prismatic">
		<origin xyz="-0.076329 0.518193 0"/>
		<axis xyz="0 0 -1"/>
		<child link="link_4"/>
		<parent link="link_9"/>
		<limit lower="0" upper="0.008000000000000007"/>
	</joint>
	<link name="link_5">
		<visual name="button-6">
			<origin xyz="0.076329 -0.518193 0"/>
			<geometry>
				<mesh filename="textured_objs/original-102.obj"/>
			</geometry>
		</visual>
		<collision>
			<origin xyz="0.076329 -0.518193 0"/>
			<geometry>
				<mesh filename="textured_objs/original-102.obj"/>
			</geometry>
		</collision>
	</link>
	<joint name="joint_5" type="prismatic">
		<origin xyz="-0.076329 0.518193 0"/>
		<axis xyz="0 0 -1"/>
		<child link="link_5"/>
		<parent link="link_9"/>
		<limit lower="0" upper="0.008000000000000007"/>
	</joint>
	<link name="link_6">
		<visual name="button-7">
			<origin xyz="0.076329 -0.518193 0"/>
			<geometry>
				<mesh filename="textured_objs/original-109.obj"/>
			</geometry>
		</visual>
		<collision>
			<origin xyz="0.076329 -0.518193 0"/>
			<geometry>
				<mesh filename="textured_objs/original-109.obj"/>
			</geometry>
		</collision>
	</link>
	<joint name="joint_6" type="prismatic">
		<origin xyz="-0.076329 0.518193 0"/>
		<axis xyz="0 0 -1"/>
		<child link="link_6"/>
		<parent link="link_9"/>
		<limit lower="0" upper="0.008000000000000007"/>
	</joint>
	<link name="link_7">
		<visual name="button-8">
			<origin xyz="0.076329 -0.518193 0"/>
			<geometry>
				<mesh filename="textured_objs/original-100.obj"/>
			</geometry>
		</visual>
		<collision>
			<origin xyz="0.076329 -0.518193 0"/>
			<geometry>
				<mesh filename="textured_objs/original-100.obj"/>
			</geometry>
		</collision>
	</link>
	<joint name="joint_7" type="prismatic">
		<origin xyz="-0.076329 0.518193 0"/>
		<axis xyz="0 0 -1"/>
		<child link="link_7"/>
		<parent link="link_9"/>
		<limit lower="0" upper="0.008000000000000007"/>
	</joint>
	<link name="link_8">
		<visual name="button-9">
			<origin xyz="0.076329 -0.518193 0"/>
			<geometry>
				<mesh filename="textured_objs/original-107.obj"/>
			</geometry>
		</visual>
		<collision>
			<origin xyz="0.076329 -0.518193 0"/>
			<geometry>
				<mesh filename="textured_objs/original-107.obj"/>
			</geometry>
		</collision>
	</link>
	<joint name="joint_8" type="prismatic">
		<origin xyz="-0.076329 0.518193 0"/>
		<axis xyz="0 0 -1"/>
		<child link="link_8"/>
		<parent link="link_9"/>
		<limit lower="0" upper="0.008000000000000007"/>
	</joint>
	<link name="link_9">
		<visual name="base_body-10">
			<origin xyz="0 0 0"/>
			<geometry>
				<mesh filename="textured_objs/original-103.obj"/>
			</geometry>
		</visual>
		<visual name="base_body-10">
			<origin xyz="0 0 0"/>
			<geometry>
				<mesh filename="textured_objs/original-21.obj"/>
			</geometry>
		</visual>
		<visual name="base_body-10">
			<origin xyz="0 0 0"/>
			<geometry>
				<mesh filename="textured_objs/original-30.obj"/>
			</geometry>
		</visual>
		<visual name="base_body-10">
			<origin xyz="0 0 0"/>
			<geometry>
				<mesh filename="textured_objs/original-36.obj"/>
			</geometry>
		</visual>
		<visual name="base_body-10">
			<origin xyz="0 0 0"/>
			<geometry>
				<mesh filename="textured_objs/original-28.obj"/>
			</geometry>
		</visual>
		<visual name="base_body-10">
			<origin xyz="0 0 0"/>
			<geometry>
				<mesh filename="textured_objs/original-96.obj"/>
			</geometry>
		</visual>
		<visual name="base_body-10">
			<origin xyz="0 0 0"/>
			<geometry>
				<mesh filename="textured_objs/original-64.obj"/>
			</geometry>
		</visual>
		<visual name="base_body-10">
			<origin xyz="0 0 0"/>
			<geometry>
				<mesh filename="textured_objs/original-43.obj"/>
			</geometry>
		</visual>
		<visual name="base_body-10">
			<origin xyz="0 0 0"/>
			<geometry>
				<mesh filename="textured_objs/original-71.obj"/>
			</geometry>
		</visual>
		<visual name="base_body-10">
			<origin xyz="0 0 0"/>
			<geometry>
				<mesh filename="textured_objs/original-83.obj"/>
			</geometry>
		</visual>
		<visual name="base_body-10">
			<origin xyz="0 0 0"/>
			<geometry>
				<mesh filename="textured_objs/original-22.obj"/>
			</geometry>
		</visual>
		<visual name="base_body-10">
			<origin xyz="0 0 0"/>
			<geometry>
				<mesh filename="textured_objs/original-26.obj"/>
			</geometry>
		</visual>
		<visual name="base_body-10">
			<origin xyz="0 0 0"/>
			<geometry>
				<mesh filename="textured_objs/original-104.obj"/>
			</geometry>
		</visual>
		<visual name="base_body-10">
			<origin xyz="0 0 0"/>
			<geometry>
				<mesh filename="textured_objs/original-65.obj"/>
			</geometry>
		</visual>
		<visual name="base_body-10">
			<origin xyz="0 0 0"/>
			<geometry>
				<mesh filename="textured_objs/original-33.obj"/>
			</geometry>
		</visual>
		<visual name="base_body-10">
			<origin xyz="0 0 0"/>
			<geometry>
				<mesh filename="textured_objs/original-44.obj"/>
			</geometry>
		</visual>
		<visual name="base_body-10">
			<origin xyz="0 0 0"/>
			<geometry>
				<mesh filename="textured_objs/original-106.obj"/>
			</geometry>
		</visual>
		<visual name="base_body-10">
			<origin xyz="0 0 0"/>
			<geometry>
				<mesh filename="textured_objs/original-16.obj"/>
			</geometry>
		</visual>
		<visual name="base_body-10">
			<origin xyz="0 0 0"/>
			<geometry>
				<mesh filename="textured_objs/original-86.obj"/>
			</geometry>
		</visual>
		<visual name="base_body-10">
			<origin xyz="0 0 0"/>
			<geometry>
				<mesh filename="textured_objs/original-13.obj"/>
			</geometry>
		</visual>
		<visual name="base_body-10">
			<origin xyz="0 0 0"/>
			<geometry>
				<mesh filename="textured_objs/original-45.obj"/>
			</geometry>
		</visual>
		<visual name="base_body-10">
			<origin xyz="0 0 0"/>
			<geometry>
				<mesh filename="textured_objs/original-35.obj"/>
			</geometry>
		</visual>
		<visual name="base_body-10">
			<origin xyz="0 0 0"/>
			<geometry>
				<mesh filename="textured_objs/original-93.obj"/>
			</geometry>
		</visual>
		<visual name="base_body-10">
			<origin xyz="0 0 0"/>
			<geometry>
				<mesh filename="textured_objs/original-61.obj"/>
			</geometry>
		</visual>
		<visual name="base_body-10">
			<origin xyz="0 0 0"/>
			<geometry>
				<mesh filename="textured_objs/original-39.obj"/>
			</geometry>
		</visual>
		<visual name="base_body-10">
			<origin xyz="0 0 0"/>
			<geometry>
				<mesh filename="textured_objs/original-59.obj"/>
			</geometry>
		</visual>
		<visual name="base_body-10">
			<origin xyz="0 0 0"/>
			<geometry>
				<mesh filename="textured_objs/original-77.obj"/>
			</geometry>
		</visual>
		<visual name="base_body-10">
			<origin xyz="0 0 0"/>
			<geometry>
				<mesh filename="textured_objs/original-63.obj"/>
			</geometry>
		</visual>
		<visual name="base_body-10">
			<origin xyz="0 0 0"/>
			<geometry>
				<mesh filename="textured_objs/original-27.obj"/>
			</geometry>
		</visual>
		<visual name="base_body-10">
			<origin xyz="0 0 0"/>
			<geometry>
				<mesh filename="textured_objs/original-87.obj"/>
			</geometry>
		</visual>
		<visual name="base_body-10">
			<origin xyz="0 0 0"/>
			<geometry>
				<mesh filename="textured_objs/original-51.obj"/>
			</geometry>
		</visual>
		<visual name="base_body-10">
			<origin xyz="0 0 0"/>
			<geometry>
				<mesh filename="textured_objs/original-55.obj"/>
			</geometry>
		</visual>
		<visual name="base_body-10">
			<origin xyz="0 0 0"/>
			<geometry>
				<mesh filename="textured_objs/original-50.obj"/>
			</geometry>
		</visual>
		<visual name="base_body-10">
			<origin xyz="0 0 0"/>
			<geometry>
				<mesh filename="textured_objs/original-31.obj"/>
			</geometry>
		</visual>
		<visual name="base_body-10">
			<origin xyz="0 0 0"/>
			<geometry>
				<mesh filename="textured_objs/original-85.obj"/>
			</geometry>
		</visual>
		<visual name="base_body-10">
			<origin xyz="0 0 0"/>
			<geometry>
				<mesh filename="textured_objs/original-56.obj"/>
			</geometry>
		</visual>
		<visual name="base_body-10">
			<origin xyz="0 0 0"/>
			<geometry>
				<mesh filename="textured_objs/original-76.obj"/>
			</geometry>
		</visual>
		<visual name="base_body-10">
			<origin xyz="0 0 0"/>
			<geometry>
				<mesh filename="textured_objs/original-108.obj"/>
			</geometry>
		</visual>
		<visual name="base_body-10">
			<origin xyz="0 0 0"/>
			<geometry>
				<mesh filename="textured_objs/original-72.obj"/>
			</geometry>
		</visual>
		<visual name="base_body-10">
			<origin xyz="0 0 0"/>
			<geometry>
				<mesh filename="textured_objs/original-99.obj"/>
			</geometry>
		</visual>
		<visual name="base_body-10">
			<origin xyz="0 0 0"/>
			<geometry>
				<mesh filename="textured_objs/original-62.obj"/>
			</geometry>
		</visual>
		<visual name="base_body-10">
			<origin xyz="0 0 0"/>
			<geometry>
				<mesh filename="textured_objs/original-75.obj"/>
			</geometry>
		</visual>
		<visual name="base_body-10">
			<origin xyz="0 0 0"/>
			<geometry>
				<mesh filename="textured_objs/original-23.obj"/>
			</geometry>
		</visual>
		<visual name="base_body-10">
			<origin xyz="0 0 0"/>
			<geometry>
				<mesh filename="textured_objs/original-66.obj"/>
			</geometry>
		</visual>
		<visual name="base_body-10">
			<origin xyz="0 0 0"/>
			<geometry>
				<mesh filename="textured_objs/original-58.obj"/>
			</geometry>
		</visual>
		<visual name="base_body-10">
			<origin xyz="0 0 0"/>
			<geometry>
				<mesh filename="textured_objs/original-98.obj"/>
			</geometry>
		</visual>
		<visual name="base_body-10">
			<origin xyz="0 0 0"/>
			<geometry>
				<mesh filename="textured_objs/original-67.obj"/>
			</geometry>
		</visual>
		<visual name="base_body-10">
			<origin xyz="0 0 0"/>
			<geometry>
				<mesh filename="textured_objs/original-69.obj"/>
			</geometry>
		</visual>
		<visual name="base_body-10">
			<origin xyz="0 0 0"/>
			<geometry>
				<mesh filename="textured_objs/original-38.obj"/>
			</geometry>
		</visual>
		<visual name="base_body-10">
			<origin xyz="0 0 0"/>
			<geometry>
				<mesh filename="textured_objs/original-68.obj"/>
			</geometry>
		</visual>
		<visual name="base_body-10">
			<origin xyz="0 0 0"/>
			<geometry>
				<mesh filename="textured_objs/original-80.obj"/>
			</geometry>
		</visual>
		<visual name="base_body-10">
			<origin xyz="0 0 0"/>
			<geometry>
				<mesh filename="textured_objs/original-34.obj"/>
			</geometry>
		</visual>
		<visual name="base_body-10">
			<origin xyz="0 0 0"/>
			<geometry>
				<mesh filename="textured_objs/original-18.obj"/>
			</geometry>
		</visual>
		<visual name="base_body-10">
			<origin xyz="0 0 0"/>
			<geometry>
				<mesh filename="textured_objs/original-70.obj"/>
			</geometry>
		</visual>
		<visual name="base_body-10">
			<origin xyz="0 0 0"/>
			<geometry>
				<mesh filename="textured_objs/original-74.obj"/>
			</geometry>
		</visual>
		<visual name="base_body-10">
			<origin xyz="0 0 0"/>
			<geometry>
				<mesh filename="textured_objs/original-91.obj"/>
			</geometry>
		</visual>
		<visual name="base_body-10">
			<origin xyz="0 0 0"/>
			<geometry>
				<mesh filename="textured_objs/original-25.obj"/>
			</geometry>
		</visual>
		<visual name="base_body-10">
			<origin xyz="0 0 0"/>
			<geometry>
				<mesh filename="textured_objs/original-73.obj"/>
			</geometry>
		</visual>
		<visual name="base_body-10">
			<origin xyz="0 0 0"/>
			<geometry>
				<mesh filename="textured_objs/original-92.obj"/>
			</geometry>
		</visual>
		<visual name="base_body-10">
			<origin xyz="0 0 0"/>
			<geometry>
				<mesh filename="textured_objs/original-79.obj"/>
			</geometry>
		</visual>
		<visual name="base_body-10">
			<origin xyz="0 0 0"/>
			<geometry>
				<mesh filename="textured_objs/original-20.obj"/>
			</geometry>
		</visual>
		<visual name="base_body-10">
			<origin xyz="0 0 0"/>
			<geometry>
				<mesh filename="textured_objs/original-88.obj"/>
			</geometry>
		</visual>
		<visual name="base_body-10">
			<origin xyz="0 0 0"/>
			<geometry>
				<mesh filename="textured_objs/original-32.obj"/>
			</geometry>
		</visual>
		<visual name="base_body-10">
			<origin xyz="0 0 0"/>
			<geometry>
				<mesh filename="textured_objs/original-95.obj"/>
			</geometry>
		</visual>
		<visual name="base_body-10">
			<origin xyz="0 0 0"/>
			<geometry>
				<mesh filename="textured_objs/original-105.obj"/>
			</geometry>
		</visual>
		<visual name="base_body-10">
			<origin xyz="0 0 0"/>
			<geometry>
				<mesh filename="textured_objs/original-81.obj"/>
			</geometry>
		</visual>
		<visual name="base_body-10">
			<origin xyz="0 0 0"/>
			<geometry>
				<mesh filename="textured_objs/original-84.obj"/>
			</geometry>
		</visual>
		<visual name="base_body-10">
			<origin xyz="0 0 0"/>
			<geometry>
				<mesh filename="textured_objs/original-94.obj"/>
			</geometry>
		</visual>
		<visual name="base_body-10">
			<origin xyz="0 0 0"/>
			<geometry>
				<mesh filename="textured_objs/original-78.obj"/>
			</geometry>
		</visual>
		<visual name="base_body-10">
			<origin xyz="0 0 0"/>
			<geometry>
				<mesh filename="textured_objs/original-97.obj"/>
			</geometry>
		</visual>
		<visual name="base_body-10">
			<origin xyz="0 0 0"/>
			<geometry>
				<mesh filename="textured_objs/original-89.obj"/>
			</geometry>
		</visual>
		<visual name="base_body-10">
			<origin xyz="0 0 0"/>
			<geometry>
				<mesh filename="textured_objs/original-10.obj"/>
			</geometry>
		</visual>
		<visual name="base_body-10">
			<origin xyz="0 0 0"/>
			<geometry>
				<mesh filename="textured_objs/original-82.obj"/>
			</geometry>
		</visual>
		<visual name="base_body-10">
			<origin xyz="0 0 0"/>
			<geometry>
				<mesh filename="textured_objs/original-60.obj"/>
			</geometry>
		</visual>
		<visual name="base_body-10">
			<origin xyz="0 0 0"/>
			<geometry>
				<mesh filename="textured_objs/original-19.obj"/>
			</geometry>
		</visual>
		<visual name="base_body-10">
			<origin xyz="0 0 0"/>
			<geometry>
				<mesh filename="textured_objs/original-90.obj"/>
			</geometry>
		</visual>
		<visual name="base_body-10">
			<origin xyz="0 0 0"/>
			<geometry>
				<mesh filename="textured_objs/original-40.obj"/>
			</geometry>
		</visual>
		<visual name="base_body-10">
			<origin xyz="0 0 0"/>
			<geometry>
				<mesh filename="textured_objs/original-57.obj"/>
			</geometry>
		</visual>
		<collision>
			<origin xyz="0 0 0"/>
			<geometry>
				<mesh filename="textured_objs/original-103.obj"/>
			</geometry>
		</collision>
		<collision>
			<origin xyz="0 0 0"/>
			<geometry>
				<mesh filename="textured_objs/original-21.obj"/>
			</geometry>
		</collision>
		<collision>
			<origin xyz="0 0 0"/>
			<geometry>
				<mesh filename="textured_objs/original-30.obj"/>
			</geometry>
		</collision>
		<collision>
			<origin xyz="0 0 0"/>
			<geometry>
				<mesh filename="textured_objs/original-36.obj"/>
			</geometry>
		</collision>
		<collision>
			<origin xyz="0 0 0"/>
			<geometry>
				<mesh filename="textured_objs/original-28.obj"/>
			</geometry>
		</collision>
		<collision>
			<origin xyz="0 0 0"/>
			<geometry>
				<mesh filename="textured_objs/original-96.obj"/>
			</geometry>
		</collision>
		<collision>
			<origin xyz="0 0 0"/>
			<geometry>
				<mesh filename="textured_objs/original-64.obj"/>
			</geometry>
		</collision>
		<collision>
			<origin xyz="0 0 0"/>
			<geometry>
				<mesh filename="textured_objs/original-43.obj"/>
			</geometry>
		</collision>
		<collision>
			<origin xyz="0 0 0"/>
			<geometry>
				<mesh filename="textured_objs/original-71.obj"/>
			</geometry>
		</collision>
		<collision>
			<origin xyz="0 0 0"/>
			<geometry>
				<mesh filename="textured_objs/original-83.obj"/>
			</geometry>
		</collision>
		<collision>
			<origin xyz="0 0 0"/>
			<geometry>
				<mesh filename="textured_objs/original-22.obj"/>
			</geometry>
		</collision>
		<collision>
			<origin xyz="0 0 0"/>
			<geometry>
				<mesh filename="textured_objs/original-26.obj"/>
			</geometry>
		</collision>
		<collision>
			<origin xyz="0 0 0"/>
			<geometry>
				<mesh filename="textured_objs/original-104.obj"/>
			</geometry>
		</collision>
		<collision>
			<origin xyz="0 0 0"/>
			<geometry>
				<mesh filename="textured_objs/original-65.obj"/>
			</geometry>
		</collision>
		<collision>
			<origin xyz="0 0 0"/>
			<geometry>
				<mesh filename="textured_objs/original-33.obj"/>
			</geometry>
		</collision>
		<collision>
			<origin xyz="0 0 0"/>
			<geometry>
				<mesh filename="textured_objs/original-44.obj"/>
			</geometry>
		</collision>
		<collision>
			<origin xyz="0 0 0"/>
			<geometry>
				<mesh filename="textured_objs/original-106.obj"/>
			</geometry>
		</collision>
		<collision>
			<origin xyz="0 0 0"/>
			<geometry>
				<mesh filename="textured_objs/original-16.obj"/>
			</geometry>
		</collision>
		<collision>
			<origin xyz="0 0 0"/>
			<geometry>
				<mesh filename="textured_objs/original-86.obj"/>
			</geometry>
		</collision>
		<collision>
			<origin xyz="0 0 0"/>
			<geometry>
				<mesh filename="textured_objs/original-13.obj"/>
			</geometry>
		</collision>
		<collision>
			<origin xyz="0 0 0"/>
			<geometry>
				<mesh filename="textured_objs/original-45.obj"/>
			</geometry>
		</collision>
		<collision>
			<origin xyz="0 0 0"/>
			<geometry>
				<mesh filename="textured_objs/original-35.obj"/>
			</geometry>
		</collision>
		<collision>
			<origin xyz="0 0 0"/>
			<geometry>
				<mesh filename="textured_objs/original-93.obj"/>
			</geometry>
		</collision>
		<collision>
			<origin xyz="0 0 0"/>
			<geometry>
				<mesh filename="textured_objs/original-61.obj"/>
			</geometry>
		</collision>
		<collision>
			<origin xyz="0 0 0"/>
			<geometry>
				<mesh filename="textured_objs/original-39.obj"/>
			</geometry>
		</collision>
		<collision>
			<origin xyz="0 0 0"/>
			<geometry>
				<mesh filename="textured_objs/original-59.obj"/>
			</geometry>
		</collision>
		<collision>
			<origin xyz="0 0 0"/>
			<geometry>
				<mesh filename="textured_objs/original-77.obj"/>
			</geometry>
		</collision>
		<collision>
			<origin xyz="0 0 0"/>
			<geometry>
				<mesh filename="textured_objs/original-63.obj"/>
			</geometry>
		</collision>
		<collision>
			<origin xyz="0 0 0"/>
			<geometry>
				<mesh filename="textured_objs/original-27.obj"/>
			</geometry>
		</collision>
		<collision>
			<origin xyz="0 0 0"/>
			<geometry>
				<mesh filename="textured_objs/original-87.obj"/>
			</geometry>
		</collision>
		<collision>
			<origin xyz="0 0 0"/>
			<geometry>
				<mesh filename="textured_objs/original-51.obj"/>
			</geometry>
		</collision>
		<collision>
			<origin xyz="0 0 0"/>
			<geometry>
				<mesh filename="textured_objs/original-55.obj"/>
			</geometry>
		</collision>
		<collision>
			<origin xyz="0 0 0"/>
			<geometry>
				<mesh filename="textured_objs/original-50.obj"/>
			</geometry>
		</collision>
		<collision>
			<origin xyz="0 0 0"/>
			<geometry>
				<mesh filename="textured_objs/original-31.obj"/>
			</geometry>
		</collision>
		<collision>
			<origin xyz="0 0 0"/>
			<geometry>
				<mesh filename="textured_objs/original-85.obj"/>
			</geometry>
		</collision>
		<collision>
			<origin xyz="0 0 0"/>
			<geometry>
				<mesh filename="textured_objs/original-56.obj"/>
			</geometry>
		</collision>
		<collision>
			<origin xyz="0 0 0"/>
			<geometry>
				<mesh filename="textured_objs/original-76.obj"/>
			</geometry>
		</collision>
		<collision>
			<origin xyz="0 0 0"/>
			<geometry>
				<mesh filename="textured_objs/original-108.obj"/>
			</geometry>
		</collision>
		<collision>
			<origin xyz="0 0 0"/>
			<geometry>
				<mesh filename="textured_objs/original-72.obj"/>
			</geometry>
		</collision>
		<collision>
			<origin xyz="0 0 0"/>
			<geometry>
				<mesh filename="textured_objs/original-99.obj"/>
			</geometry>
		</collision>
		<collision>
			<origin xyz="0 0 0"/>
			<geometry>
				<mesh filename="textured_objs/original-62.obj"/>
			</geometry>
		</collision>
		<collision>
			<origin xyz="0 0 0"/>
			<geometry>
				<mesh filename="textured_objs/original-75.obj"/>
			</geometry>
		</collision>
		<collision>
			<origin xyz="0 0 0"/>
			<geometry>
				<mesh filename="textured_objs/original-23.obj"/>
			</geometry>
		</collision>
		<collision>
			<origin xyz="0 0 0"/>
			<geometry>
				<mesh filename="textured_objs/original-66.obj"/>
			</geometry>
		</collision>
		<collision>
			<origin xyz="0 0 0"/>
			<geometry>
				<mesh filename="textured_objs/original-58.obj"/>
			</geometry>
		</collision>
		<collision>
			<origin xyz="0 0 0"/>
			<geometry>
				<mesh filename="textured_objs/original-98.obj"/>
			</geometry>
		</collision>
		<collision>
			<origin xyz="0 0 0"/>
			<geometry>
				<mesh filename="textured_objs/original-67.obj"/>
			</geometry>
		</collision>
		<collision>
			<origin xyz="0 0 0"/>
			<geometry>
				<mesh filename="textured_objs/original-69.obj"/>
			</geometry>
		</collision>
		<collision>
			<origin xyz="0 0 0"/>
			<geometry>
				<mesh filename="textured_objs/original-38.obj"/>
			</geometry>
		</collision>
		<collision>
			<origin xyz="0 0 0"/>
			<geometry>
				<mesh filename="textured_objs/original-68.obj"/>
			</geometry>
		</collision>
		<collision>
			<origin xyz="0 0 0"/>
			<geometry>
				<mesh filename="textured_objs/original-80.obj"/>
			</geometry>
		</collision>
		<collision>
			<origin xyz="0 0 0"/>
			<geometry>
				<mesh filename="textured_objs/original-34.obj"/>
			</geometry>
		</collision>
		<collision>
			<origin xyz="0 0 0"/>
			<geometry>
				<mesh filename="textured_objs/original-18.obj"/>
			</geometry>
		</collision>
		<collision>
			<origin xyz="0 0 0"/>
			<geometry>
				<mesh filename="textured_objs/original-70.obj"/>
			</geometry>
		</collision>
		<collision>
			<origin xyz="0 0 0"/>
			<geometry>
				<mesh filename="textured_objs/original-74.obj"/>
			</geometry>
		</collision>
		<collision>
			<origin xyz="0 0 0"/>
			<geometry>
				<mesh filename="textured_objs/original-91.obj"/>
			</geometry>
		</collision>
		<collision>
			<origin xyz="0 0 0"/>
			<geometry>
				<mesh filename="textured_objs/original-25.obj"/>
			</geometry>
		</collision>
		<collision>
			<origin xyz="0 0 0"/>
			<geometry>
				<mesh filename="textured_objs/original-73.obj"/>
			</geometry>
		</collision>
		<collision>
			<origin xyz="0 0 0"/>
			<geometry>
				<mesh filename="textured_objs/original-92.obj"/>
			</geometry>
		</collision>
		<collision>
			<origin xyz="0 0 0"/>
			<geometry>
				<mesh filename="textured_objs/original-79.obj"/>
			</geometry>
		</collision>
		<collision>
			<origin xyz="0 0 0"/>
			<geometry>
				<mesh filename="textured_objs/original-20.obj"/>
			</geometry>
		</collision>
		<collision>
			<origin xyz="0 0 0"/>
			<geometry>
				<mesh filename="textured_objs/original-88.obj"/>
			</geometry>
		</collision>
		<collision>
			<origin xyz="0 0 0"/>
			<geometry>
				<mesh filename="textured_objs/original-32.obj"/>
			</geometry>
		</collision>
		<collision>
			<origin xyz="0 0 0"/>
			<geometry>
				<mesh filename="textured_objs/original-95.obj"/>
			</geometry>
		</collision>
		<collision>
			<origin xyz="0 0 0"/>
			<geometry>
				<mesh filename="textured_objs/original-105.obj"/>
			</geometry>
		</collision>
		<collision>
			<origin xyz="0 0 0"/>
			<geometry>
				<mesh filename="textured_objs/original-81.obj"/>
			</geometry>
		</collision>
		<collision>
			<origin xyz="0 0 0"/>
			<geometry>
				<mesh filename="textured_objs/original-84.obj"/>
			</geometry>
		</collision>
		<collision>
			<origin xyz="0 0 0"/>
			<geometry>
				<mesh filename="textured_objs/original-94.obj"/>
			</geometry>
		</collision>
		<collision>
			<origin xyz="0 0 0"/>
			<geometry>
				<mesh filename="textured_objs/original-78.obj"/>
			</geometry>
		</collision>
		<collision>
			<origin xyz="0 0 0"/>
			<geometry>
				<mesh filename="textured_objs/original-97.obj"/>
			</geometry>
		</collision>
		<collision>
			<origin xyz="0 0 0"/>
			<geometry>
				<mesh filename="textured_objs/original-89.obj"/>
			</geometry>
		</collision>
		<collision>
			<origin xyz="0 0 0"/>
			<geometry>
				<mesh filename="textured_objs/original-10.obj"/>
			</geometry>
		</collision>
		<collision>
			<origin xyz="0 0 0"/>
			<geometry>
				<mesh filename="textured_objs/original-82.obj"/>
			</geometry>
		</collision>
		<collision>
			<origin xyz="0 0 0"/>
			<geometry>
				<mesh filename="textured_objs/original-60.obj"/>
			</geometry>
		</collision>
		<collision>
			<origin xyz="0 0 0"/>
			<geometry>
				<mesh filename="textured_objs/original-19.obj"/>
			</geometry>
		</collision>
		<collision>
			<origin xyz="0 0 0"/>
			<geometry>
				<mesh filename="textured_objs/original-90.obj"/>
			</geometry>
		</collision>
		<collision>
			<origin xyz="0 0 0"/>
			<geometry>
				<mesh filename="textured_objs/original-40.obj"/>
			</geometry>
		</collision>
		<collision>
			<origin xyz="0 0 0"/>
			<geometry>
				<mesh filename="textured_objs/original-57.obj"/>
			</geometry>
		</collision>
	</link>
	<joint name="joint_9" type="fixed">
		<origin rpy="1.570796326794897 0 -1.570796326794897" xyz="0 0 0"/>
		<child link="link_9"/>
		<parent link="base"/>
	</joint>
</robot>
