<?xml version="1.0" ?>
<robot name="partnet_9191df20dc5559a38a68adc64e25938f">
	<link name="base"/>
	<link name="link_0">
		<visual name="door-2">
			<origin xyz="-0.5489212254039852 0.20136937466374594 -0.3894739712377725"/>
			<geometry>
				<mesh filename="textured_objs/original-102.obj"/>
			</geometry>
		</visual>
		<visual name="door-2">
			<origin xyz="-0.5489212254039852 0.20136937466374594 -0.3894739712377725"/>
			<geometry>
				<mesh filename="textured_objs/original-49.obj"/>
			</geometry>
		</visual>
		<visual name="door-2">
			<origin xyz="-0.5489212254039852 0.20136937466374594 -0.3894739712377725"/>
			<geometry>
				<mesh filename="textured_objs/original-158.obj"/>
			</geometry>
		</visual>
		<visual name="door-2">
			<origin xyz="-0.5489212254039852 0.20136937466374594 -0.3894739712377725"/>
			<geometry>
				<mesh filename="textured_objs/original-159.obj"/>
			</geometry>
		</visual>
		<collision>
			<origin xyz="-0.5489212254039852 0.20136937466374594 -0.3894739712377725"/>
			<geometry>
				<mesh filename="textured_objs/original-102.obj"/>
			</geometry>
		</collision>
		<collision>
			<origin xyz="-0.5489212254039852 0.20136937466374594 -0.3894739712377725"/>
			<geometry>
				<mesh filename="textured_objs/original-49.obj"/>
			</geometry>
		</collision>
		<collision>
			<origin xyz="-0.5489212254039852 0.20136937466374594 -0.3894739712377725"/>
			<geometry>
				<mesh filename="textured_objs/original-158.obj"/>
			</geometry>
		</collision>
		<collision>
			<origin xyz="-0.5489212254039852 0.20136937466374594 -0.3894739712377725"/>
			<geometry>
				<mesh filename="textured_objs/original-159.obj"/>
			</geometry>
		</collision>
	</link>
	<joint name="joint_0" type="revolute">
		<origin xyz="0.5489212254039852 -0.20136937466374594 0.3894739712377725"/>
		<axis xyz="1 0 0"/>
		<child link="link_0"/>
		<parent link="link_11"/>
		<limit lower="0.0" upper="1.5707963267948966"/>
	</joint>
	<link name="link_1">
		<visual name="door-4">
			<origin xyz="-0.5489212254039852 0.20136937466374594 -0.3894739712377725"/>
			<geometry>
				<mesh filename="textured_objs/original-160.obj"/>
			</geometry>
		</visual>
		<visual name="door-4">
			<origin xyz="-0.5489212254039852 0.20136937466374594 -0.3894739712377725"/>
			<geometry>
				<mesh filename="textured_objs/original-50.obj"/>
			</geometry>
		</visual>
		<visual name="door-4">
			<origin xyz="-0.5489212254039852 0.20136937466374594 -0.3894739712377725"/>
			<geometry>
				<mesh filename="textured_objs/original-107.obj"/>
			</geometry>
		</visual>
		<visual name="door-4">
			<origin xyz="-0.5489212254039852 0.20136937466374594 -0.3894739712377725"/>
			<geometry>
				<mesh filename="textured_objs/original-161.obj"/>
			</geometry>
		</visual>
		<collision>
			<origin xyz="-0.5489212254039852 0.20136937466374594 -0.3894739712377725"/>
			<geometry>
				<mesh filename="textured_objs/original-160.obj"/>
			</geometry>
		</collision>
		<collision>
			<origin xyz="-0.5489212254039852 0.20136937466374594 -0.3894739712377725"/>
			<geometry>
				<mesh filename="textured_objs/original-50.obj"/>
			</geometry>
		</collision>
		<collision>
			<origin xyz="-0.5489212254039852 0.20136937466374594 -0.3894739712377725"/>
			<geometry>
				<mesh filename="textured_objs/original-107.obj"/>
			</geometry>
		</collision>
		<collision>
			<origin xyz="-0.5489212254039852 0.20136937466374594 -0.3894739712377725"/>
			<geometry>
				<mesh filename="textured_objs/original-161.obj"/>
			</geometry>
		</collision>
	</link>
	<joint name="joint_1" type="revolute">
		<origin xyz="0.5489212254039852 -0.20136937466374594 0.3894739712377725"/>
		<axis xyz="1 0 0"/>
		<child link="link_1"/>
		<parent link="link_11"/>
		<limit lower="0.0" upper="1.5707963267948966"/>
	</joint>
	<link name="link_2">
		<visual name="knob-5">
			<origin xyz="-0.3965274866293377 -0.229991298161458 0.061819660943966445"/>
			<geometry>
				<mesh filename="textured_objs/original-15.obj"/>
			</geometry>
		</visual>
		<visual name="knob-5">
			<origin xyz="-0.3965274866293377 -0.229991298161458 0.061819660943966445"/>
			<geometry>
				<mesh filename="textured_objs/original-112.obj"/>
			</geometry>
		</visual>
		<visual name="knob-5">
			<origin xyz="-0.3965274866293377 -0.229991298161458 0.061819660943966445"/>
			<geometry>
				<mesh filename="textured_objs/original-111.obj"/>
			</geometry>
		</visual>
		<collision>
			<origin xyz="-0.3965274866293377 -0.229991298161458 0.061819660943966445"/>
			<geometry>
				<mesh filename="textured_objs/original-15.obj"/>
			</geometry>
		</collision>
		<collision>
			<origin xyz="-0.3965274866293377 -0.229991298161458 0.061819660943966445"/>
			<geometry>
				<mesh filename="textured_objs/original-112.obj"/>
			</geometry>
		</collision>
		<collision>
			<origin xyz="-0.3965274866293377 -0.229991298161458 0.061819660943966445"/>
			<geometry>
				<mesh filename="textured_objs/original-111.obj"/>
			</geometry>
		</collision>
	</link>
	<joint name="joint_2" type="continuous">
		<origin xyz="0.3965274866293377 0.229991298161458 -0.061819660943966445"/>
		<axis xyz="5.564038959584587e-05 -0.2586185789798998 -0.9659795171278553"/>
		<child link="link_2"/>
		<parent link="link_11"/>
	</joint>
	<link name="link_3">
		<visual name="knob-6">
			<origin xyz="-0.3366339696288812 -0.22988625184047795 0.06187904115831878"/>
			<geometry>
				<mesh filename="textured_objs/original-23.obj"/>
			</geometry>
		</visual>
		<visual name="knob-6">
			<origin xyz="-0.3366339696288812 -0.22988625184047795 0.06187904115831878"/>
			<geometry>
				<mesh filename="textured_objs/original-128.obj"/>
			</geometry>
		</visual>
		<visual name="knob-6">
			<origin xyz="-0.3366339696288812 -0.22988625184047795 0.06187904115831878"/>
			<geometry>
				<mesh filename="textured_objs/original-127.obj"/>
			</geometry>
		</visual>
		<collision>
			<origin xyz="-0.3366339696288812 -0.22988625184047795 0.06187904115831878"/>
			<geometry>
				<mesh filename="textured_objs/original-23.obj"/>
			</geometry>
		</collision>
		<collision>
			<origin xyz="-0.3366339696288812 -0.22988625184047795 0.06187904115831878"/>
			<geometry>
				<mesh filename="textured_objs/original-128.obj"/>
			</geometry>
		</collision>
		<collision>
			<origin xyz="-0.3366339696288812 -0.22988625184047795 0.06187904115831878"/>
			<geometry>
				<mesh filename="textured_objs/original-127.obj"/>
			</geometry>
		</collision>
	</link>
	<joint name="joint_3" type="continuous">
		<origin xyz="0.3366339696288812 0.22988625184047795 -0.06187904115831878"/>
		<axis xyz="-5.6777823230002025e-05 -0.2587933182907042 -0.9659327177316054"/>
		<child link="link_3"/>
		<parent link="link_11"/>
	</joint>
	<link name="link_4">
		<visual name="knob-7">
			<origin xyz="-0.276793969615034 -0.22988713111276762 0.06187575931989689"/>
			<geometry>
				<mesh filename="textured_objs/original-18.obj"/>
			</geometry>
		</visual>
		<visual name="knob-7">
			<origin xyz="-0.276793969615034 -0.22988713111276762 0.06187575931989689"/>
			<geometry>
				<mesh filename="textured_objs/original-116.obj"/>
			</geometry>
		</visual>
		<visual name="knob-7">
			<origin xyz="-0.276793969615034 -0.22988713111276762 0.06187575931989689"/>
			<geometry>
				<mesh filename="textured_objs/original-115.obj"/>
			</geometry>
		</visual>
		<collision>
			<origin xyz="-0.276793969615034 -0.22988713111276762 0.06187575931989689"/>
			<geometry>
				<mesh filename="textured_objs/original-18.obj"/>
			</geometry>
		</collision>
		<collision>
			<origin xyz="-0.276793969615034 -0.22988713111276762 0.06187575931989689"/>
			<geometry>
				<mesh filename="textured_objs/original-116.obj"/>
			</geometry>
		</collision>
		<collision>
			<origin xyz="-0.276793969615034 -0.22988713111276762 0.06187575931989689"/>
			<geometry>
				<mesh filename="textured_objs/original-115.obj"/>
			</geometry>
		</collision>
	</link>
	<joint name="joint_4" type="continuous">
		<origin xyz="0.276793969615034 0.22988713111276762 -0.06187575931989689"/>
		<axis xyz="-5.6777823230002025e-05 -0.2587933182907042 -0.9659327177316054"/>
		<child link="link_4"/>
		<parent link="link_11"/>
	</joint>
	<link name="link_5">
		<visual name="knob-8">
			<origin xyz="-0.2172509913028825 -0.23016080379476836 0.06166470387233825"/>
			<geometry>
				<mesh filename="textured_objs/original-117.obj"/>
			</geometry>
		</visual>
		<visual name="knob-8">
			<origin xyz="-0.2172509913028825 -0.23016080379476836 0.06166470387233825"/>
			<geometry>
				<mesh filename="textured_objs/original-120.obj"/>
			</geometry>
		</visual>
		<collision>
			<origin xyz="-0.2172509913028825 -0.23016080379476836 0.06166470387233825"/>
			<geometry>
				<mesh filename="textured_objs/original-117.obj"/>
			</geometry>
		</collision>
		<collision>
			<origin xyz="-0.2172509913028825 -0.23016080379476836 0.06166470387233825"/>
			<geometry>
				<mesh filename="textured_objs/original-120.obj"/>
			</geometry>
		</collision>
	</link>
	<joint name="joint_5" type="continuous">
		<origin xyz="0.2172509913028825 0.23016080379476836 -0.06166470387233825"/>
		<axis xyz="0 -0.2587928207036303 -0.9659328527140273"/>
		<child link="link_5"/>
		<parent link="link_11"/>
	</joint>
	<link name="link_6">
		<visual name="knob-9">
			<origin xyz="0.0071486230960975715 -0.23013643181635182 0.061669596863122414"/>
			<geometry>
				<mesh filename="textured_objs/original-141.obj"/>
			</geometry>
		</visual>
		<visual name="knob-9">
			<origin xyz="0.0071486230960975715 -0.23013643181635182 0.061669596863122414"/>
			<geometry>
				<mesh filename="textured_objs/original-144.obj"/>
			</geometry>
		</visual>
		<collision>
			<origin xyz="0.0071486230960975715 -0.23013643181635182 0.061669596863122414"/>
			<geometry>
				<mesh filename="textured_objs/original-141.obj"/>
			</geometry>
		</collision>
		<collision>
			<origin xyz="0.0071486230960975715 -0.23013643181635182 0.061669596863122414"/>
			<geometry>
				<mesh filename="textured_objs/original-144.obj"/>
			</geometry>
		</collision>
	</link>
	<joint name="joint_6" type="continuous">
		<origin xyz="-0.0071486230960975715 0.23013643181635182 -0.061669596863122414"/>
		<axis xyz="0 0.2588375585204928 0.9659208654435159"/>
		<child link="link_6"/>
		<parent link="link_11"/>
	</joint>
	<link name="link_7">
		<visual name="knob-10">
			<origin xyz="0.277250302350674 -0.22989526432496335 0.061845402525703266"/>
			<geometry>
				<mesh filename="textured_objs/original-132.obj"/>
			</geometry>
		</visual>
		<visual name="knob-10">
			<origin xyz="0.277250302350674 -0.22989526432496335 0.061845402525703266"/>
			<geometry>
				<mesh filename="textured_objs/original-131.obj"/>
			</geometry>
		</visual>
		<visual name="knob-10">
			<origin xyz="0.277250302350674 -0.22989526432496335 0.061845402525703266"/>
			<geometry>
				<mesh filename="textured_objs/original-26.obj"/>
			</geometry>
		</visual>
		<collision>
			<origin xyz="0.277250302350674 -0.22989526432496335 0.061845402525703266"/>
			<geometry>
				<mesh filename="textured_objs/original-132.obj"/>
			</geometry>
		</collision>
		<collision>
			<origin xyz="0.277250302350674 -0.22989526432496335 0.061845402525703266"/>
			<geometry>
				<mesh filename="textured_objs/original-131.obj"/>
			</geometry>
		</collision>
		<collision>
			<origin xyz="0.277250302350674 -0.22989526432496335 0.061845402525703266"/>
			<geometry>
				<mesh filename="textured_objs/original-26.obj"/>
			</geometry>
		</collision>
	</link>
	<joint name="joint_7" type="continuous">
		<origin xyz="-0.277250302350674 0.22989526432496335 -0.061845402525703266"/>
		<axis xyz="-5.677724057017104e-05 -0.2587933343973364 -0.9659327134163401"/>
		<child link="link_7"/>
		<parent link="link_11"/>
	</joint>
	<link name="link_8">
		<visual name="knob-11">
			<origin xyz="0.3365650305268994 -0.22989614363904307 0.06184212053091609"/>
			<geometry>
				<mesh filename="textured_objs/original-29.obj"/>
			</geometry>
		</visual>
		<visual name="knob-11">
			<origin xyz="0.3365650305268994 -0.22989614363904307 0.06184212053091609"/>
			<geometry>
				<mesh filename="textured_objs/original-136.obj"/>
			</geometry>
		</visual>
		<visual name="knob-11">
			<origin xyz="0.3365650305268994 -0.22989614363904307 0.06184212053091609"/>
			<geometry>
				<mesh filename="textured_objs/original-135.obj"/>
			</geometry>
		</visual>
		<collision>
			<origin xyz="0.3365650305268994 -0.22989614363904307 0.06184212053091609"/>
			<geometry>
				<mesh filename="textured_objs/original-29.obj"/>
			</geometry>
		</collision>
		<collision>
			<origin xyz="0.3365650305268994 -0.22989614363904307 0.06184212053091609"/>
			<geometry>
				<mesh filename="textured_objs/original-136.obj"/>
			</geometry>
		</collision>
		<collision>
			<origin xyz="0.3365650305268994 -0.22989614363904307 0.06184212053091609"/>
			<geometry>
				<mesh filename="textured_objs/original-135.obj"/>
			</geometry>
		</collision>
	</link>
	<joint name="joint_8" type="continuous">
		<origin xyz="-0.3365650305268994 0.22989614363904307 -0.06184212053091609"/>
		<axis xyz="-5.6777823230002025e-05 -0.2587933182907042 -0.9659327177316054"/>
		<child link="link_8"/>
		<parent link="link_11"/>
	</joint>
	<link name="link_9">
		<visual name="knob-12">
			<origin xyz="0.3963515083547591 -0.2299798878029277 0.0618622732295198"/>
			<geometry>
				<mesh filename="textured_objs/original-32.obj"/>
			</geometry>
		</visual>
		<visual name="knob-12">
			<origin xyz="0.3963515083547591 -0.2299798878029277 0.0618622732295198"/>
			<geometry>
				<mesh filename="textured_objs/original-140.obj"/>
			</geometry>
		</visual>
		<visual name="knob-12">
			<origin xyz="0.3963515083547591 -0.2299798878029277 0.0618622732295198"/>
			<geometry>
				<mesh filename="textured_objs/original-139.obj"/>
			</geometry>
		</visual>
		<collision>
			<origin xyz="0.3963515083547591 -0.2299798878029277 0.0618622732295198"/>
			<geometry>
				<mesh filename="textured_objs/original-32.obj"/>
			</geometry>
		</collision>
		<collision>
			<origin xyz="0.3963515083547591 -0.2299798878029277 0.0618622732295198"/>
			<geometry>
				<mesh filename="textured_objs/original-140.obj"/>
			</geometry>
		</collision>
		<collision>
			<origin xyz="0.3963515083547591 -0.2299798878029277 0.0618622732295198"/>
			<geometry>
				<mesh filename="textured_objs/original-139.obj"/>
			</geometry>
		</collision>
	</link>
	<joint name="joint_9" type="continuous">
		<origin xyz="-0.3963515083547591 0.2299798878029277 -0.0618622732295198"/>
		<axis xyz="5.56512975216049e-05 -0.25861857869836985 -0.9659795172026"/>
		<child link="link_9"/>
		<parent link="link_11"/>
	</joint>
	<link name="link_10">
		<visual name="knob-13">
			<origin xyz="0.455948 -0.23016067880652694 0.06166467038547703"/>
			<geometry>
				<mesh filename="textured_objs/original-124.obj"/>
			</geometry>
		</visual>
		<visual name="knob-13">
			<origin xyz="0.455948 -0.23016067880652694 0.06166467038547703"/>
			<geometry>
				<mesh filename="textured_objs/original-121.obj"/>
			</geometry>
		</visual>
		<collision>
			<origin xyz="0.455948 -0.23016067880652694 0.06166467038547703"/>
			<geometry>
				<mesh filename="textured_objs/original-124.obj"/>
			</geometry>
		</collision>
		<collision>
			<origin xyz="0.455948 -0.23016067880652694 0.06166467038547703"/>
			<geometry>
				<mesh filename="textured_objs/original-121.obj"/>
			</geometry>
		</collision>
	</link>
	<joint name="joint_10" type="continuous">
		<origin xyz="-0.455948 0.23016067880652694 -0.06166467038547703"/>
		<axis xyz="0 0.25879282070364895 0.9659328527140223"/>
		<child link="link_10"/>
		<parent link="link_11"/>
	</joint>
	<link name="link_11">
		<visual name="door-1">
			<origin xyz="0 0 0"/>
			<geometry>
				<mesh filename="textured_objs/original-103.obj"/>
			</geometry>
		</visual>
		<visual name="door-1">
			<origin xyz="0 0 0"/>
			<geometry>
				<mesh filename="textured_objs/original-51.obj"/>
			</geometry>
		</visual>
		<visual name="door-3">
			<origin xyz="0 0 0"/>
			<geometry>
				<mesh filename="textured_objs/original-108.obj"/>
			</geometry>
		</visual>
		<visual name="door-3">
			<origin xyz="0 0 0"/>
			<geometry>
				<mesh filename="textured_objs/original-48.obj"/>
			</geometry>
		</visual>
		<visual name="base_body-14">
			<origin xyz="0 0 0"/>
			<geometry>
				<mesh filename="textured_objs/original-123.obj"/>
			</geometry>
		</visual>
		<visual name="base_body-14">
			<origin xyz="0 0 0"/>
			<geometry>
				<mesh filename="textured_objs/original-152.obj"/>
			</geometry>
		</visual>
		<visual name="base_body-14">
			<origin xyz="0 0 0"/>
			<geometry>
				<mesh filename="textured_objs/original-154.obj"/>
			</geometry>
		</visual>
		<visual name="base_body-14">
			<origin xyz="0 0 0"/>
			<geometry>
				<mesh filename="textured_objs/original-126.obj"/>
			</geometry>
		</visual>
		<visual name="base_body-14">
			<origin xyz="0 0 0"/>
			<geometry>
				<mesh filename="textured_objs/original-119.obj"/>
			</geometry>
		</visual>
		<visual name="base_body-14">
			<origin xyz="0 0 0"/>
			<geometry>
				<mesh filename="textured_objs/original-41.obj"/>
			</geometry>
		</visual>
		<visual name="base_body-14">
			<origin xyz="0 0 0"/>
			<geometry>
				<mesh filename="textured_objs/original-96.obj"/>
			</geometry>
		</visual>
		<visual name="base_body-14">
			<origin xyz="0 0 0"/>
			<geometry>
				<mesh filename="textured_objs/original-64.obj"/>
			</geometry>
		</visual>
		<visual name="base_body-14">
			<origin xyz="0 0 0"/>
			<geometry>
				<mesh filename="textured_objs/original-134.obj"/>
			</geometry>
		</visual>
		<visual name="base_body-14">
			<origin xyz="0 0 0"/>
			<geometry>
				<mesh filename="textured_objs/original-43.obj"/>
			</geometry>
		</visual>
		<visual name="base_body-14">
			<origin xyz="0 0 0"/>
			<geometry>
				<mesh filename="textured_objs/original-71.obj"/>
			</geometry>
		</visual>
		<visual name="base_body-14">
			<origin xyz="0 0 0"/>
			<geometry>
				<mesh filename="textured_objs/original-52.obj"/>
			</geometry>
		</visual>
		<visual name="base_body-14">
			<origin xyz="0 0 0"/>
			<geometry>
				<mesh filename="textured_objs/original-83.obj"/>
			</geometry>
		</visual>
		<visual name="base_body-14">
			<origin xyz="0 0 0"/>
			<geometry>
				<mesh filename="textured_objs/original-110.obj"/>
			</geometry>
		</visual>
		<visual name="base_body-14">
			<origin xyz="0 0 0"/>
			<geometry>
				<mesh filename="textured_objs/original-153.obj"/>
			</geometry>
		</visual>
		<visual name="base_body-14">
			<origin xyz="0 0 0"/>
			<geometry>
				<mesh filename="textured_objs/original-4.obj"/>
			</geometry>
		</visual>
		<visual name="base_body-14">
			<origin xyz="0 0 0"/>
			<geometry>
				<mesh filename="textured_objs/original-149.obj"/>
			</geometry>
		</visual>
		<visual name="base_body-14">
			<origin xyz="0 0 0"/>
			<geometry>
				<mesh filename="textured_objs/original-3.obj"/>
			</geometry>
		</visual>
		<visual name="base_body-14">
			<origin xyz="0 0 0"/>
			<geometry>
				<mesh filename="textured_objs/original-65.obj"/>
			</geometry>
		</visual>
		<visual name="base_body-14">
			<origin xyz="0 0 0"/>
			<geometry>
				<mesh filename="textured_objs/original-2.obj"/>
			</geometry>
		</visual>
		<visual name="base_body-14">
			<origin xyz="0 0 0"/>
			<geometry>
				<mesh filename="textured_objs/original-130.obj"/>
			</geometry>
		</visual>
		<visual name="base_body-14">
			<origin xyz="0 0 0"/>
			<geometry>
				<mesh filename="textured_objs/original-137.obj"/>
			</geometry>
		</visual>
		<visual name="base_body-14">
			<origin xyz="0 0 0"/>
			<geometry>
				<mesh filename="textured_objs/original-44.obj"/>
			</geometry>
		</visual>
		<visual name="base_body-14">
			<origin xyz="0 0 0"/>
			<geometry>
				<mesh filename="textured_objs/original-86.obj"/>
			</geometry>
		</visual>
		<visual name="base_body-14">
			<origin xyz="0 0 0"/>
			<geometry>
				<mesh filename="textured_objs/original-8.obj"/>
			</geometry>
		</visual>
		<visual name="base_body-14">
			<origin xyz="0 0 0"/>
			<geometry>
				<mesh filename="textured_objs/original-147.obj"/>
			</geometry>
		</visual>
		<visual name="base_body-14">
			<origin xyz="0 0 0"/>
			<geometry>
				<mesh filename="textured_objs/original-109.obj"/>
			</geometry>
		</visual>
		<visual name="base_body-14">
			<origin xyz="0 0 0"/>
			<geometry>
				<mesh filename="textured_objs/original-9.obj"/>
			</geometry>
		</visual>
		<visual name="base_body-14">
			<origin xyz="0 0 0"/>
			<geometry>
				<mesh filename="textured_objs/original-125.obj"/>
			</geometry>
		</visual>
		<visual name="base_body-14">
			<origin xyz="0 0 0"/>
			<geometry>
				<mesh filename="textured_objs/original-45.obj"/>
			</geometry>
		</visual>
		<visual name="base_body-14">
			<origin xyz="0 0 0"/>
			<geometry>
				<mesh filename="textured_objs/original-148.obj"/>
			</geometry>
		</visual>
		<visual name="base_body-14">
			<origin xyz="0 0 0"/>
			<geometry>
				<mesh filename="textured_objs/original-138.obj"/>
			</geometry>
		</visual>
		<visual name="base_body-14">
			<origin xyz="0 0 0"/>
			<geometry>
				<mesh filename="textured_objs/original-156.obj"/>
			</geometry>
		</visual>
		<visual name="base_body-14">
			<origin xyz="0 0 0"/>
			<geometry>
				<mesh filename="textured_objs/original-93.obj"/>
			</geometry>
		</visual>
		<visual name="base_body-14">
			<origin xyz="0 0 0"/>
			<geometry>
				<mesh filename="textured_objs/original-39.obj"/>
			</geometry>
		</visual>
		<visual name="base_body-14">
			<origin xyz="0 0 0"/>
			<geometry>
				<mesh filename="textured_objs/original-59.obj"/>
			</geometry>
		</visual>
		<visual name="base_body-14">
			<origin xyz="0 0 0"/>
			<geometry>
				<mesh filename="textured_objs/original-5.obj"/>
			</geometry>
		</visual>
		<visual name="base_body-14">
			<origin xyz="0 0 0"/>
			<geometry>
				<mesh filename="textured_objs/original-77.obj"/>
			</geometry>
		</visual>
		<visual name="base_body-14">
			<origin xyz="0 0 0"/>
			<geometry>
				<mesh filename="textured_objs/original-114.obj"/>
			</geometry>
		</visual>
		<visual name="base_body-14">
			<origin xyz="0 0 0"/>
			<geometry>
				<mesh filename="textured_objs/original-150.obj"/>
			</geometry>
		</visual>
		<visual name="base_body-14">
			<origin xyz="0 0 0"/>
			<geometry>
				<mesh filename="textured_objs/original-63.obj"/>
			</geometry>
		</visual>
		<visual name="base_body-14">
			<origin xyz="0 0 0"/>
			<geometry>
				<mesh filename="textured_objs/original-87.obj"/>
			</geometry>
		</visual>
		<visual name="base_body-14">
			<origin xyz="0 0 0"/>
			<geometry>
				<mesh filename="textured_objs/original-113.obj"/>
			</geometry>
		</visual>
		<visual name="base_body-14">
			<origin xyz="0 0 0"/>
			<geometry>
				<mesh filename="textured_objs/original-6.obj"/>
			</geometry>
		</visual>
		<visual name="base_body-14">
			<origin xyz="0 0 0"/>
			<geometry>
				<mesh filename="textured_objs/original-37.obj"/>
			</geometry>
		</visual>
		<visual name="base_body-14">
			<origin xyz="0 0 0"/>
			<geometry>
				<mesh filename="textured_objs/original-85.obj"/>
			</geometry>
		</visual>
		<visual name="base_body-14">
			<origin xyz="0 0 0"/>
			<geometry>
				<mesh filename="textured_objs/original-122.obj"/>
			</geometry>
		</visual>
		<visual name="base_body-14">
			<origin xyz="0 0 0"/>
			<geometry>
				<mesh filename="textured_objs/original-76.obj"/>
			</geometry>
		</visual>
		<visual name="base_body-14">
			<origin xyz="0 0 0"/>
			<geometry>
				<mesh filename="textured_objs/original-72.obj"/>
			</geometry>
		</visual>
		<visual name="base_body-14">
			<origin xyz="0 0 0"/>
			<geometry>
				<mesh filename="textured_objs/original-62.obj"/>
			</geometry>
		</visual>
		<visual name="base_body-14">
			<origin xyz="0 0 0"/>
			<geometry>
				<mesh filename="textured_objs/original-75.obj"/>
			</geometry>
		</visual>
		<visual name="base_body-14">
			<origin xyz="0 0 0"/>
			<geometry>
				<mesh filename="textured_objs/original-133.obj"/>
			</geometry>
		</visual>
		<visual name="base_body-14">
			<origin xyz="0 0 0"/>
			<geometry>
				<mesh filename="textured_objs/original-66.obj"/>
			</geometry>
		</visual>
		<visual name="base_body-14">
			<origin xyz="0 0 0"/>
			<geometry>
				<mesh filename="textured_objs/original-58.obj"/>
			</geometry>
		</visual>
		<visual name="base_body-14">
			<origin xyz="0 0 0"/>
			<geometry>
				<mesh filename="textured_objs/original-145.obj"/>
			</geometry>
		</visual>
		<visual name="base_body-14">
			<origin xyz="0 0 0"/>
			<geometry>
				<mesh filename="textured_objs/original-98.obj"/>
			</geometry>
		</visual>
		<visual name="base_body-14">
			<origin xyz="0 0 0"/>
			<geometry>
				<mesh filename="textured_objs/original-67.obj"/>
			</geometry>
		</visual>
		<visual name="base_body-14">
			<origin xyz="0 0 0"/>
			<geometry>
				<mesh filename="textured_objs/original-69.obj"/>
			</geometry>
		</visual>
		<visual name="base_body-14">
			<origin xyz="0 0 0"/>
			<geometry>
				<mesh filename="textured_objs/original-11.obj"/>
			</geometry>
		</visual>
		<visual name="base_body-14">
			<origin xyz="0 0 0"/>
			<geometry>
				<mesh filename="textured_objs/original-38.obj"/>
			</geometry>
		</visual>
		<visual name="base_body-14">
			<origin xyz="0 0 0"/>
			<geometry>
				<mesh filename="textured_objs/original-68.obj"/>
			</geometry>
		</visual>
		<visual name="base_body-14">
			<origin xyz="0 0 0"/>
			<geometry>
				<mesh filename="textured_objs/original-146.obj"/>
			</geometry>
		</visual>
		<visual name="base_body-14">
			<origin xyz="0 0 0"/>
			<geometry>
				<mesh filename="textured_objs/original-74.obj"/>
			</geometry>
		</visual>
		<visual name="base_body-14">
			<origin xyz="0 0 0"/>
			<geometry>
				<mesh filename="textured_objs/original-118.obj"/>
			</geometry>
		</visual>
		<visual name="base_body-14">
			<origin xyz="0 0 0"/>
			<geometry>
				<mesh filename="textured_objs/original-91.obj"/>
			</geometry>
		</visual>
		<visual name="base_body-14">
			<origin xyz="0 0 0"/>
			<geometry>
				<mesh filename="textured_objs/original-73.obj"/>
			</geometry>
		</visual>
		<visual name="base_body-14">
			<origin xyz="0 0 0"/>
			<geometry>
				<mesh filename="textured_objs/original-12.obj"/>
			</geometry>
		</visual>
		<visual name="base_body-14">
			<origin xyz="0 0 0"/>
			<geometry>
				<mesh filename="textured_objs/original-92.obj"/>
			</geometry>
		</visual>
		<visual name="base_body-14">
			<origin xyz="0 0 0"/>
			<geometry>
				<mesh filename="textured_objs/original-142.obj"/>
			</geometry>
		</visual>
		<visual name="base_body-14">
			<origin xyz="0 0 0"/>
			<geometry>
				<mesh filename="textured_objs/original-42.obj"/>
			</geometry>
		</visual>
		<visual name="base_body-14">
			<origin xyz="0 0 0"/>
			<geometry>
				<mesh filename="textured_objs/original-79.obj"/>
			</geometry>
		</visual>
		<visual name="base_body-14">
			<origin xyz="0 0 0"/>
			<geometry>
				<mesh filename="textured_objs/original-88.obj"/>
			</geometry>
		</visual>
		<visual name="base_body-14">
			<origin xyz="0 0 0"/>
			<geometry>
				<mesh filename="textured_objs/original-95.obj"/>
			</geometry>
		</visual>
		<visual name="base_body-14">
			<origin xyz="0 0 0"/>
			<geometry>
				<mesh filename="textured_objs/original-7.obj"/>
			</geometry>
		</visual>
		<visual name="base_body-14">
			<origin xyz="0 0 0"/>
			<geometry>
				<mesh filename="textured_objs/original-81.obj"/>
			</geometry>
		</visual>
		<visual name="base_body-14">
			<origin xyz="0 0 0"/>
			<geometry>
				<mesh filename="textured_objs/original-84.obj"/>
			</geometry>
		</visual>
		<visual name="base_body-14">
			<origin xyz="0 0 0"/>
			<geometry>
				<mesh filename="textured_objs/original-94.obj"/>
			</geometry>
		</visual>
		<visual name="base_body-14">
			<origin xyz="0 0 0"/>
			<geometry>
				<mesh filename="textured_objs/original-78.obj"/>
			</geometry>
		</visual>
		<visual name="base_body-14">
			<origin xyz="0 0 0"/>
			<geometry>
				<mesh filename="textured_objs/original-97.obj"/>
			</geometry>
		</visual>
		<visual name="base_body-14">
			<origin xyz="0 0 0"/>
			<geometry>
				<mesh filename="textured_objs/original-157.obj"/>
			</geometry>
		</visual>
		<visual name="base_body-14">
			<origin xyz="0 0 0"/>
			<geometry>
				<mesh filename="textured_objs/original-89.obj"/>
			</geometry>
		</visual>
		<visual name="base_body-14">
			<origin xyz="0 0 0"/>
			<geometry>
				<mesh filename="textured_objs/original-10.obj"/>
			</geometry>
		</visual>
		<visual name="base_body-14">
			<origin xyz="0 0 0"/>
			<geometry>
				<mesh filename="textured_objs/original-82.obj"/>
			</geometry>
		</visual>
		<visual name="base_body-14">
			<origin xyz="0 0 0"/>
			<geometry>
				<mesh filename="textured_objs/original-129.obj"/>
			</geometry>
		</visual>
		<visual name="base_body-14">
			<origin xyz="0 0 0"/>
			<geometry>
				<mesh filename="textured_objs/original-40.obj"/>
			</geometry>
		</visual>
		<visual name="base_body-14">
			<origin xyz="0 0 0"/>
			<geometry>
				<mesh filename="textured_objs/original-143.obj"/>
			</geometry>
		</visual>
		<visual name="base_body-14">
			<origin xyz="0 0 0"/>
			<geometry>
				<mesh filename="textured_objs/original-151.obj"/>
			</geometry>
		</visual>
		<visual name="base_body-14">
			<origin xyz="0 0 0"/>
			<geometry>
				<mesh filename="textured_objs/original-155.obj"/>
			</geometry>
		</visual>
		<visual name="base_body-14">
			<origin xyz="0 0 0"/>
			<geometry>
				<mesh filename="textured_objs/original-57.obj"/>
			</geometry>
		</visual>
		<collision>
			<origin xyz="0 0 0"/>
			<geometry>
				<mesh filename="textured_objs/original-103.obj"/>
			</geometry>
		</collision>
		<collision>
			<origin xyz="0 0 0"/>
			<geometry>
				<mesh filename="textured_objs/original-51.obj"/>
			</geometry>
		</collision>
		<collision>
			<origin xyz="0 0 0"/>
			<geometry>
				<mesh filename="textured_objs/original-108.obj"/>
			</geometry>
		</collision>
		<collision>
			<origin xyz="0 0 0"/>
			<geometry>
				<mesh filename="textured_objs/original-48.obj"/>
			</geometry>
		</collision>
		<collision>
			<origin xyz="0 0 0"/>
			<geometry>
				<mesh filename="textured_objs/original-123.obj"/>
			</geometry>
		</collision>
		<collision>
			<origin xyz="0 0 0"/>
			<geometry>
				<mesh filename="textured_objs/original-152.obj"/>
			</geometry>
		</collision>
		<collision>
			<origin xyz="0 0 0"/>
			<geometry>
				<mesh filename="textured_objs/original-154.obj"/>
			</geometry>
		</collision>
		<collision>
			<origin xyz="0 0 0"/>
			<geometry>
				<mesh filename="textured_objs/original-126.obj"/>
			</geometry>
		</collision>
		<collision>
			<origin xyz="0 0 0"/>
			<geometry>
				<mesh filename="textured_objs/original-119.obj"/>
			</geometry>
		</collision>
		<collision>
			<origin xyz="0 0 0"/>
			<geometry>
				<mesh filename="textured_objs/original-41.obj"/>
			</geometry>
		</collision>
		<collision>
			<origin xyz="0 0 0"/>
			<geometry>
				<mesh filename="textured_objs/original-96.obj"/>
			</geometry>
		</collision>
		<collision>
			<origin xyz="0 0 0"/>
			<geometry>
				<mesh filename="textured_objs/original-64.obj"/>
			</geometry>
		</collision>
		<collision>
			<origin xyz="0 0 0"/>
			<geometry>
				<mesh filename="textured_objs/original-134.obj"/>
			</geometry>
		</collision>
		<collision>
			<origin xyz="0 0 0"/>
			<geometry>
				<mesh filename="textured_objs/original-43.obj"/>
			</geometry>
		</collision>
		<collision>
			<origin xyz="0 0 0"/>
			<geometry>
				<mesh filename="textured_objs/original-71.obj"/>
			</geometry>
		</collision>
		<collision>
			<origin xyz="0 0 0"/>
			<geometry>
				<mesh filename="textured_objs/original-52.obj"/>
			</geometry>
		</collision>
		<collision>
			<origin xyz="0 0 0"/>
			<geometry>
				<mesh filename="textured_objs/original-83.obj"/>
			</geometry>
		</collision>
		<collision>
			<origin xyz="0 0 0"/>
			<geometry>
				<mesh filename="textured_objs/original-110.obj"/>
			</geometry>
		</collision>
		<collision>
			<origin xyz="0 0 0"/>
			<geometry>
				<mesh filename="textured_objs/original-153.obj"/>
			</geometry>
		</collision>
		<collision>
			<origin xyz="0 0 0"/>
			<geometry>
				<mesh filename="textured_objs/original-4.obj"/>
			</geometry>
		</collision>
		<collision>
			<origin xyz="0 0 0"/>
			<geometry>
				<mesh filename="textured_objs/original-149.obj"/>
			</geometry>
		</collision>
		<collision>
			<origin xyz="0 0 0"/>
			<geometry>
				<mesh filename="textured_objs/original-3.obj"/>
			</geometry>
		</collision>
		<collision>
			<origin xyz="0 0 0"/>
			<geometry>
				<mesh filename="textured_objs/original-65.obj"/>
			</geometry>
		</collision>
		<collision>
			<origin xyz="0 0 0"/>
			<geometry>
				<mesh filename="textured_objs/original-2.obj"/>
			</geometry>
		</collision>
		<collision>
			<origin xyz="0 0 0"/>
			<geometry>
				<mesh filename="textured_objs/original-130.obj"/>
			</geometry>
		</collision>
		<collision>
			<origin xyz="0 0 0"/>
			<geometry>
				<mesh filename="textured_objs/original-137.obj"/>
			</geometry>
		</collision>
		<collision>
			<origin xyz="0 0 0"/>
			<geometry>
				<mesh filename="textured_objs/original-44.obj"/>
			</geometry>
		</collision>
		<collision>
			<origin xyz="0 0 0"/>
			<geometry>
				<mesh filename="textured_objs/original-86.obj"/>
			</geometry>
		</collision>
		<collision>
			<origin xyz="0 0 0"/>
			<geometry>
				<mesh filename="textured_objs/original-8.obj"/>
			</geometry>
		</collision>
		<collision>
			<origin xyz="0 0 0"/>
			<geometry>
				<mesh filename="textured_objs/original-147.obj"/>
			</geometry>
		</collision>
		<collision>
			<origin xyz="0 0 0"/>
			<geometry>
				<mesh filename="textured_objs/original-109.obj"/>
			</geometry>
		</collision>
		<collision>
			<origin xyz="0 0 0"/>
			<geometry>
				<mesh filename="textured_objs/original-9.obj"/>
			</geometry>
		</collision>
		<collision>
			<origin xyz="0 0 0"/>
			<geometry>
				<mesh filename="textured_objs/original-125.obj"/>
			</geometry>
		</collision>
		<collision>
			<origin xyz="0 0 0"/>
			<geometry>
				<mesh filename="textured_objs/original-45.obj"/>
			</geometry>
		</collision>
		<collision>
			<origin xyz="0 0 0"/>
			<geometry>
				<mesh filename="textured_objs/original-148.obj"/>
			</geometry>
		</collision>
		<collision>
			<origin xyz="0 0 0"/>
			<geometry>
				<mesh filename="textured_objs/original-138.obj"/>
			</geometry>
		</collision>
		<collision>
			<origin xyz="0 0 0"/>
			<geometry>
				<mesh filename="textured_objs/original-156.obj"/>
			</geometry>
		</collision>
		<collision>
			<origin xyz="0 0 0"/>
			<geometry>
				<mesh filename="textured_objs/original-93.obj"/>
			</geometry>
		</collision>
		<collision>
			<origin xyz="0 0 0"/>
			<geometry>
				<mesh filename="textured_objs/original-39.obj"/>
			</geometry>
		</collision>
		<collision>
			<origin xyz="0 0 0"/>
			<geometry>
				<mesh filename="textured_objs/original-59.obj"/>
			</geometry>
		</collision>
		<collision>
			<origin xyz="0 0 0"/>
			<geometry>
				<mesh filename="textured_objs/original-5.obj"/>
			</geometry>
		</collision>
		<collision>
			<origin xyz="0 0 0"/>
			<geometry>
				<mesh filename="textured_objs/original-77.obj"/>
			</geometry>
		</collision>
		<collision>
			<origin xyz="0 0 0"/>
			<geometry>
				<mesh filename="textured_objs/original-114.obj"/>
			</geometry>
		</collision>
		<collision>
			<origin xyz="0 0 0"/>
			<geometry>
				<mesh filename="textured_objs/original-150.obj"/>
			</geometry>
		</collision>
		<collision>
			<origin xyz="0 0 0"/>
			<geometry>
				<mesh filename="textured_objs/original-63.obj"/>
			</geometry>
		</collision>
		<collision>
			<origin xyz="0 0 0"/>
			<geometry>
				<mesh filename="textured_objs/original-87.obj"/>
			</geometry>
		</collision>
		<collision>
			<origin xyz="0 0 0"/>
			<geometry>
				<mesh filename="textured_objs/original-113.obj"/>
			</geometry>
		</collision>
		<collision>
			<origin xyz="0 0 0"/>
			<geometry>
				<mesh filename="textured_objs/original-6.obj"/>
			</geometry>
		</collision>
		<collision>
			<origin xyz="0 0 0"/>
			<geometry>
				<mesh filename="textured_objs/original-37.obj"/>
			</geometry>
		</collision>
		<collision>
			<origin xyz="0 0 0"/>
			<geometry>
				<mesh filename="textured_objs/original-85.obj"/>
			</geometry>
		</collision>
		<collision>
			<origin xyz="0 0 0"/>
			<geometry>
				<mesh filename="textured_objs/original-122.obj"/>
			</geometry>
		</collision>
		<collision>
			<origin xyz="0 0 0"/>
			<geometry>
				<mesh filename="textured_objs/original-76.obj"/>
			</geometry>
		</collision>
		<collision>
			<origin xyz="0 0 0"/>
			<geometry>
				<mesh filename="textured_objs/original-72.obj"/>
			</geometry>
		</collision>
		<collision>
			<origin xyz="0 0 0"/>
			<geometry>
				<mesh filename="textured_objs/original-62.obj"/>
			</geometry>
		</collision>
		<collision>
			<origin xyz="0 0 0"/>
			<geometry>
				<mesh filename="textured_objs/original-75.obj"/>
			</geometry>
		</collision>
		<collision>
			<origin xyz="0 0 0"/>
			<geometry>
				<mesh filename="textured_objs/original-133.obj"/>
			</geometry>
		</collision>
		<collision>
			<origin xyz="0 0 0"/>
			<geometry>
				<mesh filename="textured_objs/original-66.obj"/>
			</geometry>
		</collision>
		<collision>
			<origin xyz="0 0 0"/>
			<geometry>
				<mesh filename="textured_objs/original-58.obj"/>
			</geometry>
		</collision>
		<collision>
			<origin xyz="0 0 0"/>
			<geometry>
				<mesh filename="textured_objs/original-145.obj"/>
			</geometry>
		</collision>
		<collision>
			<origin xyz="0 0 0"/>
			<geometry>
				<mesh filename="textured_objs/original-98.obj"/>
			</geometry>
		</collision>
		<collision>
			<origin xyz="0 0 0"/>
			<geometry>
				<mesh filename="textured_objs/original-67.obj"/>
			</geometry>
		</collision>
		<collision>
			<origin xyz="0 0 0"/>
			<geometry>
				<mesh filename="textured_objs/original-69.obj"/>
			</geometry>
		</collision>
		<collision>
			<origin xyz="0 0 0"/>
			<geometry>
				<mesh filename="textured_objs/original-11.obj"/>
			</geometry>
		</collision>
		<collision>
			<origin xyz="0 0 0"/>
			<geometry>
				<mesh filename="textured_objs/original-38.obj"/>
			</geometry>
		</collision>
		<collision>
			<origin xyz="0 0 0"/>
			<geometry>
				<mesh filename="textured_objs/original-68.obj"/>
			</geometry>
		</collision>
		<collision>
			<origin xyz="0 0 0"/>
			<geometry>
				<mesh filename="textured_objs/original-146.obj"/>
			</geometry>
		</collision>
		<collision>
			<origin xyz="0 0 0"/>
			<geometry>
				<mesh filename="textured_objs/original-74.obj"/>
			</geometry>
		</collision>
		<collision>
			<origin xyz="0 0 0"/>
			<geometry>
				<mesh filename="textured_objs/original-118.obj"/>
			</geometry>
		</collision>
		<collision>
			<origin xyz="0 0 0"/>
			<geometry>
				<mesh filename="textured_objs/original-91.obj"/>
			</geometry>
		</collision>
		<collision>
			<origin xyz="0 0 0"/>
			<geometry>
				<mesh filename="textured_objs/original-73.obj"/>
			</geometry>
		</collision>
		<collision>
			<origin xyz="0 0 0"/>
			<geometry>
				<mesh filename="textured_objs/original-12.obj"/>
			</geometry>
		</collision>
		<collision>
			<origin xyz="0 0 0"/>
			<geometry>
				<mesh filename="textured_objs/original-92.obj"/>
			</geometry>
		</collision>
		<collision>
			<origin xyz="0 0 0"/>
			<geometry>
				<mesh filename="textured_objs/original-142.obj"/>
			</geometry>
		</collision>
		<collision>
			<origin xyz="0 0 0"/>
			<geometry>
				<mesh filename="textured_objs/original-42.obj"/>
			</geometry>
		</collision>
		<collision>
			<origin xyz="0 0 0"/>
			<geometry>
				<mesh filename="textured_objs/original-79.obj"/>
			</geometry>
		</collision>
		<collision>
			<origin xyz="0 0 0"/>
			<geometry>
				<mesh filename="textured_objs/original-88.obj"/>
			</geometry>
		</collision>
		<collision>
			<origin xyz="0 0 0"/>
			<geometry>
				<mesh filename="textured_objs/original-95.obj"/>
			</geometry>
		</collision>
		<collision>
			<origin xyz="0 0 0"/>
			<geometry>
				<mesh filename="textured_objs/original-7.obj"/>
			</geometry>
		</collision>
		<collision>
			<origin xyz="0 0 0"/>
			<geometry>
				<mesh filename="textured_objs/original-81.obj"/>
			</geometry>
		</collision>
		<collision>
			<origin xyz="0 0 0"/>
			<geometry>
				<mesh filename="textured_objs/original-84.obj"/>
			</geometry>
		</collision>
		<collision>
			<origin xyz="0 0 0"/>
			<geometry>
				<mesh filename="textured_objs/original-94.obj"/>
			</geometry>
		</collision>
		<collision>
			<origin xyz="0 0 0"/>
			<geometry>
				<mesh filename="textured_objs/original-78.obj"/>
			</geometry>
		</collision>
		<collision>
			<origin xyz="0 0 0"/>
			<geometry>
				<mesh filename="textured_objs/original-97.obj"/>
			</geometry>
		</collision>
		<collision>
			<origin xyz="0 0 0"/>
			<geometry>
				<mesh filename="textured_objs/original-157.obj"/>
			</geometry>
		</collision>
		<collision>
			<origin xyz="0 0 0"/>
			<geometry>
				<mesh filename="textured_objs/original-89.obj"/>
			</geometry>
		</collision>
		<collision>
			<origin xyz="0 0 0"/>
			<geometry>
				<mesh filename="textured_objs/original-10.obj"/>
			</geometry>
		</collision>
		<collision>
			<origin xyz="0 0 0"/>
			<geometry>
				<mesh filename="textured_objs/original-82.obj"/>
			</geometry>
		</collision>
		<collision>
			<origin xyz="0 0 0"/>
			<geometry>
				<mesh filename="textured_objs/original-129.obj"/>
			</geometry>
		</collision>
		<collision>
			<origin xyz="0 0 0"/>
			<geometry>
				<mesh filename="textured_objs/original-40.obj"/>
			</geometry>
		</collision>
		<collision>
			<origin xyz="0 0 0"/>
			<geometry>
				<mesh filename="textured_objs/original-143.obj"/>
			</geometry>
		</collision>
		<collision>
			<origin xyz="0 0 0"/>
			<geometry>
				<mesh filename="textured_objs/original-151.obj"/>
			</geometry>
		</collision>
		<collision>
			<origin xyz="0 0 0"/>
			<geometry>
				<mesh filename="textured_objs/original-155.obj"/>
			</geometry>
		</collision>
		<collision>
			<origin xyz="0 0 0"/>
			<geometry>
				<mesh filename="textured_objs/original-57.obj"/>
			</geometry>
		</collision>
	</link>
	<joint name="joint_11" type="fixed">
		<origin rpy="1.570796326794897 0 -1.570796326794897" xyz="0 0 0"/>
		<child link="link_11"/>
		<parent link="base"/>
	</joint>
</robot>
