<?xml version="1.0"?>
<!-- =================================================================================== -->
<!-- |    This document was autogenerated by xacro from cobot_description_rm_63.urdf.xacro | -->
<!-- |    EDITING THIS FILE BY HAND IS NOT RECOMMENDED                                 | -->
<!-- =================================================================================== -->
<!-- This URDF was automatically created by SolidWorks to URDF Exporter! Originally created by
Stephen Brawner (brawner@gmail.com) 
     Commit Version: 1.6.0-1-g15f4949  Build Version: 1.6.7594.29634
     For more information, please see http://wiki.ros.org/sw_urdf_exporter -->

<robot name="ranger_mini3">
    <!-- base -->
    <link name="base_link">
        <inertial>
            <origin rpy="0 0 0" xyz="-0.18605 0.0010457 0.13419" />
            <mass value="35.137" />
            <inertia ixx="0.52213" ixy="0.00028039" ixz="-0.0048629" iyy="1.0698"
                iyz="-0.0011677" izz="1.4095" />
        </inertial>
        <visual>
            <origin rpy="0 0 3.14" xyz="0 0 0" />
            <geometry>
                <mesh filename="../meshes/base_link.STL" />
            </geometry>
            <!-- <material name="light_grayish_blue">
                <color rgba="0.77647 0.77647 0.81961 1" />
            </material> -->
            <material name="white">
                <color rgba="1 1 1 1" />
            </material>
        </visual>
        <collision>
            <origin rpy="0 0 0" xyz="0 0 0" />
            <geometry>
                <mesh filename="../meshes/base_link.STL" />
            </geometry>
        </collision>
    </link>

    <joint name="front_lidar_joint" type="fixed">
        <origin rpy="0 0 0" xyz="0.30 0 0.214" />
        <parent link="base_link" />
        <child link="front_lidar" />
        <axis xyz="0 0 0" />
    </joint>
    
    <link name="front_lidar">
        <inertial>
            <origin rpy="0 0 0" xyz="-0.00016986 -2.2612E-10 0.018642" />
            <mass value="0.15478" />
            <inertia ixx="6.9567E-05" ixy="-1.7298E-12" ixz="-4.6381E-07" iyy="7.1065E-05"
                iyz="-5.4415E-13" izz="9.8843E-05" />
        </inertial>
        <visual>
            <origin rpy="0 0 0" xyz="0 0 0" />
            <geometry>
                <mesh filename="../meshes/front_lidar.STL" />
            </geometry>
            <material name="white">
                <color rgba="1 1 1 1" />
            </material>
        </visual>
        <collision>
            <origin rpy="0 0 0" xyz="0 0 0" />
            <geometry>
                <mesh filename="../meshes/front_lidar.STL" />
            </geometry>
        </collision>
    </link>

    <!-- <joint name="basket_joint" type="fixed">
        <origin rpy="0 0 0" xyz="-0.21 0 0.26" />
        <parent link="base_link" />
        <child link="basket_Link" />
        <axis xyz="0 0 0" />
    </joint>

    <link name="basket_Link">
        <inertial>
            <origin rpy="0 0 0" xyz="-4.1633E-16 -4.4913E-14 0.021251" />
            <mass value="0.39699" />
            <inertia ixx="0.0056399" ixy="-2.6074E-10" ixz="5.7967E-18" iyy="0.0033409"
                iyz="1.9651E-17" izz="0.0081811" />
        </inertial>
        <visual>
            <origin rpy="0 0 0" xyz="0 0 0" />
            <geometry>
                <box size="0.24 0.5 0.2" />
            </geometry>
            <material name="Light_gray">
                <color rgba="0.69804 0.69804 0.69804 1" />
            </material>
        </visual>
        <collision>
            <origin rpy="0 0 0" xyz="0 0 0" />
            <geometry>
                <box size="0.1 0.1 0.1" />
            </geometry>
        </collision>
    </link> -->

    <joint name="head_joint" type="fixed">
        <origin rpy="0 0 3.1416" xyz="0.10013 0 1.1628" />
        <parent link="base_link" />
        <child link="head_Link" />
        <axis xyz="0 0 0" />
    </joint>

    <link name="head_Link">
        <inertial>
            <origin rpy="0 0 0" xyz="-0.013341 -0.0030001 0.14378" />
            <mass value="0.10888" />
            <inertia ixx="0.00015548" ixy="5.612E-11" ixz="7.7393E-06" iyy="6.2021E-05"
                iyz="-3.4676E-10" izz="0.00016861" />
        </inertial>
        <visual>
            <origin rpy="0 0 0" xyz="0 0 0" />
            <geometry>
                <mesh filename="../meshes/head_Link.STL" />
            </geometry>
            <material name="white">
                <color rgba="1 1 1 1" />
            </material>
        </visual>
        <collision>
            <origin rpy="0 0 0" xyz="0 0 0" />
            <geometry>
                <mesh filename="../meshes/head_Link.STL" />
            </geometry>
        </collision>
    </link>

    <joint name="head_camera_joint" type="fixed">
        <origin rpy="0.066568 0 1.5708" xyz="-0.033687 -0.0039804 0.18195" />
        <parent link="head_Link" />
        <child link="head_camera" />
        <axis xyz="0 0 0" />
    </joint>

    <link name="head_camera">
        <inertial>
            <origin rpy="0 0 0" xyz="0.027537 -0.14823 -1.1256" />
            <mass value="91.96" />
            <inertia ixx="16.389" ixy="0.28606" ixz="-0.57062" iyy="13.534" iyz="-2.6339"
                izz="7.1915" />
        </inertial>
        <visual>
            <origin rpy="0 0 0" xyz="0 0 0" />
            <geometry>
                <mesh filename="../meshes/head_camera.STL" />
            </geometry>
            <material name="white">
                <color rgba="1 1 1 1" />
            </material>
        </visual>
        <collision>
            <origin rpy="0 0 0" xyz="0 0 0" />
            <geometry>
                <mesh filename="../meshes/head_camera.STL" />
            </geometry>
        </collision>
    </link>

    <joint name="display_joint" type="fixed">
        <origin rpy="0 0 0" xyz="0.15 0 -0.1" />
        <parent link="head_Link" />
        <child link="display_Link" />
        <axis xyz="0 0 0" />
    </joint>

    <link name="display_Link">
        <visual>
            <origin rpy="0 0 0" xyz="0 0 0" />
            <geometry>
                <box size="0.03 0.3 0.2" />
            </geometry>
            <material name="white">
                <color rgba="1 1 1 1" />
            </material>
        </visual>
        <collision>
            <origin rpy="0 0 0" xyz="0 0 0" />
            <geometry>
                <box size="0.03 0.3 0.2" />
            </geometry>
        </collision>
    </link>

    <joint name="arm_base" type="fixed">
        <origin rpy="0 0 0" xyz="0.101 0 0.16" />
        <parent link="base_link" />
        <child link="arm_base" />
        <axis xyz="0 0 0" />
    </joint>

    <link name="arm_base">
        <inertial>
            <origin rpy="0 0 0" xyz="-0.024179 0.0061525 0.44341" />
            <mass value="8.0743" />
            <inertia ixx="0.080601" ixy="4.9995E-05" ixz="0.00052048" iyy="0.077325"
                iyz="-2.0984E-05" izz="0.024026" />
        </inertial>
        <visual>
            <origin rpy="0 0 0" xyz="0 0 0" />
            <geometry>
                <mesh filename="../meshes/arm_base.STL" />
            </geometry>
            <material name="white">
                <color rgba="1 1 1 1" />
            </material>
        </visual>
        <collision>
            <origin rpy="0 0 0" xyz="0 0 0" />
            <geometry>
                <mesh filename="../meshes/arm_base.STL" />
            </geometry>
        </collision>
    </link>

    <joint name="joint_arm_rotary" type="revolute">
        <origin rpy="3.1416 0 -3.1416" xyz="0 0 0.4878" />
        <parent link="arm_base" />
        <child link="Link7" />
        <axis xyz="0 0 -1" />
        <limit effort="300" lower="-3.49" upper="0.5" velocity="3.14" />
        <dynamics damping="50" friction="1" />
    </joint>

    <link name="Link7">
        <inertial>
            <origin rpy="0 0 0" xyz="-0.016412 0.00026497 -0.060445" />
            <mass value="0.53096" />
            <inertia ixx="0.00096525" ixy="1.49E-05" ixz="-1.7049E-05" iyy="0.0018872"
                iyz="1.0632E-06" izz="0.0018331" />
        </inertial>
        <visual>
            <origin rpy="0 0 0" xyz="0 0 0" />
            <geometry>
                <mesh filename="../meshes/Link7.STL" />
            </geometry>
            <material name="white">
                <color rgba="1 1 1 1" />
            </material>
        </visual>
        <collision>
            <origin rpy="0 0 0" xyz="0 0 0" />
            <geometry>
                <mesh filename="../meshes/Link7.STL" />
            </geometry>
        </collision>
    </link>
</robot>