<?xml version="1.0" ?>
<robot name="partnet_aff25f62a2eb92a1815b2b467e8e2eac">
	<link name="base"/>

	<link name="handle_link_2">
		<inertial>
	      <origin rpy="0 0 0" xyz="0 0 0"/>
	      <mass value="10.0"/>
	      <inertia ixx="0.0001" ixy="0" ixz="0" iyy="0.0001" iyz="0" izz="0.0001"/>
	    </inertial>
	    <visual name="xx">
	      <geometry>
	        <box size="0.1 0.2 0.02"/>
	      </geometry>
	      <material name="Gray"/>
	    </visual>
	    <collision>
	      <geometry>
	        <box size="0.1 0.2 0.02"/>
	      </geometry>
	    </collision>
	</link>
	<joint name="handle_joint_2" type="fixed">
		<origin xyz="-0.45 -0.422 0.1" rpy="0 1.57 0" />
		<child link="handle_link_2"/>
		<parent link="link_2"/>
	</joint>

	<link name="handle_link_1">
		<inertial>
	      <origin rpy="0 0 0" xyz="0 0 0"/>
	      <mass value="10.0"/>
	      <inertia ixx="0.0001" ixy="0" ixz="0" iyy="0.0001" iyz="0" izz="0.0001"/>
	    </inertial>
	    <visual name="xx">
	      <geometry>
	        <box size="0.1 0.2 0.02"/>
	      </geometry>
	      <material name="Gray"/>
	    </visual>
	    <collision>
	      <geometry>
	        <box size="0.1 0.2 0.02"/>
	      </geometry>
	    </collision>
	</link>
	<joint name="handle_joint_1" type="fixed">
		<origin xyz="0.3 -0.4 0.07" rpy="0 1.57 0" />
		<child link="handle_link_1"/>
		<parent link="link_1"/>
	</joint>

	<link name="link_0">
		<visual name="frame-5">
			<origin xyz="0 0 0"/>
			<geometry>
				<mesh filename="textured_objs/new-3.obj"/>
			</geometry>
		</visual>
		<visual name="frame-5">
			<origin xyz="0 0 0"/>
			<geometry>
				<mesh filename="textured_objs/new-2.obj"/>
			</geometry>
		</visual>
		<!-- <visual name="frame-5">
			<origin xyz="0 0 0"/>
			<geometry>
				<mesh filename="textured_objs/new-0.obj"/>
			</geometry>
		</visual> -->
		<collision>
			<origin xyz="0 0 0"/>
			<geometry>
				<mesh filename="textured_objs/new-3.obj"/>
			</geometry>
		</collision>
		<collision>
			<origin xyz="0 0 0"/>
			<geometry>
				<mesh filename="textured_objs/new-2.obj"/>
			</geometry>
		</collision>
		<!-- <collision>
			<origin xyz="0 0 0"/>
			<geometry>
				<mesh filename="textured_objs/new-0.obj"/>
			</geometry>
		</collision> -->
	</link>
	<joint name="joint_0" type="fixed">
		<origin rpy="1.570796326794897 0 -1.570796326794897" xyz="0 0 0"/>
		<child link="link_0"/>
		<parent link="base"/>
	</joint>
	<link name="link_1">
		<visual name="door_frame-11">
			<origin xyz="0.418899131366169 -0.8012689999999996 -0.3155980612593349"/>
			<geometry>
				<mesh filename="textured_objs/original-3.obj"/>
			</geometry>
		</visual>
		<collision>
			<origin xyz="0.418899131366169 -0.8012689999999996 -0.3155980612593349"/>
			<geometry>
				<mesh filename="textured_objs/original-3.obj"/>
			</geometry>
		</collision>
	</link>
	<joint name="joint_1" type="revolute">
		<origin xyz="-0.418899131366169 0.8012689999999996 0.3155980612593349"/>
		<axis xyz="0 -1 0"/>
		<child link="link_1"/>
		<parent link="link_0"/>
		<limit lower="0.0" upper="3.141592653589793"/>
	</joint>
	<link name="link_2">
		<visual name="door_frame-10">
			<origin xyz="-0.462520215344883 -0.8252869999999999 -0.2912614481365744"/>
			<geometry>
				<mesh filename="textured_objs/original-2.obj"/>
			</geometry>
		</visual>
		<collision>
			<origin xyz="-0.462520215344883 -0.8252869999999999 -0.2912614481365744"/>
			<geometry>
				<mesh filename="textured_objs/original-2.obj"/>
			</geometry>
		</collision>
	</link>
	<joint name="joint_2" type="revolute">
		<origin xyz="0.462520215344883 0.8252869999999999 0.2912614481365744"/>
		<axis xyz="0 1 0"/>
		<child link="link_2"/>
		<parent link="link_0"/>
		<limit lower="-0.0" upper="3.141592653589793"/>
	</joint>
</robot>
