<?xml version="1.0" ?>
<robot name="partnet_d9560bfc0c051109f54e1b6f41fdd78a">
	<link name="base"/>

	<link name="handle_link">
		<visual name="lid-1">
			<origin xyz="0 -0.05 0"/>
			<geometry>
				<mesh filename="textured_objs/original-8-fix.obj"/>
			</geometry>
			<material name="Transparent">
				<color rgba="1 1 1 0"/>
			</material>
		</visual>
		<collision>
			<origin xyz="0 0 0"/>
			<geometry>
				<mesh filename="textured_objs/original-8-new.obj"/>
			</geometry>
		</collision>
	</link>
	<joint name="handle_joint" type="prismatic">
		<origin xyz="0 0 0"/>
		<axis xyz="0 1 0"/>
		<child link="handle_link"/>
		<parent link="link_0"/>
		<limit lower="0" upper="0.05"/>
	</joint>

	<link name="link_0">
		<visual name="lid-1">
			<origin xyz="0 0 0"/>
			<geometry>
				<mesh filename="textured_objs/original-7-new.obj"/>
			</geometry>
		</visual>
		<visual name="lid-1">
			<origin xyz="0 0 0"/>
			<geometry>
				<mesh filename="textured_objs/original-6-new.obj"/>
			</geometry>
		</visual>
		<collision>
			<origin xyz="0 0 0"/>
			<geometry>
				<mesh filename="textured_objs/original-7-new.obj"/>
			</geometry>
		</collision>
		<collision>
			<origin xyz="0 0 0"/>
			<geometry>
				<mesh filename="textured_objs/original-6-new.obj"/>
			</geometry>
		</collision>
	</link>
	<joint name="joint_1" type="fixed">
		<!-- xyz="0 0 -0.184083333" -->
		<origin rpy="1.570796326794897 0 -1.570796326794897" xyz="0 0 0"/>
		<child link="link_0"/>
		<parent link="base"/>
	</joint>
</robot>
