<?xml version="1.0" ?>
<robot name="partnet_16c930497c0f4f4fde46457697d80">
	<link name="base"/>
	<link name="link_0">
		<visual name="leg-1">
			<origin xyz="0.5313233556592238 -0.09562729674916248 -0.08665791284939792"/>
			<geometry>
				<mesh filename="textured_objs/original-3.obj"/>
			</geometry>
		</visual>
		<collision>
			<origin xyz="0.5313233556592238 -0.09562729674916248 -0.08665791284939792"/>
			<geometry>
				<mesh filename="textured_objs/original-3.obj"/>
			</geometry>
		</collision>
	</link>
	<joint name="joint_0" type="revolute">
		<origin xyz="-0.5313233556592238 0.09562729674916248 0.08665791284939792"/>
		<axis xyz="0 -1 0"/>
		<child link="link_0"/>
		<parent link="link_2"/>
		<limit lower="-0.0" upper="1.482831732494382"/>
	</joint>
	<link name="link_1">
		<visual name="leg-2">
			<origin xyz="-0.5119565685286129 -0.09574199715869147 -0.0891778271179271"/>
			<geometry>
				<mesh filename="textured_objs/original-2.obj"/>
			</geometry>
		</visual>
		<collision>
			<origin xyz="-0.5119565685286129 -0.09574199715869147 -0.0891778271179271"/>
			<geometry>
				<mesh filename="textured_objs/original-2.obj"/>
			</geometry>
		</collision>
	</link>
	<joint name="joint_1" type="revolute">
		<origin xyz="0.5119565685286129 0.09574199715869147 0.0891778271179271"/>
		<axis xyz="0 1 0"/>
		<child link="link_1"/>
		<parent link="link_2"/>
		<limit lower="0.0" upper="1.4639821765728438"/>
	</joint>
	<link name="link_2">
		<visual name="base_body-3">
			<origin xyz="0 0 0"/>
			<geometry>
				<mesh filename="textured_objs/original-1.obj"/>
			</geometry>
		</visual>
		<collision>
			<origin xyz="0 0 0"/>
			<geometry>
				<mesh filename="textured_objs/original-1.obj"/>
			</geometry>
		</collision>
	</link>
	<joint name="joint_2" type="fixed">
		<origin rpy="1.570796326794897 0 -1.570796326794897" xyz="0 0 0"/>
		<child link="link_2"/>
		<parent link="base"/>
	</joint>
</robot>
